Workbook

Sheet แผนรายรับ-รายจ่ายเงินบำรุง 1ปี
A1: สำนักงานสาธารณสุขจังหวัด...ภูเก็ต.....
A2: โรงพยาบาล..วชิระภูเก็ต............
A3: แผนรายรับ - รายจ่ายเงินนอกงบประมาณ (เงินบำรุง) ปีงบประมาณ 2567 : ครึ่งปีหลัง
L4: หน่วย : บาท | P4: หน่วย : บาท
B5: รายการ | F5: ข้อมูลย้อนหลัง 3 ปีงบประมาณ | I5: แผนปี 2567 (เดิม) | J5: รายรับจริง ณ 31 มี.ค.67 | K5: คิดเป็น % | L5: แผนปีงบ 67 ครึ่งปีหลัง | M5: เปรียบเทียบ แผน | N5: ส่วนต่าง (บาท) | O5: ผลดำเนินงาน ไตรมาส 1 (ตค.-ธค.66) | P5: คิดเป็น%
F6: 2564 | G6: 2565 | H6: 2566
B7: รายรับ
C8: รายรับจากการดำเนินงาน
E9: รายรับค่ารักษาพยาบาลสำหรับโครงการสุขภาพถ้วนหน้า UC | F9: 5.3048621e+08 | G9: 7.0859462e+08 | H9: =256205985.2+147863308.35+108660563.33 -> 5.1272986e+08 | I9: =250000000+155000000 -> 405000000 | J9: =150133838.1+113286366.95+3886925.15 -> 2.6730713e+08 | K9: =+J9/I9*100 -> 66.001761 | L9: =+ประมาณการรายรับ!#REF!+ประมาณการรายรับ!#REF! -> #REF! | M9: =+(L9-I9)/I9*100 -> #REF! | N9: =+L9-I9 -> #REF! | O9: =82032759.91+75105825.64 -> 1.5713859e+08 | P9: =+O9/I9*100 -> 38.799651
E10: รายรับค่ารักษาพยาบาลสำหรับโครงการสุขภาพถ้วนหน้า UC งบลงทุน | F10: 19207318 | G10: 19448683 | H10: 17480288 | I10: 17000000 | J10: 0 | K10: =+J10/I10*100 -> 0 | L10: =+ประมาณการรายรับ!#REF! -> #REF! | M10: =+(L10-I10)/I10*100 -> #REF! | N10: =+L10-I10 -> #REF! | O10: 0 | P10: =+O10/I10*100 -> 0
E11: รายรับจากระบบปฏิบัติการฉุกเฉิน (EMS) | F11: 1538817.1 | G11: 1644850 | H11: 1081750 | I11: 1500000 | J11: 1060291.5 | K11: =+J11/I11*100 -> 70.6861 | L11: =+ประมาณการรายรับ!#REF! -> #REF! | M11: =+(L11-I11)/I11*100 -> #REF! | N11: =+L11-I11 -> #REF! | O11: 9754 | P11: =+O11/I11*100 -> 0.65026667
E12: รายรับค่ารักษาพยาบาลเบิกจ่ายตรงกรมบัญชีกลาง | F12: 3.1720271e+08 | G12: 3.5807166e+08 | H12: 3.357539e+08 | I12: 370000000 | J12: 1.8467863e+08 | K12: =+J12/I12*100 -> 49.913143 | L12: =+ประมาณการรายรับ!#REF! -> #REF! | M12: =+(L12-I12)/I12*100 -> #REF! | N12: =+L12-I12 -> #REF! | O12: 91062438 | P12: =+O12/I12*100 -> 24.61147
E13: รายรับค่ารักษาพยาบาลผู้ป่วยเบิกต้นสังกัด | F13: 80308337 | G13: 1.9906833e+08 | H13: 1.133913e+08 | I13: 140000000 | J13: 59921807 | K13: =+J13/I13*100 -> 42.801291 | L13: =+ประมาณการรายรับ!#REF! -> #REF! | M13: =+(L13-I13)/I13*100 -> #REF! | N13: =+L13-I13 -> #REF! | O13: 28464879 | P13: =+O13/I13*100 -> 20.332057
E14: รายรับค่ารักษาพยาบาลเบิกจาก อปท. | F14: 33520000 | G14: 34138823 | H14: 33388979 | I14: 40000000 | J14: 34162534 | K14: =+J14/I14*100 -> 85.406335 | L14: =+ประมาณการรายรับ!#REF! -> #REF! | M14: =+(L14-I14)/I14*100 -> #REF! | N14: =+L14-I14 -> #REF! | O14: 33589841 | P14: =+O14/I14*100 -> 83.974602
E15: รายรับค่ารักษาพยาบาลจากกองทุนประกันสังคม | F15: 3.1977734e+08 | G15: 4.2407996e+08 | H15: =294588801.48+8298890.2 -> 3.0288769e+08 | I15: 340000000 | J15: 2.0541363e+08 | K15: =+J15/I15*100 -> 60.415773 | L15: =+ประมาณการรายรับ!#REF! -> #REF! | M15: =+(L15-I15)/I15*100 -> #REF! | N15: =+L15-I15 -> #REF! | O15: 1.1021905e+08 | P15: =+O15/I15*100 -> 32.417369
E16: รายรับค่ารักษาพยาบาลแรงงานต่างด้าว | F16: 52237457 | G16: 59446164 | H16: 53074741 | I16: 63000000 | J16: 32355625 | K16: =+J16/I16*100 -> 51.358135 | L16: =+ประมาณการรายรับ!#REF! -> #REF! | M16: =+(L16-I16)/I16*100 -> #REF! | N16: =+L16-I16 -> #REF! | O16: 15213105 | P16: =+O16/I16*100 -> 24.147786
E17: รายรับค่ารักษาพยาบาลและการบริการอื่น | F17: 3.0661796e+08 | G17: 3.9388351e+08 | H17: =1774113364.95+152985171.02-(H9+H10+H11+H12+H13+H14+H15+H16)-H21-H22-H23 -> 4.9665033e+08 | I17: =1969000000-(I9+I10+I11+I12+I13+I14+I15+I16)-I21-I22-I23 -> 491000000 | J17: =1615290+215736235.03+20157485.24 -> 2.3750901e+08 | K17: =+J17/I17*100 -> 48.372507 | L17: =+ประมาณการรายรับ!#REF!+ประมาณการรายรับ!#REF!+ประมาณการรายรับ!#REF! -> #REF! | M17: =+(L17-I17)/I17*100 -> #REF! | N17: =+L17-I17 -> #REF! | O17: =104712808.69+9364522.61+764700 -> 1.1484203e+08 | P17: =+O17/I17*100 -> 23.389416
C18: รายรับอื่น
E19: รายรับเงินช่วยเหลือ | F19: 0 | G19: 0 | H19: 0 | I19: 0 | J19: 0 | L19: 0
E20: รายรับเงินอุดหนุน | F20: 0 | G20: 0 | H20: 0 | I20: 0 | J20: 0 | L20: 0
E21: รายรับจากการบริจาค | F21: 24490529 | G21: 23281929 | H21: 39570974 | I21: 80000000 | J21: 33693691 | K21: =+J21/I21*100 -> 42.117114 | L21: =+ประมาณการรายรับ!#REF! -> #REF! | M21: =+(L21-I21)/I21*100 -> #REF! | N21: =+L21-I21 -> #REF! | O21: 20382897 | P21: =+O21/I21*100 -> 25.478621
E22: รายรับดอกเบี้ยเงินฝากธนาคาร | F22: 365997.15 | G22: 706946.53 | H22: 2022594.5 | I22: 1500000 | J22: 1426104.8 | K22: =+J22/I22*100 -> 95.073651 | L22: =+ประมาณการรายรับ!#REF! -> #REF! | M22: =+(L22-I22)/I22*100 -> #REF! | N22: =+L22-I22 -> #REF! | O22: 1240872.2 | P22: =+O22/I22*100 -> 82.724813
E23: รายรับอื่น | F23: =20906672.21-732637 -> 20174035 | G23: 19066650 | H23: 19066136 | I23: 20000000 | J23: 10961292 | K23: =+J23/I23*100 -> 54.806459 | L23: =+ประมาณการรายรับ!#REF! -> #REF! | M23: =+(L23-I23)/I23*100 -> #REF! | N23: =+L23-I23 -> #REF! | O23: 4684540.2 | P23: =+O23/I23*100 -> 23.422701
E24: รวมรายรับ | F24: =SUM(F9:F23) -> 1.7059267e+09 | G24: =SUM(G9:G23) -> 2.2414321e+09 | H24: =SUM(H9:H23) -> 1.9270985e+09 | I24: =SUM(I9:I23) -> 1969000000 | J24: =SUM(J9:J23) -> 1.0684897e+09 | K24: =+J24/I24*100 -> 54.265604 | L24: =SUM(L9:L23) -> #REF! | M24: =+(L24-I24)/I24*100 -> #REF! | O24: =SUM(O9:O23) -> 5.76848e+08 | P24: =+O24/I24*100 -> 29.296496
B25: รายจ่าย
C26: รายจ่ายบุคลากร
E27: ค่าจ้างลูกจ้างชั่วคราว / พนักงานกระทรวง | F27: 1.8053383e+08 | G27: 1.8820402e+08 | H27: 1.8846488e+08 | I27: 195000000 | J27: 94467539 | K27: =+J27/I27*100 -> 48.444892 | L27: =+รายละเอียดรายจ่าย!X5 -> 205000000 | M27: =+(L27-I27)/I27*100 -> 5.1282051 | N27: =+L27-I27 -> 10000000 | O27: 47953471 | P27: =+O27/I27*100 -> 24.591524
E28: ค่าล่วงเวลางานบริการ / งานสนับสนุน | F28: 0 | G28: 0 | H28: 0 | I28: 0 | J28: 0 | L28: 0 | N28: =+L28-I28 -> 0 | P28: 0
E29: ค่าตอบแทนการปฏิบัติงานเวรผลัดบ่ายหรือผลัดดึกของเจ้าหน้าที่ | F29: 31484140 | G29: 30139045 | H29: 26605920 | I29: 30000000 | J29: 29945470 | K29: =+J29/I29*100 -> 99.818233 | L29: 40000000 | M29: =+(L29-I29)/I29*100 -> 33.333333 | N29: =+L29-I29 -> 10000000 | O29: 17331340 | P29: =+O29/I29*100 -> 57.771133
E30: ค่าตอบแทนเงินเพิ่มพิเศษไม่ทำเวชปฏิบัติส่วนตัว หรือปฏิบัติงาน รพ.เอกชน | F30: 1167600 | G30: 10385000 | H30: 10495200 | I30: 10960000 | J30: 5346600 | K30: =+J30/I30*100 -> 48.782847 | L30: =+รายละเอียดรายจ่าย!X111 -> 11136000 | M30: =+(L30-I30)/I30*100 -> 1.6058394 | N30: =+L30-I30 -> 176000 | O30: 2687000 | P30: =+O30/I30*100 -> 24.516423
E31: ค่าตอบแทนเบี้ยเลี้ยงเหมาจ่าย (ฉ.11) | F31: 0 | G31: 0 | H31: 0 | I31: 0 | J31: 0 | L31: 0 | N31: =+L31-I31 -> 0 | P31: 0
E32: ค่าตอบแทนตามผลการปฏิบัติงาน (ฉ.12) | F32: 10193251 | G32: 5202971 | H32: 8605551 | I32: 41200000 | J32: 17747007 | K32: =+J32/I32*100 -> 43.07526 | L32: =+รายละเอียดรายจ่าย!X10 -> 41200000 | M32: =+(L32-I32)/I32*100 -> 0 | N32: =+L32-I32 -> 0 | O32: 17747007 | P32: =+O32/I32*100 -> 43.07526
E33: เงินเพิ่ม (พ.ต.ส) | F33: 0 | G33: 0 | H33: 225000 | I33: 300000 | J33: 0 | K33: =+J33/I33*100 -> 0 | L33: =+รายละเอียดรายจ่าย!X13 -> 300000 | M33: =+(L33-I33)/I33*100 -> 0 | N33: =+L33-I33 -> 0 | O33: 0 | P33: =+O33/I33*100 -> 0
E34: ค่าตอบแทนเจ้าหน้าที่ปฏิบัติงานของเจ้าหน้าที่ (นอกเวลา) ฉ5 | F34: 2.7830997e+08 | G34: =340999774.4-G29-G30 -> 3.0047573e+08 | H34: =367202135.79+10495200-H29-H30 -> 3.4059622e+08 | I34: =432000000+10960000-I29-I30 -> 402000000 | J34: =216192538.77-J29 -> 1.8624707e+08 | K34: =+J34/I34*100 -> 46.330117 | L34: =432000000-L29 -> 392000000 | M34: =+(L34-I34)/I34*100 -> -2.4875622 | N34: =+L34-I34 -> -10000000 | O34: =107757770.55-O29 -> 90426431 | P34: =+O34/I34*100 -> 22.494137
E35: ค่าตอบแทนเจ้าหน้าที่ปฏิบัติงานในคลินิกพิเศษเฉพาะทางนอกเวลาราชการ (SMC)
E36: ค่าตอบแทนอื่น | F36: 709725 | G36: =868400+299500+618600+9852500 -> 11639000 | H36: =555000+295380+1278500 -> 2128880 | I36: =550000+300000+1250000+100000 -> 2200000 | J36: =255000+105500+1035900 -> 1396400 | K36: =+J36/I36*100 -> 63.472727 | L36: =+รายละเอียดรายจ่าย!X8+รายละเอียดรายจ่าย!X11+รายละเอียดรายจ่าย!X12+รายละเอียดรายจ่าย!X15 -> 2200000 | M36: =+(L36-I36)/I36*100 -> 0 | N36: =+L36-I36 -> 0 | O36: =130000+586800+46400 -> 763200 | P36: =+O36/I36*100 -> 34.690909
E37: เงินค่าใช้จ่ายบุคลากรอื่น | F37: 88500 | G37: 223200 | H37: =189000+247200 -> 436200 | I37: =200000+300000 -> 500000 | J37: 66300 | K37: =+J37/I37*100 -> 13.26 | L37: =+รายละเอียดรายจ่าย!X9+รายละเอียดรายจ่าย!X16 -> 500000 | M37: =+(L37-I37)/I37*100 -> 0 | N37: =+L37-I37 -> 0 | O37: 46200 | P37: =+O37/I37*100 -> 9.24
C38: รายจ่ายจากการดำเนินงาน
E39: ค่ายา | F39: 3.8156834e+08 | G39: 4.0278395e+08 | H39: 4.2364677e+08 | I39: =410000000+12000000 -> 422000000 | J39: 2.2344687e+08 | K39: =+J39/I39*100 -> 52.949496 | L39: =+รายละเอียดรายจ่าย!X136 -> 480000000 | M39: =+(L39-I39)/I39*100 -> 13.744076 | N39: =+L39-I39 -> 58000000 | O39: 1.1382866e+08 | P39: =+O39/I39*100 -> 26.973616
E40: ค่าเวชภัณฑ์มิใช่ยา
...

Sheet แผนรายรับ-รายจ่ายเงินบำรุง 3 ปี
A1: สำนักงานสาธารณสุขจังหวัด...ภูเก็ต.....
A2: โรงพยาบาล..วชิระภูเก็ต............
A3: แผนรายรับ - รายจ่ายเงินนอกงบประมาณ (เงินบำรุง) ปีงบประมาณ 2567 -2569
O4: หน่วย : บาท | Q4: หน่วย : บาท
B5: รายการ | F5: ข้อมูลย้อนหลัง 3 ปีงบประมาณ | I5: แผนปี 2567 (เดิม) | J5: รายรับจริง ณ 31 มี.ค.67 | K5: คิดเป็น % | L5: แผนครึ่งปีหลัง ปีงบ 67 | M5: เปรียบเทียบ แผน | N5: แผนปี 2568 | O5: แผนปี 2569 | P5: ผลดำเนินงาน ไตรมาส 1 (ตค.-ธค.66) | Q5: คิดเป็น%
F6: 2564 | G6: 2565 | H6: 2566
B7: รายรับ
C8: รายรับจากการดำเนินงาน
E9: รายรับค่ารักษาพยาบาลสำหรับโครงการสุขภาพถ้วนหน้า UC | F9: 5.3048621e+08 | G9: 7.0859462e+08 | H9: =256205985.2+147863308.35+108660563.33 -> 5.1272986e+08 | I9: =250000000+155000000 -> 405000000 | J9: =150133838.1+113286366.95+3886925.15 -> 2.6730713e+08 | K9: =+J9/I9*100 -> 66.001761 | L9: =+ประมาณการรายรับ!#REF!+ประมาณการรายรับ!#REF! -> #REF! | M9: =+(L9-I9)/I9*100 -> #REF! | N9: 420250000 | O9: 462275000 | P9: =82032759.91+75105825.64 -> 1.5713859e+08 | Q9: =+P9/I9*100 -> 38.799651
E10: รายรับค่ารักษาพยาบาลสำหรับโครงการสุขภาพถ้วนหน้า UC งบลงทุน | F10: 19207318 | G10: 19448683 | H10: 17480288 | I10: 17000000 | J10: 0 | K10: =+J10/I10*100 -> 0 | L10: =+ประมาณการรายรับ!#REF! -> #REF! | M10: =+(L10-I10)/I10*100 -> #REF! | N10: =+I10 -> 17000000 | O10: 18000000 | P10: 0 | Q10: =+P10/I10*100 -> 0
E11: รายรับจากระบบปฏิบัติการฉุกเฉิน (EMS) | F11: 1538817.1 | G11: 1644850 | H11: 1081750 | I11: 1500000 | J11: 1060291.5 | K11: =+J11/I11*100 -> 70.6861 | L11: =+ประมาณการรายรับ!#REF! -> #REF! | M11: =+(L11-I11)/I11*100 -> #REF! | N11: 1500000 | O11: 1500000 | P11: 9754 | Q11: =+P11/I11*100 -> 0.65026667
E12: รายรับค่ารักษาพยาบาลเบิกจ่ายตรงกรมบัญชีกลาง | F12: 3.1720271e+08 | G12: 3.5807166e+08 | H12: 3.357539e+08 | I12: 370000000 | J12: 1.8467863e+08 | K12: =+J12/I12*100 -> 49.913143 | L12: =+ประมาณการรายรับ!#REF! -> #REF! | M12: =+(L12-I12)/I12*100 -> #REF! | N12: 370000000 | O12: 370000000 | P12: 91062438 | Q12: =+P12/I12*100 -> 24.61147
E13: รายรับค่ารักษาพยาบาลผู้ป่วยเบิกต้นสังกัด | F13: 80308337 | G13: 1.9906833e+08 | H13: 1.133913e+08 | I13: 140000000 | J13: 59921807 | K13: =+J13/I13*100 -> 42.801291 | L13: =+ประมาณการรายรับ!#REF! -> #REF! | M13: =+(L13-I13)/I13*100 -> #REF! | N13: 140000000 | O13: 140000000 | P13: 28464879 | Q13: =+P13/I13*100 -> 20.332057
E14: รายรับค่ารักษาพยาบาลเบิกจาก อปท. | F14: 33520000 | G14: 34138823 | H14: 33388979 | I14: 40000000 | J14: 34162534 | K14: =+J14/I14*100 -> 85.406335 | L14: =+ประมาณการรายรับ!#REF! -> #REF! | M14: =+(L14-I14)/I14*100 -> #REF! | N14: 40000000 | O14: 40000000 | P14: 33589841 | Q14: =+P14/I14*100 -> 83.974602
E15: รายรับค่ารักษาพยาบาลจากกองทุนประกันสังคม | F15: 3.1977734e+08 | G15: 4.2407996e+08 | H15: =294588801.48+8298890.2 -> 3.0288769e+08 | I15: 340000000 | J15: 2.0541363e+08 | K15: =+J15/I15*100 -> 60.415773 | L15: =+ประมาณการรายรับ!#REF! -> #REF! | M15: =+(L15-I15)/I15*100 -> #REF! | N15: 357000000 | O15: 382000000 | P15: 1.1021905e+08 | Q15: =+P15/I15*100 -> 32.417369
E16: รายรับค่ารักษาพยาบาลแรงงานต่างด้าว | F16: 52237457 | G16: 59446164 | H16: 53074741 | I16: 63000000 | J16: 32355625 | K16: =+J16/I16*100 -> 51.358135 | L16: =+ประมาณการรายรับ!#REF! -> #REF! | M16: =+(L16-I16)/I16*100 -> #REF! | N16: 64890000 | O16: 66836700 | P16: 15213105 | Q16: =+P16/I16*100 -> 24.147786
E17: รายรับค่ารักษาพยาบาลและการบริการอื่น | F17: 3.0661796e+08 | G17: 3.9388351e+08 | H17: =1774113364.95+152985171.02-(H9+H10+H11+H12+H13+H14+H15+H16)-H21-H22-H23 -> 4.9665033e+08 | I17: =1969000000-(I9+I10+I11+I12+I13+I14+I15+I16)-I21-I22-I23 -> 491000000 | J17: =1615290+215736235.03+20157485.24 -> 2.3750901e+08 | K17: =+J17/I17*100 -> 48.372507 | L17: =+ประมาณการรายรับ!#REF!+ประมาณการรายรับ!#REF!+ประมาณการรายรับ!#REF! -> #REF! | M17: =+(L17-I17)/I17*100 -> #REF! | N17: 490000000 | O17: 490000000 | P17: =104712808.69+9364522.61+764700 -> 1.1484203e+08 | Q17: =+P17/I17*100 -> 23.389416
C18: รายรับอื่น
E19: รายรับเงินช่วยเหลือ | F19: 0 | G19: 0 | H19: 0 | I19: 0 | J19: 0 | L19: 0 | N19: 0 | O19: 0
E20: รายรับเงินอุดหนุน | F20: 0 | G20: 0 | H20: 0 | I20: 0 | J20: 0 | L20: 0 | N20: 0 | O20: 0
E21: รายรับจากการบริจาค | F21: 24490529 | G21: 23281929 | H21: 39570974 | I21: 80000000 | J21: 33693691 | K21: =+J21/I21*100 -> 42.117114 | L21: =+ประมาณการรายรับ!#REF! -> #REF! | M21: =+(L21-I21)/I21*100 -> #REF! | N21: 80000000 | O21: 80000000 | P21: 20382897 | Q21: =+P21/I21*100 -> 25.478621
E22: รายรับดอกเบี้ยเงินฝากธนาคาร | F22: 365997.15 | G22: 706946.53 | H22: 2022594.5 | I22: 1500000 | J22: 1426104.8 | K22: =+J22/I22*100 -> 95.073651 | L22: =+ประมาณการรายรับ!#REF! -> #REF! | M22: =+(L22-I22)/I22*100 -> #REF! | N22: 1000000 | O22: =+N22 -> 1000000 | P22: 1240872.2 | Q22: =+P22/I22*100 -> 82.724813
E23: รายรับอื่น | F23: =20906672.21-732637 -> 20174035 | G23: 19066650 | H23: 19066136 | I23: 20000000 | J23: 10961292 | K23: =+J23/I23*100 -> 54.806459 | L23: =+ประมาณการรายรับ!#REF! -> #REF! | M23: =+(L23-I23)/I23*100 -> #REF! | N23: 20000000 | O23: 20000000 | P23: 4684540.2 | Q23: =+P23/I23*100 -> 23.422701
E24: รวมรายรับ | F24: =SUM(F9:F23) -> 1.7059267e+09 | G24: =SUM(G9:G23) -> 2.2414321e+09 | H24: =SUM(H9:H23) -> 1.9270985e+09 | I24: =SUM(I9:I23) -> 1969000000 | J24: =SUM(J9:J23) -> 1.0684897e+09 | K24: =+J24/I24*100 -> 54.265604 | L24: =SUM(L9:L23) -> #REF! | M24: =+(L24-I24)/I24*100 -> #REF! | N24: =SUM(N9:N23) -> 2001640000 | O24: =SUM(O9:O23) -> 2071611700 | P24: =SUM(P9:P23) -> 5.76848e+08 | Q24: =+P24/I24*100 -> 29.296496
B25: รายจ่าย
C26: รายจ่ายบุคลากร
E27: ค่าจ้างลูกจ้างชั่วคราว / พนักงานกระทรวง | F27: 1.8053383e+08 | G27: 1.8820402e+08 | H27: 1.8846488e+08 | I27: 195000000 | J27: 94467539 | K27: =+J27/I27*100 -> 48.444892 | L27: =+รายละเอียดรายจ่าย!X5 -> 205000000 | M27: =+(L27-I27)/I27*100 -> 5.1282051 | N27: =+I27*0.04+I27 -> 202800000 | O27: =+N27*0.04+N27 -> 210912000 | P27: 47953471 | Q27: =+P27/I27*100 -> 24.591524
E28: ค่าล่วงเวลางานบริการ / งานสนับสนุน | F28: 0 | G28: 0 | H28: 0 | I28: 0 | J28: 0 | L28: 0 | N28: 0 | O28: 0 | Q28: 0
E29: ค่าตอบแทนการปฏิบัติงานเวรผลัดบ่ายหรือผลัดดึกของเจ้าหน้าที่ | F29: 31484140 | G29: 30139045 | H29: 26605920 | I29: 30000000 | J29: 29945470 | K29: =+J29/I29*100 -> 99.818233 | L29: 40000000 | M29: =+(L29-I29)/I29*100 -> 33.333333 | N29: 30000000 | O29: 30000000 | P29: 17331340 | Q29: =+P29/I29*100 -> 57.771133
E30: ค่าตอบแทนเงินเพิ่มพิเศษไม่ทำเวชปฏิบัติส่วนตัว หรือปฏิบัติงาน รพ.เอกชน | F30: 1167600 | G30: 10385000 | H30: 10495200 | I30: 10960000 | J30: 5346600 | K30: =+J30/I30*100 -> 48.782847 | L30: =+รายละเอียดรายจ่าย!X111 -> 11136000 | M30: =+(L30-I30)/I30*100 -> 1.6058394 | N30: 11000000 | O30: =+N30 -> 11000000 | P30: 2687000 | Q30: =+P30/I30*100 -> 24.516423
E31: ค่าตอบแทนเบี้ยเลี้ยงเหมาจ่าย (ฉ.11) | F31: 0 | G31: 0 | H31: 0 | I31: 0 | J31: 0 | L31: 0 | N31: 0 | O31: 0 | Q31: 0
E32: ค่าตอบแทนตามผลการปฏิบัติงาน (ฉ.12) | F32: 10193251 | G32: 5202971 | H32: 8605551 | I32: 41200000 | J32: 17747007 | K32: =+J32/I32*100 -> 43.07526 | L32: =+รายละเอียดรายจ่าย!X10 -> 41200000 | M32: =+(L32-I32)/I32*100 -> 0 | N32: =+I32 -> 41200000 | O32: =+N32 -> 41200000 | P32: 17747007 | Q32: =+P32/I32*100 -> 43.07526
E33: เงินเพิ่ม (พ.ต.ส) | F33: 0 | G33: 0 | H33: 225000 | I33: 300000 | J33: 0 | K33: =+J33/I33*100 -> 0 | L33: =+รายละเอียดรายจ่าย!X13 -> 300000 | M33: =+(L33-I33)/I33*100 -> 0 | N33: =+I33 -> 300000 | O33: =+N33 -> 300000 | P33: 0 | Q33: =+P33/I33*100 -> 0
E34: ค่าตอบแทนเจ้าหน้าที่ปฏิบัติงานของเจ้าหน้าที่ (นอกเวลา) ฉ5 | F34: 2.7830997e+08 | G34: =340999774.4-G29-G30 -> 3.0047573e+08 | H34: =367202135.79+10495200-H29-H30 -> 3.4059622e+08 | I34: =432000000+10960000-I29-I30 -> 402000000 | J34: =216192538.77-J29 -> 1.8624707e+08 | K34: =+J34/I34*100 -> 46.330117 | L34: =432000000-L29 -> 392000000 | M34: =+(L34-I34)/I34*100 -> -2.4875622 | N34: 402000000 | O34: 402000000 | P34: =107757770.55-P29 -> 90426431 | Q34: =+P34/I34*100 -> 22.494137
E35: ค่าตอบแทนเจ้าหน้าที่ปฏิบัติงานในคลินิกพิเศษเฉพาะทางนอกเวลาราชการ (SMC)
E36: ค่าตอบแทนอื่น | F36: 709725 | G36: =868400+299500+618600+9852500 -> 11639000 | H36: =555000+295380+1278500 -> 2128880 | I36: =550000+300000+1250000+100000 -> 2200000 | J36: =255000+105500+1035900 -> 1396400 | K36: =+J36/I36*100 -> 63.472727 | L36: =+รายละเอียดรายจ่าย!X8+รายละเอียดรายจ่าย!X11+รายละเอียดรายจ่าย!X12+รายละเอียดรายจ่าย!X15 -> 2200000 | M36: =+(L36-I36)/I36*100 -> 0 | N36: 2000000 | O36: 2000000 | P36: =130000+586800+46400 -> 763200 | Q36: =+P36/I36*100 -> 34.690909
E37: เงินค่าใช้จ่ายบุคลากรอื่น | F37: 88500 | G37: 223200 | H37: =189000+247200 -> 436200 | I37: =200000+300000 -> 500000 | J37: 66300 | K37: =+J37/I37*100 -> 13.26 | L37: =+รายละเอียดรายจ่าย!X9+รายละเอียดรายจ่าย!X16 -> 500000 | M37: =+(L37-I37)/I37*100 -> 0 | N37: 500000 | O37: 500000 | P37: 46200 | Q37: =+P37/I37*100 -> 9.24
C38: รายจ่ายจากการดำเนินงาน
E39: ค่ายา | F39: 3.8156834e+08 | G39: 4.0278395e+08 | H39: 4.2364677e+08 | I39: =410000000+12000000 -> 422000000 | J39: 2.2344687e+08 | K39: =+J39/I39*100 -> 52.949496 | L39: =+รายละเอียดรายจ่าย!X136 -> 480000000 | M39: =+(L39-I39)/I39*100 -> 13.744076 | N39: =438000000+13000000 -> 451000000 | O39: =470000000+14000000 -> 484000000 | P39: 1.1382866e+08 | Q39: =+P39/I39*100 -> 26.973616
E40: ค่าเวชภัณฑ์มิใช่ยา
...

Sheet สรุป รับ-จ่าย
A2: สรุปแผนรายรับ - รายจ่ายเงินบำรุง โรงพยาบาลวชิระภูเก็ต ประจำปีงบประมาณ พ.ศ. 2569
A4: รายการ | C4: จำนวนเงิน (บาท) | D4: หมายเหตุ
A5: 1. เงินบำรุง คงเหลือ 31 มีนาคม 2569 | D5: (หนี้ค้าง .................................... บาท + หนี้ยังไม่ได้รับ................................ บาท)
A6: 2. ประมาณการรายรับ ปีงบประมาณ 2569
A7: 3. รวมเงินบำรุง คงเหลือ ปีงบประมาณ 2569
A8: 4. ประมาณการรายจ่าย ปีงบประมาณ 2569
A9: 5. เงินบำรุง คงเหลือสุทธิ ปีงบประมาณ 2569

Sheet ประมาณการรายรับ
B1: รายรับเงินบำรุง ปีงบประมาณ 2566 - 2569 ณ เดือนมีนาคม และแผนประมาณการรายรับเงินบำรุง (ปรับแผน) ปีงบประมาณ 2569
B3: รายการ | C3: รายรับ ปี 2562 | D3: รายรับ ปี 2563 | E3: ประมาณการ รายรับ ปีงบฯ 2564 | F3: รายรับจริง ปี 2564 | G3: ประมาณการ รายรับ ปีงบฯ 2565 | H3: รายรับจริง ปี 2565 | J3: รายรับจริง ปี 2566 | L3: รายรับจริง ปี 2567 | N3: รายรับจริง ปี 2568 | O3: ประมาณการ แผนรายรับ ปีงบฯ 2569 | P3: หมายเหตุ
H4: non COVID (บาท) | I4: Covid (บาท) | J4: non COVID (บาท) | K4: Covid (บาท) | L4: non COVID (บาท) | M4: Covid (บาท) | Q4: 244256
B5: รายรับเบิกจากคลัง | C5: 2.7556507e+08 | D5: 2.2249054e+08 | E5: 290000000 | F5: 3.1720271e+08 | G5: 320000000 | R5: เพิ่มการรักษาสวนหัวใจไม่ส่งเอกชน ทบทวน DRG
B6: รายรับจากบริษัท,ห้างร้าน +ต้นสังกัด | C6: 1.2298185e+08 | D6: 1.2201365e+08 | E6: 120000000 | F6: 80308337 | G6: 180000000
B7: รายรับประกันใน - ต่างประเทศ
B8: รายรับ อปท. | F8: 33520000 | G8: 40000000
B9: รายรับ EMS | F9: 0
B10: ค่าธรรมเนียม 30 บาท | C10: 2595940 | D10: 2276789 | E10: 2000000 | F10: 2539830 | G10: 2800000
B11: ชำระเงินเอง (เงินสด + บัตรเครดิต) | C11: 2.8339581e+08 | D11: 2.757587e+08 | E11: 260000000 | F11: 2.7317702e+08 | G11: 280000000 | Q11: ต่างด้าว 51 ลบ.ต่างชาติ 90 ลบ.
B12: บัตรทอง(เหมาจ่าย) (OP+IP+PP) | C12: 2.8980271e+08 | D12: 2.9215961e+08 | E12: 257000000 | F12: 3.3194291e+08 | G12: 220000000 | Q12: 300000000
B13: บัตรทอง (CENTRAL REIMBURSE+ กองทุนต่างๆ+covid) | C13: 1.1768747e+08 | D13: 1.6613675e+08 | E13: 140000000 | F13: 1.985433e+08 | G13: 538000000
B14: ปกส. | C14: 3.9315588e+08 | D14: 3.6928577e+08 | E14: 300000000 | F14: 3.1977734e+08 | G14: 3.8512584e+08 | Q14: ผู้ประกันตน 121000 คน*1808 บาท | R14: คลอดผู้ประกันตนสิทธิ์ประกันสังคมเหมาจ่าย 13000 บาท
B15: พรบ. | C15: 48600771 | D15: 45977565 | E15: 37500000 | F15: 30901117 | G15: 25000000
B16: แรงงานต่างด้าว (กองทุนประกัน+ค่าตรวจ+ เรียกเก็บส่วนกลาง) | C16: 1.2218258e+08 | D16: 78226878 | E16: 50000000 | F16: 52237457 | G16: 52000000 | Q16: ยอดเรียกเก็บ 12ลบ.
B17: ดอกเบี้ยเงินฝากธนาคาร | C17: 424009.91 | D17: 374208.25 | E17: 300000 | F17: 365997.15 | G17: 350000
B18: งบลงทุน uc | C18: 21853803 | D18: 20101135 | E18: 19207318 | F18: 19207318 | G18: 19448683 | Q18: 70% = 17,146,016.19 10%= 5,450,000
B19: เบ็ดเตล็ด (ค่าจอดรถ + ค่าไฟเก็บจาก จนท.พยาบาล +ค่าใบรับรองแพทย์ต่างด้าว+ค่าใช้จ่ายโครงการต่างๆ) | C19: 22213083 | D19: 30480313 | E19: 22000000 | F19: 20906672 | G19: 20000000
B20: เงินบริจาค | C20: - | D20: - | F20: - | G20: -
B21: รวมเงิน | C21: =SUM(C5:C19) -> 1.700459e+09 | D21: =SUM(D5:D19) -> 1.6252819e+09 | E21: =SUM(E5:E20) -> 1.4980073e+09 | F21: =SUM(F5:F19) -> 1.68063e+09 | G21: =SUM(G5:G19) -> 2.0827245e+09 | H21: =SUM(H5:H20) -> 0 | I21: =SUM(I5:I19) -> 0 | J21: =SUM(J5:J20) -> 0 | K21: =SUM(K5:K20) -> 0 | L21: =SUM(L5:L20) -> 0 | M21: =SUM(M5:M20) -> 0 | N21: =SUM(N5:N20) -> 0
B22: กรณีไม่รวมเงินบริจาค | H22: =+H21+I21 -> 0 | J22: =+J21+K21 -> 0 | L22: =+L21+M21 -> 0 | N22: =+N21-N20 -> 0
E23: 64 | F23: =+F21/E21*100 -> 112.19104 | H23: =+H21+I21 -> 0 | J23: =+J21+K21 -> 0 | L23: =+L21+M21 -> 0 | N23: เงินลงทุนได้
E24: 65 | F24: =+H21/G21*100 -> 0 | N24: EBITDA 20%
E25: 66 | F25: =+J21/#REF!*100 -> #REF!
E26: 67 | F26: =+L21/#REF!*100 -> #REF!

Sheet ประมาณการรายจ่าย
B1: รายจ่ายเงินบำรุง ปีงบประมาณ 2566 - 2569 ณ เดือนมีนาคม และประมาณการแผนรายจ่ายเงินบำรุง (ปรับแผน) ปีงบประมาณ 2569
B3: รายการ | C3: รายจ่ายจริง ปี 2566 | D3: รายจ่ายจริง ปี 2567 | E3: รายจ่ายจริง ปี 2568 | F3: ประมาณการ แผนรายจ่าย (ปรับแผน) ปีงบฯ 2569 | G3: เปรียบเทียบไตรมาส1 กับไตรมาส 2 | H3: เพิ่มขึ้น ร้อยละ | I3: หมายเหตุ
B5: ค่าจ้างชั่วคราว | K5: =+(D5-#REF!)*100/#REF! -> #REF! | L5: =+(#REF!-D5)*100/D5 -> #REF!
B6: ค่าตอบแทน | K6: =+(D6-#REF!)*100/#REF! -> #REF! | L6: =+(#REF!-D6)*100/D6 -> #REF!
B7: ค่าใช้สอย | K7: =+(D7-#REF!)*100/#REF! -> #REF! | L7: =+(#REF!-D7)*100/D7 -> #REF!
B8: ค่าสาธารณูปโภค | K8: =+(D8-#REF!)*100/#REF! -> #REF! | L8: =+(#REF!-D8)*100/D8 -> #REF!
B9: ค่าวัสดุ | K9: =+(D9-#REF!)*100/#REF! -> #REF! | L9: =+(#REF!-D9)*100/D9 -> #REF!
B10: ครุภัณฑ์ | K10: =+(D10-#REF!)*100/#REF! -> #REF! | L10: =+(#REF!-D10)*100/D10 -> #REF!
B11: ค่าที่ดินและสิ่งก่อสร้าง | J11: จ่ายค่าทางเดินเชื่อมตึกอันดามันไปอาคารอุบัติเหตุ 10 ชั้น ค่าอาคารรังสีรักษา = 41,982,193.76 บาท | K11: =+(D11-#REF!)*100/#REF! -> #REF! | L11: =+(#REF!-D11)*100/D11 -> #REF!
B12: เงินอุดหนุน (ไม่ปฏิบัติเวช) | K12: =+(D12-#REF!)*100/#REF! -> #REF! | L12: =+(#REF!-D12)*100/D12 -> #REF!
B13: รายจ่ายอื่นๆ | J13: จ่ายสนับสนุน สสจ.สุราษฎร์ธานี = 600,000 บาท จ่ายสนับสนุนรพ.บ้านนาสาร = 2,800,000 บาท จ่ายสนับสนุนสสจ.ระนอง = 2,600,000 บาท | K13: =+(D13-#REF!)*100/#REF! -> #REF! | L13: =+(#REF!-D13)*100/D13 -> #REF!
B14: งบบริหารจัดการ 2.5% | K14: =+(D14-#REF!)*100/#REF! -> #REF! | L14: =+(#REF!-D14)*100/D14 -> #REF!
B15: =+รายละเอียดรายจ่าย!B200 -> งบบริหารจัดการแรงงานต่างด้าว | K15: =+(D15-#REF!)*100/#REF! -> #REF! | L15: =+(#REF!-D15)*100/D15 -> #REF!
B16: งบกลาง | K16: =+(D16-#REF!)*100/#REF! -> #REF! | L16: =+(#REF!-D16)*100/D16 -> #REF!
B17: รวม
B19: 64
B20: 65
B21: 66
B22: 67

Sheet ครุภัณฑ์ แผน 68
A1: แผนรายจ่ายรายการครุภัณฑ์ เงินบำรุง (ครึ่งปีหลัง) ประจำปีงบประมาณ พ.ศ. 2568
A2: ลำดับ | B2: รายการ | C2: จำนวน (หน่วย) | D2: จำนวน (บาท/หน่วย) | E2: วงเงิน งบประมาณ (บาท) | F2: หน่วยงาน | G2: ประเภทครุภัณฑ์ | H2: หมายเหตุ
A3: 1 | B3: สถานีและขยายเส้นทางระบบท่อลมรับ-ส่งพัสดุทางการแพทย์ จำนวน 1 ระบบ (2 สถานี) | C3: 1 | D3: 2247000 | E3: =C3*D3 -> 2247000 | F3: เภสัชกรรม | G3: การแพทย์ | H3: 14.เบิกจ่ายแล้ว | J3: ปี 2568
A4: 2 | B4: เครื่องดมยาพร้อมเครื่องช่วยหายใจพร้อมเครื่องติดตามสัญญาณชีพ | C4: 1 | D4: 2200000 | E4: =C4*D4 -> 2200000 | F4: กลุ่มงาน สูติ-นรีเวชกรรม | G4: การแพทย์ | H4: 14.เบิกจ่ายแล้ว | J4: ปี 2568
A5: 3 | B5: เตียงผ่าตัดทั่วไประบบไฟฟ้า | C5: 1 | D5: 1760000 | E5: =C5*D5 -> 1760000 | F5: กลุ่มงาน สูติ-นรีเวชกรรม | G5: การแพทย์ | H5: =+H4 -> 14.เบิกจ่ายแล้ว
A6: 4 | B6: โคมไฟผ่าตัดใหญ่ | C6: 1 | D6: 1450000 | E6: =C6*D6 -> 1450000 | F6: กลุ่มงาน สูติ-นรีเวชกรรม | G6: การแพทย์ | H6: =+H5 -> 14.เบิกจ่ายแล้ว | J6: ปี 2569
A7: 5 | B7: เครื่องจี้ห้ามเลือด เลาะเนื้อเยื่อ และเชื่อมปิดหลอดเลือดด้วยคลื่นความถี่สูง | C7: 1 | D7: 1600000 | E7: =C7*D7 -> 1600000 | F7: งานห้องผ่าตัด | G7: การแพทย์ | H7: ให้ใช้เครื่องที่ได้จากงบกองสลาก | J7: ปี 2569
A8: 6 | B8: กล้องส่องตรวจช่องท้องชนิดวิดีทัศน์ ขนาด 10 มม มุมมองภาพ 30 องศา | C8: 1 | D8: 1250000 | E8: 1250000 | F8: ห้องผ่าตัด | G8: การแพทย์ | H8: 10.ระยะเวลาอุทธรณ์ผลการพิจารณา
A9: 7 | B9: เลนส์สำหรับผ่าตัดผ่านกล้องในช่องท้องชนิดวิดีทัศน์ 10 มม 30 องศา | C9: 1 | D9: 1250000 | E9: 1250000 | F9: ห้องผ่าตัด | G9: การแพทย์ | H9: 13.ส่งมอบ/รายงานผลตรวจรับ
A10: 8 | B10: Removal of Ethylene oxide by catalytic system (เครื่องระบายแก๊สเอทธิลีนออกไซด์ด้วยระบบการเร่งปฏิกิริยา) | C10: 1 | D10: 1200000 | E10: =C10*D10 -> 1200000 | F10: งานจ่ายกลาง | G10: การแพทย์ | H10: =+H6 -> 14.เบิกจ่ายแล้ว
A11: 9 | B11: เครื่อง High flow oxygen | C11: 2 | D11: 250000 | E11: =C11*D11 -> 500000 | F11: Sick newborn (1/2) | G11: การแพทย์ | H11: 9.รายงานผลการพิจารณาเสนอราคา
A12: 10 | B12: ระบบเรียกพยาบาล Nurse call System | C12: 1 | D12: 499476 | E12: =C12*D12 -> 499476 | F12: หอผู้ป่วยศัลยกรรมกระดูก | G12: การแพทย์
A13: 11 | B13: เครื่องช่วยหายใจชนิดไม่สอดใส่ | C13: 1 | D13: 490000 | E13: =C13*D13 -> 490000 | F13: NICU (2/2) | G13: การแพทย์ | H13: =+H11 -> 9.รายงานผลการพิจารณาเสนอราคา
A14: 12 | B14: เครื่องให้ความอบอุ่นทารกแรกเกิด | C14: 2 | D14: 225000 | E14: =C14*D14 -> 450000 | F14: NICU | G14: การแพทย์ | H14: =+H13 -> 9.รายงานผลการพิจารณาเสนอราคา
A15: 13 | B15: ชุดภาควัดสัญญาณชีพขณะเคลื่อนย้าย | C15: 1 | D15: 330000 | E15: 330000 | F15: ไตเทียม | G15: การแพทย์ | H15: =+H148 -> 12.ครบกำหนดส่งมอบ
A16: 14 | B16: เครื่องกระตุกหัวใจด้วยไฟฟ้า | C16: 1 | D16: 330000 | E16: =C16*D16 -> 330000 | F16: หอผู้ป่วยหนักอายุรกรรม | G16: การแพทย์ | H16: =+H15 -> 12.ครบกำหนดส่งมอบ
A17: 15 | B17: เครื่องผลิตสุญญากาศทางการแพทย์ Vacuum Pump สงฆ์อาพาธ | C17: 1 | D17: 317255 | E17: 317255 | F17: งานช่าง | G17: การแพทย์ | H17: =+H16 -> 12.ครบกำหนดส่งมอบ
A18: 16 | B18: เครื่องติดตามการทำงานของหัวใจและสัญญาณชีพอัตโนมัติ | C18: 1 | D18: 250000 | E18: =C18*D18 -> 250000 | F18: ศูนย์เครื่องมือแพทย์ | G18: การแพทย์ | H18: =+H17 -> 12.ครบกำหนดส่งมอบ
A19: 17 | B19: เครื่องควบคุมระบบประกาศ | C19: 1 | D19: 229729 | E19: =C19*D19 -> 229729 | F19: ประชาสัมพันธ์ | G19: การแพทย์ | H19: =+H18 -> 12.ครบกำหนดส่งมอบ
A20: 18 | B20: ฉากกั้นรังสีแบบใส | C20: 2 | D20: 117500 | E20: =+C20*D20 -> 235000 | F20: cath lab (0/2) | G20: การแพทย์ | H20: =+H19 -> 12.ครบกำหนดส่งมอบ
A21: 19 | B21: เครื่องดึงคอและหลังอัตโนมัติพร้อมเตียง | C21: 1 | D21: 230000 | E21: 230000 | F21: กล่มงานเวชกรรมฟื้นฟู | G21: การแพทย์ | H21: =+H20 -> 12.ครบกำหนดส่งมอบ
A22: 20 | B22: ระบบ Nurse Call อาคารหลวงพ่อแช่ม ชั้น5 | C22: 1 | D22: 200000 | E22: =+C22*D22 -> 200000 | F22: หอผู้ป่วยศัลยกรรมกระดูก (หลวงพ่อแช่ม ชั้น 5) | G22: การแพทย์ | H22: =+H21 -> 12.ครบกำหนดส่งมอบ
A23: 21 | B23: เครื่องติดตามสัญญาณชีพห้องพักฟื้น | C23: 1 | D23: 200000 | E23: =C23*D23 -> 200000 | F23: กลุ่มงาน สูติ-นรีเวชกรรม | G23: การแพทย์ | H23: 2.แต่งตั้งคณะกรรมการกำหนดราคา
A24: 22 | B24: ตัว incubator เก็บน้ำเชื้อ สำหรับทำ sperm | C24: 1 | D24: 200000 | E24: =C24*D24 -> 200000 | F24: กลุ่มงาน สูติ-นรีเวชกรรม | G24: การแพทย์
A25: 23 | B25: อุปกรณ์เจาะชิ้นเนื้อเต้านม (Magnum biopsy) | C25: 2 | D25: 100000 | E25: =C25*D25 -> 200000 | F25: รังสีวิทยา | G25: การแพทย์ | H25: ดำเนินการแล้ว
A26: 24 | B26: เครื่อง Centrifuge สำหรับทำ sperm | C26: 1 | D26: 400000 | E26: =C26*D26 -> 400000 | F26: กลุ่มงาน สูติ-นรีเวชกรรม | G26: การแพทย์
A27: 25 | B27: เครื่อง warm สำหรับทำ sperm | C27: 1 | D27: 100000 | E27: =C27*D27 -> 100000 | F27: กลุ่มงาน สูติ-นรีเวชกรรม | G27: การแพทย์
A28: 26 | B28: เครื่องวัดความดันโลหิตอัตโนมัติชนิดสอดแขนพร้อมรถเข็นขาตั้งครบชุด | C28: 1 | D28: 65000 | E28: =C28*D28 -> 65000 | F28: กลุ่มการพยาบาล Echo(0/1) | G28: การแพทย์ | H28: =+H22 -> 12.ครบกำหนดส่งมอบ
A29: 27 | B29: เครื่องวัดความดันโลหิตแบบอัตโนมัติ | C29: 1 | D29: 65000 | E29: =C29*D29 -> 65000 | F29: OPD กุมารเวช | G29: การแพทย์
A30: 28 | B30: เครื่องอบอุ่นร่างกายชนิดเป่าลมร้อน | C30: 1 | D30: 50000 | E30: =+C30*D30 -> 50000 | F30: กลุ่มงานสูติ-นรีเวชกรรม | G30: การแพทย์
A31: 29 | B31: Laryngoscope ชนิดหลอด LED | C31: 1 | D31: 40000 | E31: =+C31*D31 -> 40000 | F31: กลุ่มงานสูติ-นรีเวชกรรม | G31: การแพทย์
A32: 30 | B32: อุปกรณ์-วัสดุ กระตุ้นพัฒนาการเด็ก | C32: 1 | D32: 31849 | E32: =C32*D32 -> 31849 | F32: จิตเวชและยาเสพติด | G32: การแพทย์
A33: 31 | B33: โต๊ะจัดเครื่องมือ | C33: 2 | D33: 9500 | E33: =+C33*D33 -> 19000 | F33: กลุ่มงานสูติ-นรีเวชกรรม | G33: การแพทย์
A34: 32 | B34: เกย์ออกซิเจน อัตราการไหลต่ำ (low flow) | C34: 10 | D34: 5500 | E34: =C34*D34 -> 55000 | F34: กลุ่มการพยาบาล (NICU 3 กุมาร 2 sick NB5) | G34: การแพทย์
A35: 33 | B35: เครื่องวัดความถ่วงจำเพาะ (Reflactometer) | C35: 1 | D35: 33500 | E35: =C35*D35 -> 33500 | F35: เทคนิคการแพทย์ และพยาธิวิทยาคลินิก | G35: การแพทย์
A36: 34 | B36: โต๊ะเมโยจัดเครื่องมือ | C36: 2 | D36: 4950 | E36: =+C36*D36 -> 9900 | F36: กลุ่มงานสูติ-นรีเวชกรรม | G36: การแพทย์
A37: 35 | B37: เสาน้ำเกลือ | C37: 1 | D37: 2000 | E37: =+C37*D37 -> 2000 | F37: กลุ่มงานสูติ-นรีเวชกรรม | G37: การแพทย์
A38: 36 | B38: เครื่องถ่างขยายช่องซี่โครง (Rib Spreader) | C38: 2 | D38: 130000 | E38: =+C38*D38 -> 260000 | F38: แผนกศัลยกรรมทรวงอก | G38: การแพทย์
A39: 37 | B39: เครื่องดึงคอและหลังอัตโนมัติพร้อมเตียงปรับระดับได้ | C39: 1 | D39: 350000 | E39: =+C39*D39 -> 350000 | F39: งานกายภาพบำบัด | G39: การแพทย์ | H39: =+H28 -> 12.ครบกำหนดส่งมอบ
A40: 38 | B40: ตู้เย็นเก็บเลือด | C40: 1 | D40: 650000 | E40: =+C40*D40 -> 650000 | F40: งานธนาคารเลือด | G40: การแพทย์ | H40: ส่งบันทึกข้อความให้พัสดุแล้ว
...

Sheet รายการครุภัณฑ์ปรับ
A1: แผนรายจ่ายรายการครุภัณฑ์ เงินบำรุง ประจำปีงบประมาณ พ.ศ. 2568
A2: ลำดับ | B2: รายการ | C2: จำนวน (หน่วย) | D2: จำนวน (บาท/หน่วย) | E2: วงเงิน งบประมาณ (บาท) | F2: หน่วยงาน | G2: ประเภทครุภัณฑ์ | H2: หมายเหตุ
A3: 1 | B3: สถานีและขยายเส้นทางระบบท่อลมรับ-ส่งพัสดุทางการแพทย์ จำนวน 1 ระบบ (2 สถานี) | C3: 1 | D3: 2247000 | E3: =C3*D3 -> 2247000 | F3: เภสัชกรรม | G3: การแพทย์ | H3: บริษัทฯไม่สามารถเข้างานได้ รอทางเชื่อมระหว่างอาคารบ้านคุณพุ่มไปอาคาร298
A4: 2 | B4: เครื่องดมยาพร้อมเครื่องช่วยหายใจพร้อมเครื่องติดตามสัญญาณชีพ | C4: 1 | D4: 2200000 | E4: =C4*D4 -> 2200000 | F4: กลุ่มงาน สูติ-นรีเวชกรรม | G4: การแพทย์ | H4: เบิกจ่ายแล้ว
A5: 3 | B5: เตียงผ่าตัดทั่วไประบบไฟฟ้า | C5: 1 | D5: 1760000 | E5: =C5*D5 -> 1760000 | F5: กลุ่มงาน สูติ-นรีเวชกรรม | G5: การแพทย์ | H5: เบิกจ่ายแล้ว
A6: 4 | B6: โคมไฟผ่าตัดใหญ่ | C6: 1 | D6: 1450000 | E6: =C6*D6 -> 1450000 | F6: กลุ่มงาน สูติ-นรีเวชกรรม | G6: การแพทย์ | H6: เบิกจ่ายแล้ว
A7: 5 | B7: เลนส์สำหรับผ่าตัดผ่านกล้องในช่องท้องชนิดวิดีทัศน์ 10 มม 30 องศา | C7: 1 | D7: 1250000 | E7: 1250000 | F7: ห้องผ่าตัด | G7: การแพทย์ | H7: เบิกจ่ายแล้ว
A8: 6 | B8: Removal of Ethylene oxide by catalytic system (เครื่องระบายแก๊สเอทธิลีนออกไซด์ด้วยระบบการเร่งปฏิกิริยา) | C8: 1 | D8: 1200000 | E8: =C8*D8 -> 1200000 | F8: งานจ่ายกลาง | G8: การแพทย์ | H8: เบิกจ่ายแล้ว
A9: 7 | B9: เครื่อง High flow oxygen | C9: 2 | D9: 250000 | E9: =C9*D9 -> 500000 | F9: Sick newborn (1/2) | G9: การแพทย์ | H9: เบิกจ่ายแล้ว
A10: 8 | B10: ระบบเรียกพยาบาล Nurse call System | C10: 1 | D10: 499476 | E10: =C10*D10 -> 499476 | F10: หอผู้ป่วยศัลยกรรมกระดูก | G10: การแพทย์ | H10: 257067.5 | I10: 257067.5
A11: 9 | B11: เครื่องช่วยหายใจชนิดไม่สอดใส่ | C11: 1 | D11: 490000 | E11: =C11*D11 -> 490000 | F11: NICU (2/2) | G11: การแพทย์ | H11: เบิกจ่ายแล้ว
A12: 10 | B12: เครื่องให้ความอบอุ่นทารกแรกเกิด | C12: 2 | D12: 225000 | E12: =C12*D12 -> 450000 | F12: NICU | G12: การแพทย์ | H12: เบิกจ่ายแล้ว
A13: 11 | B13: ชุดภาควัดสัญญาณชีพขณะเคลื่อนย้าย | C13: 1 | D13: 330000 | E13: 330000 | F13: ไตเทียม | G13: การแพทย์ | H13: เบิกจ่ายแล้ว
A14: 12 | B14: เครื่องกระตุกหัวใจด้วยไฟฟ้า | C14: 1 | D14: 330000 | E14: =C14*D14 -> 330000 | F14: หอผู้ป่วยหนักอายุรกรรม | G14: การแพทย์ | H14: เบิกจ่ายแล้ว
A15: 13 | B15: เครื่องผลิตสุญญากาศทางการแพทย์ Vacuum Pump สงฆ์อาพาธ | C15: 1 | D15: 317255 | E15: 317255 | F15: งานช่าง | G15: การแพทย์ | H15: เบิกจ่ายแล้ว
A16: 14 | B16: เครื่องติดตามการทำงานของหัวใจและสัญญาณชีพอัตโนมัติ | C16: 1 | D16: 250000 | E16: =C16*D16 -> 250000 | F16: ศูนย์เครื่องมือแพทย์ | G16: การแพทย์ | H16: ดำเนินการ
A17: 15 | B17: ฉากกั้นรังสีแบบใส | C17: 2 | D17: 117500 | E17: =+C17*D17 -> 235000 | F17: cath lab (0/2) | G17: การแพทย์ | H17: เบิกจ่ายแล้ว
A18: 16 | B18: เครื่องดึงคอและหลังอัตโนมัติพร้อมเตียง | C18: 1 | D18: 230000 | E18: 230000 | F18: กล่มงานเวชกรรมฟื้นฟู | G18: การแพทย์ | H18: เบิกจ่ายแล้ว
A19: 17 | B19: ระบบ Nurse Call อาคารหลวงพ่อแช่ม ชั้น5 | C19: 1 | D19: 200000 | E19: =+C19*D19 -> 200000 | F19: หอผู้ป่วยศัลยกรรมกระดูก (หลวงพ่อแช่ม ชั้น 5) | G19: การแพทย์ | H19: คืนบันทึกข้อความกลับแก้ไข
A20: 18 | B20: เครื่องติดตามสัญญาณชีพห้องพักฟื้น | C20: 1 | D20: 200000 | E20: =C20*D20 -> 200000 | F20: กลุ่มงาน สูติ-นรีเวชกรรม | G20: การแพทย์ | H20: เบิกจ่ายแล้ว
A21: 19 | B21: เครื่องวัดความถ่วงจำเพาะ (Reflactometer) | C21: 1 | D21: 33500 | E21: =C21*D21 -> 33500 | F21: เทคนิคการแพทย์และพยาธิวิทยาคลินิก | G21: การแพทย์ | H21: เบิกจ่ายแล้ว
A22: 20 | B22: เครื่องควบคุมการให้สารละลายทางหลอดเลือด | C22: 3 | D22: 85600 | E22: =+C22*D22 -> 256800 | F22: กลุ่มงานวิสัญญี | G22: การแพทย์ | H22: เบิกจ่ายแล้ว
A23: 21 | B23: เครื่องช่วยใส่ท่อช่วยหายใจ (Laryngoscope) | C23: 1 | D23: 14000 | E23: =+C23*D23 -> 14000 | F23: กลุ่มงานวิสัญญี | G23: การแพทย์ | H23: เบิกจ่ายแล้ว
A24: 22 | B24: เครื่องชั่งน้ำหนัก แบบดิจิตอลพร้อมที่วัดส่วนสูง | C24: 1 | D24: 20000 | E24: =+C24*D24 -> 20000 | F24: งานผู้ป่วยนอก (ศัลยกรรมกระดูก) | G24: การแพทย์ | H24: เบิกจ่ายแล้ว
A25: 23 | B25: ไฟอบแผลฝีเย็บ | C25: 1 | D25: 6500 | E25: =+C25*D25 -> 6500 | F25: หอผู้ป่วยสูติกรรมหลังคลอด | G25: การแพทย์ | H25: เบิกจ่ายแล้ว
A26: 24 | B26: กระดานรองหลังชนิดยาว พร้อมชุดล็อคศรีษะเข็มขัด | C26: 3 | D26: 10000 | E26: =+C26*D26 -> 30000 | F26: งานอุบัติเหตุและฉุกเฉิน | G26: การแพทย์ | H26: เบิกจ่ายแล้ว
A27: 25 | B27: เครื่องวัดกำลังเลนส์อัตโนมัติชนิดจอ LED | C27: 1 | D27: 130000 | E27: =+C27*D27 -> 130000 | F27: กลุ่มงานจักษุวิทยา | G27: การแพทย์ | H27: เบิกจ่ายแล้ว
A28: 26 | B28: เครื่องผนึกซองซีล | C28: 1 | D28: 35100 | E28: =+C28*D28 -> 35100 | F28: กลุ่มงานทันตกรรม | G28: การแพทย์ | H28: เบิกจ่ายแล้ว
A29: 27 | B29: เครื่องเขย่าปูน | C29: 1 | D29: 19000 | E29: =+C29*D29 -> 19000 | F29: กลุ่มงานทันตกรรม | G29: การแพทย์ | H29: เบิกจ่ายแล้ว
A30: 28 | B30: เครื่องวัดความยาวราก | C30: 1 | D30: 35000 | E30: =+C30*D30 -> 35000 | F30: กลุ่มงานทันตกรรม | G30: การแพทย์ | H30: เบิกจ่ายแล้ว
A31: 29 | B31: เครื่องขูดหินปูน | C31: 1 | D31: 71500 | E31: =+C31*D31 -> 71500 | F31: กลุ่มงานทันตกรรม | G31: การแพทย์
A32: 30 | B32: เครื่องดูดเสมหะ | C32: 1 | D32: 10000 | E32: =+C32*D32 -> 10000 | F32: งานศูนย์เครื่องมือแพทย์ | G32: การแพทย์ | H32: เบิกจ่ายแล้ว
A33: 31 | B33: กล้องส่องตรวจช่องท้องชนิดวิดีทัศน์ ขนาด 10 มม มุมมองภาพ 30 องศา | C33: 1 | D33: 1250000 | E33: 1250000 | F33: ห้องผ่าตัด | G33: การแพทย์ | H33: รายการเดียวกับรายการที่ 5 หรือไม่
A34: 32 | B34: เครื่องควบคุมระบบประกาศ | C34: 1 | D34: 229729 | E34: =C34*D34 -> 229729 | F34: ประชาสัมพันธ์ | G34: การแพทย์ | H34: เบิกจ่ายแล้ว
A35: 33 | B35: เครื่องวัดความดันโลหิตอัตโนมัติชนิดสอดแขนพร้อมรถเข็นขาตั้งครบชุด | C35: 1 | D35: 65000 | E35: =C35*D35 -> 65000 | F35: กลุ่มการพยาบาล Echo(0/1) | G35: การแพทย์
A36: 34 | B36: เครื่องดึงคอและหลังอัตโนมัติพร้อมเตียงปรับระดับได้ | C36: 1 | D36: 350000 | E36: =+C36*D36 -> 350000 | F36: งานกายภาพบำบัด | G36: การแพทย์ | H36: เบิกจ่ายแล้ว
A37: 35 | B37: ตู้เย็นเก็บเลือด | C37: 1 | D37: 650000 | E37: =+C37*D37 -> 650000 | F37: งานธนาคารเลือด | G37: การแพทย์ | H37: เบิกจ่ายแล้ว
A38: 36 | B38: ตู้เย็นเก็บน้ำยาทางการแพทย์ | C38: 1 | D38: 100000 | E38: =+C38*D38 -> 100000 | F38: งานธนาคารเลือด | G38: การแพทย์ | H38: เบิกจ่ายแล้ว
A39: 37 | B39: เครื่องเขย่าเลือด | C39: 2 | D39: 149000 | E39: =+C39*D39 -> 298000 | F39: งานธนาคารเลือด | G39: การแพทย์ | H39: เบิกจ่ายแล้ว
A40: 38 | B40: หุ่นยนต์ฆ่าเชื้อโรคด้วยรังสียูวี ชนิดซี พร้อมชุดควบคุมการทำงานแบบระบะไกล | C40: 1 | D40: 2495000 | E40: =+C40*D40 -> 2495000 | F40: งานห้องผ่าตัด | G40: การแพทย์ | H40: เบิกจ่ายแล้ว
...

Sheet สิ่งก่อสร้าง (25.10.67)
A1: แผนรายการสิ่งก่อสร้าง ประจำปีงบประมาณ พ.ศ. 2568 : เงินบำรุง
A3: ลำดับ | B3: รายการ | C3: จำนวน (หน่วย) | D3: จำนวน (บาท/หน่วย) | E3: วงเงิน งบประมาณ (บาท) | F3: แหล่งงบ | G3: ในแผน/นอกแผน | H3: จะจ่ายได้ในปี | I3: วันที่รับหนังสือ (ก.ยุทธ์) | J3: เลขหนังสือ | K3: วันที่ ก.พัสดุรับหนังสือ | L3: วิธีการจัดซื้อ | M3: ผู้รับผิดชอบ | N3: 1.จัดทำแผนการจัดซื้อจัดจ้าง | O3: 2.แต่งตั้งคณะกรรมการกำหนดราคา | P3: 3.รายงานผลการกำหนดราคากลาง และรายละเอียดคุณลักษณะ | Q3: 4.รายงานขอซื้อขอจ้าง | R3: 5.เผยแพร่ร่าง TOR | S3: 6.รายงานผล การเผยแพร่ร่าง TOR | T3: 7.ประกาศเชิญชวน | U3: 8.วันเสนอราคา | V3: 9.รายงานผล การพิจารณาเสนอราคา | W3: 10.ระยะเวลาอุทธรณ์ ผลการพิจารณา | X3: 11.จัดทำสัญญา/ ใบสั่งซื้อสั่งจ้าง | Y3: 12. ครบกำหนดส่งมอบ | Z3: 13.ส่งมอบ/ รายงานผลตรวจรับ | AA3: 14.เบิกจ่ายเงิน | AB3: หมายเหตุ
A4: 1 | B4: ทาสีอาคาร OPD พื้นที่ประมาณ 15000 ตรม. | C4: 1 | D4: 356900 | E4: =D4 -> 356900 | O4: 04.05.67 | P4: 22.03.67 | Q4: 22.03.67 | U4: 02.04.67 | V4: 09.04.67 เสนอหัวหน้าเจ้าหน้าที่ | AB4: ดำเนินการแล้ว
A5: 2 | B5: จ้างก่อสร้างงานเปลี่ยนกระเบื้องมุงหลังคาอาคารอันดามัน 5 ชั้น | C5: 1 | D5: 400000 | E5: =D5 -> 400000 | AB5: ดำเนินการแล้ว
A6: 3 | B6: กำแพงกันดินตึกอันดามันไปอาคารอุบัติเหตุ 10 ชั้น | C6: 1 | D6: 9057868 | E6: =+C6*D6 -> 9057868 | AB6: เบิกจ่ายแล้ว
A7: 4 | B7: จ้างก่อสร้างงานเปลี่ยนกระเบื้องมุงหลังคาและซ่อมแซมโครงหลังคาอาคารศูนย์คอมพิวเตอร์และสโตกยูนิต 482 ตร.ม. | C7: 1 | D7: 500000 | E7: =+D7 -> 500000 | AB7: เบิกจ่ายแล้ว
A8: 5 | B8: ทางเดินเชื่อมตึกอันดามันไปอาคารอุบัติเหตุ 10 ชั้น | C8: 1 | D8: 8535743.1 | E8: =+C8*D8 -> 8535743.1
A9: 6 | B9: จ้างปรับปรุงห้องตึก 298 พร้อมเฟอร์นิเจอร์ ชั้น 2-8 | C9: 1 | D9: 9500000 | E9: =+C9*D9 -> 9500000 | AB9: เบิกจ่ายแล้ว
B10: รวมทั้งสิ้น | E10: =SUM(E4:E9) -> 28350511
A11: แผนรายการสิ่งก่อสร้าง ประจำปีงบประมาณ พ.ศ. 2569 : เงินบำรุง
A12: 1 | B12: ปรับปรุงห้องแลปชั้น 4 ตึก 10 ชั้น | C12: 1 | D12: 8000000 | E12: =+D12*C12 -> 8000000
A13: 2 | B13: ปรับปรุงคุณภาพอากาศภายในพื้นที่ตรวจผู้ป่วยนอก ชั้น 2 และชั้น 3 อาคารอุบัติเหตุฉุกเฉินและวิเคราะห์บำบัด 6 ชั้น | C13: 2 | D13: 3000000 | E13: =+C13*D13 -> 6000000
A14: 3 | B14: ปรับปรุงห้องเอกซเรย์ ตึก 10 ชั้น | C14: 1 | D14: 490000 | E14: =+C14*D14 -> 490000
A15: 4 | B15: ซื้อที่ดิน 1 ไร่ 34 ตารางวา ตรงข้ามหน้าโรงพยาบาลวชิระภูเก็ต | C15: 1 | D15: 57000000 | E15: =+C15*D15 -> 57000000
A16: 5 | B16: งานก่อสร้างทางเดินเชื่อมระหว่างอาคารบ้านคุณพุ่ม ไปยังอาคารพักคนไข้ 298 เตียง | C16: 1 | D16: 8000000 | E16: =+C16*D16 -> 8000000
A17: 6 | B17: ขยายพื้นที่ด้านข้างอาคารจ่ายยาปุดจ้อ (ออกแบบเสร็จแล้ว) | C17: 1 | D17: 2000000 | E17: =+D17 -> 2000000
A18: 7 | B18: ปรับปรุงห้องแรงดันบวกสำหรับศูนย์ปลูกถ่ายเซลล์ต้นกำเนิดเม็ดเลือด ชั้น 8 (ตึก 298 ) ฝั่งด้านห้องพิเศษ | C18: 1 | D18: 15000000 | E18: =+C18*D18 -> 15000000
A19: 8 | B19: - ปรับปรุงหอผู้ป่วยเคมีบำบัดเป็นระบบปรับอากาศ clean room positive pressure (class 100,000) ในพื้นที่หอผู้ป่วยเคมีบำบัด ชั้น 8 (ฝั่งสามัญ) - ปรับปรุงระบบปรับอากาศระบายอากาศ (clean room positive pressure) ห้องแยกผู้ป่วยเคมีบำบัด จำนวน 2 ห้อง - ติดตั้งตู้กักเก็บกลิ่นและไอระเหยทางสารเคมี ชั้น 8 ฝั่งสามัญ | C19: 1 | D19: 10000000 | E19: =+C19*D19 -> 10000000
A20: 9 | B20: ปรับปรุงห้องไตเทียม (ชั้น 1) +ที่พักคอย ตึก 298 (ออกแบบเสร็จแล้ว) | C20: 1 | D20: 18522237 | E20: =+C20*D20 -> 18522237 | AB20: ปี 69 ปรับแผน 10,000,000บาท
A21: 10 | B21: ห้องแยกผู้ป่วยแพร่กระจายเชื้อ MICU ชั้น 2 ตึก 298 (Negative) | C21: 10 | D21: 1000000 | E21: =+C21*D21 -> 10000000
A22: 11 | B22: ห้องแยกผู้ป่วยแพร่กระจายเชื้อ MICU ชั้น 2-3 ตึก 298 (AIIR ) | C22: 4 | D22: 1200000 | E22: =+C22*D22 -> 4800000
A23: 12 | B23: ปรับปรุงห้องพิเศษตึกสูติกรรม (อาจจะปรับราคา) | C23: 15 | D23: 500000 | E23: =+C23*D23 -> 7500000
A24: =+B10 -> รวมทั้งสิ้น | E24: =SUM(E12:E23) -> 1.4731224e+08
B25: ปรับปรุงอาคารพักคอยสำหรับผู้มาใช้บริการตึกอุบัติเหตุฉุกเฉินและศูนย์หัวใจ 10 ชั้น ตลอดถึงงานภูมิสถาปัตย์พื้นที่ด้านข้างไปจนถึงงานออกแบบปรับปรุงทางเดินเชื่อมอาคารของเก่า | C25: 1 | D25: 15000000
B26: ปรับปรุงห้องประชุมศูนย์คุณภาพ | C26: 1 | D26: 99450
A29: แผนรายการสิ่งก่อสร้าง ประจำปีงบประมาณ พ.ศ. 2568 : เงินบริจาค
A30: ลำดับ | B30: รายการ | C30: จำนวน (หน่วย) | D30: จำนวน (บาท/หน่วย) | E30: วงเงิน งบประมาณ (บาท) | F30: แหล่งงบ | G30: ในแผน/นอกแผน | H30: จะจ่ายได้ในปี | I30: วันที่รับหนังสือ (ก.ยุทธ์) | J30: เลขหนังสือ | K30: วันที่ ก.พัสดุรับหนังสือ | L30: วิธีการจัดซื้อ | M30: ผู้รับผิดชอบ | N30: 1.จัดทำแผนการจัดซื้อจัดจ้าง | O30: 2.แต่งตั้งคณะกรรมการกำหนดราคา | P30: 3.รายงานผลการกำหนดราคากลาง และรายละเอียดคุณลักษณะ | Q30: 4.รายงานขอซื้อขอจ้าง | R30: 5.เผยแพร่ร่าง TOR | S30: 6.รายงานผล การเผยแพร่ร่าง TOR | T30: 7.ประกาศเชิญชวน | U30: 8.วันเสนอราคา | V30: 9.รายงานผล การพิจารณาเสนอราคา | W30: 10.ระยะเวลาอุทธรณ์ ผลการพิจารณา | X30: 11.จัดทำสัญญา/ ใบสั่งซื้อสั่งจ้าง | Y30: 12. ครบกำหนดส่งมอบ | Z30: 13.ส่งมอบ/ รายงานผลตรวจรับ | AA30: 14.เบิกจ่ายเงิน | AB30: หมายเหตุ
A31: 1 | B31: ปรับปรุงห้องพิเศษ ตึก 298 จำนวน 40 ห้อง (25 ล้านบาท) | C31: 1 | D31: 12465000 | E31: =+C31*D31 -> 12465000 | AB31: เงินบริจาคเพื่อกิจการ
A32: 2 | B32: ปรับปรุงใช้ห้อง Cath lab ตึก 10 ชั้น ชั้น 5 | C32: 1 | D32: 2000000 | E32: =+C32*D32 -> 2000000 | AB32: เงินบริจาคเพื่อกิจการ
D33: =+A24 -> รวมทั้งสิ้น | E33: =SUM(E31:E32) -> 14465000
A35: แผนรายการสิ่งก่อสร้าง : เงินบริจาคอาคารรังสีรักษา ประจำปีงบประมาณ 2569
A36: ลำดับ | B36: รายการ | C36: จำนวน (หน่วย) | D36: จำนวน (บาท/หน่วย) | E36: วงเงิน งบประมาณ (บาท) | F36: แหล่งงบ | G36: ในแผน/นอกแผน | H36: จะจ่ายได้ในปี | I36: วันที่รับหนังสือ (ก.ยุทธ์) | J36: เลขหนังสือ | K36: วันที่ ก.พัสดุรับหนังสือ | L36: วิธีการจัดซื้อ | M36: ผู้รับผิดชอบ | N36: 1.จัดทำแผนการจัดซื้อจัดจ้าง | O36: 2.แต่งตั้งคณะกรรมการกำหนดราคา | P36: 3.รายงานผลการกำหนดราคากลาง และรายละเอียดคุณลักษณะ | Q36: 4.รายงานขอซื้อขอจ้าง | R36: 5.เผยแพร่ร่าง TOR | S36: 6.รายงานผล การเผยแพร่ร่าง TOR | T36: 7.ประกาศเชิญชวน | U36: 8.วันเสนอราคา | V36: 9.รายงานผล การพิจารณาเสนอราคา | W36: 10.ระยะเวลาอุทธรณ์ ผลการพิจารณา | X36: 11.จัดทำสัญญา/ ใบสั่งซื้อสั่งจ้าง | Y36: 12. ครบกำหนดส่งมอบ | Z36: 13.ส่งมอบ/ รายงานผลตรวจรับ | AA36: 14.เบิกจ่ายเงิน | AB36: หมายเหตุ
A37: 1 | B37: อาคารรังสีรักษา (ราคาก่อสร้าง 421 ล้านบาท) | C37: 1 | D37: 200000000 | E37: =+C37*D37 -> 200000000 | AB37: เงินบริจาคอาคารรังสีรักษา
A39: 1 | B39: ระบบเติมอากาศในห้องคลอด | C39: 1 | D39: 2200000 | E39: =+C39*D39 -> 2200000
A40: 2 | B40: ปรับปรุงจุดนั่งพักคอยด้านหน้าประชาสัมพันธ์พร้อมก่อสร้างอาคารลานม่วงขาว | C40: 1 | D40: 4000000 | E40: =+C40*D40 -> 4000000
A41: 3 | B41: ***ปรับปรุงอาคาร 10 ชั้น ICU หัวใจ (ชั้น10) | C41: 1 | D41: 5000000 | E41: =+D41*C41 -> 5000000
A42: 4 | B42: ก่อสร้างและปรับปรุงห้องจ่ายยาผู้ป่วยนอกชั้น 1 | C42: 1 | D42: 2300000 | E42: =+D42*C42 -> 2300000
A43: 5 | B43: ปรุงทางเดินหน้าห้องคลอด | C43: 1 | D43: 500000 | E43: =+D43*C43 -> 500000
A44: 6 | B44: ปรับปรุงห้องน้ำ OPD ชั้น 1,3,4 | C44: 3 | D44: 1400000 | E44: =+C44*D44 -> 4200000
A45: 7 | B45: ซ่อมแซมอาคารศรีพัชรินทรานุสร | C45: 1 | D45: 786400 | E45: =+C45*D45 -> 786400
...

Sheet รายละเอียดรายจ่าย
A1: รายละเอียดรายจ่ายและแผนประมาณการรายจ่าย (ปรับแผน) ปีงบประมาณ 2569
B3: หมวดรายจ่าย | D3: รายจ่ายจริง ปี 2562 | E3: รายจ่ายจริง ปี 2563 | F3: รายจ่ายจริง ปี 2564 | G3: แผนรายจ่าย ปี 2565 | H3: รายจ่ายจริง ปี 2565 | I3: หนี้ค้าง ปี 2565 | J3: แผนรายจ่าย ปีงบฯ 2566 | K3: รายจ่ายจริง ปี 2566 | L3: หนี้ค้าง ปี 2566 | M3: ก่อหนี้/ตรวจรับ ณ ก.ย.66 | N3: ก่อหนี้/ยังไม่ ตรวจรับ ณ ก.ค.66 | O3: คำขอตั้ง แผนวัสดุ | P3: ประมาณการรายจ่าย ปีงบฯ 2567 | Q3: รายจ่ายจริง ปี 2567 | R3: คิดเป็นร้อยละของแผน | S3: หนี้ค้าง ปี 2567 | T3: ผลการดำเนินงาน ณ 31 ก.ค. 67 (ข้อมูลจากหน่วยจัดซื้อ) | X3: แผนประมาณการรายจ่าย ปีงบฯ 2568 | Y3: หนี้ค้าง ณ 31 มี.ค.68 | Z3: ผลการดำเนินงาน | AC3: ผลการดำเนินงาน | AE3: แผนประมาณการรายจ่าย (ครึ่งปีหลัง) ปีงบฯ 2568 | AF3: ผลการดำเนินงาน | AH3: หนี้ค้าง ณ มิ.ย.68 | AI3: แผนประมาณการ รายจ่าย ปีงบฯ 2568 | AJ3: รายจ่าย ปี 2568 | AL3: หนี้ค้าง ณ ก.ย.68 | AM3: แผนประมาณการ รายจ่าย ปีงบฯ2569 | AN3: ผลการดำเนินงาน | AP3: หนี้ค้าง ณ ธ.ค.68 | AQ3: ผลการดำเนินงาน | AS3: หนี้ค้าง ณ มี.ค.69 | AT3: แผนประมาณการรายจ่าย (ปรับแผน) ปีงบฯ 2569 | AU3: หมายเหตุ
T4: เบิกจ่ายแล้ว | U4: เจ้าหนี้คงค้าง | V4: ก่อหนี้ | Z4: ไตรมาส 1 (ต.ค.-ธ.ค.67) | AA4: คิดเป็นร้อยละของแผน | AC4: รายจ่าย ต.ค.67- มี.ค. 68 | AD4: คิดเป็นร้อยละของแผน | AF4: =+ประมาณการรายรับ!#REF! -> #REF! | AG4: =+AD4 -> คิดเป็นร้อยละของแผน | AJ4: รายจ่าย | AK4: ร้อยละ | AN4: ไตรมาส 1 | AO4: ร้อยละ | AQ4: ไตรมาส 2 | AR4: ร้อยละ
A5: 1. | B5: ค่าจ้างชั่วคราว | C5: P18 | D5: 2.2576004e+08 | E5: 2.3143377e+08 | F5: 1.8053383e+08 | G5: 192030320 | H5: 1.8820402e+08 | I5: 0 | J5: 207980000 | K5: 1.8846488e+08 | L5: 0 | P5: 195000000 | Q5: 1.917608e+08 | R5: =+(Q5/P5)*100 -> 98.338873 | X5: 205000000 | Z5: 50880936 | AA5: =+Z5/X5*100 -> 24.819969 | AB5: =+(X5-Q5)/Q5*100 -> 6.9040171 | AC5: 1.008702e+08 | AD5: =+AC5/X5*100 -> 49.204977 | AE5: =+X5 -> 205000000 | AF5: 1.5132586e+08 | AG5: =+AF5/AE5*100 -> 73.817492 | AI5: =+AE5 -> 205000000 | AJ5: 2.0640163e+08 | AK5: =+AJ5/AI5*100 -> 100.68372
A6: 2. | B6: ค่าตอบแทน | C6: P19 | D6: =SUM(D7:D14) -> 3.5793542e+08 | E6: =SUM(E7:E14) -> 3.3066539e+08 | F6: =SUM(F7:F14) -> 3.2195319e+08 | G6: 342049500 | H6: =SUM(H7:H14) -> 3.5806495e+08 | I6: 0 | J6: 411928000 | K6: =SUM(K7:K16) -> 3.7859777e+08 | L6: 0 | P6: =SUM(P7:P16) -> 476200000 | Q6: =SUM(Q7:Q16) -> 4.7581167e+08 | R6: =+(Q6/P6)*100 -> 99.918452 | X6: =SUM(X7:X16) -> 476200000 | Z6: =SUM(Z7:Z16) -> 1.1782627e+08 | AA6: =+Z6/X6*100 -> 24.743021 | AB6: =+(X6-Q6)/Q6*100 -> 0.081614278 | AC6: =SUM(AC7:AC16) -> 2.3781947e+08 | AD6: =+AC6/X6*100 -> 49.941089 | AE6: =+X6 -> 476200000 | AF6: =SUM(AF7:AF16) -> 3.6122999e+08 | AG6: =+AF6/AE6*100 -> 75.85678 | AI6: =SUM(AI7:AI16) -> 476200000 | AJ6: =SUM(AJ7:AJ16) -> 4.9167897e+08 | AK6: =+AJ6/AI6*100 -> 103.25052
B7: ค่าตอบแทน (OT) | C7: P19 | D7: 297042587 | E7: 3.1185561e+08 | F7: 3.0979411e+08 | G7: 320000000 | H7: 3.4099977e+08 | I7: 0 | J7: 365000000 | K7: 3.6720214e+08 | L7: 0 | P7: 432000000 | Q7: 4.31947e+08 | R7: =+(Q7/P7)*100 -> 99.98773 | X7: 432000000 | Z7: 1.0849952e+08 | AB7: =+(X7-Q7)/Q7*100 -> 0.012271163 | AC7: 2.2276551e+08 | AE7: =+X7 -> 432000000 | AF7: 3.4373884e+08 | AI7: =+AE7 -> 432000000 | AJ7: 4.6304949e+08
B8: ค่าตอบแทนสาขาขาดแคลน | C8: P19 | D8: 582100 | E8: 598456 | F8: 1167600 | G8: 300000 | H8: 868400 | I8: 0 | J8: 580000 | K8: 555000 | L8: 0 | P8: 550000 | Q8: 470000 | R8: =+(Q8/P8)*100 -> 85.454545 | X8: 550000 | Z8: 140000 | AB8: =+(X8-Q8)/Q8*100 -> 17.021277 | AC8: 290000 | AE8: =+X8 -> 550000 | AF8: 440000 | AI8: =+AE8 -> 550000 | AJ8: 590000
B9: ค่าตอบแทนควบคุมงาน | C9: P19 | D9: 180000 | E9: 115500 | F9: 88500 | G9: 200000 | H9: 223200 | I9: 0 | J9: 216000 | K9: =155400+33600 -> 189000 | L9: 0 | P9: 200000 | Q9: 147300 | R9: =+(Q9/P9)*100 -> 73.65 | X9: 200000 | Z9: 51000 | AB9: =+(X9-Q9)/Q9*100 -> 35.777325 | AC9: 51000 | AE9: =+X9 -> 200000 | AF9: 118192 | AI9: =+AE9 -> 200000 | AJ9: 178492
B10: ค่าตอบแทน P4P | C10: P19 | D10: 58010499 | E10: 17069627 | F10: 10193251 | G10: 9000000 | H10: 5202971 | I10: 0 | J10: 43900000 | K10: 8605551 | L10: 0 | P10: =31200000+10000000 -> 41200000 | Q10: 41374950 | R10: =+(Q10/P10)*100 -> 100.42464 | X10: 41200000 | Z10: 8839345 | AB10: =+(X10-Q10)/Q10*100 -> -0.42283957 | AC10: 13805834 | AE10: =+X10 -> 41200000 | AF10: 15644233 | AI10: =+AE10 -> 41200000 | AJ10: 25896114 | AU10: (36 ลบ.+10ลบ+PMC3.6ลบ.+Wellness3 ลบ.)
B11: ค่าตอบแทนอื่นๆ (ค่าตอบแทนกรรมการ+สปสช+ช่วยเหลือกรณีเสียชีวิต) | C11: P19 | D11: 19300 | E11: 69342 | F11: 132600 | G11: 220000 | H11: 299500 | I11: 0 | J11: 340000 | K11: =103500+126000+55680+10200 -> 295380 | L11: 0 | P11: 300000 | Q11: =2000+150300 -> 152300 | R11: =+(Q11/P11)*100 -> 50.766667 | X11: 300000 | Z11: 26700 | AB11: =+(X11-Q11)/Q11*100 -> 96.979645 | AC11: 90000 | AE11: =+X11 -> 300000 | AF11: 153000 | AI11: =+AE11 -> 300000 | AJ11: 194400
B12: ค่าตอบแทนชันสูตรพลิกศพ | C12: P19 | D12: 220600 | E12: 231450 | F12: 577125 | G12: 550000 | H12: 618600 | I12: 0 | J12: 750000 | K12: 1278500 | L12: 0 | P12: =1000000+250000 -> 1250000 | Q12: 1720125 | R12: =+(Q12/P12)*100 -> 137.61 | X12: 1250000 | Z12: 267300 | AB12: =+(X12-Q12)/Q12*100 -> -27.330863 | AC12: 814725 | AE12: =+X12 -> 1250000 | AF12: 1133325 | AI12: =+AE12 -> 1250000 | AJ12: 1698075
B13: ค่าตอบแทน พตส. | C13: P19 | D13: 1880337 | E13: 725406 | F13: 0 | G13: 1500000 | H13: 0 | I13: 0 | J13: 642000 | K13: 225000 | L13: 0 | P13: 300000 | Q13: 0 | R13: =+(Q13/P13)*100 -> 0 | X13: 300000 | Z13: 0 | AB13: =+(X13-Q13)/Q13*100 -> #DIV/0! | AE13: =+X13 -> 300000 | AF13: 0 | AI13: =+AE13 -> 300000 | AJ13: 70000
B14: ค่าตอบแทน-ความเสี่ยง Covid-19 | C14: P20 | D14: 0 | E14: 0 | F14: 0 | G14: 9879500 | H14: 9852500 | I14: 0 | J14: 0 | K14: 0 | L14: 0 | P14: 0 | Q14: 0 | R14: 0 | X14: 0 | Z14: 0 | AB14: =+(X14-Q14)/Q14*100 -> #DIV/0! | AE14: =+X14 -> 0 | AF14: 0 | AI14: =+AE14 -> 0 | AJ14: 0
B15: ค่าตอบแทนปฏิบัติงานส่งต่อผู้ป่วยทางอากาศ | G15: 0 | H15: 0 | I15: 0 | J15: 100000 | K15: 0 | L15: 0 | P15: 100000 | Q15: 0 | R15: =+(Q15/P15)*100 -> 0 | X15: 100000 | Z15: 0 | AB15: =+(X15-Q15)/Q15*100 -> #DIV/0! | AE15: =+X15 -> 100000 | AF15: 0 | AI15: =+AE15 -> 100000 | AJ15: 0
B16: ค่าตอบแทนแพทย์ผู้เชี่ยวชาญ (นอก รพ.) | G16: 0 | H16: 0 | I16: 0 | J16: 400000 | K16: =208800+38400 -> 247200 | L16: 0 | P16: 300000 | Q16: 0 | R16: =+(Q16/P16)*100 -> 0 | X16: 300000 | Z16: 2400 | AB16: =+(X16-Q16)/Q16*100 -> #DIV/0! | AC16: 2400 | AE16: =+X16 -> 300000 | AF16: 2400 | AI16: =+AE16 -> 300000 | AJ16: 2400
A17: 3. | B17: ค่าใช้สอย | D17: =SUM(D18:D52) -> 1.1273558e+08 | E17: =SUM(E18:E52) -> 1.0528358e+08 | F17: =SUM(F18:F52) -> 1.4042157e+08 | G17: 270000000 | H17: =+H18+H19+H20+H26+H31+H32+H33+H34+H35+H36+H37+H38+H39+H40+H41+H42+H43+H44+H47+H48+H49+H50+H51+H52+H53 -> 1.937167e+08 | I17: =SUM(I18:I54)+317940.91 -> 34083973 | J17: 184177860 | K17: =+K18+K19+K20+K26+K31+K32+K33+K34+K35+K36+K37+K38+K39+K40+K41+K42+K43+K44+K47+K48+K49+K50+K51+K52+K53 -> 1.7022475e+08 | M17: =SUM(M18:M56) -> 0 | N17: =SUM(N18:N56) -> 0 | P17: =SUM(P18:P58)-P20-P26 -> 191000000 | Q17: =SUM(Q18:Q58)-Q20-Q26 -> 2.1937941e+08 | R17: =+Q17/P17*100 -> 114.85833 | S17: =SUM(S18:S56) -> 11958265 | X17: =SUM(X18:X72)-X20-X26 -> 210017100 | Y17: =SUM(Y18:Y56) -> 10568878 | Z17: =SUM(Z18:Z72)-Z20-Z26 -> 53560336 | AA17: =+Z17/X17*100 -> 25.502845 | AB17: =+(X17-Q17)/Q17*100 -> -4.2676345 | AC17: =SUM(AC18:AC72)-AC20-AC26 -> 92750469 | AD17: =+AC17/X17*100 -> 44.163294 | AE17: =SUM(AE18:AE87) -> 210589190 | AF17: =SUM(AF18:AF87)-AF20-AF26 -> 1.445115e+08 | AG17: =+AF17/AE17*100 -> 68.622467 | AI17: =SUM(AI18:AI87) -> 210589190 | AJ17: =SUM(AJ18:AJ101)-AJ20-AJ26 -> 2.0009244e+08 | AK17: =+AJ17/AI17*100 -> 95.015533
B18: ค่ากำจัดขยะ | C18: P21 | D18: 1925877.8 | E18: 1813011.2 | F18: 2678763.2 | G18: 4000000 | H18: 4466088.4 | I18: 0 | J18: 4000000 | K18: 4053044.4 | L18: 0 | P18: 3000000 | Q18: 5097977.2 | R18: =+Q18/P18*100 -> 169.93257 | X18: 4600000 | Z18: 1737674 | AB18: =+(X18-Q18)/Q18*100 -> -9.7681331 | AC18: 2825471.2 | AE18: =+X18 -> 4600000 | AF18: 4351351.2 | AI18: =+AE18 -> 4600000 | AJ18: 6564191.2
B19: ค่าธนาณัติ+ธรรมเนียม | C19: P21 | D19: 701942.75 | E19: 641269.55 | F19: 601626.51 | G19: 750000 | H19: 690202.45 | I19: 0 | J19: 1000000 | K19: 934349.01 | L19: 0 | P19: 600000 | Q19: 467149.67 | R19: =+Q19/P19*100 -> 77.858278 | X19: 400000 | Z19: 130614.96 | AB19: =+(X19-Q19)/Q19*100 -> -14.374337 | AC19: 323589.04 | AE19: =+X19 -> 400000 | AF19: 430380.09 | AI19: =+AE19 -> 400000 | AJ19: 593583.71
B20: ค่าบำรุงรักษาซ่อมแซมทรัพย์สิน | C20: P21 | D20: 5938577.4 | E20: 9023205.6 | F20: 10892591 | G20: 24500000 | H20: 17040293 | I20: 3115714.1 | J20: 27500000 | K20: =SUM(K21:K25) -> 17045702 | L20: 0 | P20: =SUM(P21:P25) -> 33700000 | Q20: =SUM(Q21:Q25) -> 36441616 | X20: =SUM(X21:X25) -> 22200000 | Z20: =SUM(Z21:Z25) -> 11193839 | AB20: =+(X20-Q20)/Q20*100 -> -39.080637 | AC20: =SUM(AC21:AC25) -> 18561733 | AF20: =SUM(AF21:AF25) -> 22959561 | AJ20: =SUM(AJ21:AJ25) -> 27331574 | AL20: =SUM(AL21:AL25) -> 1991587.5
B21: - ค่าซ่อมแซมอาคารและสิ่งปลูกสร้าง | D21: 0 | E21: 0 | F21: 0 | G21: 0 | H21: 0 | I21: 0 | J21: 7000000 | K21: 3030895 | L21: 0 | P21: 5000000 | Q21: 6531583.8 | R21: =+Q21/P21*100 -> 130.63168 | X21: 5000000 | Z21: 5716412.4 | AB21: =+(X21-Q21)/Q21*100 -> -23.448888 | AC21: 7013964 | AE21: =+X21 -> 5000000 | AF21: 7939964 | AI21: =+AE21 -> 5000000 | AJ21: 8087964
B22: - ค่าซ่อมแซมครุภัณฑ์ยานพาหนะ | D22: 0 | E22: 0 | F22: 0 | G22: 0 | H22: 0 | I22: 0 | J22: 1500000 | K22: =1156778.51+46547.1+9683.5 -> 1213009.1 | L22: 0 | P22: 1200000 | Q22: 1409077.5 | R22: =+Q22/P22*100 -> 117.42312 | S22: 200600.14 | X22: 1200000 | Y22: 320369.53 | Z22: 350315.72 | AB22: =+(X22-Q22)/Q22*100 -> -14.837897 | AC22: 514094.08 | AE22: =+X22 -> 1200000 | AF22: 949146.43 | AI22: =+AE22 -> 1200000 | AJ22: 1267387.6 | AL22: 403588.1
B23: - ค่าซ่อมแซมครุภัณฑ์ไฟฟ้าและวิทยุ | D23: 0 | E23: 0 | F23: 0 | G23: 0 | H23: 0 | I23: 0 | J23: 5000000 | K23: =2109553.17+43435.44+220960.18 -> 2373948.8 | L23: 0 | P23: 3500000 | Q23: 3582671.6 | R23: =+Q23/P23*100 -> 102.36205 | S23: 2054002.7 | X23: 3000000 | Y23: 114984.9 | Z23: 2216544.2 | AB23: =+(X23-Q23)/Q23*100 -> -16.263607 | AC23: 2816301.1 | AE23: =+X23 -> 3000000 | AF23: 2935112.5 | AI23: =+AE23 -> 3000000 | AJ23: 3565991.7 | AL23: 296401.5
B24: - ค่าซ่อมแซมครุภัณฑ์วิทยาศาสตร์และการแพทย์ | D24: 0 | E24: 0 | F24: 0 | G24: 0 | H24: 0 | I24: 0 | J24: 7500000 | K24: =7725545.35+947251.94+821984.49 -> 9494781.8 | L24: 4204302.2 | P24: 21000000 | Q24: 21743663 | R24: =+Q24/P24*100 -> 103.54125 | S24: 1543543.9 | X24: 10000000 | Y24: 1512560.5 | Z24: 2828866.2 | AB24: =+(X24-Q24)/Q24*100 -> -54.00959 | AC24: 6989634.4 | AE24: =+X24 -> 10000000 | AF24: 9644812.2 | AI24: =+AE24 -> 10000000 | AJ24: 12572781 | AL24: 1291597.9
B25: - ค่าซ่อมแซมครุภัณฑ์อื่นๆ+ลิฟท์ | D25: 0 | E25: 0 | F25: 0 | G25: 0 | H25: 0 | I25: 0 | J25: 6500000 | K25: =123175.85+731383.05+78508.1 -> 933067 | L25: 0 | P25: 3000000 | Q25: 3174619.4 | R25: =+Q25/P25*100 -> 105.82065 | X25: 3000000 | Z25: 81700 | AB25: =+(X25-Q25)/Q25*100 -> -5.5004821 | AC25: 1227739.9 | AE25: =+X25 -> 3000000 | AF25: 1490526.4 | AI25: =+AE25 -> 3000000 | AJ25: 1837449.1
B26: ค่าจ้างเหมาปรับปรุงและบำรุงรักษา | C26: P21 | D26: 22969804 | E26: 16755708 | F26: 13522084 | G26: 15450000 | H26: 13341107 | I26: 3111578.2 | J26: 18000000 | K26: =SUM(K27:K30) -> 20141604 | L26: 2941584.3 | P26: =SUM(P27:P30) -> 16044000 | Q26: =SUM(Q27:Q30) -> 34859193 | S26: 3023034 | X26: =SUM(X27:X30) -> 19550000 | Y26: 2616734.2 | Z26: =SUM(Z27:Z30) -> 8121691 | AB26: =+(X26-Q26)/Q26*100 -> -43.917233 | AC26: =SUM(AC27:AC30) -> 13225585 | AF26: =SUM(AF27:AF30) -> 18688713 | AH26: 1837911.2 | AJ26: =SUM(AJ27:AJ30) -> 27275585 | AL26: 2271762
B27: - ค่าจ้างเหมาบำรุงรักษาดูแลลิฟท์ | D27: 0 | E27: 0 | F27: 0 | G27: 0 | H27: 0 | I27: 0 | J27: 1000000 | K27: =1584367.77+133641+119276 -> 1837284.8 | L27: 0 | P27: 700000 | Q27: 1222176.5 | R27: =+Q27/P27*100 -> 174.59664 | S27: 0 | X27: 700000 | Z27: 490076.51 | AB27: =+(X27-Q27)/Q27*100 -> -42.725129 | AC27: 590311.69 | AE27: =+X27 -> 700000 | AF27: 840348.34 | AI27: =+AE27 -> 700000 | AJ27: 1080036.9
B28: - ค่าจ้างเหมาบำรุงรักษาครุภัณฑ์วิทยาศาสตร์และการแพทย์ | D28: 0 | E28: 0 | F28: 0 | G28: 0 | H28: 0 | I28: 0 | J28: 11000000 | K28: =4222419.23+796875+1579346 -> 6598640.2 | L28: 0 | P28: 6844000 | Q28: 13031870 | R28: =+Q28/P28*100 -> 190.41306 | S28: 0 | X28: 15000000 | Z28: 4507104.5 | AB28: =+(X28-Q28)/Q28*100 -> 15.10244 | AC28: 7227963.5 | AE28: =+X28 -> 15000000 | AF28: 10078550 | AI28: =+AE28 -> 15000000 | AJ28: 13545719
B29: - ค่าจ้างเหมาบำรุงรักษาเครื่องปรับอากาศ | D29: 0 | E29: 0 | F29: 0 | G29: 0 | H29: 0 | I29: 0 | J29: 2000000 | K29: =2154789.9+96305+126904 -> 2377998.9 | L29: 0 | P29: 2500000 | Q29: 1374610.1 | R29: =+Q29/P29*100 -> 54.984402 | S29: 0 | X29: 2500000 | Z29: 439352.45 | AB29: =+(X29-Q29)/Q29*100 -> 81.869759 | AC29: 615554.7 | AE29: =+X29 -> 2500000 | AF29: 1209939.7 | AI29: =+AE29 -> 2500000 | AJ29: 1317046.7
B30: - ค่าจ้างเหมาบำรุงรักษาครุภัณฑ์อื่นๆ/ค่า MA อุปกรณ์ป้องกันระบบเครือข่าย | D30: 0 | E30: 0 | F30: 0 | G30: 0 | H30: 0 | I30: 0 | J30: 3000000 | K30: =7753459.52+1125328.32+448892.5 -> 9327680.3 | L30: 0 | P30: 6000000 | Q30: 19230537 | R30: =+Q30/P30*100 -> 320.50895 | S30: 0 | X30: 1350000 | Z30: 2685157.5 | AB30: =+(X30-Q30)/Q30*100 -> -92.979915 | AC30: 4791755.5 | AE30: =+X30 -> 1350000 | AF30: 6559875 | AI30: =+AE30 -> 1350000 | AJ30: 11332783
B31: ค่าใช้จ่ายโครงการ + โครงการ PP | C31: P25 | D31: 5889129 | E31: 5465724.8 | F31: 13956015 | G31: 4500000 | H31: =1732840.98+132400 -> 1865241 | I31: 0 | J31: 5000000 | K31: =3393075.1+59592 -> 3452667.1 | L31: 0 | P31: 5000000 | Q31: =7365987.08+24000 -> 7389987.1 | R31: =+Q31/P31*100 -> 147.79974 | S31: 0 | X31: 5000000 | Z31: 3831219 | AB31: =+(X31-Q31)/Q31*100 -> -32.340883 | AC31: 5446485.6 | AE31: =+X31 -> 5000000 | AF31: 6255992.6 | AI31: =+AE31 -> 5000000 | AJ31: 8156027.4
B32: ค่าพาหนะเดินทางไปราชการ+อบรม+ค่าลงทะเบียน | C32: P20,P21 | D32: 6253665.2 | E32: 3543262 | F32: 2016754.2 | G32: 5000000 | H32: =1341108.9+1700788 -> 3041896.9 | I32: 0 | J32: 5000000 | K32: =2565341.51+2880550 -> 5445891.5 | L32: 0 | P32: 5000000 | Q32: =4111517.56+3721670 -> 7833187.6 | R32: =+Q32/P32*100 -> 156.66375 | S32: 0 | X32: 5000000 | Z32: 1453545 | AB32: =+(X32-Q32)/Q32*100 -> -36.169025 | AC32: 3466626 | AE32: =+X32 -> 5000000 | AF32: 5003709.5 | AI32: =+AE32 -> 5000000 | AJ32: 7179964.5
B33: ค่าเบี้ยเลี้ยง+ค่าที่พัก | C33: P21 | D33: 4484263.4 | E33: 2090256.8 | F33: 1333386.4 | G33: 0 | H33: =691574+1416089.28 -> 2107663.3 | I33: 0 | K33: =1508694.98+2397260.83 -> 3905955.8 | L33: 0 | P33: 4000000 | Q33: =1665614+3043021 -> 4708635 | R33: =+Q33/P33*100 -> 117.71587 | S33: 0 | X33: 4000000 | Z33: 1711204 | AB33: =+(X33-Q33)/Q33*100 -> -15.049691 | AC33: 2678115 | AE33: =+X33 -> 4000000 | AF33: 3593371 | AI33: =+AE33 -> 4000000 | AJ33: 5016789
B34: ค่ากำจัดปลวก | C34: P21 | D34: 30320 | E34: 0 | F34: 366663 | G34: 200000 | H34: 286665 | I34: 0 | J34: 400000 | K34: 321672 | L34: 0 | P34: 300000 | Q34: 455000 | R34: =+Q34/P34*100 -> 151.66667 | S34: 0 | X34: 390000 | Z34: 65000 | AB34: =+(X34-Q34)/Q34*100 -> -14.285714 | AC34: 97500 | AE34: =+X34 -> 390000 | AF34: 130000 | AI34: =+AE34 -> 390000 | AJ34: 281940
B35: ค่าตรวจพยาธิ+วิเคราะห์ - ค่าจ้างตรวจทางห้องปฏิบัติการ (Lab) | C35: P21 | D35: 4954264 | E35: 3059112.9 | F35: 12777582 | G35: 4500000 | H35: =277015+2086720 -> 2363735 | I35: 504675 | J35: 3800000 | K35: =1210750+3127057.75 -> 4337807.8 | L35: 0 | P35: 4500000 | Q35: =386885+4959402.4 -> 5346287.4 | R35: =+Q35/P35*100 -> 118.80639 | S35: 0 | X35: 5000000 | Z35: 2851989.6 | AB35: =+(X35-Q35)/Q35*100 -> -6.4771565 | AC35: =211855+3511889.56 -> 3723744.6 | AE35: =+X35 -> 5000000 | AF35: 5395404.1 | AI35: =+AE35 -> 5000000 | AJ35: 7197989.1
B36: ค่าตรวจชิ้นเนื้อ ค่าจ้างตรวจทางห้องปฏิบัติการ (Lab กายวิภาค) | C36: P21 | D36: 4900365 | E36: 5619625 | F36: 6636524 | G36: 8000000 | H36: 8849600 | I36: 0 | J36: 6800000 | K36: 10042250 | L36: 1921540 | P36: 11000000 | Q36: 11773017 | R36: =+Q36/P36*100 -> 107.02743 | S36: 0 | X36: 11600000 | Z36: 2307630 | AB36: =+(X36-Q36)/Q36*100 -> -1.4696063 | AC36: 3399085 | AE36: =+X36 -> 11600000 | AF36: 9241622 | AI36: =+AE36 -> 11600000 | AJ36: 11550934
