Workbook

Sheet สรุปเพื่อยืนยัน
A1: โรงพยาบาลวชิระภูเก็ต
A2: ยืนยันรายการคำของบวัสดุ ปีงบประมาณ 2570
A3: รายการ detail ตามแท็บที่นำเข้าจากไฟล์ แบบฟอร์มที่ 3 แผนปีงบประมาณ 2570 หมวดวัสดุ.xlsx · ส่งออกจากฐาน VPK-S1 วันที่ 12 ต.ค. 2569
A4: ช่องสีเหลืองให้ผู้ใช้กรอกผลยืนยัน ช่องสีเขียวเป็นสูตร จำนวนรายการและยอดจากรายการดึงจากชีตของแต่ละแท็บ ยอดในระบบคือยอดเอกสารในฐานข้อมูล แท็บออกซิเจนถังว่างและชีตสรุปวัสดุไม่ได้สร้างเป็นคำขอ คอลัมน์รหัสสินค้าอยู่ถัดจากลำดับในแต่ละชีตแท็บ ช่องว่างให้กรอก รหัสของแท็บยาดึงจากหมายเหตุเดิม
A6: ลำดับ | B6: เลขที่เอกสาร | C6: แท็บ | D6: หน่วยงาน | E6: จำนวนรายการ | F6: ยอดจากรายการ | G6: ยอดในระบบ | H6: ผลต่าง | I6: ผลยืนยัน | J6: หมายเหตุ
A7: 1 | B7: DBR/2570/0004 | C7: วัสดุสำนักงาน | D7: หน่วยงานพัสดุ | E7: =COUNTA(วัสดุสำนักงาน!C5:C517) -> 513 | F7: =SUM(วัสดุสำนักงาน!M5:M517) -> 8614565.1 | G7: 8614565.1 | H7: =F7-G7 -> 0
A8: 2 | B8: DBR/2570/0005 | C8: งานบ้าน | D8: หน่วยงานพัสดุ | E8: =COUNTA(งานบ้าน!C5:C432) -> 428 | F8: =SUM(งานบ้าน!M5:M432) -> 19680885 | G8: 19680885 | H8: =F8-G8 -> 0
A9: 3 | B9: DBR/2570/0006 | C9: เชื้อเพลิง | D9: หน่วยงานพัสดุ | E9: =COUNTA(เชื้อเพลิง!C5:C7) -> 3 | F9: =SUM(เชื้อเพลิง!M5:M7) -> 9633924 | G9: 9633924 | H9: =F9-G9 -> 0
A10: 4 | B10: DBR/2570/0007 | C10: เครื่องแต่งกาย | D10: งานซักฟอกและตัดเย็บ | E10: =COUNTA(เครื่องแต่งกาย!C5:C103) -> 99 | F10: =SUM(เครื่องแต่งกาย!M5:M103) -> 2699621.6 | G10: 2699621.6 | H10: =F10-G10 -> 0
A11: 5 | B11: DBR/2570/0008 | C11: ออกซิเจนเหลว | D11: หน่วยงานพัสดุ | E11: =COUNTA(ออกซิเจนเหลว!C5:C7) -> 3 | F11: =SUM(ออกซิเจนเหลว!M5:M7) -> 10018000 | G11: 10018000 | H11: =F11-G11 -> 0
A12: 6 | B12: DBR/2570/0009 | C12: Lab | D12: กลุ่มงานเทคนิคการแพทย์ฯ | E12: =COUNTA(Lab!C5:C297) -> 293 | F12: =SUM(Lab!M5:M297) -> 53413677 | G12: 53413677 | H12: =F12-G12 -> 0
A13: 7 | B13: DBR/2570/0010 | C13: LabCOVID | D13: กลุ่มงานเทคนิคการแพทย์ฯ | E13: =COUNTA(LabCOVID!C5:C6) -> 2 | F13: =SUM(LabCOVID!M5:M6) -> 998960 | G13: 998960 | H13: =F13-G13 -> 0
A14: 8 | B14: DBR/2570/0011 | C14: พยาธิกายวิภาค | D14: กลุ่มงานเทคนิคการแพทย์ฯ | E14: =COUNTA(พยาธิกายวิภาค!C5:C27) -> 23 | F14: =SUM(พยาธิกายวิภาค!M5:M27) -> 1199640 | G14: 1199640 | H14: =F14-G14 -> 0
A15: 9 | B15: DBR/2570/0012 | C15: ธนาคารเลือด | D15: งานธนาคารเลือด | E15: =COUNTA(ธนาคารเลือด!C5:C81) -> 77 | F15: =SUM(ธนาคารเลือด!M5:M81) -> 17933878 | G15: 17933878 | H15: =F15-G15 -> 0
A16: 10 | B16: DBR/2570/0013 | C16: ยา | D16: กลุ่มงานเภสัชกรรม | E16: =COUNTA(ยา!C5:C1063) -> 1059 | F16: =SUM(ยา!M5:M1063) -> 5.7251695e+08 | G16: 5.7251695e+08 | H16: =F16-G16 -> 0
A17: 11 | B17: DBR/2570/0014 | C17: วัสดุเภสัชกรรม | D17: กลุ่มงานเภสัชกรรม | E17: =COUNTA(วัสดุเภสัชกรรม!C5:C112) -> 108 | F17: =SUM(วัสดุเภสัชกรรม!M5:M112) -> 11563021 | G17: 11563021 | H17: =F17-G17 -> 0
A18: 12 | B18: DBR/2570/0015 | C18: ทันตกรรม | D18: กลุ่มงานทันตกรรม | E18: =COUNTA(ทันตกรรม!C5:C554) -> 550 | F18: =SUM(ทันตกรรม!M5:M554) -> 5187197.4 | G18: 5187197.4 | H18: =F18-G18 -> 0
A19: 13 | B19: DBR/2570/0016 | C19: โภชนาการ | D19: งานโภชนาการ กลุ่มงาน โภชนศาตร์ | E19: =COUNTA(โภชนาการ!C5:C330) -> 326 | F19: =SUM(โภชนาการ!M5:M330) -> 50403620 | G19: 50403620 | H19: =F19-G19 -> 0
A20: 14 | B20: DBR/2570/0017 | C20: แบบพิมพ์ | D20: หน่วยงานพัสดุ | E20: =COUNTA(แบบพิมพ์!C5:C141) -> 137 | F20: =SUM(แบบพิมพ์!M5:M141) -> 1869950.7 | G20: 1869950.7 | H20: =F20-G20 -> 0
A21: 15 | B21: DBR/2570/0018 | C21: ซ่อมเครื่องมือแพทย์ | D21: ศูนย์เครื่องมือแพทย์ | E21: =COUNTA(ซ่อมเครื่องมือแพทย์!C5:C36) -> 32 | F21: =SUM(ซ่อมเครื่องมือแพทย์!M5:M36) -> 10970000 | G21: 10970000 | H21: =F21-G21 -> 0
A22: 16 | B22: DBR/2570/0019 | C22: ผ่าตัด | D22: งานห้องผ่าตัด | E22: =COUNTA(ผ่าตัด!C5:C878) -> 874 | F22: =SUM(ผ่าตัด!M5:M878) -> 3.6291941e+08 | G22: 3.6291941e+08 | H22: =F22-G22 -> 0
A23: 17 | B23: DBR/2570/0020 | C23: การพยาบาล | D23: กลุ่มภารกิจด้านการพยาบาล | E23: =COUNTA(การพยาบาล!C5:C328) -> 324 | F23: =SUM(การพยาบาล!M5:M328) -> 62344433 | G23: 62344433 | H23: =F23-G23 -> 0
A24: 18 | B24: DBR/2570/0021 | C24: เฝือก | D24: กลุ่มงานออร์โธปิดิกส์ | E24: =COUNTA(เฝือก!C5:C87) -> 83 | F24: =SUM(เฝือก!M5:M87) -> 5117538.2 | G24: 5117538.2 | H24: =F24-G24 -> 0
A25: 19 | B25: DBR/2570/0022 | C25: ไตเทียม | D25: หน่วยงานพัสดุ | E25: =COUNTA(ไตเทียม!C5:C54) -> 50 | F25: =SUM(ไตเทียม!M5:M54) -> 8050335.4 | G25: 8050335.4 | H25: =F25-G25 -> 0
A26: 20 | B26: DBR/2570/0023 | C26: ตรวจสวนหัวใจ | D26: แผนกศัลยกรรมหัวใจ ทรวงอก และหลอดเลือด | E26: =COUNTA(ตรวจสวนหัวใจ!C5:C157) -> 153 | F26: =SUM(ตรวจสวนหัวใจ!M5:M157) -> 109410695 | G26: 109410695 | H26: =F26-G26 -> 0
A27: 21 | B27: DBR/2570/0024 | C27: วิสัญญี | D27: งานการพยาบาลวิสัญญี | E27: =COUNTA(วิสัญญี!C5:C112) -> 108 | F27: =SUM(วิสัญญี!M5:M112) -> 2037294 | G27: 2037294 | H27: =F27-G27 -> 0
A28: 22 | B28: DBR/2570/0025 | C28: ENT | D28: หน่วยงานพัสดุ | E28: =COUNTA(ENT!C5:C12) -> 8 | F28: =SUM(ENT!M5:M12) -> 1732000 | G28: 1732000 | H28: =F28-G28 -> 0
A29: 23 | B29: DBR/2570/0026 | C29: โสต ศอ นาสิก | D29: หน่วยงานพัสดุ | E29: =COUNTA('โสต ศอ นาสิก'!C5:C17) -> 13 | F29: =SUM('โสต ศอ นาสิก'!M5:M17) -> 1732000 | G29: 1732000 | H29: =F29-G29 -> 0
A30: 24 | B30: DBR/2570/0027 | C30: ทั่วไป | D30: หน่วยงานพัสดุ | E30: =COUNTA(ทั่วไป!C5:C186) -> 182 | F30: =SUM(ทั่วไป!M5:M186) -> 48900026 | G30: 48900026 | H30: =F30-G30 -> 0
A31: 25 | B31: DBR/2570/0028 | C31: อื่นๆ | D31: หน่วยงานพัสดุ | E31: =COUNTA(อื่นๆ!C5:C18) -> 14 | F31: =SUM(อื่นๆ!M5:M18) -> 76291.5 | G31: 76291.5 | H31: =F31-G31 -> 0
A32: 26 | B32: DBR/2570/0029 | C32: โฆษณา | D32: งานประชาสัมพันธ์ | E32: =COUNTA(โฆษณา!C5:C67) -> 63 | F32: =SUM(โฆษณา!M5:M67) -> 246029.19 | G32: 246029.19 | H32: =F32-G32 -> 0
A33: 27 | B33: DBR/2570/0030 | C33: วัสดุคอมพิวเตอร์ | D33: กลุ่มภารกิจสุขภาพดิจิทัล | E33: =COUNTA(วัสดุคอมพิวเตอร์!C5:C90) -> 86 | F33: =SUM(วัสดุคอมพิวเตอร์!M5:M90) -> 961216.8 | G33: 961216.8 | H33: =F33-G33 -> 0
A34: 28 | B34: DBR/2570/0031 | C34: Wellness | D34: ศูนย์ Wellness | E34: =COUNTA(Wellness!C5:C39) -> 35 | F34: =SUM(Wellness!M5:M39) -> 2405640 | G34: 2405640 | H34: =F34-G34 -> 0
A35: รวม | E35: =SUM(E7:E34) -> 5646 | F35: =SUM(F7:F34) -> 1.3826368e+09 | G35: =SUM(G7:G34) -> 1.3826368e+09 | H35: =SUM(H7:H34) -> 0
A37: ยอดในระบบดึงจากเอกสาร DBR/2570/0004 ถึง DBR/2570/0031 ในฐาน VPK-S1 วันที่ 12 ต.ค. 2569 แหล่งเงินเงินบำรุง ปีงบประมาณ 2570 สถานะฉบับร่าง DBR/2570/0004 วัสดุสำนักงาน 513 รายการ ยอด 8,614,565.05 บาท ชื่อรายการที่ซ้ำในเอกสารเดียวกันเติม (ลำดับ n) ตามที่บันทึกในระบบ รหัสสินค้าของแท็บยาคัดจากข้อความ รหัสในไฟล์ ในหมายเหตุ

Sheet วัสดุสำนักงาน
A1: โรงพยาบาลวชิระภูเก็ต · คำของบวัสดุ ปี 2570 · แท็บ วัสดุสำนักงาน
A2: เลขที่เอกสาร | C2: DBR/2570/0004 | D2: หน่วยงาน | E2: หน่วยงานพัสดุ | H2: แหล่งเงิน | I2: เงินบำรุง | K2: ปีงบประมาณ | L2: 2570 | N2: สถานะ | O2: ฉบับร่าง
A3: ยอดในระบบ | C3: 8614565.1 | D3: ผลต่างจากรายการ | E3: =M518-C3 -> 0 | F3: ช่องรหัสสินค้าสีเหลืองกรอกหรือแก้รหัสได้ แท็บยาย้ายรหัสจากหมายเหตุมาไว้ในคอลัมน์นี้ ผลยืนยันเลือก ถูกต้อง / ต้องแก้ไข / ยังไม่ครบ / ข้าม มูลค่าที่ของบคำนวณจากปริมาณที่ของบ × ราคา/หน่วยนับ ยังไม่ผูกสินค้าในระบบ
A4: ลำดับ | B4: รหัสสินค้า | C4: รายการสินค้า | D4: ประเภทวัสดุ | E4: หน่วยนับ | F4: ปริมาณใช้ปี 2567 | G4: ปริมาณใช้ปี 2568 | H4: ปริมาณใช้ปี 2569 | I4: ปริมาณคงเหลือยกมา | J4: มูลค่าคงเหลือยกมา | K4: ปริมาณที่ของบ | L4: ราคา/หน่วยนับ | M4: มูลค่าที่ของบ | N4: หมายเหตุ | O4: ผลยืนยัน
A5: 1 | C5: DRUM BROTNER DR -2255 | D5: ค่าวัสดุสำนักงาน | E5: กล่อง | K5: 0 | L5: 2235 | M5: =IF(OR(K5="",L5=""),"",K5*L5) -> 0
A6: 2 | C6: Drum Ricch SP230 Unit (3019980) | D6: ค่าวัสดุสำนักงาน | E6: กล่อง | K6: 0 | L6: 3120 | M6: =IF(OR(K6="",L6=""),"",K6*L6) -> 0
A7: 3 | C7: Drum 32A CF 232A | D7: ค่าวัสดุสำนักงาน | E7: กล่อง | K7: 0 | L7: 3490 | M7: =IF(OR(K7="",L7=""),"",K7*L7) -> 0
A8: 4 | C8: DRUM BROTNER DR -2255 (ลำดับ 2) | D8: ค่าวัสดุสำนักงาน | E8: กล่อง | K8: 0 | L8: 2510 | M8: =IF(OR(K8="",L8=""),"",K8*L8) -> 0
A9: 5 | C9: Drum DR2355 | D9: ค่าวัสดุสำนักงาน | E9: กล่อง | K9: 0 | L9: 2300 | M9: =IF(OR(K9="",L9=""),"",K9*L9) -> 0
A10: 6 | C10: Drum HP (19A)219A | D10: ค่าวัสดุสำนักงาน | E10: กล่อง | K10: 0 | L10: 2740 | M10: =IF(OR(K10="",L10=""),"",K10*L10) -> 0
A11: 7 | C11: Drum HP(120) W1120A (3100011) | D11: ค่าวัสดุสำนักงาน | E11: กล่อง | K11: 0 | L11: 4408.4 | M11: =IF(OR(K11="",L11=""),"",K11*L11) -> 0
A12: 8 | C12: Drum OKI 431 | D12: ค่าวัสดุสำนักงาน | E12: กล่อง | K12: 0 | L12: 3290 | M12: =IF(OR(K12="",L12=""),"",K12*L12) -> 0
A13: 9 | C13: Drum Toner DL-410 | D13: ค่าวัสดุสำนักงาน | E13: กล่อง | K13: 0 | L13: 2180 | M13: =IF(OR(K13="",L13=""),"",K13*L13) -> 0
A14: 10 | C14: Drum Xerox 325 (3100032) | D14: ค่าวัสดุสำนักงาน | E14: กล่อง | K14: 0 | L14: 6313 | M14: =IF(OR(K14="",L14=""),"",K14*L14) -> 0
A15: 11 | C15: Mifare Care | D15: ค่าวัสดุสำนักงาน | E15: แผ่น | K15: 0 | L15: 19 | M15: =IF(OR(K15="",L15=""),"",K15*L15) -> 0
A16: 12 | C16: เข็มซ่อนปลาย | D16: ค่าวัสดุสำนักงาน | E16: พวง | K16: 150 | L16: 9 | M16: =IF(OR(K16="",L16=""),"",K16*L16) -> 1350
... A111: 107 | C111: กระดาษต่อเนื่อง ขนาด9x12 3ชั้น | D111: ค่าวัสดุสำนักงาน | E111: ลัง | K111: 0 | L111: 580 | M111: =IF(OR(K111="",L111=""),"",K111*L111) -> 0
A112: 108 | C112: กระดาษต่อเนื่อง ขนาด9x5.5 นิ้ว 2ชั้น | D112: ค่าวัสดุสำนักงาน | K112: 0 | L112: 680 | M112: =IF(OR(K112="",L112=""),"",K112*L112) -> 0
A113: 109 | C113: กระดาษต่อเนื่องขนาด9x11นิ้ว 2ชั้น | D113: ค่าวัสดุสำนักงาน | E113: ลัง | K113: 8 | L113: 690 | M113: =IF(OR(K113="",L113=""),"",K113*L113) -> 5520
A114: 110 | C114: กระดาษถ่ายเอกสาร A3 80G | D114: ค่าวัสดุสำนักงาน | E114: รีม | K114: 10 | L114: 270 | M114: =IF(OR(K114="",L114=""),"",K114*L114) -> 2700
A115: 111 | C115: กระดาษถ่ายเอกสารA4 70G | D115: ค่าวัสดุสำนักงาน | E115: รีม | K115: 12000 | L115: 98 | M115: =IF(OR(K115="",L115=""),"",K115*L115) -> 1176000
A116: 112 | C116: กระดาษถ่ายเอกสารA4 80G | D116: ค่าวัสดุสำนักงาน | E116: รีม | K116: 10000 | L116: 116 | M116: =IF(OR(K116="",L116=""),"",K116*L116) -> 1160000
A117: 113 | C117: กระดาษทำปกสีเขียว | D117: ค่าวัสดุสำนักงาน | E117: รีม | K117: 150 | L117: 100 | M117: =IF(OR(K117="",L117=""),"",K117*L117) -> 15000
A118: 114 | C118: กระดาษทำปกสีเหลือง | D118: ค่าวัสดุสำนักงาน | E118: รีม | K118: 500 | L118: 100 | M118: =IF(OR(K118="",L118=""),"",K118*L118) -> 50000
A119: 115 | C119: กระดาษทำปกสีครีม | D119: ค่าวัสดุสำนักงาน | E119: รีม | K119: 60 | L119: 100 | M119: =IF(OR(K119="",L119=""),"",K119*L119) -> 6000
A120: 116 | C120: กระดาษทำปกสีชมพู | D120: ค่าวัสดุสำนักงาน | E120: รีม | K120: 200 | L120: 100 | M120: =IF(OR(K120="",L120=""),"",K120*L120) -> 20000
A121: 117 | C121: กระดาษทำปกสีฟ้า | D121: ค่าวัสดุสำนักงาน | E121: รีม | K121: 200 | L121: 100 | M121: =IF(OR(K121="",L121=""),"",K121*L121) -> 20000
A122: 118 | C122: กระดาษทำปกสีม่วง | D122: ค่าวัสดุสำนักงาน | E122: รีม | K122: 120 | L122: 100 | M122: =IF(OR(K122="",L122=""),"",K122*L122) -> 12000
A123: 119 | C123: กระดาษทำปกสีส้ม | D123: ค่าวัสดุสำนักงาน | E123: รีม | K123: 120 | L123: 100 | M123: =IF(OR(K123="",L123=""),"",K123*L123) -> 12000
A124: 120 | C124: กระดาษบวกเลข | D124: ค่าวัสดุสำนักงาน | E124: ม้วน | K124: 500 | L124: 37.5 | M124: =IF(OR(K124="",L124=""),"",K124*L124) -> 18750
... A204: 200 | C204: ตุู้ลิ้นชักพลาสติก | D204: ค่าวัสดุสำนักงาน | E204: ใบ | K204: 0 | L204: 980 | M204: =IF(OR(K204="",L204=""),"",K204*L204) -> 0
A205: 201 | C205: ตู้เอกสาร | D205: ค่าวัสดุสำนักงาน | K205: 4 | L205: 750 | M205: =IF(OR(K205="",L205=""),"",K205*L205) -> 3000
A206: 202 | C206: ถ่านไฟฉาย ขนาดกลาง สีดำ | D206: ค่าวัสดุสำนักงาน | E206: ก้อน | K206: 150 | L206: 35 | M206: =IF(OR(K206="",L206=""),"",K206*L206) -> 5250
A207: 203 | C207: ถ่านไฟฉายก้อนเล็ก(4ก้อน/1ชุด) | D207: ค่าวัสดุสำนักงาน | E207: ก้อน | K207: 0 | L207: 8.75 | M207: =IF(OR(K207="",L207=""),"",K207*L207) -> 0
A208: 204 | C208: ถ่านไฟฉายก้อนใหญ่(2ก้อน/1ชุด) | D208: ค่าวัสดุสำนักงาน | E208: ชุด | K208: 130 | L208: 20 | M208: =IF(OR(K208="",L208=""),"",K208*L208) -> 2600
A209: 205 | C209: ถ่านไฟฉายอัลคาไลน์ ขนาดกลาง | D209: ค่าวัสดุสำนักงาน | E209: ก้อน | K209: 400 | L209: 70 | M209: =IF(OR(K209="",L209=""),"",K209*L209) -> 28000
A210: 206 | C210: ถ่านไฟฉายอัลคาไลน์2A | D210: ค่าวัสดุสำนักงาน | E210: ชุด | K210: 4000 | L210: 55 | M210: =IF(OR(K210="",L210=""),"",K210*L210) -> 220000
A211: 207 | C211: ถ่านไฟฉายอัลคาไลน์3A | D211: ค่าวัสดุสำนักงาน | E211: ชุด | K211: 3000 | L211: 55 | M211: =IF(OR(K211="",L211=""),"",K211*L211) -> 165000
A212: 208 | C212: ถ่านดูราเซลล์ 9 โวล | D212: ค่าวัสดุสำนักงาน | E212: ชุด | K212: 80 | L212: 100 | M212: =IF(OR(K212="",L212=""),"",K212*L212) -> 8000
A213: 209 | C213: ที่เหลาดินสอ | D213: ค่าวัสดุสำนักงาน | E213: ตัว | K213: 40 | L213: 290 | M213: =IF(OR(K213="",L213=""),"",K213*L213) -> 11600
...

Sheet งานบ้าน
A1: โรงพยาบาลวชิระภูเก็ต · คำของบวัสดุ ปี 2570 · แท็บ งานบ้าน
A2: เลขที่เอกสาร | C2: DBR/2570/0005 | D2: หน่วยงาน | E2: หน่วยงานพัสดุ | H2: แหล่งเงิน | I2: เงินบำรุง | K2: ปีงบประมาณ | L2: 2570 | N2: สถานะ | O2: ฉบับร่าง
A3: ยอดในระบบ | C3: 19680885 | D3: ผลต่างจากรายการ | E3: =M433-C3 -> 0 | F3: ช่องรหัสสินค้าสีเหลืองกรอกหรือแก้รหัสได้ แท็บยาย้ายรหัสจากหมายเหตุมาไว้ในคอลัมน์นี้ ผลยืนยันเลือก ถูกต้อง / ต้องแก้ไข / ยังไม่ครบ / ข้าม มูลค่าที่ของบคำนวณจากปริมาณที่ของบ × ราคา/หน่วยนับ ยังไม่ผูกสินค้าในระบบ
A4: ลำดับ | B4: รหัสสินค้า | C4: รายการสินค้า | D4: ประเภทวัสดุ | E4: หน่วยนับ | F4: ปริมาณใช้ปี 2567 | G4: ปริมาณใช้ปี 2568 | H4: ปริมาณใช้ปี 2569 | I4: ปริมาณคงเหลือยกมา | J4: มูลค่าคงเหลือยกมา | K4: ปริมาณที่ของบ | L4: ราคา/หน่วยนับ | M4: มูลค่าที่ของบ | N4: หมายเหตุ | O4: ผลยืนยัน
A5: 1 | C5: เกลือ | D5: งานบ้าน+น้ำดื่ม | E5: กิโลกรัม | K5: 2 | L5: 450 | M5: =IF(OR(K5="",L5=""),"",K5*L5) -> 900
A6: 2 | C6: เก้าอี้พนังพิงตั้งแขน สีขาว | D6: งานบ้าน+น้ำดื่ม | E6: ตัว | K6: 0 | L6: 290 | M6: =IF(OR(K6="",L6=""),"",K6*L6) -> 0
A7: 3 | C7: เก้าอี้ยืน สแตนเลสพร้อมแผ่นรองกันลื่น | D7: งานบ้าน+น้ำดื่ม | E7: ตัว | K7: 0 | L7: 6000 | M7: =IF(OR(K7="",L7=""),"",K7*L7) -> 0
A8: 4 | C8: เก้าอี้หัวล้าน | D8: งานบ้าน+น้ำดื่ม | E8: ตัว | K8: 12 | L8: 120 | M8: =IF(OR(K8="",L8=""),"",K8*L8) -> 1440
A9: 5 | C9: เครื่องชั่งพลาสติก | D9: งานบ้าน+น้ำดื่ม | E9: ชุด | K9: 0 | L9: 320 | M9: =IF(OR(K9="",L9=""),"",K9*L9) -> 0
A10: 6 | C10: เครื่องปั่นอาหารเหลว | D10: งานบ้าน+น้ำดื่ม | E10: เครื่อง | K10: 2 | L10: 22500 | M10: =IF(OR(K10="",L10=""),"",K10*L10) -> 45000
A11: 7 | C11: เชือกฟาง | D11: งานบ้าน+น้ำดื่ม | E11: ม้วน | K11: 1500 | L11: 30 | M11: =IF(OR(K11="",L11=""),"",K11*L11) -> 45000
A12: 8 | C12: เซ็ทผ้าคลุมเตียง | D12: งานบ้าน+น้ำดื่ม | K12: 6 | L12: 1400 | M12: =IF(OR(K12="",L12=""),"",K12*L12) -> 8400
A13: 9 | C13: เตาแก๊ส 2 หัว | D13: งานบ้าน+น้ำดื่ม | E13: อัน | K13: 2 | L13: 45000 | M13: =IF(OR(K13="",L13=""),"",K13*L13) -> 90000
A14: 10 | C14: เตาแก๊ส KBS | D14: งานบ้าน+น้ำดื่ม | E14: อัน | K14: 0 | L14: 50000 | M14: =IF(OR(K14="",L14=""),"",K14*L14) -> 0
A15: 11 | C15: เตาแก๊ส วางหัว เหลี่ยมสูงมีบังลม | D15: งานบ้าน+น้ำดื่ม | E15: อัน | K15: 1 | L15: 400 | M15: =IF(OR(K15="",L15=""),"",K15*L15) -> 400
A16: 12 | C16: เทียนหอม | D16: งานบ้าน+น้ำดื่ม | E16: ชิ้น | K16: 100 | L16: 44.94 | M16: =IF(OR(K16="",L16=""),"",K16*L16) -> 4494
A17: 13 | C17: เทียนอุ่นอาหาร | D17: งานบ้าน+น้ำดื่ม | E17: แพ็ค | K17: 0 | L17: 50.8 | M17: =IF(OR(K17="",L17=""),"",K17*L17) -> 0
A18: 14 | C18: เบาะรถเข็นเปลนอน | D18: งานบ้าน+น้ำดื่ม | E18: หลัง | K18: 10 | L18: 2000 | M18: =IF(OR(K18="",L18=""),"",K18*L18) -> 20000
A19: 15 | C19: เบาะรองนอน | D19: งานบ้าน+น้ำดื่ม | E19: หลัง | K19: 0 | L19: 17000 | M19: =IF(OR(K19="",L19=""),"",K19*L19) -> 0
A20: 16 | C20: เสื้อกันฝน | D20: งานบ้าน+น้ำดื่ม | E20: ชุด | K20: 0 | L20: 192.6 | M20: =IF(OR(K20="",L20=""),"",K20*L20) -> 0
A21: 17 | C21: เหยือกน้ำ | D21: งานบ้าน+น้ำดื่ม | E21: ใบ | K21: 0 | L21: 40 | M21: =IF(OR(K21="",L21=""),"",K21*L21) -> 0
A22: 18 | C22: เหยือกน้ำพลาสติก1000 | D22: งานบ้าน+น้ำดื่ม | E22: ใบ | K22: 350 | L22: 120 | M22: =IF(OR(K22="",L22=""),"",K22*L22) -> 42000
A23: 19 | C23: เหยือกน้ำพลาสติก1000 ไม่มีสเกว | D23: งานบ้าน+น้ำดื่ม | E23: ใบ | K23: 200 | L23: 120 | M23: =IF(OR(K23="",L23=""),"",K23*L23) -> 24000
A24: 20 | C24: แก้วกาแฟ | D24: งานบ้าน+น้ำดื่ม | E24: ลัง | K24: 2 | L24: 1250 | M24: =IF(OR(K24="",L24=""),"",K24*L24) -> 2500
... A285: 281 | C285: น้ำดื่มแซนด์บรรจุถังใส 19ลิตร | D285: งานบ้าน+น้ำดื่ม | E285: ถัง | K285: 25000 | L285: 16.98 | M285: =IF(OR(K285="",L285=""),"",K285*L285) -> 424500
A286: 282 | C286: น้ำดื่มถ้วย ขนาด220ซีซี | D286: งานบ้าน+น้ำดื่ม | K286: 0 | L286: 1.35 | M286: =IF(OR(K286="",L286=""),"",K286*L286) -> 0
A287: 283 | C287: น้ำตาลทรายแดง | D287: งานบ้าน+น้ำดื่ม | E287: กระสอบ | K287: 6 | L287: 743.75 | M287: =IF(OR(K287="",L287=""),"",K287*L287) -> 4462.5
A288: 284 | C288: น้ำมันจักรซิงเกอร์ | D288: งานบ้าน+น้ำดื่ม | E288: ขวด | K288: 0 | L288: 10 | M288: =IF(OR(K288="",L288=""),"",K288*L288) -> 0
A289: 285 | C289: น้ำยาเคมีซักฟอกสำหรับเครื่องชนิดน้ำ ขนาดบรรจุ20ลิตร | D289: งานบ้าน+น้ำดื่ม | E289: ถัง | K289: 507 | L289: 1401.7 | M289: =IF(OR(K289="",L289=""),"",K289*L289) -> 710661.9
A290: 286 | C290: น้ำยาเคมีฟอกผ้าขาวชนิดน้ำ ขนาดบรรจุ20ลิตร | D290: งานบ้าน+น้ำดื่ม | E290: ถัง | K290: 4 | L290: 642 | M290: =IF(OR(K290="",L290=""),"",K290*L290) -> 2568
A291: 287 | C291: น้ำยาเคลือบเงาพื้นคอมพลีท | D291: งานบ้าน+น้ำดื่ม | E291: แกลลอน | K291: 96 | L291: 877.4 | M291: =IF(OR(K291="",L291=""),"",K291*L291) -> 84230.4
A292: 288 | C292: น้ำยาเช็ดกระจก | D292: งานบ้าน+น้ำดื่ม | E292: ขวด | K292: 0 | L292: 171.2 | M292: =IF(OR(K292="",L292=""),"",K292*L292) -> 0
A293: 289 | C293: น้ำยาเสริมด่างชนิดเหลว ขนาดบรรจุ20ลิตร | D293: งานบ้าน+น้ำดื่ม | E293: ถัง | K293: 522 | L293: 781.1 | M293: =IF(OR(K293="",L293=""),"",K293*L293) -> 407734.2
A294: 290 | C294: น้ำยาไฮเตอร์ | D294: งานบ้าน+น้ำดื่ม | E294: ขวด | K294: 912 | L294: 35 | M294: =IF(OR(K294="",L294=""),"",K294*L294) -> 31920
A295: 291 | C295: น้ำยาช่วยให้ภาชนะแห้งเร็ว ขนาด 20 ลิตร | D295: งานบ้าน+น้ำดื่ม | E295: ถัง | K295: 63 | L295: 2782 | M295: =IF(OR(K295="",L295=""),"",K295*L295) -> 175266
A296: 292 | C296: น้ำยาดันฝุ่น | D296: งานบ้าน+น้ำดื่ม | E296: แกลลอน | K296: 12 | L296: 1786.9 | M296: =IF(OR(K296="",L296=""),"",K296*L296) -> 21442.8
A297: 293 | C297: น้ำยาถูพื้นสไตรด์ฟลอรัล | D297: งานบ้าน+น้ำดื่ม | E297: แกลลอน | K297: 240 | L297: 642 | M297: =IF(OR(K297="",L297=""),"",K297*L297) -> 154080
A298: 294 | C298: น้ำยาปรับผ้านุ่ม ขนาดบรรจุ 20ลิตร | D298: งานบ้าน+น้ำดื่ม | E298: ถัง | K298: 503 | L298: 832.46 | M298: =IF(OR(K298="",L298=""),"",K298*L298) -> 418727.38
... A408: 404 | C408: สก็อตไบร์ทมีฟองน้ำ | D408: งานบ้าน+น้ำดื่ม | E408: ชิ้น | K408: 10000 | L408: 5 | M408: =IF(OR(K408="",L408=""),"",K408*L408) -> 50000
A409: 405 | C409: สก๊อตไบร์ทมีฟองน้ำ3เอ็ม แผ่นใหญ่ ขนาด3.5x6นิ้ว | D409: งานบ้าน+น้ำดื่ม | K409: 1200 | L409: 13.91 | M409: =IF(OR(K409="",L409=""),"",K409*L409) -> 16692
...

Sheet เชื้อเพลิง
A1: โรงพยาบาลวชิระภูเก็ต · คำของบวัสดุ ปี 2570 · แท็บ เชื้อเพลิง
A2: เลขที่เอกสาร | C2: DBR/2570/0006 | D2: หน่วยงาน | E2: หน่วยงานพัสดุ | H2: แหล่งเงิน | I2: เงินบำรุง | K2: ปีงบประมาณ | L2: 2570 | N2: สถานะ | O2: ฉบับร่าง
A3: ยอดในระบบ | C3: 9633924 | D3: ผลต่างจากรายการ | E3: =M8-C3 -> 0 | F3: ช่องรหัสสินค้าสีเหลืองกรอกหรือแก้รหัสได้ แท็บยาย้ายรหัสจากหมายเหตุมาไว้ในคอลัมน์นี้ ผลยืนยันเลือก ถูกต้อง / ต้องแก้ไข / ยังไม่ครบ / ข้าม มูลค่าที่ของบคำนวณจากปริมาณที่ของบ × ราคา/หน่วยนับ ยังไม่ผูกสินค้าในระบบ
A4: ลำดับ | B4: รหัสสินค้า | C4: รายการสินค้า | D4: ประเภทวัสดุ | E4: หน่วยนับ | F4: ปริมาณใช้ปี 2567 | G4: ปริมาณใช้ปี 2568 | H4: ปริมาณใช้ปี 2569 | I4: ปริมาณคงเหลือยกมา | J4: มูลค่าคงเหลือยกมา | K4: ปริมาณที่ของบ | L4: ราคา/หน่วยนับ | M4: มูลค่าที่ของบ | N4: หมายเหตุ | O4: ผลยืนยัน
A5: 1 | C5: จำนวนประมาณการจะซื้อปี 70 แก๊ส LPG ขนาดบรรจุ 48 กิโลกรัม | D5: แก๊ส LPG | E5: ถัง | K5: 60 | L5: 455 | M5: =IF(OR(K5="",L5=""),"",K5*L5) -> 27300
A6: 2 | C6: จำนวนประมาณการจะซื้อปี 70 แก๊ส LPG ขนาดบรรจุ 48 กิโลกรัม (ลำดับ 2) | D6: แก๊ส LPG | E6: ถัง | K6: 6000 | L6: 1423 | M6: =IF(OR(K6="",L6=""),"",K6*L6) -> 8538000
A7: 3 | C7: เชื้อเพลิงยานพาหนะ | D7: เชื้อเพลิงรถยนต์ | K7: 1 | L7: 1068624 | M7: =IF(OR(K7="",L7=""),"",K7*L7) -> 1068624
A8: รวม | K8: =SUM(K5:K7) -> 6061 | M8: =SUM(M5:M7) -> 9633924
A9: รวม 3 รายการ · DBR/2570/0006 · แท็บ เชื้อเพลิง · หน่วยงาน หน่วยงานพัสดุ · โมเดล departmental.budget.request.material.detail · ส่งออกจากฐาน VPK-S1 วันที่ 12 ต.ค. 2569 · ต้นทางไฟล์ แบบฟอร์มที่ 3 แผนปีงบประมาณ 2570 หมวดวัสดุ.xlsx

Sheet เครื่องแต่งกาย
A1: โรงพยาบาลวชิระภูเก็ต · คำของบวัสดุ ปี 2570 · แท็บ เครื่องแต่งกาย
A2: เลขที่เอกสาร | C2: DBR/2570/0007 | D2: หน่วยงาน | E2: งานซักฟอกและตัดเย็บ | H2: แหล่งเงิน | I2: เงินบำรุง | K2: ปีงบประมาณ | L2: 2570 | N2: สถานะ | O2: ฉบับร่าง
A3: ยอดในระบบ | C3: 2699621.6 | D3: ผลต่างจากรายการ | E3: =M104-C3 -> 0 | F3: ช่องรหัสสินค้าสีเหลืองกรอกหรือแก้รหัสได้ แท็บยาย้ายรหัสจากหมายเหตุมาไว้ในคอลัมน์นี้ ผลยืนยันเลือก ถูกต้อง / ต้องแก้ไข / ยังไม่ครบ / ข้าม มูลค่าที่ของบคำนวณจากปริมาณที่ของบ × ราคา/หน่วยนับ ยังไม่ผูกสินค้าในระบบ
A4: ลำดับ | B4: รหัสสินค้า | C4: รายการสินค้า | D4: ประเภทวัสดุ | E4: หน่วยนับ | F4: ปริมาณใช้ปี 2567 | G4: ปริมาณใช้ปี 2568 | H4: ปริมาณใช้ปี 2569 | I4: ปริมาณคงเหลือยกมา | J4: มูลค่าคงเหลือยกมา | K4: ปริมาณที่ของบ | L4: ราคา/หน่วยนับ | M4: มูลค่าที่ของบ | N4: หมายเหตุ | O4: ผลยืนยัน
A5: 1 | C5: กางเกงผู้ป่วย มีหูรูด | D5: เครื่องแต่งกาย (ซักฟอกและตัดเย็บ) | E5: ตัว | K5: 0 | L5: 145 | M5: =IF(OR(K5="",L5=""),"",K5*L5) -> 0
A6: 2 | C6: เสื้อเด็ก+กางเกงเด็กเล็ก (3015285) | D6: เครื่องแต่งกาย (ซักฟอกและตัดเย็บ) | E6: ชุด | K6: 20 | L6: 220 | M6: =IF(OR(K6="",L6=""),"",K6*L6) -> 4400
A7: 3 | C7: เสื้อเด็ก+กางเกงเด็กโค (3015286) | D7: เครื่องแต่งกาย (ซักฟอกและตัดเย็บ) | E7: ชุด | K7: 20 | L7: 300 | M7: =IF(OR(K7="",L7=""),"",K7*L7) -> 6000
A8: 4 | C8: เสื้อเด็กและกางเกงเด็ก | D8: เครื่องแต่งกาย (ซักฟอกและตัดเย็บ) | E8: ชุด | K8: 0 | L8: 255 | M8: =IF(OR(K8="",L8=""),"",K8*L8) -> 0
A9: 5 | C9: เสื้อกั๊ก สีขาว | D9: เครื่องแต่งกาย (ซักฟอกและตัดเย็บ) | E9: ตัว | K9: 0 | L9: 604.55 | M9: =IF(OR(K9="",L9=""),"",K9*L9) -> 0
A10: 6 | C10: เสื้อกาวน์ สีเขียวอ่อน | D10: เครื่องแต่งกาย (ซักฟอกและตัดเย็บ) | E10: ตัว | K10: 0 | L10: 339 | M10: =IF(OR(K10="",L10=""),"",K10*L10) -> 0
A11: 7 | C11: เสื้อกาวน์แขนยาว | D11: เครื่องแต่งกาย (ซักฟอกและตัดเย็บ) | E11: ผืน | K11: 0 | L11: 330 | M11: =IF(OR(K11="",L11=""),"",K11*L11) -> 0
A12: 8 | C12: เสื้อกิโมโนตัวยาว (3017845) | D12: เครื่องแต่งกาย (ซักฟอกและตัดเย็บ) | E12: ตัว | K12: 20 | L12: 305 | M12: =IF(OR(K12="",L12=""),"",K12*L12) -> 6100
A13: 9 | C13: เสื้อคลุมอาบน้ำ (3013931) | D13: เครื่องแต่งกาย (ซักฟอกและตัดเย็บ) | E13: ตัว | K13: 24 | L13: 663.4 | M13: =IF(OR(K13="",L13=""),"",K13*L13) -> 15921.6
A14: 10 | C14: เสื้อผ้าผู้ป่วย (3017587) | D14: เครื่องแต่งกาย (ซักฟอกและตัดเย็บ) | E14: ตัว | K14: 300 | L14: 170 | M14: =IF(OR(K14="",L14=""),"",K14*L14) -> 51000
A15: 11 | C15: เสื้อผ้าผู้ป่วย ป้ายหน้า (3018166) | D15: เครื่องแต่งกาย (ซักฟอกและตัดเย็บ) | E15: ตัว | K15: 100 | L15: 175 | M15: =IF(OR(K15="",L15=""),"",K15*L15) -> 17500
A16: 12 | C16: เสื้อผ้าผู้ป่วย ป้ายหน้า OR (3018612) | D16: เครื่องแต่งกาย (ซักฟอกและตัดเย็บ) | E16: ตัว | K16: 50 | L16: 190 | M16: =IF(OR(K16="",L16=""),"",K16*L16) -> 9500
... A103: 99 | C103: ผ้าอ้อม สีขาว ขนาด27x34นิ้ว | D103: เครื่องแต่งกาย (ซักฟอกและตัดเย็บ) | E103: ผืน | K103: 0 | L103: 95 | M103: =IF(OR(K103="",L103=""),"",K103*L103) -> 0
A104: รวม | K104: =SUM(K5:K103) -> 26154 | M104: =SUM(M5:M103) -> 2699621.6
A105: รวม 99 รายการ · DBR/2570/0007 · แท็บ เครื่องแต่งกาย · หน่วยงาน งานซักฟอกและตัดเย็บ · โมเดล departmental.budget.request.material.detail · ส่งออกจากฐาน VPK-S1 วันที่ 12 ต.ค. 2569 · ต้นทางไฟล์ แบบฟอร์มที่ 3 แผนปีงบประมาณ 2570 หมวดวัสดุ.xlsx

Sheet ออกซิเจนเหลว
A1: โรงพยาบาลวชิระภูเก็ต · คำของบวัสดุ ปี 2570 · แท็บ ออกซิเจนเหลว
A2: เลขที่เอกสาร | C2: DBR/2570/0008 | D2: หน่วยงาน | E2: หน่วยงานพัสดุ | H2: แหล่งเงิน | I2: เงินบำรุง | K2: ปีงบประมาณ | L2: 2570 | N2: สถานะ | O2: ฉบับร่าง
A3: ยอดในระบบ | C3: 10018000 | D3: ผลต่างจากรายการ | E3: =M8-C3 -> 0 | F3: ช่องรหัสสินค้าสีเหลืองกรอกหรือแก้รหัสได้ แท็บยาย้ายรหัสจากหมายเหตุมาไว้ในคอลัมน์นี้ ผลยืนยันเลือก ถูกต้อง / ต้องแก้ไข / ยังไม่ครบ / ข้าม มูลค่าที่ของบคำนวณจากปริมาณที่ของบ × ราคา/หน่วยนับ ยังไม่ผูกสินค้าในระบบ
A4: ลำดับ | B4: รหัสสินค้า | C4: รายการสินค้า | D4: ประเภทวัสดุ | E4: หน่วยนับ | F4: ปริมาณใช้ปี 2567 | G4: ปริมาณใช้ปี 2568 | H4: ปริมาณใช้ปี 2569 | I4: ปริมาณคงเหลือยกมา | J4: มูลค่าคงเหลือยกมา | K4: ปริมาณที่ของบ | L4: ราคา/หน่วยนับ | M4: มูลค่าที่ของบ | N4: หมายเหตุ | O4: ผลยืนยัน
A5: 1 | C5: จำนวนประมาณการจะซื้อปี 70 ออกซิเจนเหลวทางการแพทย์บรรจุท่อพร้อมอุปกรณ์ลดแรงดัน ขนาด 0.7 ลูกบาศก์เมตร | D5: ออกซิเจนเหลว | E5: ถัง | K5: 4000 | L5: 294 | M5: =IF(OR(K5="",L5=""),"",K5*L5) -> 1176000
A6: 2 | C6: จำนวนประมาณการจะซื้อปี 70 แก๊สไนตรัสออกไซด์ทางการแพทย์อัดท่อแรงดันสูงขนาดบรรจุ 25 กิโลกรัม | D6: แก๊ส LPG | E6: ถัง | K6: 400 | L6: 4085 | M6: =IF(OR(K6="",L6=""),"",K6*L6) -> 1634000
A7: 3 | C7: จำนวนประมาณการจะซื้อปี 70 ออกซิเจนเหลวทางการแพทย์ | D7: ออกซิเจนเหลว | K7: 800000 | L7: 9.01 | M7: =IF(OR(K7="",L7=""),"",K7*L7) -> 7208000
A8: รวม | K8: =SUM(K5:K7) -> 804400 | M8: =SUM(M5:M7) -> 10018000
A9: รวม 3 รายการ · DBR/2570/0008 · แท็บ ออกซิเจนเหลว · หน่วยงาน หน่วยงานพัสดุ · โมเดล departmental.budget.request.material.detail · ส่งออกจากฐาน VPK-S1 วันที่ 12 ต.ค. 2569 · ต้นทางไฟล์ แบบฟอร์มที่ 3 แผนปีงบประมาณ 2570 หมวดวัสดุ.xlsx

Sheet Lab
A1: โรงพยาบาลวชิระภูเก็ต · คำของบวัสดุ ปี 2570 · แท็บ Lab
A2: เลขที่เอกสาร | C2: DBR/2570/0009 | D2: หน่วยงาน | E2: กลุ่มงานเทคนิคการแพทย์ฯ | H2: แหล่งเงิน | I2: เงินบำรุง | K2: ปีงบประมาณ | L2: 2570 | N2: สถานะ | O2: ฉบับร่าง
A3: ยอดในระบบ | C3: 53413677 | D3: ผลต่างจากรายการ | E3: =M298-C3 -> 0 | F3: ช่องรหัสสินค้าสีเหลืองกรอกหรือแก้รหัสได้ แท็บยาย้ายรหัสจากหมายเหตุมาไว้ในคอลัมน์นี้ ผลยืนยันเลือก ถูกต้อง / ต้องแก้ไข / ยังไม่ครบ / ข้าม มูลค่าที่ของบคำนวณจากปริมาณที่ของบ × ราคา/หน่วยนับ ยังไม่ผูกสินค้าในระบบ
A4: ลำดับ | B4: รหัสสินค้า | C4: รายการสินค้า | D4: ประเภทวัสดุ | E4: หน่วยนับ | F4: ปริมาณใช้ปี 2567 | G4: ปริมาณใช้ปี 2568 | H4: ปริมาณใช้ปี 2569 | I4: ปริมาณคงเหลือยกมา | J4: มูลค่าคงเหลือยกมา | K4: ปริมาณที่ของบ | L4: ราคา/หน่วยนับ | M4: มูลค่าที่ของบ | N4: หมายเหตุ | O4: ผลยืนยัน
A5: 1 | C5: EDTA K3 Tube 3 ml. | D5: LAB (ทั่วไป) | K5: 1 | L5: 504000 | M5: =IF(OR(K5="",L5=""),"",K5*L5) -> 504000 | N5: เงินบำรุงรพ.งบ 70 e-bidding
A6: 2 | C6: Lithium Heparin Tube 4 ml. | D6: LAB (ทั่วไป) | K6: 1 | L6: 540000 | M6: =IF(OR(K6="",L6=""),"",K6*L6) -> 540000 | N6: เงินบำรุงรพ.งบ 70 e-bidding
A7: 3 | C7: Serum Clot Activator Tube 4 ml. | D7: LAB (ทั่วไป) | K7: 1 | L7: 196000 | M7: =IF(OR(K7="",L7=""),"",K7*L7) -> 196000 | N7: เงินบำรุงรพ.งบ 70 e-bidding
A8: 4 | C8: Sodium Citrate Tube 3 ml. | D8: LAB (ทั่วไป) | K8: 1 | L8: 118800 | M8: =IF(OR(K8="",L8=""),"",K8*L8) -> 118800 | N8: เงินบำรุงรพ.งบ 70 e-bidding
A9: 5 | C9: Sodium Fluoride Tube 2 ml. | D9: LAB (ทั่วไป) | K9: 1 | L9: 465000 | M9: =IF(OR(K9="",L9=""),"",K9*L9) -> 465000 | N9: เงินบำรุงรพ.งบ 70 e-bidding
A10: 6 | C10: แถบตรวจน้ำตาลในเลือดปลายนิ้ว (Blood Glucose Strip) | D10: LAB (ทั่วไป) | K10: 1 | L10: 1572000 | M10: =IF(OR(K10="",L10=""),"",K10*L10) -> 1572000 | N10: เงินบำรุงรพ.งบ 70 e-bidding
A11: 7 | C11: BUN | D11: LAB (ทั่วไป) | K11: 1 | L11: 466092 | M11: =IF(OR(K11="",L11=""),"",K11*L11) -> 466092 | N11: เงินบำรุงรพ.งบ 70 e-bidding แผนการ 3 ปี (แผนการใช้ปีงบ 70)
A12: 8 | C12: Creatinine (enzymatic) | D12: LAB (ทั่วไป) | K12: 1 | L12: 755492 | M12: =IF(OR(K12="",L12=""),"",K12*L12) -> 755492 | N12: เงินบำรุงรพ.งบ 70 e-bidding แผนการ 3 ปี (แผนการใช้ปีงบ 70)
A13: 9 | C13: Sodium | D13: LAB (ทั่วไป) | K13: 1 | L13: 517880 | M13: =IF(OR(K13="",L13=""),"",K13*L13) -> 517880 | N13: เงินบำรุงรพ.งบ 70 e-bidding แผนการ 3 ปี (แผนการใช้ปีงบ 70)
A14: 10 | C14: Potassium | D14: LAB (ทั่วไป) | K14: 1 | L14: 569668 | M14: =IF(OR(K14="",L14=""),"",K14*L14) -> 569668 | N14: เงินบำรุงรพ.งบ 70 e-bidding แผนการ 3 ปี (แผนการใช้ปีงบ 70)
A15: 11 | C15: Chloride | D15: LAB (ทั่วไป) | K15: 1 | L15: 517880 | M15: =IF(OR(K15="",L15=""),"",K15*L15) -> 517880 | N15: เงินบำรุงรพ.งบ 70 e-bidding แผนการ 3 ปี (แผนการใช้ปีงบ 70)
A16: 12 | C16: ECO2 | D16: LAB (ทั่วไป) | K16: 1 | L16: 479039 | M16: =IF(OR(K16="",L16=""),"",K16*L16) -> 479039 | N16: เงินบำรุงรพ.งบ 70 e-bidding แผนการ 3 ปี (แผนการใช้ปีงบ 70)
... A297: 293 | C297: Urinanalysis Control Levels 1 and 2 12X12 ml. | D297: LAB (ทั่วไป) | K297: 1 | L297: 9000 | M297: =IF(OR(K297="",L297=""),"",K297*L297) -> 9000 | N297: เงินบำรุงรพ.งบ 70 เฉพาะเจาะจง
A298: รวม | K298: =SUM(K5:K297) -> 293 | M298: =SUM(M5:M297) -> 53413677
A299: รวม 293 รายการ · DBR/2570/0009 · แท็บ Lab · หน่วยงาน กลุ่มงานเทคนิคการแพทย์ฯ · โมเดล departmental.budget.request.material.detail · ส่งออกจากฐาน VPK-S1 วันที่ 12 ต.ค. 2569 · ต้นทางไฟล์ แบบฟอร์มที่ 3 แผนปีงบประมาณ 2570 หมวดวัสดุ.xlsx

Sheet LabCOVID
A1: โรงพยาบาลวชิระภูเก็ต · คำของบวัสดุ ปี 2570 · แท็บ LabCOVID
A2: เลขที่เอกสาร | C2: DBR/2570/0010 | D2: หน่วยงาน | E2: กลุ่มงานเทคนิคการแพทย์ฯ | H2: แหล่งเงิน | I2: เงินบำรุง | K2: ปีงบประมาณ | L2: 2570 | N2: สถานะ | O2: ฉบับร่าง
A3: ยอดในระบบ | C3: 998960 | D3: ผลต่างจากรายการ | E3: =M7-C3 -> 0 | F3: ช่องรหัสสินค้าสีเหลืองกรอกหรือแก้รหัสได้ แท็บยาย้ายรหัสจากหมายเหตุมาไว้ในคอลัมน์นี้ ผลยืนยันเลือก ถูกต้อง / ต้องแก้ไข / ยังไม่ครบ / ข้าม มูลค่าที่ของบคำนวณจากปริมาณที่ของบ × ราคา/หน่วยนับ ยังไม่ผูกสินค้าในระบบ
A4: ลำดับ | B4: รหัสสินค้า | C4: รายการสินค้า | D4: ประเภทวัสดุ | E4: หน่วยนับ | F4: ปริมาณใช้ปี 2567 | G4: ปริมาณใช้ปี 2568 | H4: ปริมาณใช้ปี 2569 | I4: ปริมาณคงเหลือยกมา | J4: มูลค่าคงเหลือยกมา | K4: ปริมาณที่ของบ | L4: ราคา/หน่วยนับ | M4: มูลค่าที่ของบ | N4: หมายเหตุ | O4: ผลยืนยัน
A5: 1 | C5: ชุดทดสอบหาแอนติเจนต่อเชื้อ SARS-CoV-2 แบบรวดเร็ว (SARS-CoV-2 Rapid Antigen Test) | D5: LAB-COVID | K5: 1 | L5: 500000 | M5: =IF(OR(K5="",L5=""),"",K5*L5) -> 500000 | N5: เงินบำรุงรพ.งบ 70 เฉพาะเจาะจง
A6: 2 | C6: ชุดน้ำยาตรวจหาเชื้อไวรัสโคโรนา 2019-nCoV Ag และเชื้อไวรัสไข้หวัดใหญ่ ชนิดเอ, เชื้อไวรัสไข้หวัดใหญ่ ชนิดบี แบบรวดเร็ว | D6: LAB-COVID | K6: 1 | L6: 498960 | M6: =IF(OR(K6="",L6=""),"",K6*L6) -> 498960 | N6: เงินบำรุงรพ.งบ 70 เฉพาะเจาะจง
A7: รวม | K7: =SUM(K5:K6) -> 2 | M7: =SUM(M5:M6) -> 998960
A8: รวม 2 รายการ · DBR/2570/0010 · แท็บ LabCOVID · หน่วยงาน กลุ่มงานเทคนิคการแพทย์ฯ · โมเดล departmental.budget.request.material.detail · ส่งออกจากฐาน VPK-S1 วันที่ 12 ต.ค. 2569 · ต้นทางไฟล์ แบบฟอร์มที่ 3 แผนปีงบประมาณ 2570 หมวดวัสดุ.xlsx

Sheet พยาธิกายวิภาค
A1: โรงพยาบาลวชิระภูเก็ต · คำของบวัสดุ ปี 2570 · แท็บ พยาธิกายวิภาค
A2: เลขที่เอกสาร | C2: DBR/2570/0011 | D2: หน่วยงาน | E2: กลุ่มงานเทคนิคการแพทย์ฯ | H2: แหล่งเงิน | I2: เงินบำรุง | K2: ปีงบประมาณ | L2: 2570 | N2: สถานะ | O2: ฉบับร่าง
A3: ยอดในระบบ | C3: 1199640 | D3: ผลต่างจากรายการ | E3: =M28-C3 -> 0 | F3: ช่องรหัสสินค้าสีเหลืองกรอกหรือแก้รหัสได้ แท็บยาย้ายรหัสจากหมายเหตุมาไว้ในคอลัมน์นี้ ผลยืนยันเลือก ถูกต้อง / ต้องแก้ไข / ยังไม่ครบ / ข้าม มูลค่าที่ของบคำนวณจากปริมาณที่ของบ × ราคา/หน่วยนับ ยังไม่ผูกสินค้าในระบบ
A4: ลำดับ | B4: รหัสสินค้า | C4: รายการสินค้า | D4: ประเภทวัสดุ | E4: หน่วยนับ | F4: ปริมาณใช้ปี 2567 | G4: ปริมาณใช้ปี 2568 | H4: ปริมาณใช้ปี 2569 | I4: ปริมาณคงเหลือยกมา | J4: มูลค่าคงเหลือยกมา | K4: ปริมาณที่ของบ | L4: ราคา/หน่วยนับ | M4: มูลค่าที่ของบ | N4: หมายเหตุ | O4: ผลยืนยัน
A5: 1 | C5: 15 ml. Centrifuge Tube Bulk Sterile (500 pcs.) | D5: พยาธิกายวิภาค | K5: 1 | L5: 12000 | M5: =IF(OR(K5="",L5=""),"",K5*L5) -> 12000 | N5: เงินบำรุงรพ.งบ 70 เฉพาะเจาะจง
A6: 2 | C6: Absolute Alcohol 2.5 L. | D6: พยาธิกายวิภาค | K6: 1 | L6: 23400 | M6: =IF(OR(K6="",L6=""),"",K6*L6) -> 23400 | N6: เงินบำรุงรพ.งบ 70 เฉพาะเจาะจง
A7: 3 | C7: Cover Glass 24 x 60 mm. (10X100 pcs.) | D7: พยาธิกายวิภาค | K7: 1 | L7: 4800 | M7: =IF(OR(K7="",L7=""),"",K7*L7) -> 4800 | N7: เงินบำรุงรพ.งบ 70 เฉพาะเจาะจง
A8: 4 | C8: Cytorich red,standard 3.8 L. | D8: พยาธิกายวิภาค | K8: 1 | L8: 69550 | M8: =IF(OR(K8="",L8=""),"",K8*L8) -> 69550 | N8: เงินบำรุงรพ.งบ 70 เฉพาะเจาะจง
A9: 5 | C9: EZ Megafunnel (25 EA) | D9: พยาธิกายวิภาค | K9: 1 | L9: 337050 | M9: =IF(OR(K9="",L9=""),"",K9*L9) -> 337050 | N9: เงินบำรุงรพ.งบ 70 เฉพาะเจาะจง
A10: 6 | C10: EZ Cytofunnel single (40 EA) | D10: พยาธิกายวิภาค | K10: 1 | L10: 192600 | M10: =IF(OR(K10="",L10=""),"",K10*L10) -> 192600 | N10: เงินบำรุงรพ.งบ 70 เฉพาะเจาะจง
A11: 7 | C11: Hydrochloric Acid 37% AR 2.5 ลิตร | D11: พยาธิกายวิภาค | K11: 1 | L11: 1000 | M11: =IF(OR(K11="",L11=""),"",K11*L11) -> 1000 | N11: เงินบำรุงรพ.งบ 70 เฉพาะเจาะจง
A12: 8 | C12: Microscope Slide Frosted (72 pcs.) | D12: พยาธิกายวิภาค | K12: 1 | L12: 3900 | M12: =IF(OR(K12="",L12=""),"",K12*L12) -> 3900 | N12: เงินบำรุงรพ.งบ 70 เฉพาะเจาะจง
A13: 9 | C13: PAP1 Hematoxyline Solution 1,000 ml. (CV LAB) | D13: พยาธิกายวิภาค | K13: 1 | L13: 10000 | M13: =IF(OR(K13="",L13=""),"",K13*L13) -> 10000 | N13: เงินบำรุงรพ.งบ 70 เฉพาะเจาะจง
A14: 10 | C14: PAP1 Hematoxyline Solution 2,500 ml. (MERCK) | D14: พยาธิกายวิภาค | K14: 1 | L14: 18000 | M14: =IF(OR(K14="",L14=""),"",K14*L14) -> 18000 | N14: เงินบำรุงรพ.งบ 70 เฉพาะเจาะจง
A15: 11 | C15: PAP2 OG-6 1,000 ml. (CV LAB) | D15: พยาธิกายวิภาค | K15: 1 | L15: 8800 | M15: =IF(OR(K15="",L15=""),"",K15*L15) -> 8800 | N15: เงินบำรุงรพ.งบ 70 เฉพาะเจาะจง
A16: 12 | C16: PAP2 OG-6 2,500 ml. (MERCK) | D16: พยาธิกายวิภาค | K16: 1 | L16: 16500 | M16: =IF(OR(K16="",L16=""),"",K16*L16) -> 16500 | N16: เงินบำรุงรพ.งบ 70 เฉพาะเจาะจง
... A27: 23 | C27: Sticker Barcode 50x20 mm. (2,000 pcs.) มีรอยปรุ (ขนาดแกน 1.5 นิ้ว) | D27: พยาธิกายวิภาค | K27: 1 | L27: 4800 | M27: =IF(OR(K27="",L27=""),"",K27*L27) -> 4800 | N27: เงินบำรุงรพ.งบ 70 เฉพาะเจาะจง
A28: รวม | K28: =SUM(K5:K27) -> 23 | M28: =SUM(M5:M27) -> 1199640
A29: รวม 23 รายการ · DBR/2570/0011 · แท็บ พยาธิกายวิภาค · หน่วยงาน กลุ่มงานเทคนิคการแพทย์ฯ · โมเดล departmental.budget.request.material.detail · ส่งออกจากฐาน VPK-S1 วันที่ 12 ต.ค. 2569 · ต้นทางไฟล์ แบบฟอร์มที่ 3 แผนปีงบประมาณ 2570 หมวดวัสดุ.xlsx

Sheet ธนาคารเลือด
A1: โรงพยาบาลวชิระภูเก็ต · คำของบวัสดุ ปี 2570 · แท็บ ธนาคารเลือด
A2: เลขที่เอกสาร | C2: DBR/2570/0012 | D2: หน่วยงาน | E2: งานธนาคารเลือด | H2: แหล่งเงิน | I2: เงินบำรุง | K2: ปีงบประมาณ | L2: 2570 | N2: สถานะ | O2: ฉบับร่าง
A3: ยอดในระบบ | C3: 17933878 | D3: ผลต่างจากรายการ | E3: =M82-C3 -> 0 | F3: ช่องรหัสสินค้าสีเหลืองกรอกหรือแก้รหัสได้ แท็บยาย้ายรหัสจากหมายเหตุมาไว้ในคอลัมน์นี้ ผลยืนยันเลือก ถูกต้อง / ต้องแก้ไข / ยังไม่ครบ / ข้าม มูลค่าที่ของบคำนวณจากปริมาณที่ของบ × ราคา/หน่วยนับ ยังไม่ผูกสินค้าในระบบ
A4: ลำดับ | B4: รหัสสินค้า | C4: รายการสินค้า | D4: ประเภทวัสดุ | E4: หน่วยนับ | F4: ปริมาณใช้ปี 2567 | G4: ปริมาณใช้ปี 2568 | H4: ปริมาณใช้ปี 2569 | I4: ปริมาณคงเหลือยกมา | J4: มูลค่าคงเหลือยกมา | K4: ปริมาณที่ของบ | L4: ราคา/หน่วยนับ | M4: มูลค่าที่ของบ | N4: หมายเหตุ | O4: ผลยืนยัน
A5: 1 | C5: ถุงสำหรับบรรจุโลหิตชนิด 2 ถุง ขนาด 350 มิลลิลิตร | D5: ธนาคารเลือด | K5: 1 | L5: 240364.8 | M5: =IF(OR(K5="",L5=""),"",K5*L5) -> 240364.8 | N5: เงินบำรุงรพ.งบ 70 E-Bidding
A6: 2 | C6: ถุงสำหรับบรรจุโลหิตชนิด 2 ถุง ขนาด 450 มิลลิลิตร | D6: ธนาคารเลือด | K6: 1 | L6: 300456 | M6: =IF(OR(K6="",L6=""),"",K6*L6) -> 300456 | N6: เงินบำรุงรพ.งบ 70 E-Bidding
A7: 3 | C7: ถุงสำหรับบรรจุโลหิตชนิด 3 ถุง ขนาด 450 มิลลิลิตร | D7: ธนาคารเลือด | K7: 1 | L7: 332812.8 | M7: =IF(OR(K7="",L7=""),"",K7*L7) -> 332812.8 | N7: เงินบำรุงรพ.งบ 70 E-Bidding
A8: 4 | C8: ถุงสำหรับบรรจุโลหิตชนิด 4 ถุง ขนาด 450 มิลลิลิตร | D8: ธนาคารเลือด | K8: 1 | L8: 1309680 | M8: =IF(OR(K8="",L8=""),"",K8*L8) -> 1309680 | N8: เงินบำรุงรพ.งบ 70 E-Bidding
A9: 5 | C9: ถุงเจาะเลือดสำหรับกรองเม็ดเลือดขาวออกจากเม็ดเลือดแดง ชนิด 5 ถุง | D9: ธนาคารเลือด | K9: 1 | L9: 5007600 | M9: =IF(OR(K9="",L9=""),"",K9*L9) -> 5007600 | N9: เงินบำรุงรพ.งบ 70 E-Bidding
A10: 6 | C10: ชุดอุปกรณ์ตัดและเชื่อมสายถุงเลือดอัตโนมัติแบบปราศจากเชื้อ | D10: ธนาคารเลือด | K10: 1 | L10: 667680 | M10: =IF(OR(K10="",L10=""),"",K10*L10) -> 667680 | N10: เงินบำรุงรพ.งบ 70 E-Bidding
A11: 7 | C11: ชุดกรองเม็ดเลือดขาวออกจากเม็ดเลือดแดง | D11: ธนาคารเลือด | K11: 1 | L11: 500760 | M11: =IF(OR(K11="",L11=""),"",K11*L11) -> 500760 | N11: เงินบำรุงรพ.งบ 70 E-Bidding
A12: 8 | C12: น้ำยา Anti-Lea 1x2 ml. | D12: ธนาคารเลือด | K12: 1 | L12: 132000 | M12: =IF(OR(K12="",L12=""),"",K12*L12) -> 132000 | N12: เงินบำรุงรพ.งบ 70 E-Bidding
A13: 9 | C13: น้ำยา Anti-Leb 1x2 ml | D13: ธนาคารเลือด | K13: 1 | L13: 96000 | M13: =IF(OR(K13="",L13=""),"",K13*L13) -> 96000 | N13: เงินบำรุงรพ.งบ 70 E-Bidding
A14: 10 | C14: น้ำยา Anti-Jka 1x2 ml. | D14: ธนาคารเลือด | K14: 1 | L14: 139200 | M14: =IF(OR(K14="",L14=""),"",K14*L14) -> 139200 | N14: เงินบำรุงรพ.งบ 70 E-Bidding
A15: 11 | C15: น้ำยา Anti-Jkb 1x2 ml. | D15: ธนาคารเลือด | K15: 1 | L15: 139200 | M15: =IF(OR(K15="",L15=""),"",K15*L15) -> 139200 | N15: เงินบำรุงรพ.งบ 70 E-Bidding
A16: 12 | C16: น้ำยา Anti-C 1x5 ml. | D16: ธนาคารเลือด | K16: 1 | L16: 81600 | M16: =IF(OR(K16="",L16=""),"",K16*L16) -> 81600 | N16: เงินบำรุงรพ.งบ 70 E-Bidding
... A81: 77 | C81: Heat Treated Freeze Dried Cryoprecipitate (HTFDC) (200 IU/Bottle) | D81: ธนาคารเลือด | K81: 1 | L81: 360000 | M81: =IF(OR(K81="",L81=""),"",K81*L81) -> 360000 | N81: เงินบำรุงรพ.งบ 70 ศูนย์บริการโลหิตแห่งชาติ สภากาชาดไทย
A82: รวม | K82: =SUM(K5:K81) -> 77 | M82: =SUM(M5:M81) -> 17933878
A83: รวม 77 รายการ · DBR/2570/0012 · แท็บ ธนาคารเลือด · หน่วยงาน งานธนาคารเลือด · โมเดล departmental.budget.request.material.detail · ส่งออกจากฐาน VPK-S1 วันที่ 12 ต.ค. 2569 · ต้นทางไฟล์ แบบฟอร์มที่ 3 แผนปีงบประมาณ 2570 หมวดวัสดุ.xlsx

Sheet ยา
A1: โรงพยาบาลวชิระภูเก็ต · คำของบวัสดุ ปี 2570 · แท็บ ยา
A2: เลขที่เอกสาร | C2: DBR/2570/0013 | D2: หน่วยงาน | E2: กลุ่มงานเภสัชกรรม | H2: แหล่งเงิน | I2: เงินบำรุง | K2: ปีงบประมาณ | L2: 2570 | N2: สถานะ | O2: ฉบับร่าง
A3: ยอดในระบบ | C3: 5.7251695e+08 | D3: ผลต่างจากรายการ | E3: =M1064-C3 -> 0 | F3: ช่องรหัสสินค้าสีเหลืองกรอกหรือแก้รหัสได้ แท็บยาย้ายรหัสจากหมายเหตุมาไว้ในคอลัมน์นี้ ผลยืนยันเลือก ถูกต้อง / ต้องแก้ไข / ยังไม่ครบ / ข้าม มูลค่าที่ของบคำนวณจากปริมาณที่ของบ × ราคา/หน่วยนับ ยังไม่ผูกสินค้าในระบบ
A4: ลำดับ | B4: รหัสสินค้า | C4: รายการสินค้า | D4: ประเภทวัสดุ | E4: หน่วยนับ | F4: ปริมาณใช้ปี 2567 | G4: ปริมาณใช้ปี 2568 | H4: ปริมาณใช้ปี 2569 | I4: ปริมาณคงเหลือยกมา | J4: มูลค่าคงเหลือยกมา | K4: ปริมาณที่ของบ | L4: ราคา/หน่วยนับ | M4: มูลค่าที่ของบ | N4: หมายเหตุ | O4: ผลยืนยัน
A5: 1 | C5: [ตลับ50g] UREA in TA1 cream 20% ตลับ50g | D5: ยา + ยาเอกซเรย์ | K5: 0 | L5: 76 | M5: =IF(OR(K5="",L5=""),"",K5*L5) -> 0
A6: 2 | B6: 13933 | C6: DOTAREM 10 mL (gadolinium contrast media) [X-RAY] 0.5 mmol/mL VIAL | D6: ยา + ยาเอกซเรย์ | K6: 0 | L6: 684.8 | M6: =IF(OR(K6="",L6=""),"",K6*L6) -> 0
A7: 3 | B7: 135 | C7: Ergotamine 1 mg +Caffeine 100 mg tablet | D7: ยา + ยาเอกซเรย์ | K7: 0 | L7: 0 | M7: =IF(OR(K7="",L7=""),"",K7*L7) -> 0
A8: 4 | B8: 858 | C8: LIDOCAINE 1% + EPINEPHRINE 50ML INJ.(1:200000) 1%+(1:200,000) VIAL | D8: ยา + ยาเอกซเรย์ | K8: 0 | L8: 64.2 | M8: =IF(OR(K8="",L8=""),"",K8*L8) -> 0
A9: 5 | B9: 857 | C9: LIDOCAINE 2%+ EPINEPHRINE 50ML INJ. 2%+(1:200,000) VIAL | D9: ยา + ยาเอกซเรย์ | K9: 0 | L9: 0 | M9: =IF(OR(K9="",L9=""),"",K9*L9) -> 0
A10: 6 | B10: 13861 | C10: Posaconazole 100 mg tablet | D10: ยา + ยาเอกซเรย์ | K10: 0 | L10: 0 | M10: =IF(OR(K10="",L10=""),"",K10*L10) -> 0
A11: 7 | B11: 784 | C11: Ribavirin เฉพาะอายุรแพทย์ทางเดินอาหาร 200 mg TABLET | D11: ยา + ยาเอกซเรย์ | K11: 0 | L11: 0 | M11: =IF(OR(K11="",L11=""),"",K11*L11) -> 0
A12: 8 | B12: 662 | C12: Vincristine 2 mg/2 mL injection | D12: ยา + ยาเอกซเรย์ | K12: 0 | L12: 0 | M12: =IF(OR(K12="",L12=""),"",K12*L12) -> 0
A13: 9 | B13: 916 | C13: Voriconazole (VFEND) [งข1] 200 mg TABLET | D13: ยา + ยาเอกซเรย์ | K13: 0 | L13: 0 | M13: =IF(OR(K13="",L13=""),"",K13*L13) -> 0
A14: 10 | B14: 90 | C14: Chlorpheniramine 4 mg tablet | D14: ยา + ยาเอกซเรย์ | K14: 2 | L14: 59.92 | M14: =IF(OR(K14="",L14=""),"",K14*L14) -> 119.84
A15: 11 | B15: 931 | C15: CLOTRIMAZOLE EAR DROPS 15 mL (CANDID) 1%w/v BOTTLE | D15: ยา + ยาเอกซเรย์ | K15: 5 | L15: 60 | M15: =IF(OR(K15="",L15=""),"",K15*L15) -> 300
A16: 12 | B16: 736 | C16: Nevirapine 10 mg/mL suspension, 60 mL | D16: ยา + ยาเอกซเรย์ | K16: 5 | L16: 65 | M16: =IF(OR(K16="",L16=""),"",K16*L16) -> 325
A17: 13 | B17: 603 | C17: Methylene blue 1%, 5 mL injection | D17: ยา + ยาเอกซเรย์ | K17: 1 | L17: 500 | M17: =IF(OR(K17="",L17=""),"",K17*L17) -> 500
... A692: 688 | B692: 551 | C692: Simvastatin 20 mg tablet | D692: ยา + ยาเอกซเรย์ | K692: 32000 | L692: 48.15 | M692: =IF(OR(K692="",L692=""),"",K692*L692) -> 1540800
A693: 689 | C693: [ตลับ50g] UREA in TA1 cream 10% ตลับ50g | D693: ยา + ยาเอกซเรย์ | K693: 22000 | L693: 72 | M693: =IF(OR(K693="",L693=""),"",K693*L693) -> 1584000
A694: 690 | B694: 13284 | C694: Ceftriaxone 2 g injection | D694: ยา + ยาเอกซเรย์ | K694: 30000 | L694: 53.5 | M694: =IF(OR(K694="",L694=""),"",K694*L694) -> 1605000
A695: 691 | B695: 151 | C695: Levodopa 200 mg + Benseraside 50 mg tablet | D695: ยา + ยาเอกซเรย์ | K695: 3000 | L695: 535 | M695: =IF(OR(K695="",L695=""),"",K695*L695) -> 1605000
A696: 692 | B696: 477 | C696: Peritoneal dialysis (1.5% CAPD2), 2 L | D696: ยา + ยาเอกซเรย์ | K696: 10000 | L696: 160.5 | M696: =IF(OR(K696="",L696=""),"",K696*L696) -> 1605000
A697: 693 | B697: 13150 | C697: Adalimumab 40 mg/0.8 mL injection | D697: ยา + ยาเอกซเรย์ | K697: 460 | L697: 3560 | M697: =IF(OR(K697="",L697=""),"",K697*L697) -> 1637600
A698: 694 | B698: 15234 | C698: Nilotinib 200 mg capsule | D698: ยา + ยาเอกซเรย์ | K698: 40 | L698: 41623 | M698: =IF(OR(K698="",L698=""),"",K698*L698) -> 1664920
A699: 695 | B699: 13268 | C699: Budesonide 1 mg/2 mL nebuliser suspension | D699: ยา + ยาเอกซเรย์ | K699: 2000 | L699: 854.93 | M699: =IF(OR(K699="",L699=""),"",K699*L699) -> 1709860
A700: 696 | B700: 13793 | C700: Brinzolamide 1% +Timolol 0.5% ED, 5 mL bottle | D700: ยา + ยาเอกซเรย์ | K700: 9000 | L700: 192.6 | M700: =IF(OR(K700="",L700=""),"",K700*L700) -> 1733400
A701: 697 | B701: 519 | C701: Clopidogrel 75 mg tablet | D701: ยา + ยาเอกซเรย์ | K701: 9000 | L701: 195 | M701: =IF(OR(K701="",L701=""),"",K701*L701) -> 1755000
A702: 698 | B702: 12 | C702: Omeprazole 20 mg capsule | D702: ยา + ยาเอกซเรย์ | K702: 33000 | L702: 55 | M702: =IF(OR(K702="",L702=""),"",K702*L702) -> 1815000
A703: 699 | B703: 873 | C703: Ertapenem sodium 1 g injection | D703: ยา + ยาเอกซเรย์ | K703: 2000 | L703: 935.18 | M703: =IF(OR(K703="",L703=""),"",K703*L703) -> 1870360
A704: 700 | B704: 242 | C704: Desmopressin 0.1 mg tablet | D704: ยา + ยาเอกซเรย์ | K704: 1000 | L704: 1887.48 | M704: =IF(OR(K704="",L704=""),"",K704*L704) -> 1887480
A705: 701 | B705: 101 | C705: ยาระบายมะขามแขก | D705: ยา + ยาเอกซเรย์ | K705: 21000 | L705: 90 | M705: =IF(OR(K705="",L705=""),"",K705*L705) -> 1890000
... A1063: 1059 | B1063: 21 | C1063: Castor oil (น้ำมันระหุ่ง) 450 mL | D1063: ยา + ยาเอกซเรย์ | K1063: 0 | L1063: 0 | M1063: =IF(OR(K1063="",L1063=""),"",K1063*L1063) -> 0
A1064: รวม | K1064: =SUM(K5:K1063) -> 2760254 | M1064: =SUM(M5:M1063) -> 5.7251695e+08
A1065: รวม 1059 รายการ · DBR/2570/0013 · แท็บ ยา · หน่วยงาน กลุ่มงานเภสัชกรรม · โมเดล departmental.budget.request.material.detail · ส่งออกจากฐาน VPK-S1 วันที่ 12 ต.ค. 2569 · ต้นทางไฟล์ แบบฟอร์มที่ 3 แผนปีงบประมาณ 2570 หมวดวัสดุ.xlsx

Sheet วัสดุเภสัชกรรม
A1: โรงพยาบาลวชิระภูเก็ต · คำของบวัสดุ ปี 2570 · แท็บ วัสดุเภสัชกรรม
A2: เลขที่เอกสาร | C2: DBR/2570/0014 | D2: หน่วยงาน | E2: กลุ่มงานเภสัชกรรม | H2: แหล่งเงิน | I2: เงินบำรุง | K2: ปีงบประมาณ | L2: 2570 | N2: สถานะ | O2: ฉบับร่าง
A3: ยอดในระบบ | C3: 11563021 | D3: ผลต่างจากรายการ | E3: =M113-C3 -> 0 | F3: ช่องรหัสสินค้าสีเหลืองกรอกหรือแก้รหัสได้ แท็บยาย้ายรหัสจากหมายเหตุมาไว้ในคอลัมน์นี้ ผลยืนยันเลือก ถูกต้อง / ต้องแก้ไข / ยังไม่ครบ / ข้าม มูลค่าที่ของบคำนวณจากปริมาณที่ของบ × ราคา/หน่วยนับ ยังไม่ผูกสินค้าในระบบ
A4: ลำดับ | B4: รหัสสินค้า | C4: รายการสินค้า | D4: ประเภทวัสดุ | E4: หน่วยนับ | F4: ปริมาณใช้ปี 2567 | G4: ปริมาณใช้ปี 2568 | H4: ปริมาณใช้ปี 2569 | I4: ปริมาณคงเหลือยกมา | J4: มูลค่าคงเหลือยกมา | K4: ปริมาณที่ของบ | L4: ราคา/หน่วยนับ | M4: มูลค่าที่ของบ | N4: หมายเหตุ | O4: ผลยืนยัน
A5: 1 | C5: 70% Sorbitol | D5: เวชภัณฑ์เภสัช | E5: ขวด | K5: 80 | L5: 35.31 | M5: =IF(OR(K5="",L5=""),"",K5*L5) -> 2824.8
A6: 2 | C6: CMC Sodium 1500 (450 gm.) | D6: เวชภัณฑ์เภสัช | E6: กรัม | K6: 2 | L6: 353.1 | M6: =IF(OR(K6="",L6=""),"",K6*L6) -> 706.2
A7: 3 | C7: Cethyl Alcohol | D7: เวชภัณฑ์เภสัช | E7: กล่อง | K7: 0 | L7: 192.6 | M7: =IF(OR(K7="",L7=""),"",K7*L7) -> 0
A8: 4 | C8: Cetomacrogol (1 kg.) | D8: เวชภัณฑ์เภสัช | E8: กล่อง | K8: 0 | L8: 642 | M8: =IF(OR(K8="",L8=""),"",K8*L8) -> 0
A9: 5 | C9: Chloral Hydrate 500 mg | D9: เวชภัณฑ์เภสัช | E9: กล่อง | K9: 5 | L9: 10165 | M9: =IF(OR(K9="",L9=""),"",K9*L9) -> 50825
A10: 6 | C10: Chlorhexidine Cream 50 gm. | D10: เวชภัณฑ์เภสัช | E10: หลอด | K10: 300 | L10: 250 | M10: =IF(OR(K10="",L10=""),"",K10*L10) -> 75000
A11: 7 | C11: Cidex OPA 0.55% | D11: เวชภัณฑ์เภสัช | E11: แกลลอน | K11: 600 | L11: 2750 | M11: =IF(OR(K11="",L11=""),"",K11*L11) -> 1650000
A12: 8 | C12: Citric Acid (450 gm.) | D12: เวชภัณฑ์เภสัช | E12: กระปุก | K12: 25 | L12: 107 | M12: =IF(OR(K12="",L12=""),"",K12*L12) -> 2675
A13: 9 | C13: Coal Tar (450 ml.) | D13: เวชภัณฑ์เภสัช | E13: ขวด | K13: 40 | L13: 963 | M13: =IF(OR(K13="",L13=""),"",K13*L13) -> 38520
A14: 10 | C14: Dettol | D14: เวชภัณฑ์เภสัช | E14: ขวด | K14: 15 | L14: 662.3 | M14: =IF(OR(K14="",L14=""),"",K14*L14) -> 9934.5
A15: 11 | C15: Dimethyl sulphoxide ( DMSO) | D15: เวชภัณฑ์เภสัช | E15: ขวด | K15: 1 | L15: 2996 | M15: =IF(OR(K15="",L15=""),"",K15*L15) -> 2996
A16: 12 | C16: Disodium hydrogen phosphate anhydrous AR | D16: เวชภัณฑ์เภสัช | E16: กระปุก | K16: 40 | L16: 1712 | M16: =IF(OR(K16="",L16=""),"",K16*L16) -> 68480
... A24: 20 | C24: Methyl Paraben (450 gm.) | D24: เวชภัณฑ์เภสัช | E24: กล่อง | K24: 8 | L24: 342.4 | M24: =IF(OR(K24="",L24=""),"",K24*L24) -> 2739.2
A25: 21 | C25: Normaline (ผงเกลือล้างจมูกนอร์มาลีน) | D25: เวชภัณฑ์เภสัช | E25: กล่อง | I25: 2060 | K25: 4000 | L25: 79.18 | M25: =IF(OR(K25="",L25=""),"",K25*L25) -> 316720
A26: 22 | C26: Parafilm 4 x 125 | D26: เวชภัณฑ์เภสัช | E26: ม้วน | K26: 15 | L26: 2300 | M26: =IF(OR(K26="",L26=""),"",K26*L26) -> 34500
A27: 23 | C27: Phosphoric acid 85% AR | D27: เวชภัณฑ์เภสัช | E27: ขวด | K27: 5 | L27: 1819 | M27: =IF(OR(K27="",L27=""),"",K27*L27) -> 9095
A28: 24 | C28: Potassium Chloride | D28: เวชภัณฑ์เภสัช | E28: กล่อง | K28: 2 | L28: 107 | M28: =IF(OR(K28="",L28=""),"",K28*L28) -> 214
A29: 25 | C29: Potassium Iodide | D29: เวชภัณฑ์เภสัช | E29: กล่อง | K29: 2 | L29: 3210 | M29: =IF(OR(K29="",L29=""),"",K29*L29) -> 6420
A30: 26 | C30: Propyl Paraben | D30: เวชภัณฑ์เภสัช | E30: กล่อง | K30: 6 | L30: 374.5 | M30: =IF(OR(K30="",L30=""),"",K30*L30) -> 2247
A31: 27 | C31: Propylene Glycol | D31: เวชภัณฑ์เภสัช | E31: ขวด | K31: 150 | L31: 74.9 | M31: =IF(OR(K31="",L31=""),"",K31*L31) -> 11235
A32: 28 | C32: Q-Bac 2%- 400ml Chlorhexidine Gluconate | D32: เวชภัณฑ์เภสัช | E32: ขวด | K32: 8000 | L32: 150 | M32: =IF(OR(K32="",L32=""),"",K32*L32) -> 1200000
A33: 29 | C33: Q-Bac 4% Liquid soap (Hibiscrb) | D33: เวชภัณฑ์เภสัช | E33: แกลลอน | K33: 400 | L33: 750 | M33: =IF(OR(K33="",L33=""),"",K33*L33) -> 300000
A34: 30 | C34: Red Cap Combi Stopper | D34: เวชภัณฑ์เภสัช | E34: กล่อง | K34: 10 | L34: 2675 | M34: =IF(OR(K34="",L34=""),"",K34*L34) -> 26750
A35: 31 | C35: Saccharin Sodium | D35: เวชภัณฑ์เภสัช | E35: กล่อง | K35: 1 | L35: 1498 | M35: =IF(OR(K35="",L35=""),"",K35*L35) -> 1498
A36: 32 | C36: Salicylic Acid | D36: เวชภัณฑ์เภสัช | E36: กล่อง | K36: 40 | L36: 299.6 | M36: =IF(OR(K36="",L36=""),"",K36*L36) -> 11984
A37: 33 | C37: Silver Nitrate | D37: เวชภัณฑ์เภสัช | E37: ขวด | K37: 3 | L37: 7490 | M37: =IF(OR(K37="",L37=""),"",K37*L37) -> 22470
... A40: 36 | C40: Sodium Citrate | D40: เวชภัณฑ์เภสัช | E40: กล่อง | K40: 10 | L40: 107 | M40: =IF(OR(K40="",L40=""),"",K40*L40) -> 1070
A41: 37 | C41: Soft paraffin (White Vaselin) 50 กรัม | D41: เวชภัณฑ์เภสัช | E41: กระปุก | I41: 3400 | K41: 15000 | L41: 17.2 | M41: =IF(OR(K41="",L41=""),"",K41*L41) -> 258000
A42: 38 | C42: Stearyl Alcohol | D42: เวชภัณฑ์เภสัช | E42: กล่อง | K42: 50 | L42: 214 | M42: =IF(OR(K42="",L42=""),"",K42*L42) -> 10700
A43: 39 | C43: Syrup Simplex | D43: เวชภัณฑ์เภสัช | E43: ขวด | K43: 50 | L43: 520 | M43: =IF(OR(K43="",L43=""),"",K43*L43) -> 26000
A44: 40 | C44: Trichloroacetic Acid | D44: เวชภัณฑ์เภสัช | E44: ขวด | K44: 2 | L44: 1819 | M44: =IF(OR(K44="",L44=""),"",K44*L44) -> 3638
A45: 41 | C45: Urea FK | D45: เวชภัณฑ์เภสัช | E45: กล่อง | K45: 5 | L45: 428 | M45: =IF(OR(K45="",L45=""),"",K45*L45) -> 2140
A46: 42 | C46: Urea 10%+TA0.1% Cream (50 กรัม) | D46: เวชภัณฑ์เภสัช | E46: กระปุก | K46: 24200 | L46: 72 | M46: =IF(OR(K46="",L46=""),"",K46*L46) -> 1742400
A47: 43 | C47: Urea 20%+TA0.1% Cream (50 กรัม) | D47: เวชภัณฑ์เภสัช | E47: กระปุก | K47: 3400 | L47: 76 | M47: =IF(OR(K47="",L47=""),"",K47*L47) -> 258400
A48: 44 | C48: Zinc Oxide Powder | D48: เวชภัณฑ์เภสัช | E48: กล่อง | K48: 20 | L48: 160.5 | M48: =IF(OR(K48="",L48=""),"",K48*L48) -> 3210
A49: 45 | C49: กรวยสแตนเลส 5 นิ้ว แบบไม่มีกรอง | D49: เวชภัณฑ์เภสัช | E49: ใบ | K49: 0 | L49: 250 | M49: =IF(OR(K49="",L49=""),"",K49*L49) -> 0
...

Sheet ทันตกรรม
A1: โรงพยาบาลวชิระภูเก็ต · คำของบวัสดุ ปี 2570 · แท็บ ทันตกรรม
A2: เลขที่เอกสาร | C2: DBR/2570/0015 | D2: หน่วยงาน | E2: กลุ่มงานทันตกรรม | H2: แหล่งเงิน | I2: เงินบำรุง | K2: ปีงบประมาณ | L2: 2570 | N2: สถานะ | O2: ฉบับร่าง
A3: ยอดในระบบ | C3: 5187197.4 | D3: ผลต่างจากรายการ | E3: =M555-C3 -> 0 | F3: ช่องรหัสสินค้าสีเหลืองกรอกหรือแก้รหัสได้ แท็บยาย้ายรหัสจากหมายเหตุมาไว้ในคอลัมน์นี้ ผลยืนยันเลือก ถูกต้อง / ต้องแก้ไข / ยังไม่ครบ / ข้าม มูลค่าที่ของบคำนวณจากปริมาณที่ของบ × ราคา/หน่วยนับ ยังไม่ผูกสินค้าในระบบ
A4: ลำดับ | B4: รหัสสินค้า | C4: รายการสินค้า | D4: ประเภทวัสดุ | E4: หน่วยนับ | F4: ปริมาณใช้ปี 2567 | G4: ปริมาณใช้ปี 2568 | H4: ปริมาณใช้ปี 2569 | I4: ปริมาณคงเหลือยกมา | J4: มูลค่าคงเหลือยกมา | K4: ปริมาณที่ของบ | L4: ราคา/หน่วยนับ | M4: มูลค่าที่ของบ | N4: หมายเหตุ | O4: ผลยืนยัน
A5: 1 | C5: DIAMOND BUR FG 861EF/010 | D5: ทันตกรรม | K5: 1 | L5: 2850 | M5: =IF(OR(K5="",L5=""),"",K5*L5) -> 2850
A6: 2 | C6: DIAMOND BUR FG 862EF/012 | D6: ทันตกรรม | K6: 1 | L6: 1140 | M6: =IF(OR(K6="",L6=""),"",K6*L6) -> 1140
A7: 3 | C7: DIAMOND BUR FG 862F/014 | D7: ทันตกรรม | K7: 1 | L7: 1710 | M7: =IF(OR(K7="",L7=""),"",K7*L7) -> 1710
A8: 4 | C8: DIAMOND BUR FG 862G/014 | D8: ทันตกรรม | K8: 1 | L8: 1710 | M8: =IF(OR(K8="",L8=""),"",K8*L8) -> 1710
A9: 5 | C9: DIAMOND BUR FG 862G/016 | D9: ทันตกรรม | K9: 1 | L9: 1710 | M9: =IF(OR(K9="",L9=""),"",K9*L9) -> 1710
A10: 6 | C10: DIAMOND BUR FG 862EF/014 | D10: ทันตกรรม | K10: 1 | L10: 1710 | M10: =IF(OR(K10="",L10=""),"",K10*L10) -> 1710
A11: 7 | C11: DIAMOND BUR FG 858EF/012 | D11: ทันตกรรม | K11: 1 | L11: 1710 | M11: =IF(OR(K11="",L11=""),"",K11*L11) -> 1710
A12: 8 | C12: DIAMOND BUR FG 858EF/014 | D12: ทันตกรรม | K12: 1 | L12: 1710 | M12: =IF(OR(K12="",L12=""),"",K12*L12) -> 1710
A13: 9 | C13: DIAMOND BUR FG 858F/014 | D13: ทันตกรรม | K13: 1 | L13: 1710 | M13: =IF(OR(K13="",L13=""),"",K13*L13) -> 1710
A14: 10 | C14: DIAMOND BUR FG 858F/012 | D14: ทันตกรรม | K14: 1 | L14: 1710 | M14: =IF(OR(K14="",L14=""),"",K14*L14) -> 1710
A15: 11 | C15: DIAMOND BUR FG 858/012 | D15: ทันตกรรม | K15: 1 | L15: 1710 | M15: =IF(OR(K15="",L15=""),"",K15*L15) -> 1710
A16: 12 | C16: DIAMOND BUR FG 858/010 | D16: ทันตกรรม | K16: 1 | L16: 1710 | M16: =IF(OR(K16="",L16=""),"",K16*L16) -> 1710
... A554: 550 | C554: ZOOM CHAIRSDE | D554: ทันตกรรม | K554: 1 | L554: 25200 | M554: =IF(OR(K554="",L554=""),"",K554*L554) -> 25200
A555: รวม | K555: =SUM(K5:K554) -> 481 | M555: =SUM(M5:M554) -> 5187197.4
A556: รวม 550 รายการ · DBR/2570/0015 · แท็บ ทันตกรรม · หน่วยงาน กลุ่มงานทันตกรรม · โมเดล departmental.budget.request.material.detail · ส่งออกจากฐาน VPK-S1 วันที่ 12 ต.ค. 2569 · ต้นทางไฟล์ แบบฟอร์มที่ 3 แผนปีงบประมาณ 2570 หมวดวัสดุ.xlsx

Sheet โภชนาการ
A1: โรงพยาบาลวชิระภูเก็ต · คำของบวัสดุ ปี 2570 · แท็บ โภชนาการ
A2: เลขที่เอกสาร | C2: DBR/2570/0016 | D2: หน่วยงาน | E2: งานโภชนาการ กลุ่มงาน โภชนศาตร์ | H2: แหล่งเงิน | I2: เงินบำรุง | K2: ปีงบประมาณ | L2: 2570 | N2: สถานะ | O2: ฉบับร่าง
A3: ยอดในระบบ | C3: 50403620 | D3: ผลต่างจากรายการ | E3: =M331-C3 -> 0 | F3: ช่องรหัสสินค้าสีเหลืองกรอกหรือแก้รหัสได้ แท็บยาย้ายรหัสจากหมายเหตุมาไว้ในคอลัมน์นี้ ผลยืนยันเลือก ถูกต้อง / ต้องแก้ไข / ยังไม่ครบ / ข้าม มูลค่าที่ของบคำนวณจากปริมาณที่ของบ × ราคา/หน่วยนับ ยังไม่ผูกสินค้าในระบบ
A4: ลำดับ | B4: รหัสสินค้า | C4: รายการสินค้า | D4: ประเภทวัสดุ | E4: หน่วยนับ | F4: ปริมาณใช้ปี 2567 | G4: ปริมาณใช้ปี 2568 | H4: ปริมาณใช้ปี 2569 | I4: ปริมาณคงเหลือยกมา | J4: มูลค่าคงเหลือยกมา | K4: ปริมาณที่ของบ | L4: ราคา/หน่วยนับ | M4: มูลค่าที่ของบ | N4: หมายเหตุ | O4: ผลยืนยัน
A5: 1 | C5: ข้าวกล้องหอมมะลิ | D5: โภชนศาสตร์ | E5: กิโลกรัม | K5: 1860 | L5: 230 | M5: =IF(OR(K5="",L5=""),"",K5*L5) -> 427800
A6: 2 | C6: วัสดุบริโภคหมวดขนมหวาน | D6: โภชนศาสตร์ | K6: 1 | L6: 26500 | M6: =IF(OR(K6="",L6=""),"",K6*L6) -> 26500 | N6: สัญญาจะซื้อจะขายฯ
A7: 3 | C7: แป้งบัวลอยสำเร็จรูป | D7: โภชนศาสตร์ | K7: 0 | L7: 75 | M7: =IF(OR(K7="",L7=""),"",K7*L7) -> 0 | N7: วงเงินคงเหลือ ณ สิงหาคม 2569 10,600.00 บาท
A8: 4 | C8: แป้งครองแครง | D8: โภชนศาสตร์ | K8: 0 | L8: 65 | M8: =IF(OR(K8="",L8=""),"",K8*L8) -> 0
A9: 5 | C9: เม็ดทับทิมกรอบสำเร็จรูป | D9: โภชนศาสตร์ | K9: 0 | L9: 175 | M9: =IF(OR(K9="",L9=""),"",K9*L9) -> 0
A10: 6 | C10: มะพร้าวขูด | D10: โภชนศาสตร์ | K10: 0 | L10: 110 | M10: =IF(OR(K10="",L10=""),"",K10*L10) -> 0
A11: 7 | C11: วัสดุบริโภคหมวดของแห้ง | D11: โภชนศาสตร์ | K11: 1 | L11: 2500000 | M11: =IF(OR(K11="",L11=""),"",K11*L11) -> 2500000
A12: 8 | C12: กระเทียมเจียว 500ก. | D12: โภชนศาสตร์ | E12: ถุง | K12: 600 | L12: 55 | M12: =IF(OR(K12="",L12=""),"",K12*L12) -> 33000
A13: 9 | C13: กะปิแกง | D13: โภชนศาสตร์ | E13: กก. | K13: 30 | L13: 60 | M13: =IF(OR(K13="",L13=""),"",K13*L13) -> 1800 | N13: สัญญาจะซื้อจะขายฯ วัสดุบริโภค 20 รายการ
A14: 10 | C14: กะปิพริก | D14: โภชนศาสตร์ | E14: กก. | K14: 110 | L14: 60 | M14: =IF(OR(K14="",L14=""),"",K14*L14) -> 6600 | N14: สัญญาจะซื้อจะขายฯ วัสดุบริโภค 20 รายการ
A15: 11 | C15: กุ้งแห้ง (ขนาดเล็ก) | D15: โภชนศาสตร์ | E15: กก. | K15: 40 | L15: 510 | M15: =IF(OR(K15="",L15=""),"",K15*L15) -> 20400
A16: 12 | C16: ขนมปัง ฟาร์มเฮ้าส์ โฮลวีต | D16: โภชนศาสตร์ | E16: ถุง | K16: 75 | L16: 46.25 | M16: =IF(OR(K16="",L16=""),"",K16*L16) -> 3468.75
A17: 13 | C17: ขนมปัง ฟาร์มเฮ้าส์ | D17: โภชนศาสตร์ | E17: ถุง | K17: 140 | L17: 43 | M17: =IF(OR(K17="",L17=""),"",K17*L17) -> 6020
A18: 14 | C18: ข้าวเหนียวดำ | D18: โภชนศาสตร์ | E18: ถุง | K18: 50 | L18: 80 | M18: =IF(OR(K18="",L18=""),"",K18*L18) -> 4000 | N18: สัญญาจะซื้อจะขายฯ วัสดุบริโภค 20 รายการ
A19: 15 | C19: ขิงชง สูตรต้นตำรับ | D19: โภชนศาสตร์ | E19: ถุง | K19: 1350 | L19: 357 | M19: =IF(OR(K19="",L19=""),"",K19*L19) -> 481950
A20: 16 | C20: ขิงชง สูตรไม่ผสมน้ำตาล | D20: โภชนศาสตร์ | E20: ถุง | K20: 50 | L20: 357 | M20: =IF(OR(K20="",L20=""),"",K20*L20) -> 17850
A21: 17 | C21: เครื่องตุ๋นยาจีน | D21: โภชนศาสตร์ | E21: แพ็ค | K21: 40 | L21: 35 | M21: =IF(OR(K21="",L21=""),"",K21*L21) -> 1400
A22: 18 | C22: เครื่องแกง ผัดเผ็ด | D22: โภชนศาสตร์ | K22: 0 | L22: 95 | M22: =IF(OR(K22="",L22=""),"",K22*L22) -> 0
A23: 19 | C23: เครื่องแกง ข้าวหมก | D23: โภชนศาสตร์ | E23: กก. | K23: 120 | L23: 95 | M23: =IF(OR(K23="",L23=""),"",K23*L23) -> 11400 | N23: สัญญาจะซื้อจะขายฯ วัสดุบริโภค 20 รายการ
A24: 20 | C24: เครื่องแกง กะทิ | D24: โภชนศาสตร์ | E24: กก. | K24: 400 | L24: 92 | M24: =IF(OR(K24="",L24=""),"",K24*L24) -> 36800 | N24: สัญญาจะซื้อจะขายฯ วัสดุบริโภค 20 รายการ
A25: 21 | C25: เครื่องแกง กะหรี่ | D25: โภชนศาสตร์ | E25: กก. | K25: 20 | L25: 95 | M25: =IF(OR(K25="",L25=""),"",K25*L25) -> 1900 | N25: สัญญาจะซื้อจะขายฯ วัสดุบริโภค 20 รายการ
A26: 22 | C26: เครื่องแกง เขียวหวาน | D26: โภชนศาสตร์ | E26: กก. | K26: 100 | L26: 95 | M26: =IF(OR(K26="",L26=""),"",K26*L26) -> 9500 | N26: สัญญาจะซื้อจะขายฯ วัสดุบริโภค 20 รายการ
A27: 23 | C27: เครื่องแกง คั่วกลิ้ง | D27: โภชนศาสตร์ | E27: กก. | K27: 200 | L27: 100 | M27: =IF(OR(K27="",L27=""),"",K27*L27) -> 20000 | N27: สัญญาจะซื้อจะขายฯ วัสดุบริโภค 20 รายการ
A28: 24 | C28: เครื่องแกง พริก | D28: โภชนศาสตร์ | E28: กก. | K28: 250 | L28: 92 | M28: =IF(OR(K28="",L28=""),"",K28*L28) -> 23000 | N28: สัญญาจะซื้อจะขายฯ วัสดุบริโภค 20 รายการ
A29: 25 | C29: เครื่องแกง พะแนง | D29: โภชนศาสตร์ | E29: กก. | K29: 100 | L29: 100 | M29: =IF(OR(K29="",L29=""),"",K29*L29) -> 10000 | N29: สัญญาจะซื้อจะขายฯ วัสดุบริโภค 20 รายการ
A30: 26 | C30: เครื่องแกง มัสมั่น | D30: โภชนศาสตร์ | E30: กก. | K30: 100 | L30: 140 | M30: =IF(OR(K30="",L30=""),"",K30*L30) -> 14000 | N30: สัญญาจะซื้อจะขายฯ วัสดุบริโภค 20 รายการ
A31: 27 | C31: เครื่องแกง ส้ม | D31: โภชนศาสตร์ | E31: กก. | K31: 300 | L31: 92 | M31: =IF(OR(K31="",L31=""),"",K31*L31) -> 27600 | N31: สัญญาจะซื้อจะขายฯ วัสดุบริโภค 20 รายการ
A32: 28 | C32: เครื่องแกง ฉู่ฉี่ | D32: โภชนศาสตร์ | E32: กก. | K32: 10 | L32: 95 | M32: =IF(OR(K32="",L32=""),"",K32*L32) -> 950 | N32: สัญญาจะซื้อจะขายฯ วัสดุบริโภค 20 รายการ
A33: 29 | C33: ซุปครีมไก่ | D33: โภชนศาสตร์ | K33: 55 | L33: 65 | M33: =IF(OR(K33="",L33=""),"",K33*L33) -> 3575
A34: 30 | C34: ซุปครีมข้าวโพด | D34: โภชนศาสตร์ | K34: 100 | L34: 69 | M34: =IF(OR(K34="",L34=""),"",K34*L34) -> 6900
A35: 31 | C35: ซุปมะเขือเทศ | D35: โภชนศาสตร์ | E35: กล่อง | K35: 20 | L35: 57 | M35: =IF(OR(K35="",L35=""),"",K35*L35) -> 1140
A36: 32 | C36: เต้าหู้ห่อใบตอง | D36: โภชนศาสตร์ | E36: ก้อน | K36: 4000 | L36: 8 | M36: =IF(OR(K36="",L36=""),"",K36*L36) -> 32000
A37: 33 | C37: เต้าหู้ไข่ไก่ | D37: โภชนศาสตร์ | E37: หลอด | K37: 40 | L37: 11 | M37: =IF(OR(K37="",L37=""),"",K37*L37) -> 440
A38: 34 | C38: เต้าหู้ปลา | D38: โภชนศาสตร์ | E38: แพ็ค | K38: 535 | L38: 98 | M38: =IF(OR(K38="",L38=""),"",K38*L38) -> 52430
A39: 35 | C39: เต้าหู้เหลือง | D39: โภชนศาสตร์ | E39: ก้อน | K39: 2800 | L39: 8 | M39: =IF(OR(K39="",L39=""),"",K39*L39) -> 22400
A40: 36 | C40: ถั่วเขียว | D40: โภชนศาสตร์ | E40: ถุง | K40: 90 | L40: 60 | M40: =IF(OR(K40="",L40=""),"",K40*L40) -> 5400 | N40: สัญญาจะซื้อจะขายฯ วัสดุบริโภค 20 รายการ
...

Sheet แบบพิมพ์
A1: โรงพยาบาลวชิระภูเก็ต · คำของบวัสดุ ปี 2570 · แท็บ แบบพิมพ์
A2: เลขที่เอกสาร | C2: DBR/2570/0017 | D2: หน่วยงาน | E2: หน่วยงานพัสดุ | H2: แหล่งเงิน | I2: เงินบำรุง | K2: ปีงบประมาณ | L2: 2570 | N2: สถานะ | O2: ฉบับร่าง
A3: ยอดในระบบ | C3: 1869950.7 | D3: ผลต่างจากรายการ | E3: =M142-C3 -> 0 | F3: ช่องรหัสสินค้าสีเหลืองกรอกหรือแก้รหัสได้ แท็บยาย้ายรหัสจากหมายเหตุมาไว้ในคอลัมน์นี้ ผลยืนยันเลือก ถูกต้อง / ต้องแก้ไข / ยังไม่ครบ / ข้าม มูลค่าที่ของบคำนวณจากปริมาณที่ของบ × ราคา/หน่วยนับ ยังไม่ผูกสินค้าในระบบ
A4: ลำดับ | B4: รหัสสินค้า | C4: รายการสินค้า | D4: ประเภทวัสดุ | E4: หน่วยนับ | F4: ปริมาณใช้ปี 2567 | G4: ปริมาณใช้ปี 2568 | H4: ปริมาณใช้ปี 2569 | I4: ปริมาณคงเหลือยกมา | J4: มูลค่าคงเหลือยกมา | K4: ปริมาณที่ของบ | L4: ราคา/หน่วยนับ | M4: มูลค่าที่ของบ | N4: หมายเหตุ | O4: ผลยืนยัน
A5: 1 | C5: กระดาษรองถาดอาหาร ข้อพึ่งปฎิบัติ 12ประการ | D5: แบบพิมพ์ | E5: แผ่น | K5: 1 | L5: 20000 | M5: =IF(OR(K5="",L5=""),"",K5*L5) -> 20000
A6: 2 | C6: กระดาษรองถาดอาหาร โรคเก๊าท์ | D6: แบบพิมพ์ | E6: แผ่น | K6: 1 | L6: 20000 | M6: =IF(OR(K6="",L6=""),"",K6*L6) -> 20000
A7: 3 | C7: กระดาษรองถาดอาหาร โรคความดันโลหิต | D7: แบบพิมพ์ | E7: แผ่น | K7: 1 | L7: 40000 | M7: =IF(OR(K7="",L7=""),"",K7*L7) -> 40000
A8: 4 | C8: กระดาษรองถาดอาหาร โรคไต | D8: แบบพิมพ์ | E8: แผ่น | K8: 1 | L8: 40000 | M8: =IF(OR(K8="",L8=""),"",K8*L8) -> 40000
A9: 5 | C9: กระดาษรองถาดอาหาร โรคเบาหวาน | D9: แบบพิมพ์ | E9: แผ่น | K9: 1 | L9: 40000 | M9: =IF(OR(K9="",L9=""),"",K9*L9) -> 40000
A10: 6 | C10: กระดาษรองถาดอาหาร โรคมะเร็ง | D10: แบบพิมพ์ | E10: แผ่น | K10: 1 | L10: 20000 | M10: =IF(OR(K10="",L10=""),"",K10*L10) -> 20000
A11: 7 | C11: กระดาษรองถาดอาหาร โรคหัวใจขาดเลือด | D11: แบบพิมพ์ | E11: แผ่น | K11: 1 | L11: 20000 | M11: =IF(OR(K11="",L11=""),"",K11*L11) -> 20000
A12: 8 | C12: กินให้ครบทุกกลุ่มให้สัดส่วนที่เหมาะสมของแต่ละคน | D12: แบบพิมพ์ | E12: แผ่น | K12: 1 | L12: 20000 | M12: =IF(OR(K12="",L12=""),"",K12*L12) -> 20000
A13: 9 | C13: การ์ดยา สีชมพู | D13: แบบพิมพ์ | E13: แผ่น | K13: 0 | L13: 0 | M13: =IF(OR(K13="",L13=""),"",K13*L13) -> 0
A14: 10 | C14: การ์ดยา สีฟ้า | D14: แบบพิมพ์ | E14: แผ่น | K14: 0 | L14: 0 | M14: =IF(OR(K14="",L14=""),"",K14*L14) -> 0
A15: 11 | C15: การ์ดยา สีเหลือง | D15: แบบพิมพ์ | E15: แผ่น | K15: 0 | L15: 0 | M15: =IF(OR(K15="",L15=""),"",K15*L15) -> 0
A16: 12 | C16: แบบบันทึกข้อมูลเฝ้าระวังการบาดเจ็บ | D16: แบบพิมพ์ | E16: แผ่น | K16: 1 | L16: 14600 | M16: =IF(OR(K16="",L16=""),"",K16*L16) -> 14600
