Workbook

Sheet ภาพรวม
A1: โรงพยาบาลวชิระภูเก็ต
A2: สรุปสถานะการนำเข้าข้อมูล ภาพรวมทุกระบบ · UAT นำเข้าข้อมูล ครั้งที่ 1
A3: รวมจากชีต “สรุปประเภทข้อมูล” ของไฟล์ คลังสินค้า · งบประมาณ · จัดซื้อจัดจ้าง · สินทรัพย์ถาวร · เจ้าหนี้บัญชีการเงิน ตัวเลขในตารางด้านล่างคำนวณจากชีต “รวมทุกประเภท” (ผลยืนยันอัปเดตตามที่กรอกในชีตนี้)
A5: ลำดับ | B5: ระบบ | C5: ประเภทข้อมูลทั้งหมด | D5: นำเข้าแล้ว | E5: มีข้อมูลในระบบ (ธุรกรรม) | F5: มีรายการคงค้าง | G5: ยังไม่นำเข้า | H5: จำนวน record ในระบบ | I5: % ประเภทที่นำเข้าแล้ว | J5: ยืนยันถูกต้อง | K5: ต้องแก้ไข / ยังไม่ครบ | L5: รอยืนยัน (นำเข้าแล้ว ยังไม่ระบุผล) | M5: ชีตสรุปต้นทาง | N5: ไฟล์ต้นทาง
A6: 1 | B6: คลังสินค้า | C6: =COUNTIFS('รวมทุกประเภท'!$B$2:$B$60,$B6,'รวมทุกประเภท'!$V$2:$V$60,"<>ซ้ำกับสินทรัพย์ถาวร") | D6: =COUNTIFS('รวมทุกประเภท'!$B$2:$B$60,$B6,'รวมทุกประเภท'!$V$2:$V$60,"<>ซ้ำกับสินทรัพย์ถาวร",'รวมทุกประเภท'!$K$2:$K$60,"นำเข้าแล้ว") | E6: =COUNTIFS('รวมทุกประเภท'!$B$2:$B$60,$B6,'รวมทุกประเภท'!$V$2:$V$60,"<>ซ้ำกับสินทรัพย์ถาวร",'รวมทุกประเภท'!$K$2:$K$60,"มีข้อมูลในระบบ (ธุรกรรม)") | F6: =COUNTIFS('รวมทุกประเภท'!$B$2:$B$60,$B6,'รวมทุกประเภท'!$V$2:$V$60,"<>ซ้ำกับสินทรัพย์ถาวร",'รวมทุกประเภท'!$K$2:$K$60,"มีรายการคงค้าง") | G6: =COUNTIFS('รวมทุกประเภท'!$B$2:$B$60,$B6,'รวมทุกประเภท'!$V$2:$V$60,"<>ซ้ำกับสินทรัพย์ถาวร",'รวมทุกประเภท'!$K$2:$K$60,"ยังไม่นำเข้า") | H6: =SUMIFS('รวมทุกประเภท'!$I$2:$I$60,'รวมทุกประเภท'!$B$2:$B$60,$B6,'รวมทุกประเภท'!$V$2:$V$60,"<>ซ้ำกับสินทรัพย์ถาวร") | I6: =IF(C6=0,"",D6/C6) | J6: =COUNTIFS('รวมทุกประเภท'!$B$2:$B$60,$B6,'รวมทุกประเภท'!$V$2:$V$60,"<>ซ้ำกับสินทรัพย์ถาวร",'รวมทุกประเภท'!$O$2:$O$60,"ถูกต้อง") | K6: =COUNTIFS('รวมทุกประเภท'!$B$2:$B$60,$B6,'รวมทุกประเภท'!$V$2:$V$60,"<>ซ้ำกับสินทรัพย์ถาวร",'รวมทุกประเภท'!$O$2:$O$60,"ต้องแก้ไข")+COUNTIFS('รวมทุกประเภท'!$B$2:$B$60,$B6,'รวมทุกประเภท'!$V$2:$V$60,"<>ซ้ำกับสินทรัพย์ถาวร",'รวมทุกประเภท'!$O$2:$O$60,"ยังไม่ครบ") | L6: =COUNTIFS('รวมทุกประเภท'!$B$2:$B$60,$B6,'รวมทุกประเภท'!$V$2:$V$60,"<>ซ้ำกับสินทรัพย์ถาวร",'รวมทุกประเภท'!$K$2:$K$60,"นำเข้าแล้ว")-COUNTIFS('รวมทุกประเภท'!$B$2:$B$60,$B6,'รวมทุกประเภท'!$V$2:$V$60,"<>ซ้ำกับสินทรัพย์ถาวร",'รวมทุกประเภท'!$K$2:$K$60,"นำเข้าแล้ว",'รวมทุกประเภท'!$O$2:$O$60,"ถูกต้อง")-COUNTIFS('รวมทุกประเภท'!$B$2:$B$60,$B6,'รวมทุกประเภท'!$V$2:$V$60,"<>ซ้ำกับสินทรัพย์ถาวร",'รวมทุกประเภท'!$K$2:$K$60,"นำเข้าแล้ว",'รวมทุกประเภท'!$O$2:$O$60,"ต้องแก้ไข")-COUNTIFS('รวมทุกประเภท'!$B$2:$B$60,$B6,'รวมทุกประเภท'!$V$2:$V$60,"<>ซ้ำกับสินทรัพย์ถาวร",'รวมทุกประเภท'!$K$2:$K$60,"นำเข้าแล้ว",'รวมทุกประเภท'!$O$2:$O$60,"ยังไม่ครบ")-COUNTIFS('รวมทุกประเภท'!$B$2:$B$60,$B6,'รวมทุกประเภท'!$V$2:$V$60,"<>ซ้ำกับสินทรัพย์ถาวร",'รวมทุกประเภท'!$K$2:$K$60,"นำเข้าแล้ว",'รวมทุกประเภท'!$O$2:$O$60,"ข้าม") | M6: สรุป-คลังสินค้า | N6: UAT-นำเข้าข้อมูล-คลังสินค้า-ครั้งที่-1.xlsx
A7: 2 | B7: งบประมาณ | C7: =COUNTIFS('รวมทุกประเภท'!$B$2:$B$60,$B7,'รวมทุกประเภท'!$V$2:$V$60,"<>ซ้ำกับสินทรัพย์ถาวร") | D7: =COUNTIFS('รวมทุกประเภท'!$B$2:$B$60,$B7,'รวมทุกประเภท'!$V$2:$V$60,"<>ซ้ำกับสินทรัพย์ถาวร",'รวมทุกประเภท'!$K$2:$K$60,"นำเข้าแล้ว") | E7: =COUNTIFS('รวมทุกประเภท'!$B$2:$B$60,$B7,'รวมทุกประเภท'!$V$2:$V$60,"<>ซ้ำกับสินทรัพย์ถาวร",'รวมทุกประเภท'!$K$2:$K$60,"มีข้อมูลในระบบ (ธุรกรรม)") | F7: =COUNTIFS('รวมทุกประเภท'!$B$2:$B$60,$B7,'รวมทุกประเภท'!$V$2:$V$60,"<>ซ้ำกับสินทรัพย์ถาวร",'รวมทุกประเภท'!$K$2:$K$60,"มีรายการคงค้าง") | G7: =COUNTIFS('รวมทุกประเภท'!$B$2:$B$60,$B7,'รวมทุกประเภท'!$V$2:$V$60,"<>ซ้ำกับสินทรัพย์ถาวร",'รวมทุกประเภท'!$K$2:$K$60,"ยังไม่นำเข้า") | H7: =SUMIFS('รวมทุกประเภท'!$I$2:$I$60,'รวมทุกประเภท'!$B$2:$B$60,$B7,'รวมทุกประเภท'!$V$2:$V$60,"<>ซ้ำกับสินทรัพย์ถาวร") | I7: =IF(C7=0,"",D7/C7) | J7: =COUNTIFS('รวมทุกประเภท'!$B$2:$B$60,$B7,'รวมทุกประเภท'!$V$2:$V$60,"<>ซ้ำกับสินทรัพย์ถาวร",'รวมทุกประเภท'!$O$2:$O$60,"ถูกต้อง") | K7: =COUNTIFS('รวมทุกประเภท'!$B$2:$B$60,$B7,'รวมทุกประเภท'!$V$2:$V$60,"<>ซ้ำกับสินทรัพย์ถาวร",'รวมทุกประเภท'!$O$2:$O$60,"ต้องแก้ไข")+COUNTIFS('รวมทุกประเภท'!$B$2:$B$60,$B7,'รวมทุกประเภท'!$V$2:$V$60,"<>ซ้ำกับสินทรัพย์ถาวร",'รวมทุกประเภท'!$O$2:$O$60,"ยังไม่ครบ") | L7: =COUNTIFS('รวมทุกประเภท'!$B$2:$B$60,$B7,'รวมทุกประเภท'!$V$2:$V$60,"<>ซ้ำกับสินทรัพย์ถาวร",'รวมทุกประเภท'!$K$2:$K$60,"นำเข้าแล้ว")-COUNTIFS('รวมทุกประเภท'!$B$2:$B$60,$B7,'รวมทุกประเภท'!$V$2:$V$60,"<>ซ้ำกับสินทรัพย์ถาวร",'รวมทุกประเภท'!$K$2:$K$60,"นำเข้าแล้ว",'รวมทุกประเภท'!$O$2:$O$60,"ถูกต้อง")-COUNTIFS('รวมทุกประเภท'!$B$2:$B$60,$B7,'รวมทุกประเภท'!$V$2:$V$60,"<>ซ้ำกับสินทรัพย์ถาวร",'รวมทุกประเภท'!$K$2:$K$60,"นำเข้าแล้ว",'รวมทุกประเภท'!$O$2:$O$60,"ต้องแก้ไข")-COUNTIFS('รวมทุกประเภท'!$B$2:$B$60,$B7,'รวมทุกประเภท'!$V$2:$V$60,"<>ซ้ำกับสินทรัพย์ถาวร",'รวมทุกประเภท'!$K$2:$K$60,"นำเข้าแล้ว",'รวมทุกประเภท'!$O$2:$O$60,"ยังไม่ครบ")-COUNTIFS('รวมทุกประเภท'!$B$2:$B$60,$B7,'รวมทุกประเภท'!$V$2:$V$60,"<>ซ้ำกับสินทรัพย์ถาวร",'รวมทุกประเภท'!$K$2:$K$60,"นำเข้าแล้ว",'รวมทุกประเภท'!$O$2:$O$60,"ข้าม") | M7: สรุป-งบประมาณ | N7: UAT-นำเข้าข้อมูล-งบประมาณ-ครั้งที่ 1.xlsx
A8: 3 | B8: จัดซื้อจัดจ้าง | C8: =COUNTIFS('รวมทุกประเภท'!$B$2:$B$60,$B8,'รวมทุกประเภท'!$V$2:$V$60,"<>ซ้ำกับสินทรัพย์ถาวร") | D8: =COUNTIFS('รวมทุกประเภท'!$B$2:$B$60,$B8,'รวมทุกประเภท'!$V$2:$V$60,"<>ซ้ำกับสินทรัพย์ถาวร",'รวมทุกประเภท'!$K$2:$K$60,"นำเข้าแล้ว") | E8: =COUNTIFS('รวมทุกประเภท'!$B$2:$B$60,$B8,'รวมทุกประเภท'!$V$2:$V$60,"<>ซ้ำกับสินทรัพย์ถาวร",'รวมทุกประเภท'!$K$2:$K$60,"มีข้อมูลในระบบ (ธุรกรรม)") | F8: =COUNTIFS('รวมทุกประเภท'!$B$2:$B$60,$B8,'รวมทุกประเภท'!$V$2:$V$60,"<>ซ้ำกับสินทรัพย์ถาวร",'รวมทุกประเภท'!$K$2:$K$60,"มีรายการคงค้าง") | G8: =COUNTIFS('รวมทุกประเภท'!$B$2:$B$60,$B8,'รวมทุกประเภท'!$V$2:$V$60,"<>ซ้ำกับสินทรัพย์ถาวร",'รวมทุกประเภท'!$K$2:$K$60,"ยังไม่นำเข้า") | H8: =SUMIFS('รวมทุกประเภท'!$I$2:$I$60,'รวมทุกประเภท'!$B$2:$B$60,$B8,'รวมทุกประเภท'!$V$2:$V$60,"<>ซ้ำกับสินทรัพย์ถาวร") | I8: =IF(C8=0,"",D8/C8) | J8: =COUNTIFS('รวมทุกประเภท'!$B$2:$B$60,$B8,'รวมทุกประเภท'!$V$2:$V$60,"<>ซ้ำกับสินทรัพย์ถาวร",'รวมทุกประเภท'!$O$2:$O$60,"ถูกต้อง") | K8: =COUNTIFS('รวมทุกประเภท'!$B$2:$B$60,$B8,'รวมทุกประเภท'!$V$2:$V$60,"<>ซ้ำกับสินทรัพย์ถาวร",'รวมทุกประเภท'!$O$2:$O$60,"ต้องแก้ไข")+COUNTIFS('รวมทุกประเภท'!$B$2:$B$60,$B8,'รวมทุกประเภท'!$V$2:$V$60,"<>ซ้ำกับสินทรัพย์ถาวร",'รวมทุกประเภท'!$O$2:$O$60,"ยังไม่ครบ") | L8: =COUNTIFS('รวมทุกประเภท'!$B$2:$B$60,$B8,'รวมทุกประเภท'!$V$2:$V$60,"<>ซ้ำกับสินทรัพย์ถาวร",'รวมทุกประเภท'!$K$2:$K$60,"นำเข้าแล้ว")-COUNTIFS('รวมทุกประเภท'!$B$2:$B$60,$B8,'รวมทุกประเภท'!$V$2:$V$60,"<>ซ้ำกับสินทรัพย์ถาวร",'รวมทุกประเภท'!$K$2:$K$60,"นำเข้าแล้ว",'รวมทุกประเภท'!$O$2:$O$60,"ถูกต้อง")-COUNTIFS('รวมทุกประเภท'!$B$2:$B$60,$B8,'รวมทุกประเภท'!$V$2:$V$60,"<>ซ้ำกับสินทรัพย์ถาวร",'รวมทุกประเภท'!$K$2:$K$60,"นำเข้าแล้ว",'รวมทุกประเภท'!$O$2:$O$60,"ต้องแก้ไข")-COUNTIFS('รวมทุกประเภท'!$B$2:$B$60,$B8,'รวมทุกประเภท'!$V$2:$V$60,"<>ซ้ำกับสินทรัพย์ถาวร",'รวมทุกประเภท'!$K$2:$K$60,"นำเข้าแล้ว",'รวมทุกประเภท'!$O$2:$O$60,"ยังไม่ครบ")-COUNTIFS('รวมทุกประเภท'!$B$2:$B$60,$B8,'รวมทุกประเภท'!$V$2:$V$60,"<>ซ้ำกับสินทรัพย์ถาวร",'รวมทุกประเภท'!$K$2:$K$60,"นำเข้าแล้ว",'รวมทุกประเภท'!$O$2:$O$60,"ข้าม") | M8: สรุป-จัดซื้อ | N8: UAT-นำเข้าข้อมูล-จัดซื้อ-ครั้งที่ 1.xlsx
A9: 4 | B9: สินทรัพย์ถาวร | C9: =COUNTIFS('รวมทุกประเภท'!$B$2:$B$60,$B9,'รวมทุกประเภท'!$V$2:$V$60,"<>ซ้ำกับสินทรัพย์ถาวร") | D9: =COUNTIFS('รวมทุกประเภท'!$B$2:$B$60,$B9,'รวมทุกประเภท'!$V$2:$V$60,"<>ซ้ำกับสินทรัพย์ถาวร",'รวมทุกประเภท'!$K$2:$K$60,"นำเข้าแล้ว") | E9: =COUNTIFS('รวมทุกประเภท'!$B$2:$B$60,$B9,'รวมทุกประเภท'!$V$2:$V$60,"<>ซ้ำกับสินทรัพย์ถาวร",'รวมทุกประเภท'!$K$2:$K$60,"มีข้อมูลในระบบ (ธุรกรรม)") | F9: =COUNTIFS('รวมทุกประเภท'!$B$2:$B$60,$B9,'รวมทุกประเภท'!$V$2:$V$60,"<>ซ้ำกับสินทรัพย์ถาวร",'รวมทุกประเภท'!$K$2:$K$60,"มีรายการคงค้าง") | G9: =COUNTIFS('รวมทุกประเภท'!$B$2:$B$60,$B9,'รวมทุกประเภท'!$V$2:$V$60,"<>ซ้ำกับสินทรัพย์ถาวร",'รวมทุกประเภท'!$K$2:$K$60,"ยังไม่นำเข้า") | H9: =SUMIFS('รวมทุกประเภท'!$I$2:$I$60,'รวมทุกประเภท'!$B$2:$B$60,$B9,'รวมทุกประเภท'!$V$2:$V$60,"<>ซ้ำกับสินทรัพย์ถาวร") | I9: =IF(C9=0,"",D9/C9) | J9: =COUNTIFS('รวมทุกประเภท'!$B$2:$B$60,$B9,'รวมทุกประเภท'!$V$2:$V$60,"<>ซ้ำกับสินทรัพย์ถาวร",'รวมทุกประเภท'!$O$2:$O$60,"ถูกต้อง") | K9: =COUNTIFS('รวมทุกประเภท'!$B$2:$B$60,$B9,'รวมทุกประเภท'!$V$2:$V$60,"<>ซ้ำกับสินทรัพย์ถาวร",'รวมทุกประเภท'!$O$2:$O$60,"ต้องแก้ไข")+COUNTIFS('รวมทุกประเภท'!$B$2:$B$60,$B9,'รวมทุกประเภท'!$V$2:$V$60,"<>ซ้ำกับสินทรัพย์ถาวร",'รวมทุกประเภท'!$O$2:$O$60,"ยังไม่ครบ") | L9: =COUNTIFS('รวมทุกประเภท'!$B$2:$B$60,$B9,'รวมทุกประเภท'!$V$2:$V$60,"<>ซ้ำกับสินทรัพย์ถาวร",'รวมทุกประเภท'!$K$2:$K$60,"นำเข้าแล้ว")-COUNTIFS('รวมทุกประเภท'!$B$2:$B$60,$B9,'รวมทุกประเภท'!$V$2:$V$60,"<>ซ้ำกับสินทรัพย์ถาวร",'รวมทุกประเภท'!$K$2:$K$60,"นำเข้าแล้ว",'รวมทุกประเภท'!$O$2:$O$60,"ถูกต้อง")-COUNTIFS('รวมทุกประเภท'!$B$2:$B$60,$B9,'รวมทุกประเภท'!$V$2:$V$60,"<>ซ้ำกับสินทรัพย์ถาวร",'รวมทุกประเภท'!$K$2:$K$60,"นำเข้าแล้ว",'รวมทุกประเภท'!$O$2:$O$60,"ต้องแก้ไข")-COUNTIFS('รวมทุกประเภท'!$B$2:$B$60,$B9,'รวมทุกประเภท'!$V$2:$V$60,"<>ซ้ำกับสินทรัพย์ถาวร",'รวมทุกประเภท'!$K$2:$K$60,"นำเข้าแล้ว",'รวมทุกประเภท'!$O$2:$O$60,"ยังไม่ครบ")-COUNTIFS('รวมทุกประเภท'!$B$2:$B$60,$B9,'รวมทุกประเภท'!$V$2:$V$60,"<>ซ้ำกับสินทรัพย์ถาวร",'รวมทุกประเภท'!$K$2:$K$60,"นำเข้าแล้ว",'รวมทุกประเภท'!$O$2:$O$60,"ข้าม") | M9: สรุป-สินทรัพย์ถาวร | N9: UAT-นำเข้าข้อมูล-สินทรัพย์ถาวร-ครั้งที่-1.xlsx
A10: 5 | B10: เจ้าหนี้บัญชีการเงิน | C10: =COUNTIFS('รวมทุกประเภท'!$B$2:$B$60,$B10,'รวมทุกประเภท'!$V$2:$V$60,"<>ซ้ำกับสินทรัพย์ถาวร") | D10: =COUNTIFS('รวมทุกประเภท'!$B$2:$B$60,$B10,'รวมทุกประเภท'!$V$2:$V$60,"<>ซ้ำกับสินทรัพย์ถาวร",'รวมทุกประเภท'!$K$2:$K$60,"นำเข้าแล้ว") | E10: =COUNTIFS('รวมทุกประเภท'!$B$2:$B$60,$B10,'รวมทุกประเภท'!$V$2:$V$60,"<>ซ้ำกับสินทรัพย์ถาวร",'รวมทุกประเภท'!$K$2:$K$60,"มีข้อมูลในระบบ (ธุรกรรม)") | F10: =COUNTIFS('รวมทุกประเภท'!$B$2:$B$60,$B10,'รวมทุกประเภท'!$V$2:$V$60,"<>ซ้ำกับสินทรัพย์ถาวร",'รวมทุกประเภท'!$K$2:$K$60,"มีรายการคงค้าง") | G10: =COUNTIFS('รวมทุกประเภท'!$B$2:$B$60,$B10,'รวมทุกประเภท'!$V$2:$V$60,"<>ซ้ำกับสินทรัพย์ถาวร",'รวมทุกประเภท'!$K$2:$K$60,"ยังไม่นำเข้า") | H10: =SUMIFS('รวมทุกประเภท'!$I$2:$I$60,'รวมทุกประเภท'!$B$2:$B$60,$B10,'รวมทุกประเภท'!$V$2:$V$60,"<>ซ้ำกับสินทรัพย์ถาวร") | I10: =IF(C10=0,"",D10/C10) | J10: =COUNTIFS('รวมทุกประเภท'!$B$2:$B$60,$B10,'รวมทุกประเภท'!$V$2:$V$60,"<>ซ้ำกับสินทรัพย์ถาวร",'รวมทุกประเภท'!$O$2:$O$60,"ถูกต้อง") | K10: =COUNTIFS('รวมทุกประเภท'!$B$2:$B$60,$B10,'รวมทุกประเภท'!$V$2:$V$60,"<>ซ้ำกับสินทรัพย์ถาวร",'รวมทุกประเภท'!$O$2:$O$60,"ต้องแก้ไข")+COUNTIFS('รวมทุกประเภท'!$B$2:$B$60,$B10,'รวมทุกประเภท'!$V$2:$V$60,"<>ซ้ำกับสินทรัพย์ถาวร",'รวมทุกประเภท'!$O$2:$O$60,"ยังไม่ครบ") | L10: =COUNTIFS('รวมทุกประเภท'!$B$2:$B$60,$B10,'รวมทุกประเภท'!$V$2:$V$60,"<>ซ้ำกับสินทรัพย์ถาวร",'รวมทุกประเภท'!$K$2:$K$60,"นำเข้าแล้ว")-COUNTIFS('รวมทุกประเภท'!$B$2:$B$60,$B10,'รวมทุกประเภท'!$V$2:$V$60,"<>ซ้ำกับสินทรัพย์ถาวร",'รวมทุกประเภท'!$K$2:$K$60,"นำเข้าแล้ว",'รวมทุกประเภท'!$O$2:$O$60,"ถูกต้อง")-COUNTIFS('รวมทุกประเภท'!$B$2:$B$60,$B10,'รวมทุกประเภท'!$V$2:$V$60,"<>ซ้ำกับสินทรัพย์ถาวร",'รวมทุกประเภท'!$K$2:$K$60,"นำเข้าแล้ว",'รวมทุกประเภท'!$O$2:$O$60,"ต้องแก้ไข")-COUNTIFS('รวมทุกประเภท'!$B$2:$B$60,$B10,'รวมทุกประเภท'!$V$2:$V$60,"<>ซ้ำกับสินทรัพย์ถาวร",'รวมทุกประเภท'!$K$2:$K$60,"นำเข้าแล้ว",'รวมทุกประเภท'!$O$2:$O$60,"ยังไม่ครบ")-COUNTIFS('รวมทุกประเภท'!$B$2:$B$60,$B10,'รวมทุกประเภท'!$V$2:$V$60,"<>ซ้ำกับสินทรัพย์ถาวร",'รวมทุกประเภท'!$K$2:$K$60,"นำเข้าแล้ว",'รวมทุกประเภท'!$O$2:$O$60,"ข้าม") | M10: สรุป-เจ้าหนี้การเงิน | N10: UAT-นำเข้าข้อมูล-เจ้าหนี้บัญชีการเงิน-ครั้งที่ 1.xlsx
B11: รวมทุกระบบ | C11: =SUM(C6:C10) | D11: =SUM(D6:D10) | E11: =SUM(E6:E10) | F11: =SUM(F6:F10) | G11: =SUM(G6:G10) | H11: =SUM(H6:H10) | I11: =IF(C11=0,"",D11/C11) | J11: =SUM(J6:J10) | K11: =SUM(K6:K10) | L11: =SUM(L6:L10)
A13: วิธีอ่าน
A14: ไฟล์เจ้าหนี้บัญชีการเงินมี 3 ประเภทที่ซ้ำกับไฟล์สินทรัพย์ถาวร (โปรไฟล์สินทรัพย์, บัตรสินทรัพย์, ครุภัณฑ์ซ่อมบำรุง) ยังแสดงในชีต “รวมทุกประเภท” (แถวสีเทา) แต่ไม่นับรวมในภาพรวมเพื่อไม่ให้นับซ้ำ
A15: นำเข้าแล้ว = ข้อมูลอยู่ในระบบและมีชีตยืนยันให้ตรวจ · มีข้อมูลในระบบ (ธุรกรรม) = เอกสารปฏิบัติงานที่มีในฐาน ไม่ใช่ข้อมูลนำเข้า · มีรายการคงค้าง = ข้อมูลคงค้าง เช่น งบทดลอง (TB) · ยังไม่นำเข้า = ยังไม่มีข้อมูล (จำนวน 0)
A16: รอยืนยัน = ประเภทที่นำเข้าแล้วแต่เจ้าของข้อมูลยังไม่เลือกผลยืนยัน (ถูกต้อง / ต้องแก้ไข / ยังไม่ครบ / ข้าม) ผลยืนยันกรอกที่ชีต “รวมทุกประเภท” หรือชีตสรุปต้นทางของแต่ละระบบ
A17: ไฟล์งบประมาณมีไฟล์รายการคำของบแยก 4 ไฟล์ (วัสดุ ครุภัณฑ์ ก่อสร้าง โครงการ) รายละเอียดอยู่ในช่องสถานะนำเข้าของแถวคำของบหน่วยงาน
A18: ข้อมูลเป็นสำเนา ณ วันที่สร้างไฟล์นี้ ถ้าไฟล์ต้นทางเปลี่ยน ให้สร้างไฟล์ภาพรวมใหม่

Sheet รวมทุกประเภท
A1: ลำดับ | B1: ระบบ | C1: ประเภทข้อมูล | D1: ข้อมูลนี้คืออะไร / ใช้ทำอะไรในระบบ | E1: กลุ่ม | F1: โมดูลที่เกี่ยวข้อง | G1: โมเดลในระบบ | H1: คีย์จับคู่ | I1: จำนวนในระบบ | J1: สถานะนำเข้า | K1: สถานะ (จัดกลุ่ม) | L1: ชีตรายการยืนยัน | M1: จำนวนต้นทาง (กรอก) | N1: ผลต่าง | O1: ผลยืนยัน | P1: ผู้ยืนยัน | Q1: ลงชื่อ | R1: วันที่ | S1: หมายเหตุ | T1: อ้างอิงการได้มาของข้อมูล | U1: ไฟล์ต้นทาง | V1: ซ้ำกับระบบอื่น (ไม่นับรวมในภาพรวม)
A2: 1 | B2: คลังสินค้า | C2: หมวดหน่วยนับ | E2: Master | F2: คลัง, สินค้า | G2: uom.category | H2: name | I2: 89 | J2: นำเข้าแล้ว | K2: นำเข้าแล้ว | L2: ยืนยัน-หมวดหน่วยนับ | N2: =IF(M2="","",I2-M2) | U2: UAT-นำเข้าข้อมูล-คลังสินค้า-ครั้งที่-1.xlsx
A3: 2 | B3: คลังสินค้า | C3: หน่วยนับ | E3: Master | F3: คลัง, สินค้า, จัดซื้อ | G3: uom.uom | H3: name + หมวด | I3: 366 | J3: นำเข้าแล้ว | K3: นำเข้าแล้ว | L3: ยืนยัน-หน่วยนับ | N3: =IF(M3="","",I3-M3) | U3: UAT-นำเข้าข้อมูล-คลังสินค้า-ครั้งที่-1.xlsx
A4: 3 | B4: คลังสินค้า | C4: หมวดหมู่สินค้า | E4: Master | F4: คลัง, สินค้า | G4: product.category | H4: complete_name | I4: 115 | J4: นำเข้าแล้ว | K4: นำเข้าแล้ว | L4: ยืนยัน-หมวดสินค้า | N4: =IF(M4="","",I4-M4) | U4: UAT-นำเข้าข้อมูล-คลังสินค้า-ครั้งที่-1.xlsx
A5: 4 | B5: คลังสินค้า | C5: สินค้า (Product Master) | E5: Master | F5: คลัง, จัดซื้อ, งบประมาณ | G5: product.template | H5: default_code | I5: 5868 | J5: นำเข้าแล้ว | K5: นำเข้าแล้ว | L5: ยืนยัน-สินค้า | N5: =IF(M5="","",I5-M5) | U5: UAT-นำเข้าข้อมูล-คลังสินค้า-ครั้งที่-1.xlsx
A6: 5 | B6: คลังสินค้า | C6: ยา (Drug Master) · alyssa | E6: Master | F6: คลัง, จัดซื้อ, งบประมาณ | G6: product.template | H6: default_code | I6: 2622 | J6: นำเข้าแล้ว | K6: นำเข้าแล้ว | L6: ยืนยัน-ยา-alyssa | N6: =IF(M6="","",I6-M6) | S6: ฐาน VPK-S3 · หมวด 01. เวชภัณฑ์ ยา · จากไฟล์ drug_master_alyssa | U6: UAT-นำเข้าข้อมูล-คลังสินค้า-ครั้งที่-1.xlsx
A7: 6 | B7: คลังสินค้า | C7: คลังสินค้า (เปิดใช้ · รับเข้า 1 ขั้น) | E7: Master | F7: คลัง | G7: stock.warehouse | H7: code | I7: 18 | J7: นำเข้าแล้ว | K7: นำเข้าแล้ว | L7: ยืนยัน-คลัง | N7: =IF(M7="","",I7-M7) | U7: UAT-นำเข้าข้อมูล-คลังสินค้า-ครั้งที่-1.xlsx
A8: 7 | B8: คลังสินค้า | C8: ตำแหน่งจัดเก็บ (internal · เปิดใช้) | E8: Master | F8: คลัง | G8: stock.location | H8: complete_name | I8: 554 | J8: นำเข้าแล้ว | K8: นำเข้าแล้ว | L8: ยืนยัน-ตำแหน่ง | N8: =IF(M8="","",I8-M8) | U8: UAT-นำเข้าข้อมูล-คลังสินค้า-ครั้งที่-1.xlsx
A9: 8 | B9: คลังสินค้า | C9: ยกยอดสต็อก (On Hand ≠ 0) | E9: ธุรกรรม | F9: คลัง | G9: stock.quant | H9: สินค้า + ตำแหน่ง + lot | I9: 9 | J9: มีข้อมูลในระบบ (ธุรกรรม) | K9: มีข้อมูลในระบบ (ธุรกรรม) | L9: — | N9: =IF(M9="","",I9-M9) | U9: UAT-นำเข้าข้อมูล-คลังสินค้า-ครั้งที่-1.xlsx
A10: 9 | B10: คลังสินค้า | C10: Lot / Serial | E10: ธุรกรรม | F10: คลัง | G10: stock.lot | H10: name + สินค้า | I10: 3 | J10: มีข้อมูลในระบบ (ธุรกรรม) | K10: มีข้อมูลในระบบ (ธุรกรรม) | L10: — | N10: =IF(M10="","",I10-M10) | U10: UAT-นำเข้าข้อมูล-คลังสินค้า-ครั้งที่-1.xlsx
A11: 10 | B11: งบประมาณ | C11: แหล่งเงิน | D11: คือที่มาของเงิน เช่น เงินงบประมาณ เงินบำรุง เงิน UC เงินบริจาค ใช้เลือกตอนหน่วยงานขอตั้งงบและตอนขอซื้อ (PR) เพื่อให้ระบบจับคู่วงเงินถูกแหล่ง ใช้ข้ามแหล่งเงินไม่ได้ | E11: Master | F11: งบประมาณ | G11: vpk.budget.fund.source | H11: code | I11: 20 | J11: นำเข้าแล้ว | K11: นำเข้าแล้ว | L11: ยืนยัน-แหล่งเงิน | M11: 20 | N11: =IF(M11="","",I11-M11) | T11: ได้รับมาจาก บันทึกข้อมูลเข้า Template TAB ยืนยัน-แหล่งเงิน | U11: UAT-นำเข้าข้อมูล-งบประมาณ-ครั้งที่ 1.xlsx
A12: 11 | B12: งบประมาณ | C12: กลุ่มงบประมาณ-วัสดุ | D12: คือกลุ่มวัสดุสำหรับจัดซื้อ เช่น ยา เวชภัณฑ์มิใช่ยา วัสดุการแพทย์ วัสดุวิทยาศาสตร์ ใช้ตอนตั้งงบวัสดุและตอนขอซื้อวัสดุ เพื่อจับคู่บรรทัดวงเงินของกลุ่มนั้น | E12: Master | F12: งบประมาณ | G12: vpk.budget.group | H12: code | I12: 9 | J12: นำเข้าแล้ว | K12: นำเข้าแล้ว | L12: ยืนยัน-กลุ่มงบ | N12: =IF(M12="","",I12-M12) | T12: ได้รับจาก File แบบฟอร์มหมวดวัสดุ-69.xlsx , โดยนำข้อมูลที่แยก TABมาใช้ เป็นประเภทวัสดุ | U12: UAT-นำเข้าข้อมูล-งบประมาณ-ครั้งที่ 1.xlsx
A13: 12 | B13: งบประมาณ | C13: ประเภทวัสดุย่อย | D13: คือรายละเอียดภายใต้กลุ่มงบวัสดุ เช่น ยา เฝือก เวชภัณฑ์การพยาบาล ใช้แยกรายการในแบบฟอร์มตั้งงบวัสดุ และผูกกับกลุ่มงบตอนขอซื้อ | E13: Master | F13: งบประมาณ | G13: vpk.budget.material.sub.type | H13: code + กลุ่มงบ | I13: 35 | J13: นำเข้าแล้ว | K13: นำเข้าแล้ว | L13: ยืนยัน-วัสดุย่อย | N13: =IF(M13="","",I13-M13) | T13: ได้รับจาก File แบบฟอร์มหมวดวัสดุ-69.xlsx , โดยนำข้อมูลประเภทในแต่ละ TAB มาใช่เป็นวัสดุย่อย | U13: UAT-นำเข้าข้อมูล-งบประมาณ-ครั้งที่ 1.xlsx
A14: 13 | B14: งบประมาณ | C14: ประเภทงบประมาณ | D14: คือประเภทหลักของงบ ได้แก่ วัสดุ ครุภัณฑ์ ก่อสร้าง โครงการ ใช้กำหนดว่าคำของบและวงเงินอยู่กลุ่มใด และผูกกับแบบฟอร์มคำของบ | E14: Master | F14: งบประมาณ | G14: vpk.budget.type | H14: code | I14: 4 | J14: นำเข้าแล้ว | K14: นำเข้าแล้ว | L14: ยืนยัน-ประเภทงบ | N14: =IF(M14="","",I14-M14) | T14: ได้รับจาก File แบบฟอร์ม คำขอตั้งแผนเงินบำรุงโรงพยาบาลวชิระ.xlsx , และ File แบบฟอร์มหมวดวัสดุ-69.xlsx | U14: UAT-นำเข้าข้อมูล-งบประมาณ-ครั้งที่ 1.xlsx
A15: 14 | B15: งบประมาณ | C15: กลุ่มครุภัณฑ์ | D15: คือกลุ่มครุภัณฑ์ เช่น ครุภัณฑ์การแพทย์ ครุภัณฑ์ไฟฟ้า ใช้ตอนตั้งงบครุภัณฑ์ และผูกกับหมวดสินค้าเพื่อให้ขอซื้อครุภัณฑ์เข้ากลุ่มที่ถูกต้อง | E15: Master | F15: งบประมาณ | G15: vpk.budget.asset.category | H15: code | I15: 15 | J15: นำเข้าแล้ว | K15: นำเข้าแล้ว | L15: ยืนยัน-กลุ่มครุภัณฑ์ | N15: =IF(M15="","",I15-M15) | T15: จาก File บัญชีรายการครุภัณฑ์ สำนักงานปลัดกระทรวงส.xlsx / TAB บัญชีแจ้งหน่วยงาน | U15: UAT-นำเข้าข้อมูล-งบประมาณ-ครั้งที่ 1.xlsx
A16: 15 | B16: งบประมาณ | C16: แบบฟอร์มคำของบ | D16: คือชนิดแบบฟอร์มที่หน่วยงานใช้ขอตั้งงบ เช่น แบบฟอร์มตั้งงบวัสดุ แบบฟอร์มครุภัณฑ์ ใช้เปิดหน้าคำของบให้กรอกตามประเภทงาน | E16: Master | F16: งบประมาณ | G16: vpk.budget.request.form.type | H16: code | I16: 4 | J16: นำเข้าแล้ว | K16: นำเข้าแล้ว | L16: ยืนยัน-แบบฟอร์ม | N16: =IF(M16="","",I16-M16) | T16: ได้รับจาก File แบบฟอร์ม คำขอตั้งแผนเงินบำรุงโรงพยาบาลวชิระ.xlsx , และ File แบบฟอร์มหมวดวัสดุ-69.xlsx | U16: UAT-นำเข้าข้อมูล-งบประมาณ-ครั้งที่ 1.xlsx
A17: 16 | B17: งบประมาณ | C17: ประเภทงบในแบบฟอร์ม | D17: คือการผูกว่าแบบฟอร์มแต่ละใบใช้ประเภทงบใด ใช้ให้ระบบเปิดแท็บและตรวจวงเงินให้ตรงประเภทงบของแบบฟอร์มนั้น | E17: Master | F17: งบประมาณ | G17: vpk.budget.request.form.type.line | H17: form + ประเภทงบ | I17: 4 | J17: นำเข้าแล้ว | K17: นำเข้าแล้ว | L17: ยืนยัน-แท็บแบบฟอร์ม | N17: =IF(M17="","",I17-M17) | T17: ได้รับจาก File แบบฟอร์ม คำขอตั้งแผนเงินบำรุงโรงพยาบาลวชิระ.xlsx , และ File แบบฟอร์มหมวดวัสดุ-69.xlsx | U17: UAT-นำเข้าข้อมูล-งบประมาณ-ครั้งที่ 1.xlsx
A18: 17 | B18: งบประมาณ | C18: บัญชีวิเคราะห์ / หน่วยงาน | D18: คือหน่วยงานหรือโครงการที่ถือวงเงิน ใช้ใส่ในแผนงบ คำของบ และใบขอซื้อ เพื่อกันเงินและตัดงบรายหน่วยงาน | E18: Master | F18: งบประมาณ, จัดซื้อ, บัญชี | G18: account.analytic.account | H18: code | I18: 71 | J18: นำเข้าแล้ว | K18: นำเข้าแล้ว | L18: ยืนยัน-หน่วยงานวิเคราะห์ | N18: =IF(M18="","",I18-M18) | T18: ได้รับจาก File รวมรายการคำขอตั้งแผนเงินบำรุงโรงพยาบาลวชิระภูเก็ต ปีงบประมาณ 2569.xlsx , ปะหน้า | U18: UAT-นำเข้าข้อมูล-งบประมาณ-ครั้งที่ 1.xlsx
A19: 18 | B19: งบประมาณ | C19: แผนงบประมาณประจำปี | D19: คือแผนวงเงินของปีงบประมาณ พร้อมวันเริ่มและวันสิ้นสุด ใช้เป็นกรอบที่บรรทัดวงเงินและคำของบของปีนั้นอ้างอิง | E19: Master | F19: งบประมาณ | G19: budget.budget | H19: name + ช่วงวันที่ | I19: 1 | J19: นำเข้าแล้ว | K19: นำเข้าแล้ว | L19: ยืนยัน-แผนปี | N19: =IF(M19="","",I19-M19) | T19: บันทึกเข้าระบบตรงๆ Function การตั้งงบประมาณ | U19: UAT-นำเข้าข้อมูล-งบประมาณ-ครั้งที่ 1.xlsx
A20: 19 | B20: งบประมาณ | C20: หมวดงบประมาณ | D20: คือหมวดที่ใช้ควบคุมวงเงิน เช่น ครุภัณฑ์คอมพิวเตอร์ ครุภัณฑ์สำนักงาน ใช้จับคู่ตอนเช็คงบและกันเงินในใบขอซื้อกับบรรทัดวงเงิน | E20: Master | F20: งบประมาณ, จัดซื้อ | G20: account.budget.post | H20: name | I20: 46 | J20: นำเข้าแล้ว | K20: นำเข้าแล้ว | L20: ยืนยัน-หมวดงบ | N20: =IF(M20="","",I20-M20) | T20: จาก File บัญชีรายการครุภัณฑ์ สำนักงานปลัดกระทรวงส.xlsx แท็บ บัญชีแจ้งหน่วยงาน ฉบับตุลาคม 2569 จับคู่รหัสครุภัณฑ์กับสินค้าในระบบ , Chart of Account ของบัญชี , กลุ่มวัสดุของคลัง | U20: UAT-นำเข้าข้อมูล-งบประมาณ-ครั้งที่ 1.xlsx
A21: 20 | B21: งบประมาณ | C21: คำของบหน่วยงาน | D21: คือเอกสารที่หน่วยงานกรอกเพื่อขอตั้งงบประจำปี ใช้รวบรวมความต้องการก่อนจัดสรรวงเงินลงแผน เป็นเอกสารทำงาน ไม่ใช่ข้อมูลหลักสำหรับนำเข้า | E21: ธุรกรรม | F21: งบประมาณ | G21: departmental.budget.request | H21: เลขที่เอกสาร | I21: 35 | J21: นำเข้าแล้ว · รายการอยู่ในไฟล์แยก 1. UAT-นำเข้าข้อมูล-งบประมาณ-รายการคำขอวัสดุ-ครั้งที่ 1.xlsx 2. UAT-นำเข้าข้อมูล-งบประมาณ-รายการคำขอครุภัณฑ์-ครั้งที่ 1.xlsx 3. UAT-นำเข้าข้อมูล-งบประมาณ-รายการคำขอก่อสร้าง-ครั้งที่ 1.xlsx 4. UAT-นำเข้าข้อมูล-งบประมาณ-รายการคำขอโครงการ-ครั้งที่ 1.xlsx | K21: นำเข้าแล้ว | L21: ยืนยัน-คำของบ | N21: =IF(M21="","",I21-M21) | T21: ส่งออกจากฐาน VPK-S1 วันที่ 12 ต.ค. 2569 มีคำของบในระบบ 35 ใบ ในจำนวนนี้ 28 ใบนำเข้าจากไฟล์ แบบฟอร์มที่ 3 แผนปีงบประมาณ 2570 หมวดวัสดุ.xlsx แยกตามแท็บ ใส่ชื่อรายการในรายการสินค้า ยังไม่ผูกสินค้า DBR/2570/0004 วัสดุสำนักงาน 513 รายการ ยอด 8,614,565.05 บาท เท่ากับผลรวมวงเงินในแท็บ เพิ่มอีก 3 ใบในวันเดียวกัน: DBR/2570/0032 แบบฟอร์มก่อสร้าง กลุ่มงานโครงสร้างพื้นฐานฯ 27 รายการ 51,682,986.12 บาท จากไฟล์ 15.กลุ่มงานโครงสร้าง, DBR/2570/0033 แบบฟอร์มครุภัณฑ์ กลุ่มงานกุมารเวชกรรม 22 รายการ 14,162,390.00 บาท และ DBR/2570/0034 แบบฟอร์มโครงการ 3 รายการ 164,200.00 บาท จากไฟล์ 14.กลุ่มงานกุมารเวชกรรม รายละเอียดอยู่ใน UAT-นำเข้าข้อมูล-งบประมาณ-รายการคำขอครุภัณฑ์-ครั้งที่ 1.xlsx, UAT-นำเข้าข้อมูล-งบประมาณ-รายการคำขอก่อสร้าง-ครั้งที่ 1.xlsx และ UAT-นำเข้าข้อมูล-งบประมาณ-รายการคำขอโครงการ-ครั้งที่ 1.xlsx | U21: UAT-นำเข้าข้อมูล-งบประมาณ-ครั้งที่ 1.xlsx
A22: 21 | B22: งบประมาณ | C22: รายการสินค้าครุภัณฑ์ | D22: คือรหัสรายการครุภัณฑ์ที่นำเข้าจากบัญชีสำนักงานปลัดกระทรวงสาธารณสุขแล้ว ใช้เลือกตอนตั้งงบครุภัณฑ์ รายการยืนยันอยู่ในแท็บ ข้อมูล-item-ครุภัณฑ์ | E22: รายการ | F22: งบประมาณ | G22: product.template | H22: รหัสครุภัณฑ์ | I22: 1374 | J22: นำเข้าแล้ว | K22: นำเข้าแล้ว | L22: ข้อมูล-item-ครุภัณฑ์ | N22: =IF(M22="","",I22-M22) | T22: จาก File บัญชีรายการครุภัณฑ์ สำนักงานปลัดกระทรวงส.xlsx แท็บ บัญชีแจ้งหน่วยงาน ฉบับตุลาคม 2569 จับคู่รหัสครุภัณฑ์กับสินค้าในระบบ | U22: UAT-นำเข้าข้อมูล-งบประมาณ-ครั้งที่ 1.xlsx
A23: 22 | B23: จัดซื้อจัดจ้าง | C23: ผู้จำหน่าย / เจ้าหนี้ | D23: คือรายชื่อผู้ขายและเจ้าหนี้ที่ใช้งานในระบบ ใช้เลือกผู้ขายตอนออกใบขอซื้อ (PR) และใบสั่งซื้อ (PO) และใช้ตั้งหนี้ในงานเจ้าหนี้ จับคู่ด้วยรหัสอ้างอิง เลขผู้เสียภาษี หรือชื่อ | E23: Master | F23: จัดซื้อ, เจ้าหนี้ | G23: res.partner (ผู้ขายที่นำเข้า, ไม่รวมข้อมูลตัวอย่าง) | H23: ref / vat / ชื่อ | I23: 1154 | J23: นำเข้าแล้ว | K23: นำเข้าแล้ว | L23: ยืนยัน-ผู้จำหน่าย | N23: =IF(M23="","",I23-M23) | T23: ส่งออกจากฐาน VPK-S1 วันที่ 30 ส.ค. 2569 | U23: UAT-นำเข้าข้อมูล-จัดซื้อ-ครั้งที่ 1.xlsx
... A29: 28 | B29: จัดซื้อจัดจ้าง | C29: PO คงค้าง (ค้างรับ / ค้างตั้งหนี้) | D29: คือใบสั่งซื้อที่ยังรับของไม่ครบหรือยังตั้งหนี้ไม่ครบ ใช้ติดตามงานค้างรับและค้างตั้งหนี้ | E29: คงค้าง | F29: จัดซื้อ, คลัง, เจ้าหนี้ | G29: purchase.order (คงค้าง) | H29: name | I29: 0 | J29: ยังไม่นำเข้า (คงค้าง) | K29: ยังไม่นำเข้า | L29: ยืนยัน-POคงค้าง | N29: =IF(M29="","",I29-M29) | T29: ยังไม่มีรายการในฐาน VPK-S1 ณ วันที่ 30 ส.ค. 2569 | U29: UAT-นำเข้าข้อมูล-จัดซื้อ-ครั้งที่ 1.xlsx
A30: 29 | B30: สินทรัพย์ถาวร | C30: กลุ่มสินทรัพย์ | E30: Master | F30: บัญชี, ครุภัณฑ์ | G30: account.asset.group | H30: code | I30: 1 | J30: นำเข้าแล้ว | K30: นำเข้าแล้ว | L30: ยืนยัน-กลุ่มสินทรัพย์ | N30: =IF(M30="","",I30-M30) | U30: UAT-นำเข้าข้อมูล-สินทรัพย์ถาวร-ครั้งที่-1.xlsx
A31: 30 | B31: สินทรัพย์ถาวร | C31: โปรไฟล์สินทรัพย์ถาวร | E31: Master | F31: บัญชี, ครุภัณฑ์ | G31: account.asset.profile | H31: name | I31: 14 | J31: นำเข้าแล้ว | K31: นำเข้าแล้ว | L31: ยืนยัน-โปรไฟล์สินทรัพย์ | N31: =IF(M31="","",I31-M31) | U31: UAT-นำเข้าข้อมูล-สินทรัพย์ถาวร-ครั้งที่-1.xlsx
A32: 31 | B32: สินทรัพย์ถาวร | C32: สถานะย่อยสินทรัพย์ | E32: Master | F32: บัญชี, ครุภัณฑ์ | G32: account.asset.sub.state | H32: name | I32: 8 | J32: นำเข้าแล้ว | K32: นำเข้าแล้ว | L32: ยืนยัน-สถานะย่อย | N32: =IF(M32="","",I32-M32) | U32: UAT-นำเข้าข้อมูล-สินทรัพย์ถาวร-ครั้งที่-1.xlsx
A33: 32 | B33: สินทรัพย์ถาวร | C33: ชุดสินทรัพย์ (Asset Set) | E33: Master | F33: บัญชี, ครุภัณฑ์ | G33: account.asset.parent | H33: code | I33: 3 | J33: นำเข้าแล้ว | K33: นำเข้าแล้ว | L33: ยืนยัน-ชุดสินทรัพย์ | N33: =IF(M33="","",I33-M33) | U33: UAT-นำเข้าข้อมูล-สินทรัพย์ถาวร-ครั้งที่-1.xlsx
A34: 33 | B34: สินทรัพย์ถาวร | C34: บัตรสินทรัพย์ / ครุภัณฑ์ | E34: Master | F34: บัญชี, งบประมาณ, ซ่อมบำรุง | G34: account.asset | H34: number / code | I34: 22039 | J34: นำเข้าแล้ว | K34: นำเข้าแล้ว | L34: ยืนยัน-บัตรสินทรัพย์ | N34: =IF(M34="","",I34-M34) | U34: UAT-นำเข้าข้อมูล-สินทรัพย์ถาวร-ครั้งที่-1.xlsx
A35: 34 | B35: สินทรัพย์ถาวร | C35: ตารางค่าเสื่อม | E35: ตั้งค่า | F35: บัญชี | G35: account.asset.line | H35: สินทรัพย์ + วันที่ + ประเภท | I35: 20116 | J35: นำเข้าแล้ว | K35: นำเข้าแล้ว | L35: ยืนยัน-ตารางค่าเสื่อม | N35: =IF(M35="","",I35-M35) | U35: UAT-นำเข้าข้อมูล-สินทรัพย์ถาวร-ครั้งที่-1.xlsx
A36: 35 | B36: สินทรัพย์ถาวร | C36: หมวดครุภัณฑ์ซ่อมบำรุง | E36: Master | F36: ซ่อมบำรุง, สินทรัพย์ | G36: maintenance.equipment.category | H36: name | I36: 1 | J36: นำเข้าแล้ว | K36: นำเข้าแล้ว | L36: ยืนยัน-หมวดครุภัณฑ์ซ่อม | N36: =IF(M36="","",I36-M36) | U36: UAT-นำเข้าข้อมูล-สินทรัพย์ถาวร-ครั้งที่-1.xlsx
A37: 36 | B37: สินทรัพย์ถาวร | C37: ครุภัณฑ์ซ่อมบำรุง (Equipment) | E37: Master | F37: ซ่อมบำรุง, สินทรัพย์ | G37: maintenance.equipment | H37: asset_number / serial_no / ชื่อ | I37: 5 | J37: นำเข้าแล้ว | K37: นำเข้าแล้ว | L37: ยืนยัน-ครุภัณฑ์ซ่อม | N37: =IF(M37="","",I37-M37) | U37: UAT-นำเข้าข้อมูล-สินทรัพย์ถาวร-ครั้งที่-1.xlsx
A38: 37 | B38: เจ้าหนี้บัญชีการเงิน | C38: ผังบัญชี | E38: Master | F38: บัญชี | G38: account.account | H38: code | I38: 878 | J38: นำเข้าแล้ว | K38: นำเข้าแล้ว | L38: ยืนยัน-ผังบัญชี | N38: =IF(M38="","",I38-M38) | U38: UAT-นำเข้าข้อมูล-เจ้าหนี้บัญชีการเงิน-ครั้งที่ 1.xlsx
A39: 38 | B39: เจ้าหนี้บัญชีการเงิน | C39: สมุดรายวัน | E39: Master | F39: บัญชี, การเงิน | G39: account.journal | H39: code | I39: 57 | J39: นำเข้าแล้ว | K39: นำเข้าแล้ว | L39: ยืนยัน-สมุดรายวัน | N39: =IF(M39="","",I39-M39) | U39: UAT-นำเข้าข้อมูล-เจ้าหนี้บัญชีการเงิน-ครั้งที่ 1.xlsx
A40: 39 | B40: เจ้าหนี้บัญชีการเงิน | C40: บัญชีธนาคารของโรงพยาบาล | E40: Master | F40: การเงิน, บัญชี | G40: res.partner.bank (บริษัท) + account.journal | H40: เลขบัญชี / รหัสสมุดรายวัน | I40: 45 | J40: นำเข้าแล้ว | K40: นำเข้าแล้ว | L40: ยืนยัน-บัญชีธนาคารรพ | N40: =IF(M40="","",I40-M40) | U40: UAT-นำเข้าข้อมูล-เจ้าหนี้บัญชีการเงิน-ครั้งที่ 1.xlsx
A41: 40 | B41: เจ้าหนี้บัญชีการเงิน | C41: ภาษี (VAT) | E41: Master | F41: บัญชี, เจ้าหนี้ | G41: account.tax | H41: name | I41: 18 | J41: นำเข้าแล้ว | K41: นำเข้าแล้ว | L41: ยืนยัน-ภาษี | N41: =IF(M41="","",I41-M41) | U41: UAT-นำเข้าข้อมูล-เจ้าหนี้บัญชีการเงิน-ครั้งที่ 1.xlsx
... A49: 48 | B49: เจ้าหนี้บัญชีการเงิน | C49: ลูกหนี้ ประกันสังคม | E49: Master | F49: ลูกหนี้, บัญชี | G49: res.partner + res.partner.category | H49: ref / ชื่อ + แท็ก | I49: 75 | J49: นำเข้าแล้ว | K49: นำเข้าแล้ว | L49: ยืนยัน-ลูกหนี้ประกันสังคม | N49: =IF(M49="","",I49-M49) | U49: UAT-นำเข้าข้อมูล-เจ้าหนี้บัญชีการเงิน-ครั้งที่ 1.xlsx
A50: 49 | B50: เจ้าหนี้บัญชีการเงิน | C50: โปรไฟล์สินทรัพย์ถาวร | E50: Master | F50: บัญชี, ครุภัณฑ์ | G50: account.asset.profile | H50: name | I50: 14 | J50: นำเข้าแล้ว | K50: นำเข้าแล้ว | L50: ยืนยัน-โปรไฟล์สินทรัพย์ | N50: =IF(M50="","",I50-M50) | U50: UAT-นำเข้าข้อมูล-เจ้าหนี้บัญชีการเงิน-ครั้งที่ 1.xlsx | V50: ซ้ำกับสินทรัพย์ถาวร
A51: 50 | B51: เจ้าหนี้บัญชีการเงิน | C51: บัตรสินทรัพย์ / ครุภัณฑ์ | E51: Master | F51: บัญชี, งบประมาณ | G51: account.asset | H51: code | I51: 22039 | J51: นำเข้าแล้ว | K51: นำเข้าแล้ว | L51: ยืนยัน-บัตรสินทรัพย์ | N51: =IF(M51="","",I51-M51) | U51: UAT-นำเข้าข้อมูล-เจ้าหนี้บัญชีการเงิน-ครั้งที่ 1.xlsx | V51: ซ้ำกับสินทรัพย์ถาวร
A52: 51 | B52: เจ้าหนี้บัญชีการเงิน | C52: ครุภัณฑ์ซ่อมบำรุง (Equipment) | E52: Master | F52: ซ่อมบำรุง, สินทรัพย์ | G52: maintenance.equipment | H52: name | I52: 5 | J52: นำเข้าแล้ว | K52: นำเข้าแล้ว | L52: ยืนยัน-ครุภัณฑ์ซ่อม | N52: =IF(M52="","",I52-M52) | U52: UAT-นำเข้าข้อมูล-เจ้าหนี้บัญชีการเงิน-ครั้งที่ 1.xlsx | V52: ซ้ำกับสินทรัพย์ถาวร
...

Sheet สรุป-คลังสินค้า
A1: ลำดับ | B1: ประเภทข้อมูล | C1: กลุ่ม | D1: โมดูลที่เกี่ยวข้อง | E1: โมเดลในระบบ | F1: คีย์จับคู่ | G1: จำนวนในระบบ | H1: สถานะนำเข้า | I1: ชีตรายการยืนยัน | J1: จำนวนต้นทาง (กรอก) | K1: ผลต่าง | L1: ผลยืนยัน | M1: ผู้ยืนยัน | N1: ลงชื่อ | O1: วันที่ | P1: หมายเหตุ
A2: 1 | B2: หมวดหน่วยนับ | C2: Master | D2: คลัง, สินค้า | E2: uom.category | F2: name | G2: 89 | H2: นำเข้าแล้ว | I2: ยืนยัน-หมวดหน่วยนับ | K2: =IF(J2="","",G2-J2)
A3: 2 | B3: หน่วยนับ | C3: Master | D3: คลัง, สินค้า, จัดซื้อ | E3: uom.uom | F3: name + หมวด | G3: 366 | H3: นำเข้าแล้ว | I3: ยืนยัน-หน่วยนับ | K3: =IF(J3="","",G3-J3)
A4: 3 | B4: หมวดหมู่สินค้า | C4: Master | D4: คลัง, สินค้า | E4: product.category | F4: complete_name | G4: 115 | H4: นำเข้าแล้ว | I4: ยืนยัน-หมวดสินค้า | K4: =IF(J4="","",G4-J4)
A5: 4 | B5: สินค้า (Product Master) | C5: Master | D5: คลัง, จัดซื้อ, งบประมาณ | E5: product.template | F5: default_code | G5: 5868 | H5: นำเข้าแล้ว | I5: ยืนยัน-สินค้า | K5: =IF(J5="","",G5-J5)
A6: 5 | B6: ยา (Drug Master) · alyssa | C6: Master | D6: คลัง, จัดซื้อ, งบประมาณ | E6: product.template | F6: default_code | G6: 2622 | H6: นำเข้าแล้ว | I6: ยืนยัน-ยา-alyssa | K6: =IF(J6="","",G6-J6) | P6: ฐาน VPK-S3 · หมวด 01. เวชภัณฑ์ ยา · จากไฟล์ drug_master_alyssa
A7: 6 | B7: คลังสินค้า (เปิดใช้ · รับเข้า 1 ขั้น) | C7: Master | D7: คลัง | E7: stock.warehouse | F7: code | G7: 18 | H7: นำเข้าแล้ว | I7: ยืนยัน-คลัง | K7: =IF(J7="","",G7-J7)
A8: 7 | B8: ตำแหน่งจัดเก็บ (internal · เปิดใช้) | C8: Master | D8: คลัง | E8: stock.location | F8: complete_name | G8: 554 | H8: นำเข้าแล้ว | I8: ยืนยัน-ตำแหน่ง | K8: =IF(J8="","",G8-J8)
A9: 8 | B9: ยกยอดสต็อก (On Hand ≠ 0) | C9: ธุรกรรม | D9: คลัง | E9: stock.quant | F9: สินค้า + ตำแหน่ง + lot | G9: 9 | H9: มีข้อมูลในระบบ (ธุรกรรม) | I9: — | K9: =IF(J9="","",G9-J9)
A10: 9 | B10: Lot / Serial | C10: ธุรกรรม | D10: คลัง | E10: stock.lot | F10: name + สินค้า | G10: 3 | H10: มีข้อมูลในระบบ (ธุรกรรม) | I10: — | K10: =IF(J10="","",G10-J10)
B11: รวมจำนวนทุกประเภทในชีตนี้ | G11: =SUM(G2:G10)
A12: ข้อมูล ณ 30 ส.ค. 2569 23:24 จากฐาน VPK-S1 คอลัมน์ “จำนวนต้นทาง” ให้เจ้าของข้อมูลกรอกจากไฟล์ที่ส่งมา ถ้าผลต่าง ≠ 0 ให้เลือกผลยืนยันเป็น ต้องแก้ไข หรือ ยังไม่ครบ กลุ่ม Master = ข้อมูลหลักที่ใช้ทั้งระบบ · ตั้งค่า = วงเงิน/ค่าคงที่ · ธุรกรรม = เอกสารปฏิบัติงาน · คงค้าง = PO ค้างรับ/ค้างตั้งหนี้, เจ้าหนี้ค้างจ่าย, งบทดลอง TB ปี 2569 (ปีงบประมาณ 1 ต.ค. 2568 – 30 ก.ย. 2569)

Sheet สรุป-งบประมาณ
A1: ลำดับ | B1: ประเภทข้อมูล | C1: ข้อมูลนี้คืออะไร / ใช้ทำอะไรในระบบ | D1: กลุ่ม | E1: โมดูลที่เกี่ยวข้อง | F1: โมเดลในระบบ | G1: คีย์จับคู่ | H1: จำนวนในระบบ | I1: สถานะนำเข้า | J1: ชีตรายการยืนยัน | K1: จำนวนต้นทาง (กรอก) | L1: ผลต่าง | M1: ผลยืนยัน | N1: ผู้ยืนยัน | O1: ลงชื่อ | P1: วันที่ | Q1: หมายเหตุ | R1: อ้างอิงการได้มาของข้อมูล
A2: 1 | B2: แหล่งเงิน | C2: คือที่มาของเงิน เช่น เงินงบประมาณ เงินบำรุง เงิน UC เงินบริจาค ใช้เลือกตอนหน่วยงานขอตั้งงบและตอนขอซื้อ (PR) เพื่อให้ระบบจับคู่วงเงินถูกแหล่ง ใช้ข้ามแหล่งเงินไม่ได้ | D2: Master | E2: งบประมาณ | F2: vpk.budget.fund.source | G2: code | H2: 20 | I2: นำเข้าแล้ว | J2: ยืนยัน-แหล่งเงิน | K2: 20 | L2: =IF(K2="","",H2-K2) | R2: ได้รับมาจาก บันทึกข้อมูลเข้า Template TAB ยืนยัน-แหล่งเงิน
A3: 2 | B3: กลุ่มงบประมาณ-วัสดุ | C3: คือกลุ่มวัสดุสำหรับจัดซื้อ เช่น ยา เวชภัณฑ์มิใช่ยา วัสดุการแพทย์ วัสดุวิทยาศาสตร์ ใช้ตอนตั้งงบวัสดุและตอนขอซื้อวัสดุ เพื่อจับคู่บรรทัดวงเงินของกลุ่มนั้น | D3: Master | E3: งบประมาณ | F3: vpk.budget.group | G3: code | H3: 9 | I3: นำเข้าแล้ว | J3: ยืนยัน-กลุ่มงบ | L3: =IF(K3="","",H3-K3) | R3: ได้รับจาก File แบบฟอร์มหมวดวัสดุ-69.xlsx , โดยนำข้อมูลที่แยก TABมาใช้ เป็นประเภทวัสดุ
A4: 3 | B4: ประเภทวัสดุย่อย | C4: คือรายละเอียดภายใต้กลุ่มงบวัสดุ เช่น ยา เฝือก เวชภัณฑ์การพยาบาล ใช้แยกรายการในแบบฟอร์มตั้งงบวัสดุ และผูกกับกลุ่มงบตอนขอซื้อ | D4: Master | E4: งบประมาณ | F4: vpk.budget.material.sub.type | G4: code + กลุ่มงบ | H4: 35 | I4: นำเข้าแล้ว | J4: ยืนยัน-วัสดุย่อย | L4: =IF(K4="","",H4-K4) | R4: ได้รับจาก File แบบฟอร์มหมวดวัสดุ-69.xlsx , โดยนำข้อมูลประเภทในแต่ละ TAB มาใช่เป็นวัสดุย่อย
A5: 4 | B5: ประเภทงบประมาณ | C5: คือประเภทหลักของงบ ได้แก่ วัสดุ ครุภัณฑ์ ก่อสร้าง โครงการ ใช้กำหนดว่าคำของบและวงเงินอยู่กลุ่มใด และผูกกับแบบฟอร์มคำของบ | D5: Master | E5: งบประมาณ | F5: vpk.budget.type | G5: code | H5: 4 | I5: นำเข้าแล้ว | J5: ยืนยัน-ประเภทงบ | L5: =IF(K5="","",H5-K5) | R5: ได้รับจาก File แบบฟอร์ม คำขอตั้งแผนเงินบำรุงโรงพยาบาลวชิระ.xlsx , และ File แบบฟอร์มหมวดวัสดุ-69.xlsx
A6: 5 | B6: กลุ่มครุภัณฑ์ | C6: คือกลุ่มครุภัณฑ์ เช่น ครุภัณฑ์การแพทย์ ครุภัณฑ์ไฟฟ้า ใช้ตอนตั้งงบครุภัณฑ์ และผูกกับหมวดสินค้าเพื่อให้ขอซื้อครุภัณฑ์เข้ากลุ่มที่ถูกต้อง | D6: Master | E6: งบประมาณ | F6: vpk.budget.asset.category | G6: code | H6: 15 | I6: นำเข้าแล้ว | J6: ยืนยัน-กลุ่มครุภัณฑ์ | L6: =IF(K6="","",H6-K6) | R6: จาก File บัญชีรายการครุภัณฑ์ สำนักงานปลัดกระทรวงส.xlsx / TAB บัญชีแจ้งหน่วยงาน
A7: 6 | B7: แบบฟอร์มคำของบ | C7: คือชนิดแบบฟอร์มที่หน่วยงานใช้ขอตั้งงบ เช่น แบบฟอร์มตั้งงบวัสดุ แบบฟอร์มครุภัณฑ์ ใช้เปิดหน้าคำของบให้กรอกตามประเภทงาน | D7: Master | E7: งบประมาณ | F7: vpk.budget.request.form.type | G7: code | H7: 4 | I7: นำเข้าแล้ว | J7: ยืนยัน-แบบฟอร์ม | L7: =IF(K7="","",H7-K7) | R7: ได้รับจาก File แบบฟอร์ม คำขอตั้งแผนเงินบำรุงโรงพยาบาลวชิระ.xlsx , และ File แบบฟอร์มหมวดวัสดุ-69.xlsx
A8: 7 | B8: ประเภทงบในแบบฟอร์ม | C8: คือการผูกว่าแบบฟอร์มแต่ละใบใช้ประเภทงบใด ใช้ให้ระบบเปิดแท็บและตรวจวงเงินให้ตรงประเภทงบของแบบฟอร์มนั้น | D8: Master | E8: งบประมาณ | F8: vpk.budget.request.form.type.line | G8: form + ประเภทงบ | H8: 4 | I8: นำเข้าแล้ว | J8: ยืนยัน-แท็บแบบฟอร์ม | L8: =IF(K8="","",H8-K8) | R8: ได้รับจาก File แบบฟอร์ม คำขอตั้งแผนเงินบำรุงโรงพยาบาลวชิระ.xlsx , และ File แบบฟอร์มหมวดวัสดุ-69.xlsx
A9: 8 | B9: บัญชีวิเคราะห์ / หน่วยงาน | C9: คือหน่วยงานหรือโครงการที่ถือวงเงิน ใช้ใส่ในแผนงบ คำของบ และใบขอซื้อ เพื่อกันเงินและตัดงบรายหน่วยงาน | D9: Master | E9: งบประมาณ, จัดซื้อ, บัญชี | F9: account.analytic.account | G9: code | H9: 71 | I9: นำเข้าแล้ว | J9: ยืนยัน-หน่วยงานวิเคราะห์ | L9: =IF(K9="","",H9-K9) | R9: ได้รับจาก File รวมรายการคำขอตั้งแผนเงินบำรุงโรงพยาบาลวชิระภูเก็ต ปีงบประมาณ 2569.xlsx , ปะหน้า
A10: 9 | B10: แผนงบประมาณประจำปี | C10: คือแผนวงเงินของปีงบประมาณ พร้อมวันเริ่มและวันสิ้นสุด ใช้เป็นกรอบที่บรรทัดวงเงินและคำของบของปีนั้นอ้างอิง | D10: Master | E10: งบประมาณ | F10: budget.budget | G10: name + ช่วงวันที่ | H10: 1 | I10: นำเข้าแล้ว | J10: ยืนยัน-แผนปี | L10: =IF(K10="","",H10-K10) | R10: บันทึกเข้าระบบตรงๆ Function การตั้งงบประมาณ
A11: 10 | B11: หมวดงบประมาณ | C11: คือหมวดที่ใช้ควบคุมวงเงิน เช่น ครุภัณฑ์คอมพิวเตอร์ ครุภัณฑ์สำนักงาน ใช้จับคู่ตอนเช็คงบและกันเงินในใบขอซื้อกับบรรทัดวงเงิน | D11: Master | E11: งบประมาณ, จัดซื้อ | F11: account.budget.post | G11: name | H11: 46 | I11: นำเข้าแล้ว | J11: ยืนยัน-หมวดงบ | L11: =IF(K11="","",H11-K11) | R11: จาก File บัญชีรายการครุภัณฑ์ สำนักงานปลัดกระทรวงส.xlsx แท็บ บัญชีแจ้งหน่วยงาน ฉบับตุลาคม 2569 จับคู่รหัสครุภัณฑ์กับสินค้าในระบบ , Chart of Account ของบัญชี , กลุ่มวัสดุของคลัง
A12: 11 | B12: คำของบหน่วยงาน | C12: คือเอกสารที่หน่วยงานกรอกเพื่อขอตั้งงบประจำปี ใช้รวบรวมความต้องการก่อนจัดสรรวงเงินลงแผน เป็นเอกสารทำงาน ไม่ใช่ข้อมูลหลักสำหรับนำเข้า | D12: ธุรกรรม | E12: งบประมาณ | F12: departmental.budget.request | G12: เลขที่เอกสาร | H12: 35 | I12: นำเข้าแล้ว · รายการอยู่ในไฟล์แยก 1. UAT-นำเข้าข้อมูล-งบประมาณ-รายการคำขอวัสดุ-ครั้งที่ 1.xlsx 2. UAT-นำเข้าข้อมูล-งบประมาณ-รายการคำขอครุภัณฑ์-ครั้งที่ 1.xlsx 3. UAT-นำเข้าข้อมูล-งบประมาณ-รายการคำขอก่อสร้าง-ครั้งที่ 1.xlsx 4. UAT-นำเข้าข้อมูล-งบประมาณ-รายการคำขอโครงการ-ครั้งที่ 1.xlsx | J12: ยืนยัน-คำของบ | L12: =IF(K12="","",H12-K12) | R12: ส่งออกจากฐาน VPK-S1 วันที่ 12 ต.ค. 2569 มีคำของบในระบบ 35 ใบ ในจำนวนนี้ 28 ใบนำเข้าจากไฟล์ แบบฟอร์มที่ 3 แผนปีงบประมาณ 2570 หมวดวัสดุ.xlsx แยกตามแท็บ ใส่ชื่อรายการในรายการสินค้า ยังไม่ผูกสินค้า DBR/2570/0004 วัสดุสำนักงาน 513 รายการ ยอด 8,614,565.05 บาท เท่ากับผลรวมวงเงินในแท็บ เพิ่มอีก 3 ใบในวันเดียวกัน: DBR/2570/0032 แบบฟอร์มก่อสร้าง กลุ่มงานโครงสร้างพื้นฐานฯ 27 รายการ 51,682,986.12 บาท จากไฟล์ 15.กลุ่มงานโครงสร้าง, DBR/2570/0033 แบบฟอร์มครุภัณฑ์ กลุ่มงานกุมารเวชกรรม 22 รายการ 14,162,390.00 บาท และ DBR/2570/0034 แบบฟอร์มโครงการ 3 รายการ 164,200.00 บาท จากไฟล์ 14.กลุ่มงานกุมารเวชกรรม รายละเอียดอยู่ใน UAT-นำเข้าข้อมูล-งบประมาณ-รายการคำขอครุภัณฑ์-ครั้งที่ 1.xlsx, UAT-นำเข้าข้อมูล-งบประมาณ-รายการคำขอก่อสร้าง-ครั้งที่ 1.xlsx และ UAT-นำเข้าข้อมูล-งบประมาณ-รายการคำขอโครงการ-ครั้งที่ 1.xlsx
A13: 12 | B13: รายการสินค้าครุภัณฑ์ | C13: คือรหัสรายการครุภัณฑ์ที่นำเข้าจากบัญชีสำนักงานปลัดกระทรวงสาธารณสุขแล้ว ใช้เลือกตอนตั้งงบครุภัณฑ์ รายการยืนยันอยู่ในแท็บ ข้อมูล-item-ครุภัณฑ์ | D13: รายการ | E13: งบประมาณ | F13: product.template | G13: รหัสครุภัณฑ์ | H13: 1374 | I13: นำเข้าแล้ว | J13: ข้อมูล-item-ครุภัณฑ์ | L13: =IF(K13="","",H13-K13) | R13: จาก File บัญชีรายการครุภัณฑ์ สำนักงานปลัดกระทรวงส.xlsx แท็บ บัญชีแจ้งหน่วยงาน ฉบับตุลาคม 2569 จับคู่รหัสครุภัณฑ์กับสินค้าในระบบ
B14: รวมจำนวนทุกประเภทในชีตนี้ | H14: =SUM(H2:H13)
A15: ข้อมูล ณ 30 ส.ค. 2569 23:24 จากฐาน VPK-S1 คอลัมน์ “จำนวนต้นทาง” ให้เจ้าของข้อมูลกรอกจากไฟล์ที่ส่งมา ถ้าผลต่าง ≠ 0 ให้เลือกผลยืนยันเป็น ต้องแก้ไข หรือ ยังไม่ครบ กลุ่ม Master = ข้อมูลหลักที่ใช้ทั้งระบบ · ตั้งค่า = วงเงิน/ค่าคงที่ · ธุรกรรม = เอกสารปฏิบัติงาน · คงค้าง = PO ค้างรับ/ค้างตั้งหนี้, เจ้าหนี้ค้างจ่าย, งบทดลอง TB ปี 2569 (ปีงบประมาณ 1 ต.ค. 2568 – 30 ก.ย. 2569) คอลัมน์ “อ้างอิงการได้มาของข้อมูล” บันทึกว่าแต่ละประเภทได้มาจากข้อมูลตั้งต้นของโมดูล ไฟล์แม่แบบที่นำเข้า หรือสร้างในระบบ

Sheet สรุป-จัดซื้อ
A1: ลำดับ | B1: ประเภทข้อมูล | C1: ข้อมูลนี้คืออะไร / ใช้ทำอะไรในระบบ | D1: กลุ่ม | E1: โมดูลที่เกี่ยวข้อง | F1: โมเดลในระบบ | G1: คีย์จับคู่ | H1: จำนวนในระบบ | I1: สถานะนำเข้า | J1: ชีตรายการยืนยัน | K1: จำนวนต้นทาง (กรอก) | L1: ผลต่าง | M1: ผลยืนยัน | N1: ผู้ยืนยัน | O1: ลงชื่อ | P1: วันที่ | Q1: หมายเหตุ | R1: อ้างอิงการได้มาของข้อมูล
A2: 1 | B2: ผู้จำหน่าย / เจ้าหนี้ | C2: คือรายชื่อผู้ขายและเจ้าหนี้ที่ใช้งานในระบบ ใช้เลือกผู้ขายตอนออกใบขอซื้อ (PR) และใบสั่งซื้อ (PO) และใช้ตั้งหนี้ในงานเจ้าหนี้ จับคู่ด้วยรหัสอ้างอิง เลขผู้เสียภาษี หรือชื่อ | D2: Master | E2: จัดซื้อ, เจ้าหนี้ | F2: res.partner (ผู้ขายที่นำเข้า, ไม่รวมข้อมูลตัวอย่าง) | G2: ref / vat / ชื่อ | H2: 1154 | I2: นำเข้าแล้ว | J2: ยืนยัน-ผู้จำหน่าย | L2: =IF(K2="","",H2-K2) | R2: ส่งออกจากฐาน VPK-S1 วันที่ 30 ส.ค. 2569
A3: 2 | B3: บัญชีธนาคารผู้ขาย | C3: คือเลขที่บัญชีธนาคารของแต่ละผู้ขาย ใช้ตอนจ่ายเงินให้ผู้ขายในงานการเงิน โดยผูกบัญชีกับผู้ขาย | D3: Master | E3: จัดซื้อ, การเงิน | F3: res.partner.bank | G3: partner + เลขบัญชี | H3: 0 | I3: ยังไม่นำเข้า | J3: ยืนยัน-บัญชีผู้ขาย | L3: =IF(K3="","",H3-K3) | R3: ยังไม่มีรายการในฐาน VPK-S1 ณ วันที่ 30 ส.ค. 2569
A4: 3 | B4: ราคา / MOQ ผู้ขาย | C4: คือราคาและจำนวนสั่งขั้นต่ำ (MOQ) ที่ผู้ขายกำหนดต่อสินค้า ใช้ดึงราคาตอนจัดซื้อ จับคู่ด้วยผู้ขายและสินค้า | D4: Master | E4: จัดซื้อ, สินค้า | F4: product.supplierinfo | G4: ผู้ขาย + สินค้า | H4: 1 | I4: นำเข้าแล้ว | J4: ยืนยัน-ราคาผู้ขาย | L4: =IF(K4="","",H4-K4) | R4: ส่งออกจากฐาน VPK-S1 วันที่ 30 ส.ค. 2569
A5: 4 | B5: กลุ่มผู้จำหน่ายจัดซื้อ | C5: คือกลุ่มที่ใช้จัดประเภทผู้ขาย เช่น กลุ่มยา เจ้าหนี้ตรง ส่วนสาธารณูปโภค ใช้กรองผู้ขายและออกรายงานตามกลุ่ม จับคู่ด้วยรหัสกลุ่ม | D5: Master | E5: จัดซื้อ, เจ้าหนี้ | F5: procurement.vendor.group | G5: code | H5: 7 | I5: นำเข้าแล้ว | J5: ยืนยัน-กลุ่มผู้จำหน่าย | L5: =IF(K5="","",H5-K5) | R5: ส่งออกจากฐาน VPK-S1 วันที่ 30 ส.ค. 2569
A6: 5 | B6: ใบขอซื้อ (PR) | C6: คือเอกสารที่หน่วยงานขอให้พัสดุจัดซื้อ ใช้เริ่มกระบวนการก่อนออกใบสั่งซื้อ จับคู่ด้วยเลขที่ใบขอซื้อ | D6: ธุรกรรม | E6: จัดซื้อ | F6: purchase.request | G6: name | H6: 0 | I6: ยังไม่นำเข้า | J6: ยืนยัน-PR | L6: =IF(K6="","",H6-K6) | R6: ยังไม่มีรายการในฐาน VPK-S1 ณ วันที่ 30 ส.ค. 2569
A7: 6 | B7: ใบสั่งซื้อ (PO) ทั้งหมด | C7: คือใบสั่งซื้อที่ออกให้ผู้ขายแล้ว ใช้รับของเข้าคลังและตั้งหนี้เจ้าหนี้ จับคู่ด้วยเลขที่ใบสั่งซื้อ | D7: ธุรกรรม | E7: จัดซื้อ, คลัง, เจ้าหนี้ | F7: purchase.order | G7: name | H7: 0 | I7: ยังไม่นำเข้า | J7: ยืนยัน-POทั้งหมด | L7: =IF(K7="","",H7-K7) | R7: ยังไม่มีรายการในฐาน VPK-S1 ณ วันที่ 30 ส.ค. 2569
A8: 7 | B8: PO คงค้าง (ค้างรับ / ค้างตั้งหนี้) | C8: คือใบสั่งซื้อที่ยังรับของไม่ครบหรือยังตั้งหนี้ไม่ครบ ใช้ติดตามงานค้างรับและค้างตั้งหนี้ | D8: คงค้าง | E8: จัดซื้อ, คลัง, เจ้าหนี้ | F8: purchase.order (คงค้าง) | G8: name | H8: 0 | I8: ยังไม่นำเข้า (คงค้าง) | J8: ยืนยัน-POคงค้าง | L8: =IF(K8="","",H8-K8) | R8: ยังไม่มีรายการในฐาน VPK-S1 ณ วันที่ 30 ส.ค. 2569
B9: รวมจำนวนทุกประเภทในชีตนี้ | H9: =SUM(H2:H8)
A11: ข้อมูล ณ 30 ส.ค. 2569 23:24 จากฐาน VPK-S1 คอลัมน์ “จำนวนต้นทาง” ให้เจ้าของข้อมูลกรอกจากไฟล์ที่ส่งมา ถ้าผลต่าง ≠ 0 ให้เลือกผลยืนยันเป็น ต้องแก้ไข หรือ ยังไม่ครบ กลุ่ม Master = ข้อมูลหลักที่ใช้ทั้งระบบ · ตั้งค่า = วงเงิน/ค่าคงที่ · ธุรกรรม = เอกสารปฏิบัติงาน · คงค้าง = PO ค้างรับ/ค้างตั้งหนี้, เจ้าหนี้ค้างจ่าย, งบทดลอง TB ปี 2569 (ปีงบประมาณ 1 ต.ค. 2568 – 30 ก.ย. 2569) คอลัมน์ “อ้างอิงการได้มาของข้อมูล” บันทึกว่าแต่ละประเภทได้มาจากข้อมูลตั้งต้นของโมดูล ไฟล์แม่แบบที่นำเข้า หรือสร้างในระบบ

Sheet สรุป-สินทรัพย์ถาวร
A1: ลำดับ | B1: ประเภทข้อมูล | C1: กลุ่ม | D1: โมดูลที่เกี่ยวข้อง | E1: โมเดลในระบบ | F1: คีย์จับคู่ | G1: จำนวนในระบบ | H1: สถานะนำเข้า | I1: ชีตรายการยืนยัน | J1: จำนวนต้นทาง (กรอก) | K1: ผลต่าง | L1: ผลยืนยัน | M1: ผู้ยืนยัน | N1: ลงชื่อ | O1: วันที่ | P1: หมายเหตุ
A2: 1 | B2: กลุ่มสินทรัพย์ | C2: Master | D2: บัญชี, ครุภัณฑ์ | E2: account.asset.group | F2: code | G2: 1 | H2: นำเข้าแล้ว | I2: ยืนยัน-กลุ่มสินทรัพย์ | K2: =IF(J2="","",G2-J2)
A3: 2 | B3: โปรไฟล์สินทรัพย์ถาวร | C3: Master | D3: บัญชี, ครุภัณฑ์ | E3: account.asset.profile | F3: name | G3: 14 | H3: นำเข้าแล้ว | I3: ยืนยัน-โปรไฟล์สินทรัพย์ | K3: =IF(J3="","",G3-J3)
A4: 3 | B4: สถานะย่อยสินทรัพย์ | C4: Master | D4: บัญชี, ครุภัณฑ์ | E4: account.asset.sub.state | F4: name | G4: 8 | H4: นำเข้าแล้ว | I4: ยืนยัน-สถานะย่อย | K4: =IF(J4="","",G4-J4)
A5: 4 | B5: ชุดสินทรัพย์ (Asset Set) | C5: Master | D5: บัญชี, ครุภัณฑ์ | E5: account.asset.parent | F5: code | G5: 3 | H5: นำเข้าแล้ว | I5: ยืนยัน-ชุดสินทรัพย์ | K5: =IF(J5="","",G5-J5)
A6: 5 | B6: บัตรสินทรัพย์ / ครุภัณฑ์ | C6: Master | D6: บัญชี, งบประมาณ, ซ่อมบำรุง | E6: account.asset | F6: number / code | G6: 22039 | H6: นำเข้าแล้ว | I6: ยืนยัน-บัตรสินทรัพย์ | K6: =IF(J6="","",G6-J6)
A7: 6 | B7: ตารางค่าเสื่อม | C7: ตั้งค่า | D7: บัญชี | E7: account.asset.line | F7: สินทรัพย์ + วันที่ + ประเภท | G7: 20116 | H7: นำเข้าแล้ว | I7: ยืนยัน-ตารางค่าเสื่อม | K7: =IF(J7="","",G7-J7)
A8: 7 | B8: หมวดครุภัณฑ์ซ่อมบำรุง | C8: Master | D8: ซ่อมบำรุง, สินทรัพย์ | E8: maintenance.equipment.category | F8: name | G8: 1 | H8: นำเข้าแล้ว | I8: ยืนยัน-หมวดครุภัณฑ์ซ่อม | K8: =IF(J8="","",G8-J8)
A9: 8 | B9: ครุภัณฑ์ซ่อมบำรุง (Equipment) | C9: Master | D9: ซ่อมบำรุง, สินทรัพย์ | E9: maintenance.equipment | F9: asset_number / serial_no / ชื่อ | G9: 5 | H9: นำเข้าแล้ว | I9: ยืนยัน-ครุภัณฑ์ซ่อม | K9: =IF(J9="","",G9-J9)
B10: รวมจำนวนทุกประเภทในชีตนี้ | G10: =SUM(G2:G9)
A12: ข้อมูล ณ 30 ส.ค. 2569 23:24 จากฐาน VPK-S1 คอลัมน์ “จำนวนต้นทาง” ให้เจ้าของข้อมูลกรอกจากไฟล์ที่ส่งมา ถ้าผลต่าง ≠ 0 ให้เลือกผลยืนยันเป็น ต้องแก้ไข หรือ ยังไม่ครบ กลุ่ม Master = ข้อมูลหลักที่ใช้ทั้งระบบ · ตั้งค่า = วงเงิน/ค่าคงที่ · ธุรกรรม = เอกสารปฏิบัติงาน · คงค้าง = PO ค้างรับ/ค้างตั้งหนี้, เจ้าหนี้ค้างจ่าย, งบทดลอง TB ปี 2569 (ปีงบประมาณ 1 ต.ค. 2568 – 30 ก.ย. 2569)

Sheet สรุป-เจ้าหนี้การเงิน
A1: ลำดับ | B1: ประเภทข้อมูล | C1: กลุ่ม | D1: โมดูลที่เกี่ยวข้อง | E1: โมเดลในระบบ | F1: คีย์จับคู่ | G1: จำนวนในระบบ | H1: สถานะนำเข้า | I1: ชีตรายการยืนยัน | J1: จำนวนต้นทาง (กรอก) | K1: ผลต่าง | L1: ผลยืนยัน | M1: ผู้ยืนยัน | N1: ลงชื่อ | O1: วันที่ | P1: หมายเหตุ
A2: 1 | B2: ผังบัญชี | C2: Master | D2: บัญชี | E2: account.account | F2: code | G2: 878 | H2: นำเข้าแล้ว | I2: ยืนยัน-ผังบัญชี | K2: =IF(J2="","",G2-J2)
A3: 2 | B3: สมุดรายวัน | C3: Master | D3: บัญชี, การเงิน | E3: account.journal | F3: code | G3: 57 | H3: นำเข้าแล้ว | I3: ยืนยัน-สมุดรายวัน | K3: =IF(J3="","",G3-J3)
A4: 3 | B4: บัญชีธนาคารของโรงพยาบาล | C4: Master | D4: การเงิน, บัญชี | E4: res.partner.bank (บริษัท) + account.journal | F4: เลขบัญชี / รหัสสมุดรายวัน | G4: 45 | H4: นำเข้าแล้ว | I4: ยืนยัน-บัญชีธนาคารรพ | K4: =IF(J4="","",G4-J4)
A5: 4 | B5: ภาษี (VAT) | C5: Master | D5: บัญชี, เจ้าหนี้ | E5: account.tax | F5: name | G5: 18 | H5: นำเข้าแล้ว | I5: ยืนยัน-ภาษี | K5: =IF(J5="","",G5-J5)
A6: 5 | B6: ภาษีหัก ณ ที่จ่าย (WHT) | C6: Master | D6: บัญชี, การเงิน | E6: account.withholding.tax | F6: name | G6: 0 | H6: ยังไม่นำเข้า | I6: — | K6: =IF(J6="","",G6-J6)
A7: 6 | B7: เงื่อนไขการชำระ | C7: Master | D7: เจ้าหนี้, การเงิน | E7: account.payment.term | F7: name | G7: 10 | H7: นำเข้าแล้ว | I7: ยืนยัน-เงื่อนไขชำระ | K7: =IF(J7="","",G7-J7)
A8: 7 | B8: ลูกหนี้สิทธิ HIS | C8: Master | D8: ลูกหนี้, บัญชี | E8: res.partner + res.partner.category | F8: ref / ชื่อ + แท็ก | G8: 6 | H8: นำเข้าแล้ว | I8: ยืนยัน-ลูกหนี้สิทธิHIS | K8: =IF(J8="","",G8-J8)
A9: 8 | B9: ลูกหนี้คนไข้ IPD HIS | C9: Master | D9: ลูกหนี้, บัญชี | E9: res.partner + res.partner.category | F9: ref / ชื่อ + แท็ก | G9: 1 | H9: นำเข้าแล้ว | I9: ยืนยัน-ลูกหนี้IPD HIS | K9: =IF(J9="","",G9-J9)
A10: 9 | B10: ลูกหนี้ พรบ | C10: Master | D10: ลูกหนี้, บัญชี | E10: res.partner + res.partner.category | F10: ref / ชื่อ + แท็ก | G10: 27 | H10: นำเข้าแล้ว | I10: ยืนยัน-ลูกหนี้พรบ | K10: =IF(J10="","",G10-J10)
A11: 10 | B11: ลูกหนี้ บริษัท | C11: Master | D11: ลูกหนี้, บัญชี | E11: res.partner + res.partner.category | F11: ref / ชื่อ + แท็ก | G11: 69 | H11: นำเข้าแล้ว | I11: ยืนยัน-ลูกหนี้บริษัท | K11: =IF(J11="","",G11-J11)
A12: 11 | B12: ลูกหนี้ ประกัน | C12: Master | D12: ลูกหนี้, บัญชี | E12: res.partner + res.partner.category | F12: ref / ชื่อ + แท็ก | G12: 69 | H12: นำเข้าแล้ว | I12: ยืนยัน-ลูกหนี้ประกัน | K12: =IF(J12="","",G12-J12)
A13: 12 | B13: ลูกหนี้ ประกันสังคม | C13: Master | D13: ลูกหนี้, บัญชี | E13: res.partner + res.partner.category | F13: ref / ชื่อ + แท็ก | G13: 75 | H13: นำเข้าแล้ว | I13: ยืนยัน-ลูกหนี้ประกันสังคม | K13: =IF(J13="","",G13-J13)
... A21: 20 | B21: Bank Statement | C21: ธุรกรรม | D21: การเงิน | E21: account.bank.statement | F21: name | G21: 0 | H21: ยังไม่นำเข้า | I21: — | K21: =IF(J21="","",G21-J21)
A22: 21 | B22: รายการบัญชีทั่วไป / ยกยอด GL | C22: ธุรกรรม | D22: บัญชี | E22: account.move (entry) | F22: name + วันที่ | G22: 1 | H22: นำเข้าแล้ว | I22: ยืนยัน-รายการบัญชีทั่วไป | K22: =IF(J22="","",G22-J22) | P22: ยกยอด ณ 31 ส.ค. 2569 จากไฟล์ งบการเงิน รพ.วชิระภูเก็ต ส.ค.69 ชีท สค.69 · JV MISC/2026/08/0001 (JV-ยกยอด-31082569) · เดบิต = เครดิต 12,566,477,193.75 บาท
A23: 22 | B23: งบทดลอง (TB) ปีงบประมาณ 2569 | C23: คงค้าง | D23: บัญชี | E23: account.move.line (posted) 1 ต.ค. 2568 – 30 ก.ย. 2569 | F23: รหัสบัญชี | G23: 371 | H23: นำเข้าแล้ว · ยกยอด ณ 31 ส.ค. 2569 | I23: ยืนยัน-TB2569 | K23: =IF(J23="","",G23-J23) | P23: ยกยอด ณ 31 ส.ค. 2569 จากไฟล์ งบการเงิน รพ.วชิระภูเก็ต ส.ค.69 ชีท สค.69 · JV MISC/2026/08/0001 (JV-ยกยอด-31082569) · เดบิต = เครดิต 12,566,477,193.75 บาท · จำนวนในระบบ = จำนวนบัญชี
A24: 23 | B24: หนังสือรับรองหัก ณ ที่จ่าย | C24: ธุรกรรม | D24: การเงิน, บัญชี | E24: withholding.tax.cert | F24: number | G24: 0 | H24: ยังไม่นำเข้า | I24: — | K24: =IF(J24="","",G24-J24)
B25: รวมจำนวนทุกประเภทในชีตนี้ | G25: =SUM(G2:G24)
A27: ข้อมูล ณ 19 ก.ย. 2569 03:56 จากฐาน VPK-S1 คอลัมน์ “จำนวนต้นทาง” ให้เจ้าของข้อมูลกรอกจากไฟล์ที่ส่งมา ถ้าผลต่าง ≠ 0 ให้เลือกผลยืนยันเป็น ต้องแก้ไข หรือ ยังไม่ครบ กลุ่ม Master = ข้อมูลหลักที่ใช้ทั้งระบบ · ตั้งค่า = วงเงิน/ค่าคงที่ · ธุรกรรม = เอกสารปฏิบัติงาน · คงค้าง = PO ค้างรับ/ค้างตั้งหนี้, เจ้าหนี้ค้างจ่าย, งบทดลอง TB ปี 2569 (ปีงบประมาณ 1 ต.ค. 2568 – 30 ก.ย. 2569) อัปเดต: JV ยกยอด/งบทดลอง ณ 31 ส.ค. 2569 นำเข้าเมื่อ 10 ต.ค. 2569 (รายการบัญชีทั่วไป 1 รายการ · TB 371 บัญชี)
