Workbook

Sheet แผนรายรับ-รายจ่ายเงินบำรุง 1ปี
A1: สำนักงานสาธารณสุขจังหวัด...ภูเก็ต.....
A2: โรงพยาบาล..วชิระภูเก็ต............
A3: แผนรายรับ - รายจ่ายเงินนอกงบประมาณ (เงินบำรุง) ปีงบประมาณ 2567 : ครึ่งปีหลัง
L4: หน่วย : บาท | P4: หน่วย : บาท
B5: รายการ | F5: ข้อมูลย้อนหลัง 3 ปีงบประมาณ | I5: แผนปี 2567 (เดิม) | J5: รายรับจริง ณ 31 มี.ค.67 | K5: คิดเป็น % | L5: แผนปีงบ 67 ครึ่งปีหลัง | M5: เปรียบเทียบ แผน | N5: ส่วนต่าง (บาท) | O5: ผลดำเนินงาน ไตรมาส 1 (ตค.-ธค.66) | P5: คิดเป็น%
F6: 2564 | G6: 2565 | H6: 2566
B7: รายรับ
C8: รายรับจากการดำเนินงาน
E9: รายรับค่ารักษาพยาบาลสำหรับโครงการสุขภาพถ้วนหน้า UC | F9: 5.3048621e+08 | G9: 7.0859462e+08 | H9: =256205985.2+147863308.35+108660563.33 -> 5.1272986e+08 | I9: =250000000+155000000 -> 405000000 | J9: =150133838.1+113286366.95+3886925.15 -> 2.6730713e+08 | K9: =+J9/I9*100 -> 66.001761 | L9: =+ประมาณการรายรับ!P12+ประมาณการรายรับ!P13 -> 1.5267757e+08 | M9: =+(L9-I9)/I9*100 -> -62.301835 | N9: =+L9-I9 -> -2.5232243e+08 | O9: =82032759.91+75105825.64 -> 1.5713859e+08 | P9: =+O9/I9*100 -> 38.799651
E10: รายรับค่ารักษาพยาบาลสำหรับโครงการสุขภาพถ้วนหน้า UC งบลงทุน | F10: 19207318 | G10: 19448683 | H10: 17480288 | I10: 17000000 | J10: 0 | K10: =+J10/I10*100 -> 0 | L10: =+ประมาณการรายรับ!P18 -> 0 | M10: =+(L10-I10)/I10*100 -> -100 | N10: =+L10-I10 -> -17000000 | O10: 0 | P10: =+O10/I10*100 -> 0
E11: รายรับจากระบบปฏิบัติการฉุกเฉิน (EMS) | F11: 1538817.1 | G11: 1644850 | H11: 1081750 | I11: 1500000 | J11: 1060291.5 | K11: =+J11/I11*100 -> 70.6861 | L11: =+ประมาณการรายรับ!P9 -> 0 | M11: =+(L11-I11)/I11*100 -> -100 | N11: =+L11-I11 -> -1500000 | O11: 9754 | P11: =+O11/I11*100 -> 0.65026667
E12: รายรับค่ารักษาพยาบาลเบิกจ่ายตรงกรมบัญชีกลาง | F12: 3.1720271e+08 | G12: 3.5807166e+08 | H12: 3.357539e+08 | I12: 370000000 | J12: 1.8467863e+08 | K12: =+J12/I12*100 -> 49.913143 | L12: =+ประมาณการรายรับ!P5 -> 1.0131855e+08 | M12: =+(L12-I12)/I12*100 -> -72.616608 | N12: =+L12-I12 -> -2.6868145e+08 | O12: 91062438 | P12: =+O12/I12*100 -> 24.61147
E13: รายรับค่ารักษาพยาบาลผู้ป่วยเบิกต้นสังกัด | F13: 80308337 | G13: 1.9906833e+08 | H13: 1.133913e+08 | I13: 140000000 | J13: 59921807 | K13: =+J13/I13*100 -> 42.801291 | L13: =+ประมาณการรายรับ!P6 -> 30508548 | M13: =+(L13-I13)/I13*100 -> -78.20818 | N13: =+L13-I13 -> -1.0949145e+08 | O13: 28464879 | P13: =+O13/I13*100 -> 20.332057
E14: รายรับค่ารักษาพยาบาลเบิกจาก อปท. | F14: 33520000 | G14: 34138823 | H14: 33388979 | I14: 40000000 | J14: 34162534 | K14: =+J14/I14*100 -> 85.406335 | L14: =+ประมาณการรายรับ!P8 -> 49241186 | M14: =+(L14-I14)/I14*100 -> 23.102964 | N14: =+L14-I14 -> 9241185.8 | O14: 33589841 | P14: =+O14/I14*100 -> 83.974602
E15: รายรับค่ารักษาพยาบาลจากกองทุนประกันสังคม | F15: 3.1977734e+08 | G15: 4.2407996e+08 | H15: =294588801.48+8298890.2 -> 3.0288769e+08 | I15: 340000000 | J15: 2.0541363e+08 | K15: =+J15/I15*100 -> 60.415773 | L15: =+ประมาณการรายรับ!P14 -> 89799429 | M15: =+(L15-I15)/I15*100 -> -73.588403 | N15: =+L15-I15 -> -2.5020057e+08 | O15: 1.1021905e+08 | P15: =+O15/I15*100 -> 32.417369
E16: รายรับค่ารักษาพยาบาลแรงงานต่างด้าว | F16: 52237457 | G16: 59446164 | H16: 53074741 | I16: 63000000 | J16: 32355625 | K16: =+J16/I16*100 -> 51.358135 | L16: =+ประมาณการรายรับ!P16 -> 17533965 | M16: =+(L16-I16)/I16*100 -> -72.16831 | N16: =+L16-I16 -> -45466035 | O16: 15213105 | P16: =+O16/I16*100 -> 24.147786
E17: รายรับค่ารักษาพยาบาลและการบริการอื่น | F17: 3.0661796e+08 | G17: 3.9388351e+08 | H17: =1774113364.95+152985171.02-(H9+H10+H11+H12+H13+H14+H15+H16)-H21-H22-H23 -> 4.9665033e+08 | I17: =1969000000-(I9+I10+I11+I12+I13+I14+I15+I16)-I21-I22-I23 -> 491000000 | J17: =1615290+215736235.03+20157485.24 -> 2.3750901e+08 | K17: =+J17/I17*100 -> 48.372507 | L17: =+ประมาณการรายรับ!P10+ประมาณการรายรับ!P11+ประมาณการรายรับ!P15 -> 1.3139386e+08 | M17: =+(L17-I17)/I17*100 -> -73.23954 | N17: =+L17-I17 -> -3.5960614e+08 | O17: =104712808.69+9364522.61+764700 -> 1.1484203e+08 | P17: =+O17/I17*100 -> 23.389416
C18: รายรับอื่น
E19: รายรับเงินช่วยเหลือ | F19: 0 | G19: 0 | H19: 0 | I19: 0 | J19: 0 | L19: 0
E20: รายรับเงินอุดหนุน | F20: 0 | G20: 0 | H20: 0 | I20: 0 | J20: 0 | L20: 0
E21: รายรับจากการบริจาค | F21: 24490529 | G21: 23281929 | H21: 39570974 | I21: 80000000 | J21: 33693691 | K21: =+J21/I21*100 -> 42.117114 | L21: =+ประมาณการรายรับ!P20 -> 99899938 | M21: =+(L21-I21)/I21*100 -> 24.874923 | N21: =+L21-I21 -> 19899938 | O21: 20382897 | P21: =+O21/I21*100 -> 25.478621
E22: รายรับดอกเบี้ยเงินฝากธนาคาร | F22: 365997.15 | G22: 706946.53 | H22: 2022594.5 | I22: 1500000 | J22: 1426104.8 | K22: =+J22/I22*100 -> 95.073651 | L22: =+ประมาณการรายรับ!P17 -> 1097158 | M22: =+(L22-I22)/I22*100 -> -26.856136 | N22: =+L22-I22 -> -402842.04 | O22: 1240872.2 | P22: =+O22/I22*100 -> 82.724813
E23: รายรับอื่น | F23: =20906672.21-732637 -> 20174035 | G23: 19066650 | H23: 19066136 | I23: 20000000 | J23: 10961292 | K23: =+J23/I23*100 -> 54.806459 | L23: =+ประมาณการรายรับ!P19 -> 10121037 | M23: =+(L23-I23)/I23*100 -> -49.394814 | N23: =+L23-I23 -> -9878962.8 | O23: 4684540.2 | P23: =+O23/I23*100 -> 23.422701
E24: รวมรายรับ | F24: =SUM(F9:F23) -> 1.7059267e+09 | G24: =SUM(G9:G23) -> 2.2414321e+09 | H24: =SUM(H9:H23) -> 1.9270985e+09 | I24: =SUM(I9:I23) -> 1969000000 | J24: =SUM(J9:J23) -> 1.0684897e+09 | K24: =+J24/I24*100 -> 54.265604 | L24: =SUM(L9:L23) -> 6.8359124e+08 | M24: =+(L24-I24)/I24*100 -> -65.282314 | O24: =SUM(O9:O23) -> 5.76848e+08 | P24: =+O24/I24*100 -> 29.296496
B25: รายจ่าย
C26: รายจ่ายบุคลากร
E27: ค่าจ้างลูกจ้างชั่วคราว / พนักงานกระทรวง | F27: 1.8053383e+08 | G27: 1.8820402e+08 | H27: 1.8846488e+08 | I27: 195000000 | J27: 94467539 | K27: =+J27/I27*100 -> 48.444892 | L27: =+รายละเอียดรายจ่าย!Y5 -> 205000000 | M27: =+(L27-I27)/I27*100 -> 5.1282051 | N27: =+L27-I27 -> 10000000 | O27: 47953471 | P27: =+O27/I27*100 -> 24.591524
E28: ค่าล่วงเวลางานบริการ / งานสนับสนุน | F28: 0 | G28: 0 | H28: 0 | I28: 0 | J28: 0 | L28: 0 | N28: =+L28-I28 -> 0 | P28: 0
E29: ค่าตอบแทนการปฏิบัติงานเวรผลัดบ่ายหรือผลัดดึกของเจ้าหน้าที่ | F29: 31484140 | G29: 30139045 | H29: 26605920 | I29: 30000000 | J29: 29945470 | K29: =+J29/I29*100 -> 99.818233 | L29: 40000000 | M29: =+(L29-I29)/I29*100 -> 33.333333 | N29: =+L29-I29 -> 10000000 | O29: 17331340 | P29: =+O29/I29*100 -> 57.771133
E30: ค่าตอบแทนเงินเพิ่มพิเศษไม่ทำเวชปฏิบัติส่วนตัว หรือปฏิบัติงาน รพ.เอกชน | F30: 1167600 | G30: 10385000 | H30: 10495200 | I30: 10960000 | J30: 5346600 | K30: =+J30/I30*100 -> 48.782847 | L30: =+รายละเอียดรายจ่าย!Y130 -> 11136000 | M30: =+(L30-I30)/I30*100 -> 1.6058394 | N30: =+L30-I30 -> 176000 | O30: 2687000 | P30: =+O30/I30*100 -> 24.516423
E31: ค่าตอบแทนเบี้ยเลี้ยงเหมาจ่าย (ฉ.11) | F31: 0 | G31: 0 | H31: 0 | I31: 0 | J31: 0 | L31: 0 | N31: =+L31-I31 -> 0 | P31: 0
E32: ค่าตอบแทนตามผลการปฏิบัติงาน (ฉ.12) | F32: 10193251 | G32: 5202971 | H32: 8605551 | I32: 41200000 | J32: 17747007 | K32: =+J32/I32*100 -> 43.07526 | L32: =+รายละเอียดรายจ่าย!Y10 -> 41200000 | M32: =+(L32-I32)/I32*100 -> 0 | N32: =+L32-I32 -> 0 | O32: 17747007 | P32: =+O32/I32*100 -> 43.07526
E33: เงินเพิ่ม (พ.ต.ส) | F33: 0 | G33: 0 | H33: 225000 | I33: 300000 | J33: 0 | K33: =+J33/I33*100 -> 0 | L33: =+รายละเอียดรายจ่าย!Y13 -> 300000 | M33: =+(L33-I33)/I33*100 -> 0 | N33: =+L33-I33 -> 0 | O33: 0 | P33: =+O33/I33*100 -> 0
E34: ค่าตอบแทนเจ้าหน้าที่ปฏิบัติงานของเจ้าหน้าที่ (นอกเวลา) ฉ5 | F34: 2.7830997e+08 | G34: =340999774.4-G29-G30 -> 3.0047573e+08 | H34: =367202135.79+10495200-H29-H30 -> 3.4059622e+08 | I34: =432000000+10960000-I29-I30 -> 402000000 | J34: =216192538.77-J29 -> 1.8624707e+08 | K34: =+J34/I34*100 -> 46.330117 | L34: =432000000-L29 -> 392000000 | M34: =+(L34-I34)/I34*100 -> -2.4875622 | N34: =+L34-I34 -> -10000000 | O34: =107757770.55-O29 -> 90426431 | P34: =+O34/I34*100 -> 22.494137
E35: ค่าตอบแทนเจ้าหน้าที่ปฏิบัติงานในคลินิกพิเศษเฉพาะทางนอกเวลาราชการ (SMC)
E36: ค่าตอบแทนอื่น | F36: 709725 | G36: =868400+299500+618600+9852500 -> 11639000 | H36: =555000+295380+1278500 -> 2128880 | I36: =550000+300000+1250000+100000 -> 2200000 | J36: =255000+105500+1035900 -> 1396400 | K36: =+J36/I36*100 -> 63.472727 | L36: =+รายละเอียดรายจ่าย!Y8+รายละเอียดรายจ่าย!Y11+รายละเอียดรายจ่าย!Y12+รายละเอียดรายจ่าย!Y15 -> 2200000 | M36: =+(L36-I36)/I36*100 -> 0 | N36: =+L36-I36 -> 0 | O36: =130000+586800+46400 -> 763200 | P36: =+O36/I36*100 -> 34.690909
E37: เงินค่าใช้จ่ายบุคลากรอื่น | F37: 88500 | G37: 223200 | H37: =189000+247200 -> 436200 | I37: =200000+300000 -> 500000 | J37: 66300 | K37: =+J37/I37*100 -> 13.26 | L37: =+รายละเอียดรายจ่าย!Y9+รายละเอียดรายจ่าย!Y16 -> 500000 | M37: =+(L37-I37)/I37*100 -> 0 | N37: =+L37-I37 -> 0 | O37: 46200 | P37: =+O37/I37*100 -> 9.24
C38: รายจ่ายจากการดำเนินงาน
E39: ค่ายา | F39: 3.8156834e+08 | G39: 4.0278395e+08 | H39: 4.2364677e+08 | I39: =410000000+12000000 -> 422000000 | J39: 2.2344687e+08 | K39: =+J39/I39*100 -> 52.949496 | L39: =+รายละเอียดรายจ่าย!Y155 -> 480000000 | M39: =+(L39-I39)/I39*100 -> 13.744076 | N39: =+L39-I39 -> 58000000 | O39: 1.1382866e+08 | P39: =+O39/I39*100 -> 26.973616
E40: ค่าเวชภัณฑ์มิใช่ยา
...

Sheet แผนรายรับ-รายจ่ายเงินบำรุง 3 ปี
A1: สำนักงานสาธารณสุขจังหวัด...ภูเก็ต.....
A2: โรงพยาบาล..วชิระภูเก็ต............
A3: แผนรายรับ - รายจ่ายเงินนอกงบประมาณ (เงินบำรุง) ปีงบประมาณ 2567 -2569
O4: หน่วย : บาท | Q4: หน่วย : บาท
B5: รายการ | F5: ข้อมูลย้อนหลัง 3 ปีงบประมาณ | I5: แผนปี 2567 (เดิม) | J5: รายรับจริง ณ 31 มี.ค.67 | K5: คิดเป็น % | L5: แผนครึ่งปีหลัง ปีงบ 67 | M5: เปรียบเทียบ แผน | N5: แผนปี 2568 | O5: แผนปี 2569 | P5: ผลดำเนินงาน ไตรมาส 1 (ตค.-ธค.66) | Q5: คิดเป็น%
F6: 2564 | G6: 2565 | H6: 2566
B7: รายรับ
C8: รายรับจากการดำเนินงาน
E9: รายรับค่ารักษาพยาบาลสำหรับโครงการสุขภาพถ้วนหน้า UC | F9: 5.3048621e+08 | G9: 7.0859462e+08 | H9: =256205985.2+147863308.35+108660563.33 -> 5.1272986e+08 | I9: =250000000+155000000 -> 405000000 | J9: =150133838.1+113286366.95+3886925.15 -> 2.6730713e+08 | K9: =+J9/I9*100 -> 66.001761 | L9: =+ประมาณการรายรับ!P12+ประมาณการรายรับ!P13 -> 1.5267757e+08 | M9: =+(L9-I9)/I9*100 -> -62.301835 | N9: 420250000 | O9: 462275000 | P9: =82032759.91+75105825.64 -> 1.5713859e+08 | Q9: =+P9/I9*100 -> 38.799651
E10: รายรับค่ารักษาพยาบาลสำหรับโครงการสุขภาพถ้วนหน้า UC งบลงทุน | F10: 19207318 | G10: 19448683 | H10: 17480288 | I10: 17000000 | J10: 0 | K10: =+J10/I10*100 -> 0 | L10: =+ประมาณการรายรับ!P18 -> 0 | M10: =+(L10-I10)/I10*100 -> -100 | N10: =+I10 -> 17000000 | O10: 18000000 | P10: 0 | Q10: =+P10/I10*100 -> 0
E11: รายรับจากระบบปฏิบัติการฉุกเฉิน (EMS) | F11: 1538817.1 | G11: 1644850 | H11: 1081750 | I11: 1500000 | J11: 1060291.5 | K11: =+J11/I11*100 -> 70.6861 | L11: =+ประมาณการรายรับ!P9 -> 0 | M11: =+(L11-I11)/I11*100 -> -100 | N11: 1500000 | O11: 1500000 | P11: 9754 | Q11: =+P11/I11*100 -> 0.65026667
E12: รายรับค่ารักษาพยาบาลเบิกจ่ายตรงกรมบัญชีกลาง | F12: 3.1720271e+08 | G12: 3.5807166e+08 | H12: 3.357539e+08 | I12: 370000000 | J12: 1.8467863e+08 | K12: =+J12/I12*100 -> 49.913143 | L12: =+ประมาณการรายรับ!P5 -> 1.0131855e+08 | M12: =+(L12-I12)/I12*100 -> -72.616608 | N12: 370000000 | O12: 370000000 | P12: 91062438 | Q12: =+P12/I12*100 -> 24.61147
E13: รายรับค่ารักษาพยาบาลผู้ป่วยเบิกต้นสังกัด | F13: 80308337 | G13: 1.9906833e+08 | H13: 1.133913e+08 | I13: 140000000 | J13: 59921807 | K13: =+J13/I13*100 -> 42.801291 | L13: =+ประมาณการรายรับ!P6 -> 30508548 | M13: =+(L13-I13)/I13*100 -> -78.20818 | N13: 140000000 | O13: 140000000 | P13: 28464879 | Q13: =+P13/I13*100 -> 20.332057
E14: รายรับค่ารักษาพยาบาลเบิกจาก อปท. | F14: 33520000 | G14: 34138823 | H14: 33388979 | I14: 40000000 | J14: 34162534 | K14: =+J14/I14*100 -> 85.406335 | L14: =+ประมาณการรายรับ!P8 -> 49241186 | M14: =+(L14-I14)/I14*100 -> 23.102964 | N14: 40000000 | O14: 40000000 | P14: 33589841 | Q14: =+P14/I14*100 -> 83.974602
E15: รายรับค่ารักษาพยาบาลจากกองทุนประกันสังคม | F15: 3.1977734e+08 | G15: 4.2407996e+08 | H15: =294588801.48+8298890.2 -> 3.0288769e+08 | I15: 340000000 | J15: 2.0541363e+08 | K15: =+J15/I15*100 -> 60.415773 | L15: =+ประมาณการรายรับ!P14 -> 89799429 | M15: =+(L15-I15)/I15*100 -> -73.588403 | N15: 357000000 | O15: 382000000 | P15: 1.1021905e+08 | Q15: =+P15/I15*100 -> 32.417369
E16: รายรับค่ารักษาพยาบาลแรงงานต่างด้าว | F16: 52237457 | G16: 59446164 | H16: 53074741 | I16: 63000000 | J16: 32355625 | K16: =+J16/I16*100 -> 51.358135 | L16: =+ประมาณการรายรับ!P16 -> 17533965 | M16: =+(L16-I16)/I16*100 -> -72.16831 | N16: 64890000 | O16: 66836700 | P16: 15213105 | Q16: =+P16/I16*100 -> 24.147786
E17: รายรับค่ารักษาพยาบาลและการบริการอื่น | F17: 3.0661796e+08 | G17: 3.9388351e+08 | H17: =1774113364.95+152985171.02-(H9+H10+H11+H12+H13+H14+H15+H16)-H21-H22-H23 -> 4.9665033e+08 | I17: =1969000000-(I9+I10+I11+I12+I13+I14+I15+I16)-I21-I22-I23 -> 491000000 | J17: =1615290+215736235.03+20157485.24 -> 2.3750901e+08 | K17: =+J17/I17*100 -> 48.372507 | L17: =+ประมาณการรายรับ!P10+ประมาณการรายรับ!P11+ประมาณการรายรับ!P15 -> 1.3139386e+08 | M17: =+(L17-I17)/I17*100 -> -73.23954 | N17: 490000000 | O17: 490000000 | P17: =104712808.69+9364522.61+764700 -> 1.1484203e+08 | Q17: =+P17/I17*100 -> 23.389416
C18: รายรับอื่น
E19: รายรับเงินช่วยเหลือ | F19: 0 | G19: 0 | H19: 0 | I19: 0 | J19: 0 | L19: 0 | N19: 0 | O19: 0
E20: รายรับเงินอุดหนุน | F20: 0 | G20: 0 | H20: 0 | I20: 0 | J20: 0 | L20: 0 | N20: 0 | O20: 0
E21: รายรับจากการบริจาค | F21: 24490529 | G21: 23281929 | H21: 39570974 | I21: 80000000 | J21: 33693691 | K21: =+J21/I21*100 -> 42.117114 | L21: =+ประมาณการรายรับ!P20 -> 99899938 | M21: =+(L21-I21)/I21*100 -> 24.874923 | N21: 80000000 | O21: 80000000 | P21: 20382897 | Q21: =+P21/I21*100 -> 25.478621
E22: รายรับดอกเบี้ยเงินฝากธนาคาร | F22: 365997.15 | G22: 706946.53 | H22: 2022594.5 | I22: 1500000 | J22: 1426104.8 | K22: =+J22/I22*100 -> 95.073651 | L22: =+ประมาณการรายรับ!P17 -> 1097158 | M22: =+(L22-I22)/I22*100 -> -26.856136 | N22: 1000000 | O22: =+N22 -> 1000000 | P22: 1240872.2 | Q22: =+P22/I22*100 -> 82.724813
E23: รายรับอื่น | F23: =20906672.21-732637 -> 20174035 | G23: 19066650 | H23: 19066136 | I23: 20000000 | J23: 10961292 | K23: =+J23/I23*100 -> 54.806459 | L23: =+ประมาณการรายรับ!P19 -> 10121037 | M23: =+(L23-I23)/I23*100 -> -49.394814 | N23: 20000000 | O23: 20000000 | P23: 4684540.2 | Q23: =+P23/I23*100 -> 23.422701
E24: รวมรายรับ | F24: =SUM(F9:F23) -> 1.7059267e+09 | G24: =SUM(G9:G23) -> 2.2414321e+09 | H24: =SUM(H9:H23) -> 1.9270985e+09 | I24: =SUM(I9:I23) -> 1969000000 | J24: =SUM(J9:J23) -> 1.0684897e+09 | K24: =+J24/I24*100 -> 54.265604 | L24: =SUM(L9:L23) -> 6.8359124e+08 | M24: =+(L24-I24)/I24*100 -> -65.282314 | N24: =SUM(N9:N23) -> 2001640000 | O24: =SUM(O9:O23) -> 2071611700 | P24: =SUM(P9:P23) -> 5.76848e+08 | Q24: =+P24/I24*100 -> 29.296496
B25: รายจ่าย
C26: รายจ่ายบุคลากร
E27: ค่าจ้างลูกจ้างชั่วคราว / พนักงานกระทรวง | F27: 1.8053383e+08 | G27: 1.8820402e+08 | H27: 1.8846488e+08 | I27: 195000000 | J27: 94467539 | K27: =+J27/I27*100 -> 48.444892 | L27: =+รายละเอียดรายจ่าย!Y5 -> 205000000 | M27: =+(L27-I27)/I27*100 -> 5.1282051 | N27: =+I27*0.04+I27 -> 202800000 | O27: =+N27*0.04+N27 -> 210912000 | P27: 47953471 | Q27: =+P27/I27*100 -> 24.591524
E28: ค่าล่วงเวลางานบริการ / งานสนับสนุน | F28: 0 | G28: 0 | H28: 0 | I28: 0 | J28: 0 | L28: 0 | N28: 0 | O28: 0 | Q28: 0
E29: ค่าตอบแทนการปฏิบัติงานเวรผลัดบ่ายหรือผลัดดึกของเจ้าหน้าที่ | F29: 31484140 | G29: 30139045 | H29: 26605920 | I29: 30000000 | J29: 29945470 | K29: =+J29/I29*100 -> 99.818233 | L29: 40000000 | M29: =+(L29-I29)/I29*100 -> 33.333333 | N29: 30000000 | O29: 30000000 | P29: 17331340 | Q29: =+P29/I29*100 -> 57.771133
E30: ค่าตอบแทนเงินเพิ่มพิเศษไม่ทำเวชปฏิบัติส่วนตัว หรือปฏิบัติงาน รพ.เอกชน | F30: 1167600 | G30: 10385000 | H30: 10495200 | I30: 10960000 | J30: 5346600 | K30: =+J30/I30*100 -> 48.782847 | L30: =+รายละเอียดรายจ่าย!Y130 -> 11136000 | M30: =+(L30-I30)/I30*100 -> 1.6058394 | N30: 11000000 | O30: =+N30 -> 11000000 | P30: 2687000 | Q30: =+P30/I30*100 -> 24.516423
E31: ค่าตอบแทนเบี้ยเลี้ยงเหมาจ่าย (ฉ.11) | F31: 0 | G31: 0 | H31: 0 | I31: 0 | J31: 0 | L31: 0 | N31: 0 | O31: 0 | Q31: 0
E32: ค่าตอบแทนตามผลการปฏิบัติงาน (ฉ.12) | F32: 10193251 | G32: 5202971 | H32: 8605551 | I32: 41200000 | J32: 17747007 | K32: =+J32/I32*100 -> 43.07526 | L32: =+รายละเอียดรายจ่าย!Y10 -> 41200000 | M32: =+(L32-I32)/I32*100 -> 0 | N32: =+I32 -> 41200000 | O32: =+N32 -> 41200000 | P32: 17747007 | Q32: =+P32/I32*100 -> 43.07526
E33: เงินเพิ่ม (พ.ต.ส) | F33: 0 | G33: 0 | H33: 225000 | I33: 300000 | J33: 0 | K33: =+J33/I33*100 -> 0 | L33: =+รายละเอียดรายจ่าย!Y13 -> 300000 | M33: =+(L33-I33)/I33*100 -> 0 | N33: =+I33 -> 300000 | O33: =+N33 -> 300000 | P33: 0 | Q33: =+P33/I33*100 -> 0
E34: ค่าตอบแทนเจ้าหน้าที่ปฏิบัติงานของเจ้าหน้าที่ (นอกเวลา) ฉ5 | F34: 2.7830997e+08 | G34: =340999774.4-G29-G30 -> 3.0047573e+08 | H34: =367202135.79+10495200-H29-H30 -> 3.4059622e+08 | I34: =432000000+10960000-I29-I30 -> 402000000 | J34: =216192538.77-J29 -> 1.8624707e+08 | K34: =+J34/I34*100 -> 46.330117 | L34: =432000000-L29 -> 392000000 | M34: =+(L34-I34)/I34*100 -> -2.4875622 | N34: 402000000 | O34: 402000000 | P34: =107757770.55-P29 -> 90426431 | Q34: =+P34/I34*100 -> 22.494137
E35: ค่าตอบแทนเจ้าหน้าที่ปฏิบัติงานในคลินิกพิเศษเฉพาะทางนอกเวลาราชการ (SMC)
E36: ค่าตอบแทนอื่น | F36: 709725 | G36: =868400+299500+618600+9852500 -> 11639000 | H36: =555000+295380+1278500 -> 2128880 | I36: =550000+300000+1250000+100000 -> 2200000 | J36: =255000+105500+1035900 -> 1396400 | K36: =+J36/I36*100 -> 63.472727 | L36: =+รายละเอียดรายจ่าย!Y8+รายละเอียดรายจ่าย!Y11+รายละเอียดรายจ่าย!Y12+รายละเอียดรายจ่าย!Y15 -> 2200000 | M36: =+(L36-I36)/I36*100 -> 0 | N36: 2000000 | O36: 2000000 | P36: =130000+586800+46400 -> 763200 | Q36: =+P36/I36*100 -> 34.690909
E37: เงินค่าใช้จ่ายบุคลากรอื่น | F37: 88500 | G37: 223200 | H37: =189000+247200 -> 436200 | I37: =200000+300000 -> 500000 | J37: 66300 | K37: =+J37/I37*100 -> 13.26 | L37: =+รายละเอียดรายจ่าย!Y9+รายละเอียดรายจ่าย!Y16 -> 500000 | M37: =+(L37-I37)/I37*100 -> 0 | N37: 500000 | O37: 500000 | P37: 46200 | Q37: =+P37/I37*100 -> 9.24
C38: รายจ่ายจากการดำเนินงาน
E39: ค่ายา | F39: 3.8156834e+08 | G39: 4.0278395e+08 | H39: 4.2364677e+08 | I39: =410000000+12000000 -> 422000000 | J39: 2.2344687e+08 | K39: =+J39/I39*100 -> 52.949496 | L39: =+รายละเอียดรายจ่าย!Y155 -> 480000000 | M39: =+(L39-I39)/I39*100 -> 13.744076 | N39: =438000000+13000000 -> 451000000 | O39: =470000000+14000000 -> 484000000 | P39: 1.1382866e+08 | Q39: =+P39/I39*100 -> 26.973616
E40: ค่าเวชภัณฑ์มิใช่ยา
...

Sheet คำนิยาม
B1: คำนิยาม ในการจัดทำแผนรายรับ-รายจ่ายเงินบำรุง
B2: รายการ | E2: รายละเอียดรายรับเงินสด
B3: รายรับ
B4: รายรับจากการดำเนินงาน
C5: รายรับค่ารักษาพยาบาลสำหรับโครงการสุขภาพถ้วนหน้า UC | E5: รายรับค่าบริการทางการแพทย์จากเงินกองทุนเหมาจ่ายรายหัว UC OP/PP, IP, รายรับอื่นๆ จากสปสช., จากการตามเรียกเก็บสิทธิ UC (รวมของ รพ.สต.)
C6: รายรับค่ารักษาพยาบาลสำหรับโครงการสุขภาพถ้วนหน้า UC งบลงทุน | E6: รายรับเงินกองทุน UC งบลงทุน จากสปสช. (รวมของ รพ.สต.)
C7: รายรับจากระบบปฏิบัติการฉุกเฉิน (EMS) | E7: รายรับค่าบริการทางการแพทย์จากระบบปฏิบัติการ EMS จาก สพฉ.
C8: รายรับค่ารักษาพยาบาลเบิกจ่ายตรงกรมบัญชีกลาง | E8: รายรับค่าบริการทางการแพทย์จากสิทธิข้าราชการเบิกจ่ายตรงจากกรมบัญชีกลาง
C9: รายรับค่ารักษาพยาบาลผู้ป่วยเบิกต้นสังกัด | E9: รายรับค่าบริการทางการแพทย์จากสิทธิ พนักงานของรัฐ รัฐวิสาหกิจ จากต้นสังกัด เช่น กฟภ. กฟฝ. การประปา รฟท. กสกช. บมจ.โทรคมนาคมแห่งชาติ
C10: รายรับค่ารักษาพยาบาลเบิกจาก อปท. | E10: รายรับค่าบริการทางการแพทย์สิทธิเบิกจ่ายตรง อปท. (อบต. เทศบาล อบจ. กทม. และเมืองพัทยา)
C11: รายรับค่ารักษาพยาบาลจากกองทุนประกันสังคม | E11: รายรับค่าบริการทางการแพทย์เงินจัดสรรเหมาจ่ายรายหัว OP/IP, ภาระเสี่ยงโรคเรื้อรัง, HA, รายรับอื่นๆ จากกองทุนปกส., จากการเรียกเก็บสิทธิ ปกส.
C12: รายรับค่ารักษาพยาบาลแรงงานต่างด้าว | E12: รายรับค่าขึ้นทะเบียนฯ (บัตรประกันสุขภาพ) ค่าตรวจสุขภาพคนต่างด้าวแรงงานต่างด้าว, ค่าธรรมเนียม 30 บาท, จากการเรียกเก็บสิทธิ คนต่างด้าวและแรงงานต่างด้าว
C13: รายรับค่ารักษาพยาบาลและการบริการอื่น | E13: รายรับค่าบริการทางการแพทย์จากสิทธิชำระเงิน, พรบ., บุคคลที่มีปัญหาสถานะและสิทธิ,ค่าตรวจสุขภาพบุคคลภายนอก, ค่าสิ่งส่งตรวจ, ค่าใบรับรองแพทย์, ค่าธรรมเนียม UC, ค่าบริการอื่นๆ
B14: รายรับอื่น
C15: รายรับเงินช่วยเหลือ | E15: รายรับเงินโดยสมัครใจจากรัฐบาลต่างประเทศ หรือองค์กรระหว่างประเทศ
C16: รายรับเงินอุดหนุน | E16: รายรับเงินสนับสนุนการดำเนินงาน หรือเพื่อการลงทุน จากส่วนราชการ หรือหน่วยงานของรัฐ (เช่น โครงการจัดซื้อครุภัณฑ์ฯจากกรมพัฒนาพลังงานทดแทนและอนุรักษ์พลังงาน,โครงการสร้างเสริมสุขภาพ จากองค์กรปกครองส่วนท้องถิ่น, เงินสนับสนุนสำหรับโครงการผลิตแพทย์ จากมหาวิทยาลัยในกำกับของรัฐ
C17: รายรับจากการบริจาค | E17: รายรับงินบริจาค บุคคลธรรมดา หรือภาคเอกชน โดยความสมัครใจ ทั้งระบุวัตถุประสงค์ และไม่ระบุวัตถุประสงค์ (ตัวอย่าง บุคคลทั่วไป บริจาคเงินเพื่อสนับสนุนการจัดหาครุภัณฑ์ทางการแพทย์, เงินสนับสนุนสำหรับโครงการผลิตแพทย์ จากมหาวิทยาลัยเอกชน เป็นต้น)
C18: รายรับดอกเบี้ยเงินฝากธนาคาร | E18: รายรับดอกเบี้ยเงินฝากธนาคาร ประเภทเงินบำรุง เงินนอกงบประมาณอื่น ที่ได้รับอนุญาตให้ใช้จ่าย โดยไม่ต้องนำส่งเป็นรายได้แผ่นดิน
C19: รายรับอื่น ๆ | E19: รายรับเงินสนับสนุนจากหน่วยบริการในสังกัดสป.สธ. ตามข้อตกลง (เขต สสจ. รพศ.รพท. รพช. รพ.สต), รายรับจากการดำเนินการด้วยเงินบำรุงหรือทรัพย์สินจากเงินบำรุง เช่น ค่าบริการสถานที่จัดประชุม ค่าเช่าอาคาร ค่าขายแบบ ค่าปรับผิดสัญญา ค่าขายครุภัณฑ์ สิ่งก่อสร้าง เงินประกัน / เงินมัดจำ / เงินรับฝากอื่น ฯ
B20: รายจ่าย
B21: รายจ่ายบุคลากร
C22: ค่าจ้างลูกจ้างชั่วคราว / พนักงานกระทรวง | E22: ได้แก่ ค่าจ้างชั่วคราวรายวัน รายเดือน รายคาบ พกส. ของหน่วยบริการ
C23: ค่าล่วงเวลางานบริการ / งานสนับสนุน | E23: ค่าตอบแทนปฏิบัติงานนอกเวลาตามระเบียบ กระทรวงการคลัง ปี พ.ศ. 2550
C24: ค่าตอบแทนการปฏิบัติงานเวรผลัดบ่ายหรือผลัดดึกของเจ้าหน้าที่ | E24: ค่าเวรผลัดบ่ายหรือผลัดดึกของพยาบาล และเจ้าหน้าที่อื่น ตามหลักเกณฑ์ฯ พ.ศ. 2566
C25: ค่าตอบแทนเงินเพิ่มพิเศษไม่ทำเวชปฏิบัติส่วนตัว หรือปฏิบัติงาน รพ.เอกชน | E25: ค่าตอบแทน ไม่ทำเวชของแพทย์ ทันตแพทย์ เภสัชกร ตามหลักเกณฑ์ฯ พ.ศ. 2566
C26: ค่าตอบแทนเบี้ยเลี้ยงเหมาจ่าย (ฉ.11) | E26: ค่าตอบแทนลักษณะเบี้ยเลี้ยงเหมาจ่าย ตามหลักเกณฑ์ ฯ พ.ศ. 2566
C27: ค่าตอบแทนตามผลการปฏิบัติงาน (ฉ.12) | E27: ค่าตอบแทนผลการปฏิบัติงาน ตามหลักเกณฑ์ ฯ พ.ศ. 2566
C28: เงินเพิ่ม (พ.ต.ส) | E28: ค่าตอบแทนเทียบเคียงเงินเพิ่ม (พตส.) สำหรับแพทย์ ทันตแพทย์ เภสัช และสหสาขาวิชาชีพ 7 สาขา
C29: ค่าตอบแทนเจ้าหน้าที่ปฏิบัติงานของเจ้าหน้าที่ (นอกเวลา) ฉ5 | E29: ค่าตอบแทนในการปฏิบัติงานของเจ้าหน้าที่ ตามหลักเกณฑ์ ฯ พ.ศ. 2566
C30: ค่าตอบแทนเจ้าหน้าที่ปฏิบัติงานในคลินิกพิเศษเฉพาะทางนอกเวลาราชการ (SMC) | E30: ค่าตอบแทนการปฏิบัติงานในคลินิกพิเศษนอกเวลา ตามหลักเกณฑ์ฯ พ.ศ. 2566
C31: ค่าตอบแทนอื่น | E31: เช่น ค่าตอบแทนชันสูตรพลิกศพ, สาขาส่งเสริมพิเศษ, ส่งเสริมสุขภาพและเวชปฏิบัติ และค่าตอบแทนอื่นๆ
C32: เงินค่าใช้จ่ายบุคลากรอื่น | E32: เช่น เงินสมทบกองทุนปกส.ส่วนของนายจ้าง เงินสมทบกองทุนสำรองเลี้ยงชีพพนักงานและเจ้าหน้าที่รัฐ (พกส.) เงินสมทบกองทุนทดแทน ปกส. เงินช่วยพิเศษกรณีเสียชีวิต (เงินนอกงบประมาณ)
B33: รายจ่ายดำเนินงาน
C34: ค่ายา | E34: ค่ายา (จากแผนบริหารจัดการเจ้าหนี้ ช่อง [7] แผนการจ่ายชำระปี 25xx ด้วยเงินนอกงบประมาณ)
C35: เวชภัณฑ์มิใช่ยา | E35: ค่าวัสดุการแพทย์ /วัสดุวิทยาศาสตร์การแพทย์/ วัสดุเภสัช /วัสดุทันตกรรม /วัสดุเอ๊กซเรย์ (จากแผนบริหารจัดการเจ้าหนี้ ช่อง [7] แผนการจ่ายชำระปี 25xx ด้วยเงินนอกงบประมาณ)
C36: ค่าวัสดุ | E36: ค่าวัสดุบริโภค วัสดุเครื่องแต่งกาย วัสดุสำนักงาน วัสดุยานพาหนะและขนส่ง วัสดุเชื้อเพลิงและหล่อลื่น วัสดุไฟฟ้าและวิทยุ วัสดุโฆษณาและเผยแพร่ วัสดุคอมพิวเตอร์ วัสดุงานบ้านงานครัว วัสดุก่อสร้าง และวัสดุอื่น (จากแผนบริหารจัดการเจ้าหนี้ ช่อง [7] แผนการจ่ายชำระปี 25xx ด้วยเงินนอกงบประมาณ)
C37: ค่าสาธารณูปโภค | E37: ค่าไฟฟ้า น้ำประปา ค่าบริการไปรษณีย์ ค่าบริการอินเตอร์เน็ต ค่าบริการเช่าสัญญาณเคเบิ้ลทีวี
C38: ค่าใช้สอย | E38: ค่าใช้จ่ายเดินทางไปราชการ ฝึกอบรม, ค่าจ้างเหมา ค่าซ่อมแซมคอาคารและครุภัณฑ์, ค่าเช่าครุภัณฑ์, ค่าเบี้ยประกันภัย, ค่าธรรมเนียมธนาคาร
C39: ค่าใช้จ่ายดำเนินงานอื่น | E39: ค่าใช้จ่ายตามโครงการ ตามแผนงานประจำเงินบำรุง หรือโครงการสร้างเสริมสุขภาพฯ เช่น PP UC , เงินต่างด้าว, เงินอุดหนุนบุคคลที่มีปัญหาสถานะและสิทธิ
B40: รายจ่ายลงทุน
...

Sheet 1 ปี (69) 
A1: สำนักงานสาธารณสุขจังหวัด...ภูเก็ต.....
A2: โรงพยาบาล..วชิระภูเก็ต............
A3: แผนรายรับ - รายจ่าย เงินบำรุง ปีงบประมาณ 2569
K4: หน่วย : บาท | N4: หน่วย : บาท
B5: รายการ | F5: ข้อมูลย้อนหลัง 3 ปีงบประมาณ | Q5: แผนปี 2569 | R5: ผลการดำเนินงาน | T5: ปรับแผน | U5: รายรับ-รายจ่าย เพิ่มจากแผนเดิม (%) | V5: ส่วนต่าง
F6: 2566 | G6: 2567 | O6: 2568 | P6: =+M6 -> 0 | R6: ต.ค. 68 - มี.ค.69 | S6: ร้อยละ
B7: รายรับ
C8: รายรับจากการดำเนินงาน
E9: รายรับค่ารักษาพยาบาลสำหรับโครงการสุขภาพถ้วนหน้า UC | F9: =+ประมาณการรายรับ!K12+ประมาณการรายรับ!K13+ประมาณการรายรับ!L13 -> 5.1272986e+08 | G9: =+ประมาณการรายรับ!M12+ประมาณการรายรับ!M13+ประมาณการรายรับ!N13 -> 6.1287527e+08 | H9: =+ประมาณการรายรับ!O12+ประมาณการรายรับ!O13 -> 620000000 | I9: =+ประมาณการรายรับ!R12+ประมาณการรายรับ!R13 -> 2.8652223e+08 | J9: =+I9/H9*100 -> 46.213262 | K9: =+ประมาณการรายรับ!T12+ประมาณการรายรับ!T13 -> 605000000 | L9: =+ประมาณการรายรับ!V12+ประมาณการรายรับ!V13 -> 4.2974538e+08 | M9: =+L9/K9*100 -> 71.032295 | N9: =+ประมาณการรายรับ!Y12+ประมาณการรายรับ!Y13 -> 555000000 | O9: =+ประมาณการรายรับ!Z12+ประมาณการรายรับ!Z13 -> 5.1153919e+08 | P9: =+O9/N9*100 -> 92.169223 | Q9: =+ประมาณการรายรับ!AB12+ประมาณการรายรับ!AB13 -> 550000000 | R9: =+ประมาณการรายรับ!AE12+ประมาณการรายรับ!AE13 -> 3.8946249e+08 | S9: =+R9/Q9*100 -> 70.811362 | T9: =+ประมาณการรายรับ!AG12+ประมาณการรายรับ!AG13 -> 590000000 | U9: =+(T9-Q9)/T9*100 -> 6.779661 | V9: =+T9-Q9 -> 40000000
E10: รายรับค่ารักษาพยาบาลสำหรับโครงการสุขภาพถ้วนหน้า UC งบลงทุน | F10: =+ประมาณการรายรับ!K18 -> 17480288 | G10: =+ประมาณการรายรับ!M18 -> 16162273 | H10: =+ประมาณการรายรับ!O18 -> 16000000 | I10: =+ประมาณการรายรับ!R18 -> 0 | J10: =+I10/H10*100 -> 0 | K10: =+ประมาณการรายรับ!T18 -> 30827352 | L10: =+ประมาณการรายรับ!V18 -> 30827352 | M10: =+L10/K10*100 -> 100 | N10: =+ประมาณการรายรับ!Y18 -> 30827352 | O10: =+ประมาณการรายรับ!Z18 -> 30827352 | P10: =+O10/N10*100 -> 100 | Q10: =+ประมาณการรายรับ!AB18 -> 17000000 | R10: =+ประมาณการรายรับ!AE18 -> 22596016 | S10: =+R10/Q10*100 -> 132.91774 | T10: =+ประมาณการรายรับ!AG18 -> 22596016 | U10: =+(T10-Q10)/T10*100 -> 24.765499 | V10: =+T10-Q10 -> 5596016.2
E11: รายรับจากระบบปฏิบัติการฉุกเฉิน (EMS) | F11: =+ประมาณการรายรับ!K9 -> 1081750 | G11: =+ประมาณการรายรับ!M9 -> 2316591.5 | H11: =+ประมาณการรายรับ!O9 -> 2500000 | I11: 0 | J11: =+I11/H11*100 -> 0 | K11: =+ประมาณการรายรับ!T9 -> 1500000 | L11: =+ประมาณการรายรับ!V9 -> 446800 | M11: =+L11/K11*100 -> 29.786667 | N11: =+ประมาณการรายรับ!Y9 -> 1500000 | O11: =+ประมาณการรายรับ!Z9 -> 1023450 | P11: =+O11/N11*100 -> 68.23 | Q11: =+ประมาณการรายรับ!AB9 -> 1500000 | R11: =+ประมาณการรายรับ!AE9 -> 565632 | S11: =+R11/Q11*100 -> 37.7088 | T11: =+ประมาณการรายรับ!AG9 -> 1500000 | U11: =+(T11-Q11)/T11*100 -> 0 | V11: =+T11-Q11 -> 0
E12: รายรับค่ารักษาพยาบาลเบิกจ่ายตรงกรมบัญชีกลาง | F12: =+ประมาณการรายรับ!K5 -> 3.357539e+08 | G12: =+ประมาณการรายรับ!M5 -> 3.773114e+08 | H12: =+ประมาณการรายรับ!O5 -> 380000000 | I12: =+ประมาณการรายรับ!R5 -> 2.0388857e+08 | J12: =+I12/H12*100 -> 53.654886 | K12: =+ประมาณการรายรับ!T5 -> 380000000 | L12: =+ประมาณการรายรับ!V5 -> 3.0698713e+08 | M12: =+L12/K12*100 -> 80.786086 | N12: =+ประมาณการรายรับ!Y5 -> 380000000 | O12: =+ประมาณการรายรับ!Z5 -> 4.0901102e+08 | P12: =+O12/N12*100 -> 107.63448 | Q12: =+ประมาณการรายรับ!AB5 -> 420000000 | R12: =+ประมาณการรายรับ!AE5 -> 2.4714886e+08 | S12: =+R12/Q12*100 -> 58.844966 | T12: =+ประมาณการรายรับ!AG5 -> 420000000 | U12: =+(T12-Q12)/T12*100 -> 0 | V12: =+T12-Q12 -> 0
E13: รายรับค่ารักษาพยาบาลผู้ป่วยเบิกต้นสังกัด | F13: =+ประมาณการรายรับ!K6+ประมาณการรายรับ!K7 -> 1.133913e+08 | G13: =+ประมาณการรายรับ!M6 -> 1.4978291e+08 | H13: =+ประมาณการรายรับ!O6 -> 160000000 | I13: =+ประมาณการรายรับ!R6 -> 68939728 | J13: =+I13/H13*100 -> 43.08733 | K13: =+ประมาณการรายรับ!T6 -> 160000000 | L13: =+ประมาณการรายรับ!V6 -> 1.0669321e+08 | M13: =+L13/K13*100 -> 66.683254 | N13: =+ประมาณการรายรับ!Y6 -> 160000000 | O13: =+ประมาณการรายรับ!Z6+ประมาณการรายรับ!Z7 -> 1.4031422e+08 | P13: =+O13/N13*100 -> 87.696387 | Q13: =+ประมาณการรายรับ!AB6+ประมาณการรายรับ!AB7 -> 150000000 | R13: =+ประมาณการรายรับ!AE6+ประมาณการรายรับ!AE7 -> 79330277 | S13: =+R13/Q13*100 -> 52.886851 | T13: =+ประมาณการรายรับ!AG6+ประมาณการรายรับ!AG7 -> 160000000 | U13: =+(T13-Q13)/T13*100 -> 6.25 | V13: =+T13-Q13 -> 10000000
E14: รายรับค่ารักษาพยาบาลเบิกจาก อปท. | F14: =+ประมาณการรายรับ!K8 -> 33388979 | G14: =+ประมาณการรายรับ!M8 -> 53444241 | H14: =+ประมาณการรายรับ!O8 -> 60000000 | I14: =+ประมาณการรายรับ!R8 -> 55379690 | J14: =+I14/H14*100 -> 92.299483 | K14: =+ประมาณการรายรับ!T8 -> 60000000 | L14: =+ประมาณการรายรับ!V8 -> 75077176 | M14: =+L14/K14*100 -> 125.12863 | N14: =+ประมาณการรายรับ!Y8 -> 60000000 | O14: =+ประมาณการรายรับ!Z8 -> 75273784 | P14: =+O14/N14*100 -> 125.45631 | Q14: =+ประมาณการรายรับ!AB8 -> 60000000 | R14: =+ประมาณการรายรับ!AE8 -> 23904233 | S14: =+R14/Q14*100 -> 39.840388 | T14: =+ประมาณการรายรับ!AG8 -> 60000000 | U14: =+(T14-Q14)/T14*100 -> 0 | V14: =+T14-Q14 -> 0
E15: รายรับค่ารักษาพยาบาลจากกองทุนประกันสังคม | F15: =+ประมาณการรายรับ!K14+ประมาณการรายรับ!L14 -> 3.0288769e+08 | G15: =+ประมาณการรายรับ!M14 -> 3.7264421e+08 | H15: =+ประมาณการรายรับ!O14 -> 3.81583e+08 | I15: =+ประมาณการรายรับ!R14 -> 1.746126e+08 | J15: =+I15/H15*100 -> 45.760058 | K15: =+ประมาณการรายรับ!T14 -> 365000000 | L15: =+ประมาณการรายรับ!V14 -> 2.4442917e+08 | M15: =+L15/K15*100 -> 66.966895 | N15: =+ประมาณการรายรับ!Y14 -> 315000000 | O15: =+ประมาณการรายรับ!Z14 -> 3.4698031e+08 | P15: =+O15/N15*100 -> 110.15248 | Q15: =+ประมาณการรายรับ!AB14 -> 350000000 | R15: =+ประมาณการรายรับ!AE14 -> 1.2993182e+08 | S15: =+R15/Q15*100 -> 37.123377 | T15: =+ประมาณการรายรับ!AG14 -> 350000000 | U15: =+(T15-Q15)/T15*100 -> 0 | V15: =+T15-Q15 -> 0
E16: รายรับค่ารักษาพยาบาลแรงงานต่างด้าว | F16: =+ประมาณการรายรับ!K16 -> 53074741 | G16: =+ประมาณการรายรับ!M16 -> 62740891 | H16: =+ประมาณการรายรับ!O16 -> 63000000 | I16: =+ประมาณการรายรับ!R16 -> 53809231 | J16: =+I16/H16*100 -> 85.411478 | K16: =+ประมาณการรายรับ!T16 -> 65000000 | L16: =+ประมาณการรายรับ!V16 -> 67600170 | M16: =+L16/K16*100 -> 104.00026 | N16: =+ประมาณการรายรับ!Y16 -> 65000000 | O16: =+ประมาณการรายรับ!Z16 -> 87645151 | P16: =+O16/N16*100 -> 134.83869 | Q16: =+ประมาณการรายรับ!AB16 -> 60000000 | R16: =+ประมาณการรายรับ!AE16 -> 51470548 | S16: =+R16/Q16*100 -> 85.784247 | T16: =+ประมาณการรายรับ!AG16 -> 60000000 | U16: =+(T16-Q16)/T16*100 -> 0 | V16: =+T16-Q16 -> 0
E17: รายรับค่ารักษาพยาบาลและการบริการอื่น | F17: =+ประมาณการรายรับ!K10+ประมาณการรายรับ!K11+ประมาณการรายรับ!K15+ประมาณการรายรับ!L11 -> 4.6062461e+08 | G17: =+ประมาณการรายรับ!M10+ประมาณการรายรับ!M15+ประมาณการรายรับ!M11 -> 4.9229072e+08 | H17: =+ประมาณการรายรับ!O10+ประมาณการรายรับ!O11+ประมาณการรายรับ!O15 -> 549000000 | I17: =+ประมาณการรายรับ!R10+ประมาณการรายรับ!R15+ประมาณการรายรับ!R11 -> 2.884586e+08 | J17: =+I17/H17*100 -> 52.542551 | K17: =+ประมาณการรายรับ!T10+ประมาณการรายรับ!T11+ประมาณการรายรับ!T15 -> 544000000 | L17: =+ประมาณการรายรับ!V10+ประมาณการรายรับ!V11+ประมาณการรายรับ!V15 -> 4.392999e+08 | M17: =+L17/K17*100 -> 80.753659 | N17: =+ประมาณการรายรับ!Y10+ประมาณการรายรับ!Y11+ประมาณการรายรับ!Y15 -> 544000000 | O17: =+ประมาณการรายรับ!Z10+ประมาณการรายรับ!Z11+ประมาณการรายรับ!Z15 -> 5.9269145e+08 | P17: =+O17/N17*100 -> 108.95063 | Q17: =+ประมาณการรายรับ!AB10+ประมาณการรายรับ!AB11+ประมาณการรายรับ!AB15 -> 610273460 | R17: =+ประมาณการรายรับ!AE10+ประมาณการรายรับ!AE11+ประมาณการรายรับ!AE15 -> 3.2780044e+08 | S17: =+R17/Q17*100 -> 53.713697 | T17: =+ประมาณการรายรับ!AG10+ประมาณการรายรับ!AG11+ประมาณการรายรับ!AG15 -> 614500000 | U17: =+(T17-Q17)/T17*100 -> 0.68780146 | V17: =+T17-Q17 -> 4226540
C18: รายรับอื่น
E19: รายรับเงินช่วยเหลือ | F19: 0 | G19: 0 | H19: 0 | I19: 0 | J19: 0 | K19: 0 | L19: 0 | M19: 0 | N19: 0 | O19: 0 | P19: 0 | Q19: 0 | R19: 0 | S19: 0 | T19: 0 | U19: 0
E20: รายรับเงินอุดหนุน | F20: 0 | G20: 0 | H20: 0 | I20: 0 | J20: 0 | K20: 0 | L20: 0 | M20: 0 | N20: 0 | O20: 0 | P20: 0 | Q20: 0 | R20: 0 | S20: 0 | T20: 0 | U20: 0
E21: รายรับจากการบริจาค | F21: =+ประมาณการรายรับ!K20 -> 39570974 | G21: =+ประมาณการรายรับ!M20 -> 57795480 | H21: =+ประมาณการรายรับ!O20 -> 123000000 | I21: =+ประมาณการรายรับ!R20 -> 3.3596509e+08 | J21: =+I21/H21*100 -> 273.14235 | K21: =+ประมาณการรายรับ!T20 -> 420000000 | L21: =+ประมาณการรายรับ!V20 -> 4.119507e+08 | M21: =+L21/K21*100 -> 98.083499 | N21: =+ประมาณการรายรับ!Y20 -> 4.119507e+08 | O21: =+ประมาณการรายรับ!Z20 -> 4.2419399e+08 | P21: =+O21/N21*100 -> 102.97203 | Q21: =+ประมาณการรายรับ!AB20 -> 100000000 | R21: =+ประมาณการรายรับ!AE20 -> 60933732 | S21: =+R21/Q21*100 -> 60.933732 | T21: =+ประมาณการรายรับ!AG20 -> 150000000 | U21: =+(T21-Q21)/T21*100 -> 33.333333 | V21: =+T21-Q21 -> 50000000
E22: รายรับดอกเบี้ยเงินฝากธนาคาร | F22: =+ประมาณการรายรับ!K17 -> 2022594.5 | G22: =+ประมาณการรายรับ!M17 -> 2896990.4 | H22: =+ประมาณการรายรับ!O17 -> 3000000 | I22: =+ประมาณการรายรับ!R17 -> 1322097.3 | J22: =+I22/H22*100 -> 44.069909 | K22: =+ประมาณการรายรับ!T17 -> 2500000 | L22: =+ประมาณการรายรับ!V17 -> 3096143.2 | M22: =+L22/K22*100 -> 123.84573 | N22: =+ประมาณการรายรับ!Y17 -> 2500000 | O22: =+ประมาณการรายรับ!Z17 -> 3269077.6 | P22: =+O22/N22*100 -> 130.7631 | Q22: =+ประมาณการรายรับ!AB17 -> 2500000 | R22: =+ประมาณการรายรับ!AE17 -> 1353525.5 | S22: =+R22/Q22*100 -> 54.14102 | T22: =+ประมาณการรายรับ!AG17 -> 2500000 | U22: =+(T22-Q22)/T22*100 -> 0 | V22: =+T22-Q22 -> 0
E23: รายรับอื่น | F23: =+ประมาณการรายรับ!K19 -> 19066136 | G23: =+ประมาณการรายรับ!M19 -> 52743682 | H23: =+ประมาณการรายรับ!O19 -> 52540891 | I23: =+ประมาณการรายรับ!R19 -> 18239955 | J23: =+I23/H23*100 -> 34.715733 | K23: =+ประมาณการรายรับ!T19 -> 25000000 | L23: =+ประมาณการรายรับ!V19 -> 21765857 | M23: =+L23/K23*100 -> 87.063429 | N23: =+ประมาณการรายรับ!Y19 -> 25000000 | O23: =+ประมาณการรายรับ!Z19 -> 55181492 | P23: =+O23/N23*100 -> 220.72597 | Q23: =+ประมาณการรายรับ!AB19 -> 28000000 | R23: =+ประมาณการรายรับ!AE19 -> 10378143 | S23: =+R23/Q23*100 -> 37.064797 | T23: =+ประมาณการรายรับ!AG19 -> 28000000 | U23: =+(T23-Q23)/T23*100 -> 0 | V23: =+T23-Q23 -> 0
E24: รวมรายรับ | F24: =SUM(F9:F23) -> 1.8910728e+09 | G24: =SUM(G9:G23) -> 2.2530046e+09 | H24: =SUM(H9:H23) -> 2.4106239e+09 | I24: =SUM(I9:I23) -> 1.4871378e+09 | J24: =+I24/H24*100 -> 61.690992 | K24: =SUM(K9:K23) -> 2.6588274e+09 | L24: =SUM(L9:L23) -> 2.137919e+09 | M24: =+L24/K24*100 -> 80.408342 | N24: =SUM(N9:N23) -> 2.550778e+09 | O24: =SUM(O9:O23) -> 2.6779505e+09 | P24: =+O24/N24*100 -> 104.98563 | Q24: =SUM(Q9:Q23) -> 2349273460 | R24: =SUM(R9:R23) -> 1.3448757e+09 | S24: =+R24/Q24*100 -> 57.246452 | T24: =SUM(T9:T23) -> 2.459096e+09 | U24: =+(T24-Q24)/T24*100 -> 4.4659727 | V24: =+T24-Q24 -> 1.0982256e+08
B25: รายจ่าย
C26: รายจ่ายบุคลากร
E27: ค่าจ้างลูกจ้างชั่วคราว / พนักงานกระทรวง | F27: 1.8846488e+08 | G27: =+ประมาณการรายจ่าย!M5 -> 1.917608e+08 | H27: =+รายละเอียดรายจ่าย!Y5 -> 205000000 | I27: =+ประมาณการรายจ่าย!R5 -> 1.008702e+08 | J27: =+I27/H27*100 -> 49.204977 | K27: =+รายละเอียดรายจ่าย!AF5 -> 205000000 | L27: =+รายละเอียดรายจ่าย!AG5 -> 1.5132586e+08 | M27: =+L27/K27*100 -> 73.817492 | N27: =+รายละเอียดรายจ่าย!AJ5 -> 205000000 | O27: =+ประมาณการรายจ่าย!Z5 -> 2.0640163e+08 | P27: =+O27/N27*100 -> 100.68372 | Q27: =+รายละเอียดรายจ่าย!AN5+รายละเอียดรายจ่าย!AN222 -> 212329680 | R27: =+รายละเอียดรายจ่าย!AR5 -> 1.1330709e+08 | S27: =+R27/Q27*100 -> 53.363754 | T27: =+รายละเอียดรายจ่าย!AU5 -> 212000000 | U27: =+(T27-Q27)/T27*100 -> -0.15550943 | V27: =+T27-Q27 -> -329680
E28: ค่าล่วงเวลางานบริการ / งานสนับสนุน | F28: 0 | G28: 0 | H28: 0 | I28: 0 | J28: 0 | K28: 0 | L28: 0 | M28: 0 | N28: 0 | O28: 0 | P28: 0 | Q28: 0 | R28: 0 | S28: 0 | T28: 0 | V28: =+T28-Q28 -> 0
E29: ค่าตอบแทนการปฏิบัติงานเวรผลัดบ่ายหรือผลัดดึกของเจ้าหน้าที่ | F29: 26605920 | G29: =3801440+5627970+3063870+2496060+3050640+2634390+3027090+2362770+2731950+2622150+2979720+2955780 -> 37353830 | H29: 40000000 | I29: 28124363 | J29: =+I29/H29*100 -> 70.310907 | K29: 48000000 | L29: 41070563 | M29: =+L29/K29*100 -> 85.563673 | N29: =+K29 -> 48000000 | O29: =49997833+2609125 -> 52606958 | P29: =+O29/N29*100 -> 109.59783 | Q29: 50000000 | R29: 28232440 | S29: =+R29/Q29*100 -> 56.46488 | T29: 50000000 | U29: =+(T29-Q29)/T29*100 -> 0 | V29: =+T29-Q29 -> 0
E30: ค่าตอบแทนเงินเพิ่มพิเศษไม่ทำเวชปฏิบัติส่วนตัว หรือปฏิบัติงาน รพ.เอกชน | F30: 10495200 | G30: =+ประมาณการรายจ่าย!M12 -> 10899200 | H30: =+รายละเอียดรายจ่าย!Y130 -> 11136000 | I30: =+รายละเอียดรายจ่าย!AD131+รายละเอียดรายจ่าย!AD132+รายละเอียดรายจ่าย!AD133 -> 5445000 | J30: =+I30/H30*100 -> 48.895474 | K30: =+รายละเอียดรายจ่าย!AF131+รายละเอียดรายจ่าย!AF132+รายละเอียดรายจ่าย!AF133 -> 11040000 | L30: =+รายละเอียดรายจ่าย!AG131+รายละเอียดรายจ่าย!AG132+รายละเอียดรายจ่าย!AG133 -> 8100000 | M30: =+L30/K30*100 -> 73.369565 | N30: =+รายละเอียดรายจ่าย!AJ131+รายละเอียดรายจ่าย!AJ132+รายละเอียดรายจ่าย!AJ133 -> 11040000 | O30: =+รายละเอียดรายจ่าย!AK131+รายละเอียดรายจ่าย!AK132+รายละเอียดรายจ่าย!AK133 -> 10915000 | P30: =+O30/N30*100 -> 98.867754 | Q30: =+รายละเอียดรายจ่าย!AN131+รายละเอียดรายจ่าย!AN132+รายละเอียดรายจ่าย!AN133 -> 11040000 | R30: =+รายละเอียดรายจ่าย!AR131+รายละเอียดรายจ่าย!AR132+รายละเอียดรายจ่าย!AR133 -> 5185000 | S30: =+R30/Q30*100 -> 46.96558 | T30: =+รายละเอียดรายจ่าย!AU131+รายละเอียดรายจ่าย!AU132+รายละเอียดรายจ่าย!AU133 -> 11040000 | U30: =+(T30-Q30)/T30*100 -> 0 | V30: =+T30-Q30 -> 0
E31: ค่าตอบแทนเบี้ยเลี้ยงเหมาจ่าย (ฉ.11) | F31: 0 | G31: 0 | H31: 0 | I31: 0 | J31: 0 | K31: 0 | L31: 0 | M31: 0 | N31: 0 | O31: 0 | P31: 0 | Q31: 0 | R31: 0 | S31: 0 | T31: 0 | V31: =+T31-Q31 -> 0
E32: ค่าตอบแทนตามผลการปฏิบัติงาน (ฉ.12) | F32: 8605551 | G32: =+รายละเอียดรายจ่าย!R10 -> 41374950 | H32: =+รายละเอียดรายจ่าย!Y10 -> 41200000 | I32: =+รายละเอียดรายจ่าย!AD10 -> 13805834 | J32: =+I32/H32*100 -> 33.509306 | K32: =+รายละเอียดรายจ่าย!AF10 -> 41200000 | L32: =+รายละเอียดรายจ่าย!AG10 -> 15644233 | M32: =+L32/K32*100 -> 37.971439 | N32: =+รายละเอียดรายจ่าย!AJ10 -> 41200000 | O32: =+รายละเอียดรายจ่าย!AK10 -> 25896114 | P32: =+O32/N32*100 -> 62.854646 | Q32: =+รายละเอียดรายจ่าย!AN10 -> 52600000 | R32: =+รายละเอียดรายจ่าย!AR10 -> 10163706 | S32: =+R32/Q32*100 -> 19.322635 | T32: =+รายละเอียดรายจ่าย!AU10 -> 52600000 | U32: =+(T32-Q32)/T32*100 -> 0 | V32: =+T32-Q32 -> 0
E33: เงินเพิ่ม (พ.ต.ส) | F33: 225000 | G33: =+รายละเอียดรายจ่าย!R13 -> 0 | H33: =+รายละเอียดรายจ่าย!Y13 -> 300000 | I33: 0 | J33: =+I33/H33*100 -> 0 | K33: =+รายละเอียดรายจ่าย!AF13 -> 300000 | L33: =+รายละเอียดรายจ่าย!AG13 -> 0 | M33: =+รายละเอียดรายจ่าย!AI13 -> 0 | N33: =+รายละเอียดรายจ่าย!AJ13 -> 300000 | O33: =+รายละเอียดรายจ่าย!AK13 -> 70000 | P33: =+O33/N33*100 -> 23.333333 | Q33: =+รายละเอียดรายจ่าย!AN13 -> 300000 | R33: =+รายละเอียดรายจ่าย!AR13 -> 210000 | S33: =+R33/Q33*100 -> 70 | T33: =+รายละเอียดรายจ่าย!AU13 -> 300000 | U33: =+(T33-Q33)/T33*100 -> 0 | V33: =+T33-Q33 -> 0
E34: ค่าตอบแทนเจ้าหน้าที่ปฏิบัติงานของเจ้าหน้าที่ (นอกเวลา) ฉ5 | F34: =367202135.79+10495200-F29-F30 -> 3.4059622e+08 | G34: =+รายละเอียดรายจ่าย!R7-G29 -> 3.9459317e+08 | H34: =432000000-H29 -> 392000000 | I34: =+รายละเอียดรายจ่าย!AD7-I29 -> 1.9464115e+08 | J34: =+I34/H34*100 -> 49.653353 | K34: =+รายละเอียดรายจ่าย!AF7-K29 -> 384000000 | L34: =+รายละเอียดรายจ่าย!AG7-L29 -> 3.0266828e+08 | M34: =+L34/K34*100 -> 78.819863 | N34: =+รายละเอียดรายจ่าย!AJ7-N29 -> 384000000 | O34: =+รายละเอียดรายจ่าย!AK7-O29 -> 4.1044253e+08 | P34: =+O34/N34*100 -> 106.88608 | Q34: =+รายละเอียดรายจ่าย!AN7-Q29 -> 382000000 | R34: =+รายละเอียดรายจ่าย!AR7-R29 -> 2.0588715e+08 | S34: =+R34/Q34*100 -> 53.89716 | T34: =+รายละเอียดรายจ่าย!AU7-T29 -> 382000000 | U34: =+(T34-Q34)/T34*100 -> 0 | V34: =+T34-Q34 -> 0
E35: ค่าตอบแทนเจ้าหน้าที่ปฏิบัติงานในคลินิกพิเศษเฉพาะทางนอกเวลาราชการ (SMC) | V35: =+T35-Q35 -> 0
E36: ค่าตอบแทนอื่น | F36: =555000+295380+1278500 -> 2128880 | G36: =+รายละเอียดรายจ่าย!R8+รายละเอียดรายจ่าย!R11+รายละเอียดรายจ่าย!R12 -> 2342425 | H36: =+รายละเอียดรายจ่าย!Y8+รายละเอียดรายจ่าย!Y11+รายละเอียดรายจ่าย!Y12+รายละเอียดรายจ่าย!Y15 -> 2200000 | I36: =+รายละเอียดรายจ่าย!AD134+รายละเอียดรายจ่าย!AD8+รายละเอียดรายจ่าย!AD11+รายละเอียดรายจ่าย!AD12 -> 1219775 | J36: =+I36/H36*100 -> 55.444318 | K36: =+รายละเอียดรายจ่าย!AF134+รายละเอียดรายจ่าย!AF8+รายละเอียดรายจ่าย!AF11+รายละเอียดรายจ่าย!AF12+รายละเอียดรายจ่าย!AF15 -> 2296000 | L36: =+รายละเอียดรายจ่าย!AG8+รายละเอียดรายจ่าย!AG11+รายละเอียดรายจ่าย!AG12+รายละเอียดรายจ่าย!AG134 -> 1765925 | M36: =+L36/K36*100 -> 76.91311 | N36: =+รายละเอียดรายจ่าย!AJ8+รายละเอียดรายจ่าย!AJ11+รายละเอียดรายจ่าย!AJ12+รายละเอียดรายจ่าย!AJ15+รายละเอียดรายจ่าย!AJ134 -> 2296000 | O36: =+รายละเอียดรายจ่าย!AK11+รายละเอียดรายจ่าย!AK12+รายละเอียดรายจ่าย!AK8 -> 2482475 | P36: =+O36/N36*100 -> 108.12173 | Q36: =+รายละเอียดรายจ่าย!AN8+รายละเอียดรายจ่าย!AN11+รายละเอียดรายจ่าย!AN12+รายละเอียดรายจ่าย!AN15+รายละเอียดรายจ่าย!AN134 -> 2296000 | R36: =+รายละเอียดรายจ่าย!AR8+รายละเอียดรายจ่าย!AR11+รายละเอียดรายจ่าย!AR12+รายละเอียดรายจ่าย!AR15+รายละเอียดรายจ่าย!AR134 -> 1290015 | S36: =+R36/Q36*100 -> 56.185322 | T36: =+รายละเอียดรายจ่าย!AU8+รายละเอียดรายจ่าย!AU11+รายละเอียดรายจ่าย!AU12+รายละเอียดรายจ่าย!AU15+รายละเอียดรายจ่าย!AU134 -> 2296000 | U36: =+(T36-Q36)/T36*100 -> 0 | V36: =+T36-Q36 -> 0
E37: เงินค่าใช้จ่ายบุคลากรอื่น | F37: =189000+247200 -> 436200 | G37: =+รายละเอียดรายจ่าย!R9 -> 147300 | H37: =+รายละเอียดรายจ่าย!Y9+รายละเอียดรายจ่าย!Y16 -> 500000 | I37: =+รายละเอียดรายจ่าย!AD9+รายละเอียดรายจ่าย!AD16 -> 53400 | J37: =+I37/H37*100 -> 10.68 | K37: =+รายละเอียดรายจ่าย!AF16+รายละเอียดรายจ่าย!AF9 -> 500000 | L37: =+รายละเอียดรายจ่าย!AG16+รายละเอียดรายจ่าย!AG9 -> 120592 | M37: =+L37/K37*100 -> 24.1184 | N37: =+รายละเอียดรายจ่าย!AJ9+รายละเอียดรายจ่าย!AJ16 -> 500000 | O37: =+รายละเอียดรายจ่าย!AK16+รายละเอียดรายจ่าย!AK9+รายละเอียดรายจ่าย!AK134 -> 229492 | P37: =+O37/N37*100 -> 45.8984 | Q37: =+รายละเอียดรายจ่าย!AN9+รายละเอียดรายจ่าย!AN16 -> 500000 | R37: =+รายละเอียดรายจ่าย!AR9+รายละเอียดรายจ่าย!AR16 -> 164400 | S37: =+R37/Q37*100 -> 32.88 | T37: =+รายละเอียดรายจ่าย!AU9+รายละเอียดรายจ่าย!AU16 -> 500000 | U37: =+(T37-Q37)/T37*100 -> 0 | V37: =+T37-Q37 -> 0
C38: รายจ่ายจากการดำเนินงาน
E39: ค่ายา | F39: 4.2364677e+08 | G39: =+รายละเอียดรายจ่าย!R155 -> 5.0685247e+08 | H39: =+รายละเอียดรายจ่าย!Y155 -> 480000000 | I39: =+รายละเอียดรายจ่าย!AD155 -> 2.4986011e+08 | J39: =+I39/H39*100 -> 52.05419 | K39: =+รายละเอียดรายจ่าย!AF155 -> 500000000 | L39: =+รายละเอียดรายจ่าย!AG155 -> 3.8111785e+08 | M39: =+L39/K39*100 -> 76.223569 | N39: =+รายละเอียดรายจ่าย!AJ155 -> 530000000 | O39: =+รายละเอียดรายจ่าย!AK155 -> 5.4328725e+08 | P39: =+O39/N39*100 -> 102.50703 | Q39: =+รายละเอียดรายจ่าย!AN155 -> 500000000 | R39: =+รายละเอียดรายจ่าย!AR155 -> 3.292986e+08 | S39: =+R39/Q39*100 -> 65.85972 | T39: =+รายละเอียดรายจ่าย!AU155 -> 530000000 | U39: =+(T39-Q39)/T39*100 -> 5.6603774 | V39: =+T39-Q39 -> 30000000
E40: ค่าเวชภัณฑ์มิใช่ยา
...

Sheet 3ปี
B1: สำนักงานสาธารณสุขจังหวัด...ภูเก็ต.....
B2: โรงพยาบาล..วชิระภูเก็ต............
B3: แผนรายรับ - รายจ่ายเงินบำรุง ปีงบประมาณ 2569 - 2571
L4: หน่วย : บาท
A5: รายการ | E5: ข้อมูลย้อนหลัง 3 ปีงบประมาณ | J5: แผนปี 2569 | K5: แผนปี 2570 | L5: แผนปี 2571
E6: 2566 | F6: 2567 | G6: แผนปี 2568 | H6: แผนครึ่งปีหลัง | I6: 2568
A7: รายรับ
B8: รายรับจากการดำเนินงาน
D9: รายรับค่ารักษาพยาบาลสำหรับโครงการสุขภาพถ้วนหน้า UC | E9: =+'1 ปี (69) '!F9 -> 5.1272986e+08 | F9: =+'1 ปี (69) '!G9 -> 6.1287527e+08 | G9: =+'1 ปี (69) '!H9 -> 620000000 | H9: =+'1 ปี (69) '!K9 -> 605000000 | I9: =+'1 ปี (69) '!O9 -> 5.1153919e+08 | J9: =+'1 ปี (69) '!T9 -> 590000000 | K9: =+J9*3%+J9 -> 607700000 | L9: =+K9*3%+K9 -> 625931000
D10: รายรับค่ารักษาพยาบาลสำหรับโครงการสุขภาพถ้วนหน้า UC งบลงทุน | E10: =+'1 ปี (69) '!F10 -> 17480288 | F10: =+'1 ปี (69) '!G10 -> 16162273 | G10: =+'1 ปี (69) '!H10 -> 16000000 | H10: =+'1 ปี (69) '!K10 -> 30827352 | I10: =+'1 ปี (69) '!O10 -> 30827352 | J10: =+'1 ปี (69) '!T10 -> 22596016 | K10: 17000000 | L10: 17000000
D11: รายรับจากระบบปฏิบัติการฉุกเฉิน (EMS) | E11: =+'1 ปี (69) '!F11 -> 1081750 | F11: =+'1 ปี (69) '!G11 -> 2316591.5 | G11: =+'1 ปี (69) '!H11 -> 2500000 | H11: =+'1 ปี (69) '!K11 -> 1500000 | I11: =+'1 ปี (69) '!O11 -> 1023450 | J11: =+'1 ปี (69) '!T11 -> 1500000 | K11: 1500000 | L11: 1500000
D12: รายรับค่ารักษาพยาบาลเบิกจ่ายตรงกรมบัญชีกลาง | E12: =+'1 ปี (69) '!F12 -> 3.357539e+08 | F12: =+'1 ปี (69) '!G12 -> 3.773114e+08 | G12: =+'1 ปี (69) '!H12 -> 380000000 | H12: =+'1 ปี (69) '!K12 -> 380000000 | I12: =+'1 ปี (69) '!O12 -> 4.0901102e+08 | J12: =+'1 ปี (69) '!T12 -> 420000000 | K12: =+J12*3%+J12 -> 432600000 | L12: =+K12*3%+K12 -> 445578000
D13: รายรับค่ารักษาพยาบาลผู้ป่วยเบิกต้นสังกัด | E13: =+'1 ปี (69) '!F13 -> 1.133913e+08 | F13: =+'1 ปี (69) '!G13 -> 1.4978291e+08 | G13: =+'1 ปี (69) '!H13 -> 160000000 | H13: =+'1 ปี (69) '!K13 -> 160000000 | I13: =+'1 ปี (69) '!O13 -> 1.4031422e+08 | J13: =+'1 ปี (69) '!T13 -> 160000000 | K13: =+J13*5%+J13 -> 168000000 | L13: =+K13*3%+K13 -> 173040000
D14: รายรับค่ารักษาพยาบาลเบิกจาก อปท. | E14: =+'1 ปี (69) '!F14 -> 33388979 | F14: =+'1 ปี (69) '!G14 -> 53444241 | G14: =+'1 ปี (69) '!H14 -> 60000000 | H14: =+'1 ปี (69) '!K14 -> 60000000 | I14: =+'1 ปี (69) '!O14 -> 75273784 | J14: =+'1 ปี (69) '!T14 -> 60000000 | K14: =+J14*3%+J14 -> 61800000 | L14: =+K14*3%+K14 -> 63654000
D15: รายรับค่ารักษาพยาบาลจากกองทุนประกันสังคม | E15: =+'1 ปี (69) '!F15 -> 3.0288769e+08 | F15: =+'1 ปี (69) '!G15 -> 3.7264421e+08 | G15: =+'1 ปี (69) '!H15 -> 3.81583e+08 | H15: =+'1 ปี (69) '!K15 -> 365000000 | I15: =+'1 ปี (69) '!O15 -> 3.4698031e+08 | J15: =+'1 ปี (69) '!T15 -> 350000000 | K15: =+J15*3%+J15 -> 360500000 | L15: =+K15*3%+K15 -> 371315000
D16: รายรับค่ารักษาพยาบาลแรงงานต่างด้าว | E16: =+'1 ปี (69) '!F16 -> 53074741 | F16: =+'1 ปี (69) '!G16 -> 62740891 | G16: =+'1 ปี (69) '!H16 -> 63000000 | H16: =+'1 ปี (69) '!K16 -> 65000000 | I16: =+'1 ปี (69) '!O16 -> 87645151 | J16: =+'1 ปี (69) '!T16 -> 60000000 | K16: =+J16*3%+J16 -> 61800000 | L16: =+K16*3%+K16 -> 63654000
D17: รายรับค่ารักษาพยาบาลและการบริการอื่น | E17: =+'1 ปี (69) '!F17 -> 4.6062461e+08 | F17: =+'1 ปี (69) '!G17 -> 4.9229072e+08 | G17: =+'1 ปี (69) '!H17 -> 549000000 | H17: =+'1 ปี (69) '!K17 -> 544000000 | I17: =+'1 ปี (69) '!O17 -> 5.9269145e+08 | J17: =+'1 ปี (69) '!T17 -> 614500000 | K17: =+J17*5%+J17 -> 645225000 | L17: =+K17*8%+K17 -> 696843000
B18: รายรับอื่น
D19: รายรับเงินช่วยเหลือ | E19: 0 | F19: 0 | G19: 0 | H19: =+'1 ปี (69) '!K19 -> 0 | I19: =+'1 ปี (69) '!L19 -> 0 | J19: 0 | K19: 0 | L19: 0
D20: รายรับเงินอุดหนุน | E20: 0 | F20: 0 | G20: 0 | H20: =+'1 ปี (69) '!K20 -> 0 | I20: =+'1 ปี (69) '!L20 -> 0 | J20: 0 | K20: 0 | L20: 0
D21: รายรับจากการบริจาค | E21: =+'1 ปี (69) '!F21 -> 39570974 | F21: =+'1 ปี (69) '!G21 -> 57795480 | G21: =+'1 ปี (69) '!H21 -> 123000000 | H21: =+'1 ปี (69) '!K21 -> 420000000 | I21: =+'1 ปี (69) '!O21 -> 4.2419399e+08 | J21: =+'1 ปี (69) '!T21 -> 150000000 | K21: 100000000 | L21: 100000000
D22: รายรับดอกเบี้ยเงินฝากธนาคาร | E22: =+'1 ปี (69) '!F22 -> 2022594.5 | F22: =+'1 ปี (69) '!G22 -> 2896990.4 | G22: =+'1 ปี (69) '!H22 -> 3000000 | H22: =+'1 ปี (69) '!K22 -> 2500000 | I22: =+'1 ปี (69) '!O22 -> 3269077.6 | J22: =+'1 ปี (69) '!T22 -> 2500000 | K22: =+J22*3%+J22 -> 2575000 | L22: =+K22*3%+K22 -> 2652250
D23: รายรับอื่น | E23: =+'1 ปี (69) '!F23 -> 19066136 | F23: =+'1 ปี (69) '!G23 -> 52743682 | G23: =+'1 ปี (69) '!H23 -> 52540891 | H23: =+'1 ปี (69) '!K23 -> 25000000 | I23: =+'1 ปี (69) '!O23 -> 55181492 | J23: =+'1 ปี (69) '!T23 -> 28000000 | K23: =+J23*3%+J23 -> 28840000 | L23: =+K23*3%+K23 -> 29705200
D24: รวมรายรับ | E24: =SUM(E9:E23) -> 1.8910728e+09 | F24: =+'1 ปี (69) '!G24 -> 2.2530046e+09 | G24: =SUM(G9:G23) -> 2.4106239e+09 | H24: =SUM(H9:H23) -> 2.6588274e+09 | I24: =SUM(I9:I23) -> 2.6779505e+09 | J24: =SUM(J9:J23) -> 2.459096e+09 | K24: =SUM(K9:K23) -> 2487540000 | L24: =SUM(L9:L23) -> 2590872450
A25: รายจ่าย
B26: รายจ่ายบุคลากร
D27: ค่าจ้างลูกจ้างชั่วคราว / พนักงานกระทรวง | E27: =+'1 ปี (69) '!F27 -> 1.8846488e+08 | F27: =+'1 ปี (69) '!G27 -> 1.917608e+08 | G27: =+'1 ปี (69) '!H27 -> 205000000 | H27: =+'1 ปี (69) '!K27 -> 205000000 | I27: =+'1 ปี (69) '!O27 -> 2.0640163e+08 | J27: =+'1 ปี (69) '!T27 -> 212000000 | K27: =+J27*4%+J27 -> 220480000 | L27: =+K27*4%+K27 -> 229299200
D28: ค่าล่วงเวลางานบริการ / งานสนับสนุน | E28: 0 | F28: 0 | G28: 0 | H28: =+'1 ปี (69) '!K28 -> 0 | I28: =+'1 ปี (69) '!O28 -> 0 | J28: =+'1 ปี (69) '!Q28 -> 0 | K28: 0 | L28: 0
D29: ค่าตอบแทนการปฏิบัติงานเวรผลัดบ่ายหรือผลัดดึกของเจ้าหน้าที่ | E29: 26605920 | F29: =+'1 ปี (69) '!G29 -> 37353830 | G29: =+'1 ปี (69) '!H29 -> 40000000 | H29: =+'1 ปี (69) '!K29 -> 48000000 | I29: =+'1 ปี (69) '!O29 -> 52606958 | J29: =+'1 ปี (69) '!T29 -> 50000000 | K29: =+J29*3%+J29 -> 51500000 | L29: =+K29*3%+K29 -> 53045000
D30: ค่าตอบแทนเงินเพิ่มพิเศษไม่ทำเวชปฏิบัติส่วนตัว หรือปฏิบัติงาน รพ.เอกชน | E30: 10495200 | F30: =+'1 ปี (69) '!G30 -> 10899200 | G30: =+'1 ปี (69) '!H30 -> 11136000 | H30: =+'1 ปี (69) '!K30 -> 11040000 | I30: =+'1 ปี (69) '!O30 -> 10915000 | J30: =+'1 ปี (69) '!T30 -> 11040000 | K30: =+J30*3%+J30 -> 11371200 | L30: =+K30*3%+K30 -> 11712336
D31: ค่าตอบแทนเบี้ยเลี้ยงเหมาจ่าย (ฉ.11) | E31: 0 | F31: 0 | G31: 0 | H31: =+'1 ปี (69) '!K31 -> 0 | I31: =+'1 ปี (69) '!O31 -> 0 | J31: =+'1 ปี (69) '!Q31 -> 0 | K31: 0 | L31: 0
D32: ค่าตอบแทนตามผลการปฏิบัติงาน (ฉ.12) | E32: 8605551 | F32: =+'1 ปี (69) '!G32 -> 41374950 | G32: =+'1 ปี (69) '!H32 -> 41200000 | H32: =+'1 ปี (69) '!K32 -> 41200000 | I32: =+'1 ปี (69) '!O32 -> 25896114 | J32: =+'1 ปี (69) '!T32 -> 52600000 | K32: =+J32*3%+J32 -> 54178000 | L32: =+K32*3%+K32 -> 55803340
D33: เงินเพิ่ม (พ.ต.ส) | E33: 225000 | F33: =+'1 ปี (69) '!G33 -> 0 | G33: =+'1 ปี (69) '!H33 -> 300000 | H33: =+'1 ปี (69) '!K33 -> 300000 | I33: =+'1 ปี (69) '!O33 -> 70000 | J33: =+'1 ปี (69) '!T33 -> 300000 | K33: 0 | L33: 0
D34: ค่าตอบแทนเจ้าหน้าที่ปฏิบัติงานของเจ้าหน้าที่ (นอกเวลา) ฉ5 | E34: =367202135.79+10495200-E29-E30 -> 3.4059622e+08 | F34: =+'1 ปี (69) '!G34 -> 3.9459317e+08 | G34: =+'1 ปี (69) '!H34:H35 -> 392000000 | H34: =+'1 ปี (69) '!K34 -> 384000000 | I34: =+'1 ปี (69) '!O34:O35 -> 4.1044253e+08 | J34: =+'1 ปี (69) '!T34:T35 -> 382000000 | K34: =+J34*3%+J34 -> 393460000 | L34: =+K34*3%+K34 -> 405263800
D35: ค่าตอบแทนเจ้าหน้าที่ปฏิบัติงานในคลินิกพิเศษเฉพาะทางนอกเวลาราชการ (SMC)
D36: ค่าตอบแทนอื่น | E36: =555000+295380+1278500 -> 2128880 | F36: =+'1 ปี (69) '!G36 -> 2342425 | G36: =+'1 ปี (69) '!H36 -> 2200000 | H36: =+'1 ปี (69) '!K36 -> 2296000 | I36: =+'1 ปี (69) '!O36 -> 2482475 | J36: =+'1 ปี (69) '!T36 -> 2296000 | K36: =+J36*3%+J36 -> 2364880 | L36: =+K36*3%+K36 -> 2435826.4
D37: เงินค่าใช้จ่ายบุคลากรอื่น | E37: =189000+247200 -> 436200 | F37: =+'1 ปี (69) '!G37 -> 147300 | G37: =+'1 ปี (69) '!H37 -> 500000 | H37: =+'1 ปี (69) '!K37 -> 500000 | I37: =+'1 ปี (69) '!O37 -> 229492 | J37: =+'1 ปี (69) '!T37 -> 500000 | K37: 500000 | L37: 500000
B38: รายจ่ายจากการดำเนินงาน
D39: ค่ายา | E39: =+'1 ปี (69) '!F39 -> 4.2364677e+08 | F39: =+'1 ปี (69) '!G39 -> 5.0685247e+08 | G39: =+'1 ปี (69) '!H39 -> 480000000 | H39: =+'1 ปี (69) '!K39 -> 500000000 | I39: =+'1 ปี (69) '!O39 -> 5.4328725e+08 | J39: =+'1 ปี (69) '!T39 -> 530000000 | K39: 510000000 | L39: 510000000
D40: ค่าเวชภัณฑ์มิใช่ยา
...

Sheet แผนลงทุน 1ปี 
A1: แบบฟอร์ม แผนการลงทุนด้วยเงินบำรุง 1 ปี ปีงบประมาณ 2569
A2: ตามนโยบายการลงทุน Environment , Modernization And Smart Service : EMS
A3: หน่วยบริการ....โรงพยาบาลวชิระภูเก็ต....วงเงินลงทุนปีงบประมาณ 2569 = 404,611,992.80 บ.
A5: ลำดับ | B5: รายการ | C5: ราคาต่อหน่วย (บาท) | D5: จำนวนหน่วย | E5: รวมเป็นเงิน (บาท) | F5: แหล่งเงิน (งบค่าเสื่อม/งบบริจาค/เงินบำรุง) | G5: ประเภทงบ (ครุภัณฑ์/สิ่งก่อสร้าง) | H5: **สอดคล้อง นโยบายด้านใด
A6: 1 | B6: กล้องกำลังขยายสูงสำหรับงานทันตกรรม | C6: =+'ครุภัณฑ์ (NEW) (การแพทย์)'!D4 -> 1950000 | D6: =+'ครุภัณฑ์ (NEW) (การแพทย์)'!C4 -> 1 | E6: =+C6*D6 -> 1950000 | F6: เงินบำรุง | G6: ครุภัณฑ์ | H6: M
A7: 2 | B7: เครื่องติดตามการทำงานของหัวใจและสัญญาณชีพอัตโนมัติ | C7: =+'ครุภัณฑ์ (NEW) (การแพทย์)'!D5 -> 250000 | D7: =+'ครุภัณฑ์ (NEW) (การแพทย์)'!C5 -> 1 | E7: =+C7*D7 -> 250000 | F7: เงินบำรุง | G7: ครุภัณฑ์ | H7: M
A8: 3 | B8: ระบบ Nurse Call อาคารหลวงพ่อแช่ม ชั้น 5 | C8: =+'ครุภัณฑ์ (NEW) (การแพทย์)'!D6 -> 200000 | D8: =+'ครุภัณฑ์ (NEW) (การแพทย์)'!C6 -> 1 | E8: =+C8*D8 -> 200000 | F8: เงินบำรุง | G8: ครุภัณฑ์ | H8: M
A9: 4 | B9: เครื่องตรวจคลื่นไฟฟ้าหัวใจพร้อมระบบวิเคราะห์ผลและจัดเก็บภาพในระบบเครือข่าย | C9: =+'ครุภัณฑ์ (NEW) (การแพทย์)'!D7 -> 150000 | D9: =+'ครุภัณฑ์ (NEW) (การแพทย์)'!C7 -> 1 | E9: =+C9*D9 -> 150000 | F9: เงินบำรุง | G9: ครุภัณฑ์ | H9: M
A10: 5 | B10: เครื่องช่วยหายใจควบคุมปริมาตรและความดันเคลื่อนย้ายได้ | C10: =+'ครุภัณฑ์ (NEW) (การแพทย์)'!D8 -> 550000 | D10: =+'ครุภัณฑ์ (NEW) (การแพทย์)'!C8 -> 2 | E10: =+C10*D10 -> 1100000 | F10: เงินบำรุง | G10: ครุภัณฑ์ | H10: M
A11: 6 | B11: foot switch voluson e6 | C11: =+'ครุภัณฑ์ (NEW) (การแพทย์)'!D9 -> 30000 | D11: =+'ครุภัณฑ์ (NEW) (การแพทย์)'!C9 -> 1 | E11: =+C11*D11 -> 30000 | F11: เงินบำรุง | G11: ครุภัณฑ์ | H11: M
A12: 7 | B12: เครื่องให้การรักษาด้วยแสงเลเซอร์ สำหรับรักษาความผิดปกติของเม็ดสี ริ้วรอย สิว ความไม่สม่ำเสมอของผิวและแผลเป็น | C12: =+'ครุภัณฑ์ (NEW) (การแพทย์)'!D10 -> 2700000 | D12: =+'ครุภัณฑ์ (NEW) (การแพทย์)'!C10 -> 1 | E12: =+C12*D12 -> 2700000 | F12: เงินบำรุง | G12: ครุภัณฑ์ | H12: M
A13: 8 | B13: เครื่องเลเซอร์คาร์บอนไดออกไซด์แบบ Ultra Pulse | C13: =+'ครุภัณฑ์ (NEW) (การแพทย์)'!D11 -> 650000 | D13: =+'ครุภัณฑ์ (NEW) (การแพทย์)'!C11 -> 1 | E13: =+C13*D13 -> 650000 | F13: เงินบำรุง | G13: ครุภัณฑ์ | H13: M
A14: 9 | B14: เครื่องวิเคราะห์สภาพผิวหน้า VISIA | C14: =+'ครุภัณฑ์ (NEW) (การแพทย์)'!D12 -> 1337500 | D14: =+'ครุภัณฑ์ (NEW) (การแพทย์)'!C12 -> 1 | E14: =+C14*D14 -> 1337500 | F14: เงินบำรุง | G14: ครุภัณฑ์ | H14: M
A15: 10 | B15: เครื่องพ่นลมเย็น | C15: =+'ครุภัณฑ์ (NEW) (การแพทย์)'!D13 -> 448598.13 | D15: =+'ครุภัณฑ์ (NEW) (การแพทย์)'!C13 -> 1 | E15: =+C15*D15 -> 448598.13 | F15: เงินบำรุง | G15: ครุภัณฑ์ | H15: M
A16: 11 | B16: เครื่องยกกระชับใบหน้าโดยไม่ต้องผ่าตัด ULTHERA | C16: =+'ครุภัณฑ์ (NEW) (การแพทย์)'!D14 -> 4500000 | D16: =+'ครุภัณฑ์ (NEW) (การแพทย์)'!C14 -> 1 | E16: =+C16*D16 -> 4500000 | F16: เงินบำรุง | G16: ครุภัณฑ์ | H16: M
A17: 12 | B17: ยูนิตทำฟัน | C17: =+'ครุภัณฑ์ (NEW) (การแพทย์)'!D15 -> 579900 | D17: =+'ครุภัณฑ์ (NEW) (การแพทย์)'!C15 -> 1 | E17: =+C17*D17 -> 579900 | F17: เงินบำรุง | G17: ครุภัณฑ์ | H17: M
... A142: 137 | B142: เครื่องควบคุมการให้สารละลายทางหลอดเลือดดำ (Infusion pump) | C142: =+'ครุภัณฑ์ (NEW) (การแพทย์)'!D140 -> 39000 | D142: =+'ครุภัณฑ์ (NEW) (การแพทย์)'!C140 -> 4 | E142: =+C142*D142 -> 156000 | F142: เงินบำรุง | G142: ครุภัณฑ์ | H142: M
A143: 138 | B143: Pressure bag | D143: =+'ครุภัณฑ์ (NEW) (การแพทย์)'!C141 -> 7 | E143: =+'ครุภัณฑ์ (NEW) (การแพทย์)'!E141 -> 44000 | F143: เงินบำรุง | G143: ครุภัณฑ์ | H143: M
A144: 139 | B144: Laryngoscop | C144: =+'ครุภัณฑ์ (NEW) (การแพทย์)'!D142 -> 17500 | D144: =+'ครุภัณฑ์ (NEW) (การแพทย์)'!C142 -> 8 | E144: =+C144*D144 -> 140000 | F144: เงินบำรุง | G144: ครุภัณฑ์ | H144: M
A145: 140 | B145: เกย์ออกซิเจน | C145: =+'ครุภัณฑ์ (NEW) (การแพทย์)'!D143 -> 0 | D145: =+'ครุภัณฑ์ (NEW) (การแพทย์)'!C143 -> 11 | E145: =+'ครุภัณฑ์ (NEW) (การแพทย์)'!E143 -> 28700 | F145: เงินบำรุง | G145: ครุภัณฑ์ | H145: M
A146: 141 | B146: เกจ์ Suction | C146: =+'ครุภัณฑ์ (NEW) (การแพทย์)'!D144 -> 1000 | D146: =+'ครุภัณฑ์ (NEW) (การแพทย์)'!C144 -> 7 | E146: =+C146*D146 -> 7000 | F146: เงินบำรุง | G146: ครุภัณฑ์ | H146: M
A147: 142 | B147: เครื่องควบคุมอุณหภูมิผู้ป่วยแรงลมร้อน Bair Hugger Temprature management cnits | C147: =+'ครุภัณฑ์ (NEW) (การแพทย์)'!D145 -> 80250 | D147: =+'ครุภัณฑ์ (NEW) (การแพทย์)'!C145 -> 4 | E147: =+C147*D147 -> 321000 | F147: เงินบำรุง | G147: ครุภัณฑ์ | H147: M
A148: 143 | B148: เตียงสำหรับส่องตรวจเนื้อเยื่อปากมดลูก ปรับด้วยระบบไฟฟ้า | C148: =+'ครุภัณฑ์ (NEW) (การแพทย์)'!D146 -> 750000 | D148: =+'ครุภัณฑ์ (NEW) (การแพทย์)'!C146 -> 1 | E148: =+C148*D148 -> 750000 | F148: เงินบำรุง | G148: ครุภัณฑ์ | H148: M
A149: 144 | B149: เครื่องตรวจอวัยวะภายในด้วยคลื่นเสียงความถี่สูงสองมิติ | C149: =+'ครุภัณฑ์ (NEW) (การแพทย์)'!D147 -> 1500000 | D149: =+'ครุภัณฑ์ (NEW) (การแพทย์)'!C147 -> 1 | E149: =+C149*D149 -> 1500000 | F149: เงินบำรุง | G149: ครุภัณฑ์ | H149: M
A150: 145 | B150: Larygeal Mirror 3K (มีด้าม) | C150: =+'ครุภัณฑ์ (NEW) (การแพทย์)'!D148 -> 180 | D150: =+'ครุภัณฑ์ (NEW) (การแพทย์)'!C148 -> 10 | E150: =+C150*D150 -> 1800 | F150: เงินบำรุง | G150: ครุภัณฑ์ | H150: M
A151: 146 | B151: Larygeal Mirror 4K (มีด้าม) | C151: =+'ครุภัณฑ์ (NEW) (การแพทย์)'!D149 -> 180 | D151: =+'ครุภัณฑ์ (NEW) (การแพทย์)'!C149 -> 50 | E151: =+C151*D151 -> 9000 | F151: เงินบำรุง | G151: ครุภัณฑ์ | H151: M
A152: 147 | B152: Larygeal Mirror 5K (มีด้าม) | C152: =+'ครุภัณฑ์ (NEW) (การแพทย์)'!D150 -> 180 | D152: =+'ครุภัณฑ์ (NEW) (การแพทย์)'!C150 -> 50 | E152: =+C152*D152 -> 9000 | F152: เงินบำรุง | G152: ครุภัณฑ์ | H152: M
A153: 148 | B153: ระบบเรียกพยาบาล | C153: =+'ครุภัณฑ์ (NEW) (การแพทย์)'!D151 -> 243853 | D153: =+'ครุภัณฑ์ (NEW) (การแพทย์)'!C151 -> 1 | E153: =+C153*D153 -> 243853 | F153: เงินบำรุง | G153: ครุภัณฑ์ | H153: M
A154: 149 | B154: เครื่องตรวจสอบซองยา พร้อมแกนม้วนซองยา | C154: =+'ครุภัณฑ์ (NEW) (การแพทย์)'!D152 -> 3000000 | D154: =+'ครุภัณฑ์ (NEW) (การแพทย์)'!C152 -> 1 | E154: =+C154*D154 -> 3000000 | F154: เงินบำรุง | G154: ครุภัณฑ์ | H154: M
A155: 150 | B155: ตู้จ่ายยาอัจฉริยะบนหอผู้ป่วย | C155: =+'ครุภัณฑ์ (NEW) (การแพทย์)'!D153 -> 800000 | D155: =+'ครุภัณฑ์ (NEW) (การแพทย์)'!C153 -> 1 | E155: =+C155*D155 -> 800000 | F155: เงินบำรุง | G155: ครุภัณฑ์ | H155: M
A156: 151 | B156: ตู้จัดเก็บยาและชั้นวางของสำหรับห้องยาอาคารศูนย์อุบัติเหตุฉุกเฉินและศูนย์หัวใจ | C156: =+'ครุภัณฑ์ (NEW) (การแพทย์)'!D154 -> 162308.3 | D156: =+'ครุภัณฑ์ (NEW) (การแพทย์)'!C154 -> 1 | E156: =+C156*D156 -> 162308.3 | F156: เงินบำรุง | G156: ครุภัณฑ์ | H156: M
A157: 152 | B157: โคมไฟผ่าตัดส่องทำหัตถการ | C157: =+'ครุภัณฑ์ (NEW) (การแพทย์)'!D155 -> 450000 | D157: =+'ครุภัณฑ์ (NEW) (การแพทย์)'!C155 -> 1 | E157: =+C157*D157 -> 450000 | F157: เงินบำรุง | G157: ครุภัณฑ์ | H157: M
... A230: 225 | B230: เก้าอี้นั่งตรวจ/ผ่าตัดสำหรับแพทย์ ระบบโช๊อัพแก๊ส ปรับระดับใช้เท้า | C230: =+'ครุภัณฑ์ (NEW) (การแพทย์)'!D228 -> 13000 | D230: =+'ครุภัณฑ์ (NEW) (การแพทย์)'!C228 -> 1 | E230: =+C230*D230 -> 13000 | F230: เงินบำรุง | G230: ครุภัณฑ์ | H230: M
A231: 226 | B231: Gerald Tissue FCPS STR 1x2 175MM | C231: =+'ครุภัณฑ์ (NEW) (การแพทย์)'!D234 -> 3200 | D231: =+'ครุภัณฑ์ (NEW) (การแพทย์)'!C234 -> 4 | E231: =+C231*D231 -> 12800 | F231: เงินบริจาค | G231: ครุภัณฑ์ | H231: M
A232: 227 | B232: Std. Straight Handpiece200 M | C232: =+'ครุภัณฑ์ (NEW) (การแพทย์)'!D235 -> 90900 | D232: =+'ครุภัณฑ์ (NEW) (การแพทย์)'!C235 -> 2 | E232: =+C232*D232 -> 181800 | F232: เงินบริจาค | G232: ครุภัณฑ์ | H232: M
A233: 228 | B233: ชุดอุปกรณ์ดูดจ่ายของเหลวสำหรับผ่าตัด แบบปรับได้ SuperBypass Suction-Lrrigation system starter kit 1 | C233: =+'ครุภัณฑ์ (NEW) (การแพทย์)'!D236 -> 250000 | D233: =+'ครุภัณฑ์ (NEW) (การแพทย์)'!C236 -> 1 | E233: =+C233*D233 -> 250000 | F233: เงินบริจาค | G233: ครุภัณฑ์ | H233: M
A234: 229 | B234: Kamiya - Tsuboi Micro Rongeur K-Bayonet 200 mm (90 mm W.L.) Straight Tip | C234: =+'ครุภัณฑ์ (NEW) (การแพทย์)'!D237 -> 98600 | D234: =+'ครุภัณฑ์ (NEW) (การแพทย์)'!C237 -> 1 | E234: =+C234*D234 -> 98600 | F234: เงินบริจาค | G234: ครุภัณฑ์ | H234: M
A235: 230 | B235: Super-Bypass Needle Holder Scissors Mario Zuccarello Special Small-size | C235: =+'ครุภัณฑ์ (NEW) (การแพทย์)'!D238 -> 91400 | D235: =+'ครุภัณฑ์ (NEW) (การแพทย์)'!C238 -> 1 | E235: =+C235*D235 -> 91400 | F235: เงินบริจาค | G235: ครุภัณฑ์ | H235: M
A236: 231 | B236: SILVER NON-STICK BIPOLA-FORCEPE 180 mm./2.0mm BAYONET2 PIN-PLUG | C236: =+'ครุภัณฑ์ (NEW) (การแพทย์)'!D239 -> 32000 | D236: =+'ครุภัณฑ์ (NEW) (การแพทย์)'!C239 -> 5 | E236: =+C236*D236 -> 160000 | F236: เงินบริจาค | G236: ครุภัณฑ์ | H236: M
A237: 232 | B237: SILVER NON-STICK BIPOLA-FORCEPE 200 mm./2.0mm BAYONET2 PIN-PLUG | C237: =+'ครุภัณฑ์ (NEW) (การแพทย์)'!D240 -> 32000 | D237: =+'ครุภัณฑ์ (NEW) (การแพทย์)'!C240 -> 5 | E237: =+C237*D237 -> 160000 | F237: เงินบริจาค | G237: ครุภัณฑ์ | H237: M
...

Sheet แผนลงทุน 3 ปี
A1: แบบฟอร์ม แผนการลงทุนด้วยเงินบำรุง 3 ปี งบประมาณ 2569 - 2571
A2: ตามนโยบายการลงทุน Environment , Modernization And Smart Service : EMS
A3: หน่วยบริการ....โรงพยาบาลวชิระภูเก็ต..วงเงินลงทุนปีงบประมาณ 2569-2571…= 1,261,097,216.32 บ.
M4: หน่วย : บาท
B5: ลำดับ | C5: รายการ | D5: หน่วยนับ | E5: ราคา ต่อหน่วย | F5: ปีงบประมาณ 2569 | H5: ปีงบประมาณ 2570 | J5: ปีงบประมาณ 2571 | L5: รวม 2569-2571 | N5: แหล่งเงิน (งบค่าเสื่อม/งบบริจาค/เงินบำรุง) | O5: ประเภทงบ (ครุภัณฑ์/ สิ่งก่อสร้าง) | P5: **สอดคล้องนโยบายด้านใด
