Workbook

Sheet แบบฟอร์มที่ 1
A1: สรุปแผนการใช้เงินบำรุง หมวดค่าวัสดุ ปีงบประมาณ 2562
A2: และ
A3: ตั้งแผนเงินบำรุง หมวดค่าวัสดุ ปีงบประมาณ 2563
B4: ประเภทวัสดุ…………………
A5: ลำดับ | B5: ตั้งแผนเงินบำรุง | C5: ยอดสั่งปีงบ 2562 | D5: เงินเหลือ (+) (บาท) | E5: วัสดุคงเหลือ | F5: จำนวนผู้ใช้บริการ | G5: คาดว่าปีงบฯ 2563 | H5: ตั้งแผน | I5: หมายเหตุ
A6: ที่ | B6: ปีงบฯ 2562 (บาท) | C6: รวมทั้งหมด (บาท) | D6: เกินแผน (-) (บาท) | E6: ณ มิ.ย. 2562(บาท) | F6: ปีงบฯ 2562 | G6: มีผู้ใช้บริการ | H6: ปีงบฯ 2563 (บาท)
A9: เหตุผลประกอบคำขอตั้ง (ถ้ามี).....................................................................................................................................................................................................................................................................................................................................
A10: ..................................................................................................................................................................................................................................................................................................................................................................................................
A11: ..................................................................................................................................................................................................................................................................................................................................................................................................
A12: ..............................................................................................................................................................................................................................................................................................................................................................................
A13: ...................................................................................................................................................................................................................................................................................................................................................................................
E15: ลงชื่อ | H15: (หัวหน้าฝ่าย/กลุ่มงาน/งาน)
F16: / /
A19: สรุปแผนการใช้เงินบำรุง หมวดค่าวัสดุ ปีงบประมาณ 2562
A20: และ
A21: ตั้งแผนเงินบำรุง หมวดค่าวัสดุ ปีงบประมาณ 2563
B22: ประเภทวัสดุ ยา
A23: ลำดับ | B23: ตั้งแผนเงินบำรุง | C23: ยอดสั่งปีงบ 256 | D23: เงินเหลือ (+) (บาท) | E23: วัสดุคงเหลือ | F23: จำนวนผู้ใช้บริการ | G23: คาดว่าปีงบฯ 2562 | H23: ตั้งแผน | I23: หมายเหตุ
A24: ที่ | B24: ปีงบฯ 2562 (บาท) | C24: รวมทั้งหมด (บาท) | D24: เกินแผน (-) (บาท) | E24: ณ พ.ค. 2562(บาท) | F24: ปีงบฯ 2562 | G24: มีผู้ใช้บริการ | H24: ปีงบฯ 2562 (บาท)
A25: 1 | B25: 320000000
A27: เหตุผลประกอบคำขอตั้ง (ถ้ามี).....................................................................................................................................................................................................................................................................................................................................
A28: ..................................................................................................................................................................................................................................................................................................................................................................................................
A29: ..................................................................................................................................................................................................................................................................................................................................................................................................
A30: ...................................................................................................................................................................................................................................................................................................................................................................................
E32: ลงชื่อ | H32: (หัวหน้าฝ่าย/กลุ่มงาน/งาน)
F33: / /
A34: *** กรุณาส่งคืน ก.ยุทธศาสตร์และแผนงานโครงการ ภายในวันที่ 31 กรกฎาคม 2561
A37: สรุปแผนการใช้เงินบำรุง หมวดค่าวัสดุ ปีงบประมาณ 2562
A38: และ
A39: ตั้งแผนเงินบำรุง หมวดค่าวัสดุ ปีงบประมาณ 2563
B40: ประเภทวัสดุ เฝือก
A41: ลำดับ | B41: ตั้งแผนเงินบำรุง | C41: ยอดสั่งปีงบ 2562 | D41: เงินเหลือ (+) (บาท) | E41: วัสดุคงเหลือ | F41: จำนวนผู้ใช้บริการ | G41: คาดว่าปีงบฯ 2563 | H41: ตั้งแผน | I41: หมายเหตุ
A42: ที่ | B42: ปีงบฯ 2562 (บาท) | C42: รวมทั้งหมด (บาท) | D42: เกินแผน (-) (บาท) | E42: ณ พ.ค. 2562(บาท) | F42: ปีงบฯ 2562 | G42: มีผู้ใช้บริการ | H42: ปีงบฯ 2563 (บาท)
A43: 6 | B43: 2500000
A45: เหตุผลประกอบคำขอตั้ง (ถ้ามี).....................................................................................................................................................................................................................................................................................................................................
A46: ..................................................................................................................................................................................................................................................................................................................................................................................................
A47: ..................................................................................................................................................................................................................................................................................................................................................................................................
A48: ..............................................................................................................................................................................................................................................................................................................................................................................
A49: ...................................................................................................................................................................................................................................................................................................................................................................................
E51: ลงชื่อ | H51: (หัวหน้าฝ่าย/กลุ่มงาน/งาน)
...

Sheet 1.เวชภัณฑ์ ยา (2)
A1: สรุปแผนการใช้เงินบำรุง หมวดค่าวัสดุ ปีงบประมาณ 2568 (ต.ค67- มิ.ย.68)
A2: และ
A3: คำขอตั้งปรับแผนเงินบำรุง หมวดค่าวัสดุ ประจำปีงบประมาณ 2569
B4: ประเภทวัสดุ ยา + ยาเอกซเรย์
A5: ลำดับที่ | B5: แผนปีงบฯ 2568 (บาท) | C5: ผลการดำเนินงาน ณ 30 มิ.ย. 2568 (บาท) | F5: ยอดเงิน คงเหลือ (บาท) | G5: วัสดุคงคลัง (บาท) | H5: คำขอตั้งแผน ปีงบฯ 2569 (บาท) | I5: หมายเหตุ
C6: เบิกจ่ายแล้ว | D6: เจ้าหนี้คงค้าง | E6: ก่อหนี้/ยังไม่ตรวจรับ
A7: 1 | B7: 500000000 | C7: 3.8111785e+08 | D7: 1.2563588e+08
A9: เหตุผลประกอบคำขอตั้ง (ถ้ามี).............................................................................................................................................................................................................................................................................................................................................................................................
A10: .......................................................................................................................................................................................................................................................................................................................................................................................................................................................
A11: .......................................................................................................................................................................................................................................................................................................................................................................................................................................................
A12: .......................................................................................................................................................................................................................................................................................................................................................................................................................................................
A13: .......................................................................................................................................................................................................................................................................................................................................................................................................................................................
E15: ลงชื่อ | H15: (หัวหน้าฝ่าย/กลุ่มงาน/งาน)
F16: ลงวันที่ ส.ค. พ.ศ. 2568
A17: *** กรุณาส่งคืน ก.ยุทธศาสตร์และแผนงานโครงการ ภายในวันที่ 15 สิงหาคม 2568

Sheet 2.เวชภัณฑ์มิใช่ยา
A1: =+'1.เวชภัณฑ์ ยา (2)'!A1:I1 -> สรุปแผนการใช้เงินบำรุง หมวดค่าวัสดุ ปีงบประมาณ 2568 (ต.ค67- มิ.ย.68)
A2: และ
A3: =+'1.เวชภัณฑ์ ยา (2)'!A3:I3 -> คำขอตั้งปรับแผนเงินบำรุง หมวดค่าวัสดุ ประจำปีงบประมาณ 2569
B4: ประเภทวัสดุ เวชภัณฑ์การพยาบาล
A5: ลำดับที่ | B5: แผนปีงบฯ 2568 (บาท) | C5: ผลการดำเนินงาน ณ 30 มิ.ย. 2568 (บาท) | F5: ยอดเงิน คงเหลือ (บาท) | G5: วัสดุคงคลัง (บาท) | H5: คำขอตั้งแผน ปีงบฯ 2569 (บาท) | I5: หมายเหตุ
C6: เบิกจ่ายแล้ว | D6: เจ้าหนี้คงค้าง | E6: ก่อหนี้/ยังไม่ตรวจรับ
A7: 2 | B7: 47500000 | C7: 31776018
A9: เหตุผลประกอบคำขอตั้ง (ถ้ามี).............................................................................................................................................................................................................................................................................................................................................................
A10: .................................................................................................................................................................................................................................................................................................................................................................................................................................
A11: .................................................................................................................................................................................................................................................................................................................................................................................................................................
A12: .................................................................................................................................................................................................................................................................................................................................................................................................................................
A13: .................................................................................................................................................................................................................................................................................................................................................................................................................................
E15: ลงชื่อ | H15: (หัวหน้าฝ่าย/กลุ่มงาน/งาน)
F16: ลงวันที่ ส.ค. พ.ศ. 2568
A17: *** กรุณาส่งคืน ก.ยุทธศาสตร์และแผนงานโครงการ ภายในวันที่ 15 สิงหาคม 2568
A20: =+A1 -> สรุปแผนการใช้เงินบำรุง หมวดค่าวัสดุ ปีงบประมาณ 2568 (ต.ค67- มิ.ย.68)
A21: และ
A22: =+A3 -> คำขอตั้งปรับแผนเงินบำรุง หมวดค่าวัสดุ ประจำปีงบประมาณ 2569
B23: ประเภทวัสดุ เฝือก
A24: =+A5 -> ลำดับที่ | B24: =+B5 -> แผนปีงบฯ 2568 (บาท) | C24: =+C5 -> ผลการดำเนินงาน ณ 30 มิ.ย. 2568 (บาท) | F24: =+F5 -> ยอดเงิน คงเหลือ (บาท) | G24: =+G5 -> วัสดุคงคลัง (บาท) | H24: =+H5 -> คำขอตั้งแผน ปีงบฯ 2569 (บาท) | I24: =+I5 -> หมายเหตุ
C25: =+C6 -> เบิกจ่ายแล้ว | D25: =+D6 -> เจ้าหนี้คงค้าง | E25: =+E6 -> ก่อหนี้/ยังไม่ตรวจรับ
A26: 3 | B26: 2000000 | C26: 2201018.5
A28: เหตุผลประกอบคำขอตั้ง (ถ้ามี).............................................................................................................................................................................................................................................................................................................................................................
A29: .................................................................................................................................................................................................................................................................................................................................................................................................................................
A30: .................................................................................................................................................................................................................................................................................................................................................................................................................................
A31: .................................................................................................................................................................................................................................................................................................................................................................................................................................
A32: .................................................................................................................................................................................................................................................................................................................................................................................................................................
E34: ลงชื่อ | H34: (หัวหน้าฝ่าย/กลุ่มงาน/งาน)
F35: ลงวันที่ ส.ค. พ.ศ. 2568
A36: *** กรุณาส่งคืน ก.ยุทธศาสตร์และแผนงานโครงการ ภายในวันที่ 15 สิงหาคม 2568
A37: =+A20 -> สรุปแผนการใช้เงินบำรุง หมวดค่าวัสดุ ปีงบประมาณ 2568 (ต.ค67- มิ.ย.68)
A38: และ
A39: =+A22 -> คำขอตั้งปรับแผนเงินบำรุง หมวดค่าวัสดุ ประจำปีงบประมาณ 2569
B40: ประเภทวัสดุ เวชศาสตร์ฟื้นฟู
A41: =+A24 -> ลำดับที่ | B41: =+B5 -> แผนปีงบฯ 2568 (บาท) | C41: =+C24 -> ผลการดำเนินงาน ณ 30 มิ.ย. 2568 (บาท) | F41: =+F24 -> ยอดเงิน คงเหลือ (บาท) | G41: =+G24 -> วัสดุคงคลัง (บาท) | H41: =+H24 -> คำขอตั้งแผน ปีงบฯ 2569 (บาท) | I41: =+I24 -> หมายเหตุ
C42: =+C25 -> เบิกจ่ายแล้ว | D42: =+D25 -> เจ้าหนี้คงค้าง | E42: =+E25 -> ก่อหนี้/ยังไม่ตรวจรับ
A43: 4 | B43: 2000000 | C43: 1686445
A45: เหตุผลประกอบคำขอตั้ง (ถ้ามี).............................................................................................................................................................................................................................................................................................................................................................
A46: .................................................................................................................................................................................................................................................................................................................................................................................................................................
A47: .................................................................................................................................................................................................................................................................................................................................................................................................................................
...

Sheet 3.วัสดุการแพทย์
A1: =+'2.เวชภัณฑ์มิใช่ยา'!A170:I170 -> สรุปแผนการใช้เงินบำรุง หมวดค่าวัสดุ ปีงบประมาณ 2568 (ต.ค67- มิ.ย.68)
A2: และ
A3: =+'2.เวชภัณฑ์มิใช่ยา'!A172:I172 -> คำขอตั้งปรับแผนเงินบำรุง หมวดค่าวัสดุ ประจำปีงบประมาณ 2569
B4: ประเภทวัสดุ วัสดุการแพทย์ (ซ่อม)
A5: ลำดับที่ | B5: แผนปีงบฯ 2568 (บาท) | C5: ผลการดำเนินงาน ณ 30 มิ.ย. 2568 (บาท) | F5: ยอดเงิน คงเหลือ (บาท) | G5: วัสดุคงคลัง (บาท) | H5: คำขอตั้งแผน ปีงบฯ 2569 (บาท) | I5: หมายเหตุ
C6: เบิกจ่ายแล้ว | D6: เจ้าหนี้คงค้าง | E6: ก่อหนี้/ยังไม่ตรวจรับ
A7: 12 | B7: 25000000 | C7: 24389393 | D7: 2357622.8
A9: เหตุผลประกอบคำขอตั้ง (ถ้ามี).............................................................................................................................................................................................................................................................................................................................................................
A10: .................................................................................................................................................................................................................................................................................................................................................................................................................................
A11: .................................................................................................................................................................................................................................................................................................................................................................................................................................
A12: .................................................................................................................................................................................................................................................................................................................................................................................................................................
A13: .................................................................................................................................................................................................................................................................................................................................................................................................................................
E14: ลงชื่อ | H14: (หัวหน้าฝ่าย/กลุ่มงาน/งาน)
F15: ลงวันที่ ส.ค. พ.ศ. 2568
A16: *** กรุณาส่งคืน ก.ยุทธศาสตร์และแผนงานโครงการ ภายในวันที่ 15 สิงหาคม 2568
A20: =+A1 -> สรุปแผนการใช้เงินบำรุง หมวดค่าวัสดุ ปีงบประมาณ 2568 (ต.ค67- มิ.ย.68)
A21: =+A2 -> และ
A22: =+A3 -> คำขอตั้งปรับแผนเงินบำรุง หมวดค่าวัสดุ ประจำปีงบประมาณ 2569
B23: ประเภทวัสดุ การแพทย์ผ่าตัด
A24: =+A5 -> ลำดับที่ | B24: =+B5 -> แผนปีงบฯ 2568 (บาท) | C24: =+C5 -> ผลการดำเนินงาน ณ 30 มิ.ย. 2568 (บาท) | F24: =+F5 -> ยอดเงิน คงเหลือ (บาท) | G24: =+G5 -> วัสดุคงคลัง (บาท) | H24: =+H5 -> คำขอตั้งแผน ปีงบฯ 2569 (บาท) | I24: =+I5 -> หมายเหตุ
C25: =+C6 -> เบิกจ่ายแล้ว | D25: =+D6 -> เจ้าหนี้คงค้าง | E25: =+E6 -> ก่อหนี้/ยังไม่ตรวจรับ
A26: 13 | B26: 170000000 | C26: 1.4260707e+08
A28: เหตุผลประกอบคำขอตั้ง (ถ้ามี).............................................................................................................................................................................................................................................................................................................................................................
A29: .................................................................................................................................................................................................................................................................................................................................................................................................................................
A30: .................................................................................................................................................................................................................................................................................................................................................................................................................................
A31: .................................................................................................................................................................................................................................................................................................................................................................................................................................
A32: .................................................................................................................................................................................................................................................................................................................................................................................................................................
E33: ลงชื่อ | H33: (หัวหน้าฝ่าย/กลุ่มงาน/งาน)
F34: ลงวันที่ ส.ค. พ.ศ. 2568
A35: =+A16 -> *** กรุณาส่งคืน ก.ยุทธศาสตร์และแผนงานโครงการ ภายในวันที่ 15 สิงหาคม 2568
A38: =+A20 -> สรุปแผนการใช้เงินบำรุง หมวดค่าวัสดุ ปีงบประมาณ 2568 (ต.ค67- มิ.ย.68)
A39: =+A21 -> และ
A40: =+A22 -> คำขอตั้งปรับแผนเงินบำรุง หมวดค่าวัสดุ ประจำปีงบประมาณ 2569
B41: ประเภทวัสดุ เอกซเรย์ (เวชภัณฑ์+intervention)
A42: =+A24 -> ลำดับที่ | B42: =+B24 -> แผนปีงบฯ 2568 (บาท) | C42: =+C24 -> ผลการดำเนินงาน ณ 30 มิ.ย. 2568 (บาท) | F42: =+F24 -> ยอดเงิน คงเหลือ (บาท) | G42: =+G24 -> วัสดุคงคลัง (บาท) | H42: =+H24 -> คำขอตั้งแผน ปีงบฯ 2569 (บาท) | I42: =+I24 -> หมายเหตุ
C43: =+C25 -> เบิกจ่ายแล้ว | D43: =+D25 -> เจ้าหนี้คงค้าง | E43: =+E25 -> ก่อหนี้/ยังไม่ตรวจรับ
A44: 14 | B44: 30000000 | C44: 17196707 | D44: 3680330.9
A46: เหตุผลประกอบคำขอตั้ง (ถ้ามี).............................................................................................................................................................................................................................................................................................................................................................
A47: .................................................................................................................................................................................................................................................................................................................................................................................................................................
A48: .................................................................................................................................................................................................................................................................................................................................................................................................................................
...

Sheet 4.วัสุดวิทยาศาสตร์
A1: =+'3.วัสดุการแพทย์'!A57:I57 -> สรุปแผนการใช้เงินบำรุง หมวดค่าวัสดุ ปีงบประมาณ 2568 (ต.ค67- มิ.ย.68)
A2: =+'3.วัสดุการแพทย์'!A58:I58 -> และ
A3: =+'3.วัสดุการแพทย์'!A59:I59 -> คำขอตั้งปรับแผนเงินบำรุง หมวดค่าวัสดุ ประจำปีงบประมาณ 2569
B4: ประเภทวัสดุ ออกซิเจนเหลว
A5: ลำดับที่ | B5: แผนปีงบฯ 2568 (บาท) | C5: ผลการดำเนินงาน ณ 30 มิ.ย. 2568 (บาท) | F5: ยอดเงิน คงเหลือ (บาท) | G5: วัสดุคงคลัง (บาท) | H5: คำขอตั้งแผน ปีงบฯ 2569 (บาท) | I5: หมายเหตุ
C6: เบิกจ่ายแล้ว | D6: เจ้าหนี้คงค้าง | E6: ก่อหนี้/ยังไม่ตรวจรับ
A7: 16 | B7: 5000000
A9: เหตุผลประกอบคำขอตั้ง (ถ้ามี).............................................................................................................................................................................................................................................................................................................................................................
A10: .................................................................................................................................................................................................................................................................................................................................................................................................................................
A11: .................................................................................................................................................................................................................................................................................................................................................................................................................................
A12: .................................................................................................................................................................................................................................................................................................................................................................................................................................
A13: .................................................................................................................................................................................................................................................................................................................................................................................................................................
E14: ลงชื่อ | H14: (หัวหน้าฝ่าย/กลุ่มงาน/งาน)
F15: ลงวันที่ ส.ค. พ.ศ. 2568
A18: =+'3.วัสดุการแพทย์'!A16:G16 -> *** กรุณาส่งคืน ก.ยุทธศาสตร์และแผนงานโครงการ ภายในวันที่ 15 สิงหาคม 2568
A20: =+A1 -> สรุปแผนการใช้เงินบำรุง หมวดค่าวัสดุ ปีงบประมาณ 2568 (ต.ค67- มิ.ย.68)
A21: =+A2 -> และ
A22: =+A3 -> คำขอตั้งปรับแผนเงินบำรุง หมวดค่าวัสดุ ประจำปีงบประมาณ 2569
B23: ประเภทวัสดุ LAB
A24: =+A5 -> ลำดับที่ | B24: =+B5 -> แผนปีงบฯ 2568 (บาท) | C24: =+C5 -> ผลการดำเนินงาน ณ 30 มิ.ย. 2568 (บาท) | F24: =+F5 -> ยอดเงิน คงเหลือ (บาท) | G24: =+G5 -> วัสดุคงคลัง (บาท) | H24: =+H5 -> คำขอตั้งแผน ปีงบฯ 2569 (บาท) | I24: =+I5 -> หมายเหตุ
C25: =+C6 -> เบิกจ่ายแล้ว | D25: =+D6 -> เจ้าหนี้คงค้าง | E25: =+E6 -> ก่อหนี้/ยังไม่ตรวจรับ
A26: 17 | B26: 4000000 | I26: Lab (โควิด)
A27: 18 | B27: 72000000 | I27: LAB (ทั่วไป)
A29: เหตุผลประกอบคำขอตั้ง (ถ้ามี).............................................................................................................................................................................................................................................................................................................................................................
A30: .................................................................................................................................................................................................................................................................................................................................................................................................................................
A31: .................................................................................................................................................................................................................................................................................................................................................................................................................................
A32: .................................................................................................................................................................................................................................................................................................................................................................................................................................
A33: .................................................................................................................................................................................................................................................................................................................................................................................................................................
E34: ลงชื่อ | H34: (หัวหน้าฝ่าย/กลุ่มงาน/งาน)
F35: ลงวันที่ ส.ค. พ.ศ. 2567
A36: =+A18 -> *** กรุณาส่งคืน ก.ยุทธศาสตร์และแผนงานโครงการ ภายในวันที่ 15 สิงหาคม 2568
A40: =+A20 -> สรุปแผนการใช้เงินบำรุง หมวดค่าวัสดุ ปีงบประมาณ 2568 (ต.ค67- มิ.ย.68)
A41: =+A21 -> และ
A42: =+A22 -> คำขอตั้งปรับแผนเงินบำรุง หมวดค่าวัสดุ ประจำปีงบประมาณ 2569
B43: ประเภทวัสดุ ธนาคารเลือด
A44: =+A24 -> ลำดับที่ | B44: =+B24 -> แผนปีงบฯ 2568 (บาท) | C44: =+C24 -> ผลการดำเนินงาน ณ 30 มิ.ย. 2568 (บาท) | F44: =+F24 -> ยอดเงิน คงเหลือ (บาท) | G44: =+G24 -> วัสดุคงคลัง (บาท) | H44: =+H24 -> คำขอตั้งแผน ปีงบฯ 2569 (บาท) | I44: =+I24 -> หมายเหตุ
C45: =+C25 -> เบิกจ่ายแล้ว | D45: =+D25 -> เจ้าหนี้คงค้าง | E45: =+E25 -> ก่อหนี้/ยังไม่ตรวจรับ
A46: 19 | B46: 30000000
A48: เหตุผลประกอบคำขอตั้ง (ถ้ามี).............................................................................................................................................................................................................................................................................................................................................................
A49: .................................................................................................................................................................................................................................................................................................................................................................................................................................
...

Sheet 5.วัสดุทั่วไป
A1: =+'4.วัสุดวิทยาศาสตร์'!A1:I1 -> สรุปแผนการใช้เงินบำรุง หมวดค่าวัสดุ ปีงบประมาณ 2568 (ต.ค67- มิ.ย.68)
A2: =+'4.วัสุดวิทยาศาสตร์'!A2:I2 -> และ
A3: =+'4.วัสุดวิทยาศาสตร์'!A3:I3 -> คำขอตั้งปรับแผนเงินบำรุง หมวดค่าวัสดุ ประจำปีงบประมาณ 2569
A4: ประเภทวัสดุ วัสดุทั่วไป
A5: ลำดับที่ | B5: ประเภทวัสดุ | C5: แผนปีงบฯ 2568 (บาท) | D5: ผลการดำเนินงาน ณ 30 มิ.ย. 2568 (บาท) | G5: ยอดเงิน คงเหลือ (บาท) | H5: วัสดุคงคลัง (บาท) | I5: คำขอตั้งแผน ปีงบฯ 2569 (บาท) | J5: หมายเหตุ
D6: เบิกจ่ายแล้ว | E6: เจ้าหนี้คงค้าง | F6: ก่อหนี้/ยังไม่ตรวจรับ
A7: 21 | B7: ค่าวัสดุสำนักงาน | C7: 12000000 | D7: 8017181.1 | E7: 6388369.9
A8: 22 | B8: งานบ้าน+น้ำดื่ม | C8: 12000000 | D8: 7904507.6 | E8: 4829485
A9: 23 | B9: แบบพิมพ์ | C9: 1900000 | D9: 1759287.8
A10: 24 | B10: อื่นๆ | C10: 100000 | D10: 45595.45
A11: 25 | B11: วัสดุคอมพิวเตอร์ | C11: 4000000 | D11: 360743 | E11: 374580
A12: 26 | B12: วัสดุโฆษณาและเผยแพร่ | C12: 120000 | D12: 74343 | E12: 148510
A14: เหตุผลประกอบคำขอตั้ง (ถ้ามี)............................................................................................................................................................................................................................................................................................................................................................................
A15: ...........................................................................................................................................................................................................................................................................................................................................................................................................................................
A16: ..............................................................................................................................................................................................................................................................................................................................................................................................................................................
A17: ............................................................................................................................................................................................................................................................................................................................................................................................................................................
F18: ลงชื่อ | I18: (หัวหน้าฝ่าย/กลุ่มงาน/งาน)
G19: ลงวันที่ ส.ค. พ.ศ. 2568
B20: *** กรุณาส่งคืน ก.ยุทธศาสตร์และแผนงานโครงการ ภายในวันที่ 15 สิงหาคม 2567

Sheet 6.เชื้อเพลิง
A1: =+'5.วัสดุทั่วไป'!A1:J1 -> สรุปแผนการใช้เงินบำรุง หมวดค่าวัสดุ ปีงบประมาณ 2568 (ต.ค67- มิ.ย.68)
A2: =+'5.วัสดุทั่วไป'!A2:J2 -> และ
A3: =+'5.วัสดุทั่วไป'!A3:J3 -> คำขอตั้งปรับแผนเงินบำรุง หมวดค่าวัสดุ ประจำปีงบประมาณ 2569
A4: ประเภทวัสดุ เชื้อเพลิง
A5: ลำดับที่ | B5: ประเภทวัสดุ | C5: แผนปีงบฯ 2568 (บาท) | D5: ผลการดำเนินงาน ณ 30 มิ.ย. 2567 (บาท) | G5: ยอดเงิน คงเหลือ (บาท) | H5: วัสดุคงคลัง (บาท) | I5: คำขอตั้งแผน ปีงบฯ 2569 (บาท) | J5: หมายเหตุ
D6: เบิกจ่ายแล้ว | E6: เจ้าหนี้คงค้าง | F6: ก่อหนี้/ยังไม่ตรวจรับ
A7: 27 | B7: เชื้อเพลิงรถยนต์ | C7: 1000000 | D7: 6241096.1 | E7: 1220719.2
A8: 28 | B8: เชื้อเพลิงช่าง | C8: 270000
A9: 29 | B9: แก๊ส LPG | C9: 7000000
A10: 30 | B10: ออกซิเจนถัง | C10: 1000000
A12: เหตุผลประกอบคำขอตั้ง (ถ้ามี)............................................................................................................................................................................................................................................................................................................................................................................
A13: ...........................................................................................................................................................................................................................................................................................................................................................................................................................................
A14: ..............................................................................................................................................................................................................................................................................................................................................................................................................................................
A15: ............................................................................................................................................................................................................................................................................................................................................................................................................................................
F16: ลงชื่อ | I16: (หัวหน้าฝ่าย/กลุ่มงาน/งาน)
G17: ลงวันที่ ส.ค. พ.ศ. 2568
B18: *** กรุณาส่งคืน ก.ยุทธศาสตร์และแผนงานโครงการ ภายในวันที่ 15 สิงหาคม 2568

Sheet 7.ช่าง
A1: =+'6.เชื้อเพลิง'!A1:J1 -> สรุปแผนการใช้เงินบำรุง หมวดค่าวัสดุ ปีงบประมาณ 2568 (ต.ค67- มิ.ย.68)
A2: =+'6.เชื้อเพลิง'!A2:J2 -> และ
A3: =+'6.เชื้อเพลิง'!A3:J3 -> คำขอตั้งปรับแผนเงินบำรุง หมวดค่าวัสดุ ประจำปีงบประมาณ 2569
A4: ประเภทวัสดุ ช่าง
A5: ลำดับที่ | B5: ประเภทวัสดุ | C5: แผน ปีงบฯ 2568 (บาท) | D5: ผลการดำเนินงาน ณ 30 มิ.ย. 2568 (บาท) | G5: ยอดเงิน คงเหลือ (บาท) | H5: วัสดุคงคลัง (บาท) | I5: คำขอตั้งแผน ปีงบฯ 2569 (บาท) | J5: หมายเหตุ
D6: เบิกจ่ายแล้ว | E6: เจ้าหนี้คงค้าง | F6: ก่อหนี้/ยังไม่ตรวจรับ
A7: 31 | B7: ค่าวัสดุไฟฟ้า | C7: 4500000 | D7: 2368781.5 | E7: 430588.11
A8: 32 | B8: ค่าวัสุดก่อสร้าง | C8: 5000000 | D8: 2153418.9 | E8: 508550.74
A9: 33 | B9: ยานพาหนะ | C9: 1000000 | D9: 297003.6 | E9: 30923
A11: เหตุผลประกอบคำขอตั้ง (ถ้ามี)............................................................................................................................................................................................................................................................................................................................................................................
A12: ...........................................................................................................................................................................................................................................................................................................................................................................................................................................
A13: ..............................................................................................................................................................................................................................................................................................................................................................................................................................................
A14: ............................................................................................................................................................................................................................................................................................................................................................................................................................................
F15: ลงชื่อ | I15: (หัวหน้าฝ่าย/กลุ่มงาน/งาน)
G16: ลงวันที่ ส.ค. พ.ศ. 2568
B17: *** กรุณาส่งคืน ก.ยุทธศาสตร์และแผนงานโครงการ ภายในวันที่ 15 สิงหาคม 2568

Sheet 8.โภชนาการ
A1: =+'7.ช่าง'!A1:J1 -> สรุปแผนการใช้เงินบำรุง หมวดค่าวัสดุ ปีงบประมาณ 2568 (ต.ค67- มิ.ย.68)
A2: =+'7.ช่าง'!A2:J2 -> และ
A3: =+'7.ช่าง'!A3:J3 -> คำขอตั้งปรับแผนเงินบำรุง หมวดค่าวัสดุ ประจำปีงบประมาณ 2569
A4: ประเภทวัสดุ โภชนศาสตร์
A5: ลำดับที่ | B5: แผน ปีงบฯ 2568 (บาท) | C5: ผลการดำเนินงาน ณ 30 มิ.ย. 2568 (บาท) | F5: ยอดเงิน คงเหลือ (บาท) | G5: วัสดุคงคลัง (บาท) | H5: คำขอตั้งแผน ปีงบฯ 2569 (บาท) | I5: หมายเหตุ
C6: เบิกจ่ายแล้ว | D6: เจ้าหนี้คงค้าง | E6: ก่อหนี้/ยังไม่ตรวจรับ
A7: 34 | B7: 18000000 | C7: 15380356 | D7: 1420644.9
A9: เหตุผลประกอบคำขอตั้ง (ถ้ามี).............................................................................................................................................................................................................................................................................................................................................................
A10: .................................................................................................................................................................................................................................................................................................................................................................................................................................
A11: .................................................................................................................................................................................................................................................................................................................................................................................................................................
A12: .................................................................................................................................................................................................................................................................................................................................................................................................................................
E14: ลงชื่อ | H14: (หัวหน้าฝ่าย/กลุ่มงาน/งาน)
F15: ลงวันที่ ส.ค. พ.ศ. 2568
A16: *** กรุณาส่งคืน ก.ยุทธศาสตร์และแผนงานโครงการ ภายในวันที่ 15 สิงหาคม 2568

Sheet 9.เครื่องแต่งกาย
A1: =+'8.โภชนาการ'!A1:I1 -> สรุปแผนการใช้เงินบำรุง หมวดค่าวัสดุ ปีงบประมาณ 2568 (ต.ค67- มิ.ย.68)
A2: =+'8.โภชนาการ'!A2:I2 -> และ
A3: =+'8.โภชนาการ'!A3:I3 -> คำขอตั้งปรับแผนเงินบำรุง หมวดค่าวัสดุ ประจำปีงบประมาณ 2569
B4: ประเภท เครื่องแต่งกาย (ซักฟอกและตัดเย็บ)
A5: ลำดับที่ | B5: =+'8.โภชนาการ'!B5:B6 -> แผน ปีงบฯ 2568 (บาท) | C5: =+'8.โภชนาการ'!C5:E5 -> ผลการดำเนินงาน ณ 30 มิ.ย. 2568 (บาท) | F5: =+'8.โภชนาการ'!F5:F6 -> ยอดเงิน คงเหลือ (บาท) | G5: =+'8.โภชนาการ'!G5:G6 -> วัสดุคงคลัง (บาท) | H5: =+'8.โภชนาการ'!H5:H6 -> คำขอตั้งแผน ปีงบฯ 2569 (บาท) | I5: =+'8.โภชนาการ'!I5:I6 -> หมายเหตุ
C6: =+'8.โภชนาการ'!C6 -> เบิกจ่ายแล้ว | D6: =+'8.โภชนาการ'!D6 -> เจ้าหนี้คงค้าง | E6: =+'8.โภชนาการ'!E6 -> ก่อหนี้/ยังไม่ตรวจรับ
A7: 35 | B7: 7000000 | C7: 3810600
A9: เหตุผลประกอบคำขอตั้ง (ถ้ามี)……………………………………………………………………………………………………………………………………………………………………………………………………………………………………………………………………..
A10: .................................................................................................................................................................................................................................................................................................................................................................................................................................
A11: .................................................................................................................................................................................................................................................................................................................................................................................................................................
A12: .................................................................................................................................................................................................................................................................................................................................................................................................................................
A13: .................................................................................................................................................................................................................................................................................................................................................................................................................................
E15: ลงชื่อ | H15: (หัวหน้าฝ่าย/กลุ่มงาน/งาน)
F16: ลงวันที่ ส.ค. พ.ศ. 2568
A17: *** กรุณาส่งคืน ก.ยุทธศาสตร์และแผนงานโครงการ ภายในวันที่ 15 สิงหาคม 2568

Sheet รวม
A1: สรุปแผนการใช้เงินบำรุง หมวดค่าวัสดุ ปีงบประมาณ 2568 (ต.ค67- มิ.ย.68) และ คำขอตั้งปรับแผนเงินเงินบำรุง หมวดค่าวัสดุ ประจำปีงบประมาณ 2569
A2: ลำดับที่ | B2: ประเภทหมวดวัสดุ | C2: ผลการดำเนินงาน ปีงบฯ 2565 | D2: แผน ปีงบฯ 2567 (บาท) | E2: เบิกจ่ายแล้ว (บาท) (1) | F2: เจ้าหนี้คงค้าง (บาท) (2) | G2: ก่อหนี้/ยังไม่ตรวจรับ (บาท) (3) | H2: รวมรายจ่าย (บาท) (1+2+3) | I2: ยอดเงิน คงเหลือ (บาท) | J2: วัสดุคงคลัง (บาท) | K2: คำขอตั้งแผน ปีงบฯ 2569 (บาท) | L2: หมายเหตุ
A3: 1 | B3: ยา+ยาเอกซเรย์ | C3: ='1.เวชภัณฑ์ ยา (2)'!#REF! -> #REF! | D3: =+'1.เวชภัณฑ์ ยา (2)'!B7 -> 500000000 | E3: =+'1.เวชภัณฑ์ ยา (2)'!C7 -> 3.8111785e+08 | F3: =+'1.เวชภัณฑ์ ยา (2)'!D7 -> 1.2563588e+08
A4: 2 | B4: เวชภัณฑ์การพยาบาล | C4: ='2.เวชภัณฑ์มิใช่ยา'!#REF! -> #REF! | D4: =+'2.เวชภัณฑ์มิใช่ยา'!B7 -> 47500000 | E4: 2.7699986e+08 | F4: 89542496
A5: 3 | B5: เฝือก | C5: ='2.เวชภัณฑ์มิใช่ยา'!#REF! -> #REF! | D5: =+'2.เวชภัณฑ์มิใช่ยา'!B26 -> 2000000
A6: 4 | B6: เวชศาสตร์ฟื้นฟู | C6: ='2.เวชภัณฑ์มิใช่ยา'!#REF! -> #REF! | D6: =+'2.เวชภัณฑ์มิใช่ยา'!B43 -> 2000000
A7: 5 | B7: ไตเทียม | C7: ='2.เวชภัณฑ์มิใช่ยา'!#REF! -> #REF! | D7: =+'2.เวชภัณฑ์มิใช่ยา'!B62 -> 6800000
A8: 6 | B8: โสต ศอ นาสิก ลาริงซ์ | C8: ='2.เวชภัณฑ์มิใช่ยา'!#REF! -> #REF! | D8: =+'2.เวชภัณฑ์มิใช่ยา'!B81 -> 1800000
A9: 7 | B9: จักษุ | C9: ='2.เวชภัณฑ์มิใช่ยา'!#REF! -> #REF! | D9: =+'2.เวชภัณฑ์มิใช่ยา'!B100 -> 5000000
A10: 8 | B10: ตรวจสวนหัวใจ | C10: ='2.เวชภัณฑ์มิใช่ยา'!#REF! -> #REF! | D10: =+'2.เวชภัณฑ์มิใช่ยา'!B120 -> 60000000
A11: 9 | B11: เวชภัณฑ์ทั่วไป | C11: ='2.เวชภัณฑ์มิใช่ยา'!#REF! -> #REF! | D11: =+'2.เวชภัณฑ์มิใช่ยา'!B138 -> 35000000
A12: 10 | B12: เวชภัณฑ์เภสัช | C12: ='2.เวชภัณฑ์มิใช่ยา'!#REF! -> #REF! | D12: =+'2.เวชภัณฑ์มิใช่ยา'!B157 -> 8000000 | E12: 24267019 | F12: =+'2.เวชภัณฑ์มิใช่ยา'!D157 -> 1185247.1
A13: 11 | B13: วิสัญญี | C13: ='2.เวชภัณฑ์มิใช่ยา'!#REF! -> #REF! | D13: =+'2.เวชภัณฑ์มิใช่ยา'!B176 -> 2750000
A14: 12 | B14: วัสดุการแพทย์ (ซ่อม) | C14: ='3.วัสดุการแพทย์'!#REF! -> #REF! | D14: =+'3.วัสดุการแพทย์'!B7 -> 25000000
A15: 13 | B15: การแพทย์ผ่าตัด | C15: ='3.วัสดุการแพทย์'!#REF! -> #REF! | D15: =+'3.วัสดุการแพทย์'!B26 -> 170000000
A16: 14 | B16: เอกซเรย์ (เวชภัณฑ์+intervention) | C16: ='3.วัสดุการแพทย์'!#REF! -> #REF! | D16: =+'3.วัสดุการแพทย์'!B44 -> 30000000 | F16: =+'3.วัสดุการแพทย์'!D44 -> 3680330.9
A17: 15 | B17: ทันตกรรม | C17: ='3.วัสดุการแพทย์'!#REF! -> #REF! | D17: =+'3.วัสดุการแพทย์'!B63 -> 13000000 | F17: =+'3.วัสดุการแพทย์'!D63 -> 2287465.2
A18: 16 | B18: ออกซิเจนเหลว | C18: ='4.วัสุดวิทยาศาสตร์'!#REF! -> #REF! | D18: =+'4.วัสุดวิทยาศาสตร์'!B7 -> 5000000 | E18: 88907703 | F18: 9523898.5
A19: 17 | B19: Lab (โควิด) | C19: ='4.วัสุดวิทยาศาสตร์'!#REF! -> #REF! | D19: =+'4.วัสุดวิทยาศาสตร์'!B26 -> 4000000
A20: 18 | B20: LAB (ทั่วไป) | C20: ='4.วัสุดวิทยาศาสตร์'!#REF! -> #REF! | D20: =+'4.วัสุดวิทยาศาสตร์'!B27 -> 72000000
A21: 19 | B21: ธนาคารเลือด | C21: ='4.วัสุดวิทยาศาสตร์'!#REF! -> #REF! | D21: =+'4.วัสุดวิทยาศาสตร์'!B46 -> 30000000
A22: 20 | B22: พยาธิกายวิภาค | C22: ='4.วัสุดวิทยาศาสตร์'!#REF! -> #REF! | D22: =+'4.วัสุดวิทยาศาสตร์'!B65 -> 3000000
A23: 21 | B23: ค่าวัสดุสำนักงาน | C23: ='5.วัสดุทั่วไป'!#REF! -> #REF! | D23: =+'5.วัสดุทั่วไป'!C7 -> 12000000 | E23: =+'5.วัสดุทั่วไป'!D7 -> 8017181.1 | F23: =+'5.วัสดุทั่วไป'!E7 -> 6388369.9
A24: 22 | B24: งานบ้าน+น้ำดื่ม | C24: ='5.วัสดุทั่วไป'!#REF! -> #REF! | D24: =+'5.วัสดุทั่วไป'!C8 -> 12000000 | E24: =+'5.วัสดุทั่วไป'!D8 -> 7904507.6 | F24: =+'5.วัสดุทั่วไป'!E8 -> 4829485
A25: 23 | B25: แบบพิมพ์ | C25: ='5.วัสดุทั่วไป'!#REF! -> #REF! | D25: =+'5.วัสดุทั่วไป'!C9 -> 1900000 | E25: =+'5.วัสดุทั่วไป'!D9 -> 1759287.8 | F25: =+'5.วัสดุทั่วไป'!E9 -> 0
A26: 24 | B26: อื่นๆ | C26: ='5.วัสดุทั่วไป'!#REF! -> #REF! | D26: =+'5.วัสดุทั่วไป'!C10 -> 100000 | E26: =+'5.วัสดุทั่วไป'!D10 -> 45595.45 | F26: =+'5.วัสดุทั่วไป'!E10 -> 0
A27: 25 | B27: วัสดุคอมพิวเตอร์ | C27: ='5.วัสดุทั่วไป'!#REF! -> #REF! | D27: =+'5.วัสดุทั่วไป'!C11 -> 4000000 | E27: =+'5.วัสดุทั่วไป'!D11 -> 360743 | F27: =+'5.วัสดุทั่วไป'!E11 -> 374580
A28: 26 | B28: วัสดุโฆษณาและเผยแพร่ | D28: =+'5.วัสดุทั่วไป'!C12 -> 120000 | E28: =+'5.วัสดุทั่วไป'!D12 -> 74343 | F28: =+'5.วัสดุทั่วไป'!E12 -> 148510
A29: 27 | B29: เชื้อเพลิงรถยนต์ | C29: ='6.เชื้อเพลิง'!#REF! -> #REF! | D29: =+'6.เชื้อเพลิง'!C7 -> 1000000 | E29: =+'6.เชื้อเพลิง'!D7 -> 6241096.1 | F29: =+'6.เชื้อเพลิง'!E7 -> 1220719.2
A30: 28 | B30: เชื้อเพลิงช่าง | C30: ='6.เชื้อเพลิง'!#REF! -> #REF! | D30: =+'6.เชื้อเพลิง'!C8 -> 270000
A31: 29 | B31: แก๊ส LPG | C31: ='6.เชื้อเพลิง'!#REF! -> #REF! | D31: =+'6.เชื้อเพลิง'!C9 -> 7000000
A32: 30 | B32: ออกซิเจนถัง | C32: ='6.เชื้อเพลิง'!#REF! -> #REF! | D32: =+'6.เชื้อเพลิง'!C10 -> 1000000
A33: 31 | B33: ค่าวัสดุไฟฟ้า | C33: ='7.ช่าง'!#REF! -> #REF! | D33: =+'7.ช่าง'!C7 -> 4500000 | E33: =+'7.ช่าง'!D7 -> 2368781.5 | F33: =+'7.ช่าง'!E7 -> 430588.11
A34: 32 | B34: ค่าวัสุดก่อสร้าง | C34: ='7.ช่าง'!#REF! -> #REF! | D34: =+'7.ช่าง'!C8 -> 5000000 | E34: =+'7.ช่าง'!D8 -> 2153418.9 | F34: =+'7.ช่าง'!E8 -> 508550.74
A35: 33 | B35: ยานพาหนะ | C35: ='7.ช่าง'!#REF! -> #REF! | D35: =+'7.ช่าง'!C9 -> 1000000 | E35: =+'7.ช่าง'!D9 -> 297003.6 | F35: =+'7.ช่าง'!E9 -> 30923
A36: 34 | B36: โภชนศาสตร์ | C36: ='8.โภชนาการ'!#REF! -> #REF! | D36: =+'8.โภชนาการ'!B7 -> 18000000 | E36: =+'8.โภชนาการ'!C7 -> 15380356 | F36: =+'8.โภชนาการ'!D7 -> 1420644.9
A37: 35 | B37: เครื่องแต่งกาย (ซักฟอกและตัดเย็บ) | C37: ='9.เครื่องแต่งกาย'!#REF! -> #REF! | D37: =+'9.เครื่องแต่งกาย'!B7 -> 7000000 | E37: =+'9.เครื่องแต่งกาย'!C7 -> 3810600 | F37: =+'9.เครื่องแต่งกาย'!D7 -> 0
D38: =SUM(D3:D37) -> 1097740000 | E38: =SUM(E3:E37) -> 8.1970535e+08 | F38: =SUM(F3:F37) -> 2.4720768e+08 | G38: =SUM(G3:G37) -> 0 | H38: =SUM(H3:H37) -> 0 | I38: =SUM(I3:I37) -> 0 | J38: =SUM(J3:J37) -> 0 | K38: =SUM(K3:K37) -> 0
