Workbook

Sheet 1-30 มิย.63-เงินสด
A1: รายงานสรุปค่ารักษาพยาบาลประจำวัน
A2: ประจำเดือน สิงหาคม 2563
A3: รายการ / วันที่ | C3: 1 พค.63 | E3: 2 พค.63 | G3: 3 พค.63 | I3: 4 พค.63 | K3: 5 พค.63 | M3: 6 พค.63 | O3: 7 พค.63 | Q3: 8 พค.63 | S3: 9 พค.63 | U3: 10 พค.63 | W3: 11 พค.63 | Y3: 12 พค.63 | AA3: 13 พค.63 | AC3: 14 พค.63 | AE3: 15 พค.63 | AG3: 16 พค.63 | AI3: 17 พค.63 | AK3: 18 พค.63 | AM3: 19 พค.63 | AO3: 20 พค.63 | AQ3: 21 พค.63 | AS3: 22 พค.63 | AU3: 23 พค.63 | AW3: 24 พค.63 | AY3: 25 พค.63 | BA3: 26 พค.63 | BC3: 27 พค.63 | BE3: 28 พค.63 | BG3: 29 พค.63 | BI3: 30 พค.63 | BK3: 31 พค.63 | BM3: รวม | BO3: 1-30 Report | BQ3: ผลต่าง
A4: ลำดับ | B4: สิทธิการรักษา | C4: ราย | D4: จำนวนเงิน | E4: ราย | F4: จำนวนเงิน | G4: ราย | H4: จำนวนเงิน | I4: ราย | J4: จำนวนเงิน | K4: ราย | L4: จำนวนเงิน | M4: ราย | N4: จำนวนเงิน | O4: ราย | P4: จำนวนเงิน | Q4: ราย | R4: จำนวนเงิน | S4: ราย | T4: จำนวนเงิน | U4: ราย | V4: จำนวนเงิน | W4: ราย | X4: จำนวนเงิน | Y4: ราย | Z4: จำนวนเงิน | AA4: ราย | AB4: จำนวนเงิน | AC4: ราย | AD4: จำนวนเงิน | AE4: ราย | AF4: จำนวนเงิน | AG4: ราย | AH4: จำนวนเงิน | AI4: ราย | AJ4: จำนวนเงิน | AK4: ราย | AL4: จำนวนเงิน | AM4: ราย | AN4: จำนวนเงิน | AO4: ราย | AP4: จำนวนเงิน | AQ4: ราย | AR4: จำนวนเงิน | AS4: ราย | AT4: จำนวนเงิน | AU4: ราย | AV4: จำนวนเงิน | AW4: ราย | AX4: จำนวนเงิน | AY4: ราย | AZ4: จำนวนเงิน | BA4: ราย | BB4: จำนวนเงิน | BC4: ราย | BD4: จำนวนเงิน | BE4: ราย | BF4: จำนวนเงิน | BG4: ราย | BH4: จำนวนเงิน | BI4: ราย | BJ4: จำนวนเงิน | BK4: ราย | BL4: จำนวนเงิน | BM4: ราย | BN4: จำนวนเงิน | BO4: ราย | BP4: จำนวนเงิน | BQ4: ราย | BR4: จำนวนเงิน
A5: 1 | B5: ชำระเงินสด (OPD) | C5: =+'01'!C4 -> 0 | D5: =+'01'!D4 -> 0 | E5: =+'02'!C4 -> 0 | F5: =+'02'!D4 -> 0 | G5: =+'03'!C4 -> 0 | H5: =+'03'!D4 -> 0 | I5: =+'04'!C4 -> 0 | J5: =+'04'!D4 -> 0 | K5: =+'05'!C4 -> 0 | L5: =+'05'!D4 -> 0 | M5: =+'06'!C4 -> 0 | N5: =+'06'!D4 -> 0 | O5: =+'07'!C4 -> 0 | P5: =+'07'!D4 -> 0 | Q5: =+'08'!C4 -> 0 | R5: =+'08'!D4 -> 0 | S5: =+'09'!C4 -> 0 | T5: =+'09'!D4 -> 0 | U5: =+'10'!C4 -> 0 | V5: =+'10'!D4 -> 0 | W5: =+'11'!C4 -> 0 | X5: =+'11'!D4 -> 0 | Y5: =+'12'!C4 -> 0 | Z5: =+'12'!D4 -> 0 | AA5: =+'13'!C4 -> 0 | AB5: =+'13'!D4 -> 0 | AC5: =+'14'!C4 -> 0 | AD5: =+'14'!D4 -> 0 | AE5: =+'15'!C4 -> 0 | AF5: =+'15'!D4 -> 0 | AG5: =+'16'!C4 -> 0 | AH5: =+'16'!D4 -> 0 | AI5: =+'17'!C4 -> 0 | AJ5: =+'17'!D4 -> 0 | AK5: =+'18'!C4 -> 0 | AL5: =+'18'!D4 -> 0 | AM5: =+'19'!C4 -> 0 | AN5: =+'19'!D4 -> 0 | AO5: =+'20'!C4 -> 0 | AP5: =+'20'!D4 -> 0 | AQ5: =+'21'!C4 -> 0 | AR5: =+'21'!D4 -> 0 | AS5: =+'22'!C4 -> 0 | AT5: =+'22'!D4 -> 0 | AU5: =+'23'!C4 -> 0 | AV5: =+'23'!D4 -> 0 | AW5: =+'24'!C4 -> 0 | AX5: =+'24'!D4 -> 0 | AY5: =+'25'!C4 -> 0 | AZ5: =+'25'!D4 -> 0 | BA5: =+'26'!C4 -> 0 | BB5: =+'26'!D4 -> 0 | BC5: =+'27'!C4 -> 0 | BD5: =+'27'!D4 -> 0 | BE5: =+'28'!C4 -> 0 | BF5: =+'28'!D4 -> 0 | BG5: =+'29'!C4 -> 0 | BH5: =+'29'!D4 -> 0 | BI5: =+'30'!C4 -> 0 | BJ5: =+'30'!D4 -> 0 | BK5: =+'31'!C4 -> 0 | BL5: =+'31'!D4 -> 0 | BM5: =+C5+E5+G5+I5+K5+M5+O5+Q5+S5+U5+W5+Y5+AA5+AC5+AE5+AG5+AI5+AK5+AM5+AO5+AQ5+AS5+AU5+AW5+AY5+BA5+BC5+BE5+BG5+BI5+BK5 -> 0 | BN5: =+D5+F5+H5+J5+L5+N5+P5+R5+T5+V5+X5+Z5+AB5+AD5+AF5+AH5+AJ5+AL5+AN5+AP5+AR5+AT5+AV5+AX5+AZ5+BB5+BD5+BF5+BH5+BJ5+BL5 -> 0 | BO5: 11321 | BP5: 5259401.1 | BQ5: =+BM5-BO5 -> -11321 | BR5: =+BN5-BP5 -> -5259401.1
A6: 2 | B6: ชำระเงินสด (IPD) | C6: =+'01'!C5 -> 0 | D6: =+'01'!D5 -> 0 | E6: =+'02'!C5 -> 0 | F6: =+'02'!D5 -> 0 | G6: =+'03'!C5 -> 0 | H6: =+'03'!D5 -> 0 | I6: =+'04'!C5 -> 0 | J6: =+'04'!D5 -> 0 | K6: =+'05'!C5 -> 0 | L6: =+'05'!D5 -> 0 | M6: =+'06'!C5 -> 0 | N6: =+'06'!D5 -> 0 | O6: =+'07'!C5 -> 0 | P6: =+'07'!D5 -> 0 | Q6: =+'08'!C5 -> 0 | R6: =+'08'!D5 -> 0 | S6: =+'09'!C5 -> 0 | T6: =+'09'!D5 -> 0 | U6: =+'10'!C5 -> 0 | V6: =+'10'!D5 -> 0 | W6: =+'11'!C5 -> 0 | X6: =+'11'!D5 -> 0 | Y6: =+'12'!C5 -> 0 | Z6: =+'12'!D5 -> 0 | AA6: =+'13'!C5 -> 0 | AB6: =+'13'!D5 -> 0 | AC6: =+'14'!C5 -> 0 | AD6: =+'14'!D5 -> 0 | AE6: =+'15'!C5 -> 0 | AF6: =+'15'!D5 -> 0 | AG6: =+'16'!C5 -> 0 | AH6: =+'16'!D5 -> 0 | AI6: =+'17'!C5 -> 0 | AJ6: =+'17'!D5 -> 0 | AK6: =+'18'!C5 -> 0 | AL6: =+'18'!D5 -> 0 | AM6: =+'19'!C5 -> 0 | AN6: =+'19'!D5 -> 0 | AO6: =+'20'!C5 -> 0 | AP6: =+'20'!D5 -> 0 | AQ6: =+'21'!C5 -> 0 | AR6: =+'21'!D5 -> 0 | AS6: =+'22'!C5 -> 0 | AT6: =+'22'!D5 -> 0 | AU6: =+'23'!C5 -> 0 | AV6: =+'23'!D5 -> 0 | AW6: =+'24'!C5 -> 0 | AX6: =+'24'!D5 -> 0 | AY6: =+'25'!C5 -> 0 | AZ6: =+'25'!D5 -> 0 | BA6: =+'26'!C5 -> 0 | BB6: =+'26'!D5 -> 0 | BC6: =+'27'!C5 -> 0 | BD6: =+'27'!D5 -> 0 | BE6: =+'28'!C5 -> 0 | BF6: =+'28'!D5 -> 0 | BG6: =+'29'!C5 -> 0 | BH6: =+'29'!D5 -> 0 | BI6: =+'30'!C5 -> 0 | BJ6: =+'30'!D5 -> 0 | BK6: =+'31'!C5 -> 0 | BL6: =+'31'!D5 -> 0 | BM6: =+C6+E6+G6+I6+K6+M6+O6+Q6+S6+U6+W6+Y6+AA6+AC6+AE6+AG6+AI6+AK6+AM6+AO6+AQ6+AS6+AU6+AW6+AY6+BA6+BC6+BE6+BG6+BI6+BK6 -> 0 | BN6: =+D6+F6+H6+J6+L6+N6+P6+R6+T6+V6+X6+Z6+AB6+AD6+AF6+AH6+AJ6+AL6+AN6+AP6+AR6+AT6+AV6+AX6+AZ6+BB6+BD6+BF6+BH6+BJ6+BL6 -> 0 | BO6: 2255 | BP6: 8615754.8 | BQ6: =+BM6-BO6 -> -2255 | BR6: =+BN6-BP6 -> -8615754.8
B7: รวมเงิน | C7: =SUM(C5:C6) -> 0 | D7: =SUM(D5:D6) -> 0 | E7: =SUM(E5:E6) -> 0 | F7: =SUM(F5:F6) -> 0 | G7: =SUM(G5:G6) -> 0 | H7: =SUM(H5:H6) -> 0 | I7: =SUM(I5:I6) -> 0 | J7: =SUM(J5:J6) -> 0 | ... BQ7: =SUM(BQ5:BQ6) -> -13576 | BR7: =+BN7-BP7 -> -13875156
BP9: *** ผลต่างจุดทศนิยมจากโปรแกรมทศนิยม 3 ตำแหน่ง

Sheet 1-12 กค.63-ส้ม-
A1: รายงานสรุปค่ารักษาพยาบาลประจำวัน
A2: ประจำเดือน สิงหาคม 2563
A3: รายการ / วันที่ | C3: 1 มค.64 | D3: 2 มค.64 | E3: 3 มค.64 | F3: 4 มค.64 | G3: 5 มค.64 | H3: 6 มค.64 | I3: 7 มค.64 | J3: 8 มค.64 | K3: 9 มค.64 | L3: 10 มค.64 | M3: 11 มค.64 | N3: 12 มค.64 | O3: 13 มค.64 | P3: 14 มค.64 | Q3: 15 มค.64 | R3: 16 มค.64 | S3: 17 มค.64 | T3: 18 มค.64 | U3: 19 มค.64 | V3: 20 มค.64 | W3: 21 มค.64 | X3: 22 มค.64 | Y3: 23 มค.64 | Z3: 24 มค.64 | AA3: 25 มค.64 | AB3: 26 มค.64 | AC3: 27 มค.64 | AD3: 28 มค.64 | AE3: 29 มค.64 | AF3: 30 มค.64 | AG3: 31 มค.64 | AH3: รวม
A4: ลำดับ | B4: สิทธิการรักษา | C4: จำนวนเงิน | D4: จำนวนเงิน | E4: จำนวนเงิน | F4: จำนวนเงิน | G4: จำนวนเงิน | H4: จำนวนเงิน | I4: จำนวนเงิน | J4: จำนวนเงิน | K4: จำนวนเงิน | L4: จำนวนเงิน | M4: จำนวนเงิน | N4: จำนวนเงิน | O4: จำนวนเงิน | P4: จำนวนเงิน | Q4: จำนวนเงิน | R4: จำนวนเงิน | S4: จำนวนเงิน | T4: จำนวนเงิน | U4: จำนวนเงิน | V4: จำนวนเงิน | W4: จำนวนเงิน | X4: จำนวนเงิน | Y4: จำนวนเงิน | Z4: จำนวนเงิน | AA4: จำนวนเงิน | AB4: จำนวนเงิน | AC4: จำนวนเงิน | AD4: จำนวนเงิน | AE4: จำนวนเงิน | AF4: จำนวนเงิน | AG4: จำนวนเงิน | AH4: จำนวนเงิน
A5: 1 | B5: ชำระเงินสด (OPD) >>ไม่ลงบ/ช.<< | C5: =+'01'!D4 -> 0 | D5: =+'02'!D4 -> 0 | E5: =+'03'!D4 -> 0 | F5: =+'04'!D4 -> 0 | G5: =+'05'!D4 -> 0 | H5: =+'06'!D4 -> 0 | I5: =+'06'!D4 -> 0 | J5: =+'08'!D4 -> 0 | K5: =+'09'!D4 -> 0 | L5: =+'10'!D4 -> 0 | M5: =+'11'!D4 -> 0 | N5: =+'12'!D4 -> 0 | AH5: =+C5+D5+E5+F5+G5+H5+I5+J5+K5+L5+M5+N5+O5+P5+Q5+R5+S5+T5+U5+V5+W5+X5+Y5+Z5+AA5+AB5+AC5+AD5+AE5+AF5+AG5 -> 0
A6: 2 | B6: ชำระเงินสด (IPD) >>ไม่ลงบ/ช.<< | C6: =+'01'!D5 -> 0 | D6: =+'02'!D5 -> 0 | E6: =+'03'!D5 -> 0 | F6: =+'04'!D5 -> 0 | G6: =+'05'!D5 -> 0 | H6: =+'06'!D5 -> 0 | I6: =+'06'!D5 -> 0 | J6: =+'08'!D5 -> 0 | K6: =+'09'!D5 -> 0 | L6: =+'10'!D5 -> 0 | M6: =+'11'!D5 -> 0 | N6: =+'12'!D5 -> 0 | AH6: =+C6+D6+E6+F6+G6+H6+I6+J6+K6+L6+M6+N6+O6+P6+Q6+R6+S6+T6+U6+V6+W6+X6+Y6+Z6+AA6+AB6+AC6+AD6+AE6+AF6+AG6 -> 0
A7: 3 | B7: เบิกกรมบัญชีกลาง (OPD) ((1.3)) | C7: =+'01'!D6 -> 1196065.4 | D7: =+'02'!D6 -> 991915.36 | E7: =+'03'!D6 -> 1013029.4 | F7: =+'04'!D6 -> 1091659.6 | G7: =+'05'!D6 -> 201880 | H7: =+'06'!D6 -> 258386.09 | I7: =+'07'!D6 -> 1297943.5 | J7: =+'08'!D6 -> 996194.45 | K7: =+'09'!D6 -> 1017542.3 | L7: =+'10'!D6 -> 1108876.4 | M7: =+'11'!D6 -> 986978.24 | N7: =+'12'!D6 -> 110870.75 | AH7: =+C7+D7+E7+F7+G7+H7+I7+J7+K7+L7+M7+N7+O7+P7+Q7+R7+S7+T7+U7+V7+W7+X7+Y7+Z7+AA7+AB7+AC7+AD7+AE7+AF7+AG7 -> 10271341 | AK7: =+AH7-AJ7 -> 10271341
B8: เบิกกรมบัญชีกลาง (OPD) ไตเทียม ((1.4)) | C8: =+'01'!D8 -> 0 | D8: =+'02'!D8 -> 0 | E8: =+'03'!D8 -> 0 | F8: =+'04'!D8 -> 0 | G8: =+'05'!D8 -> 0 | H8: =+'06'!D8 -> 0 | I8: =+'07'!D8 -> 0 | J8: =+'08'!D8 -> 0 | K8: =+'09'!D8 -> 0 | L8: =+'10'!D8 -> 0 | M8: =+'11'!D8 -> 0 | N8: =+'12'!D8 -> 0 | AH8: =+C8+D8+E8+F8+G8+H8+I8+J8+K8+L8+M8+N8+O8+P8+Q8+R8+S8+T8+U8+V8+W8+X8+Y8+Z8+AA8+AB8+AC8+AD8+AE8+AF8+AG8 -> 0 | AK8: =+AH8-AJ8 -> 0
A9: 4 | B9: เบิกกรมบัญชีกลาง (IPD) ((1.5)) | C9: =+'01'!D9 -> 14625.57 | D9: =+'02'!D9 -> 10241.75 | E9: =+'03'!D9 -> 1002440.3 | F9: =+'04'!D9 -> 301960.54 | G9: =+'05'!D9 -> 2011182.8 | H9: =+'06'!D9 -> 119707.28 | I9: =+'07'!D9 -> 395076.87 | J9: =+'08'!D9 -> 39275.5 | K9: =+'09'!D9 -> 606366.98 | L9: =+'10'!D9 -> 520167.66 | M9: =+'11'!D9 -> 511836.05 | N9: =+'12'!D9 -> 97675.5 | AH9: =+C9+D9+E9+F9+G9+H9+I9+J9+K9+L9+M9+N9+O9+P9+Q9+R9+S9+T9+U9+V9+W9+X9+Y9+Z9+AA9+AB9+AC9+AD9+AE9+AF9+AG9 -> 5630556.8 | AK9: =+AH9-AJ9 -> 5630556.8
B10: เบิกกรมบัญชีกลาง (IPD) ไตเทียม ((1.1)) | C10: =+'01'!D11 -> 0 | D10: =+'02'!D11 -> 0 | E10: =+'03'!D11 -> 0 | F10: =+'04'!D11 -> 0 | G10: =+'05'!D11 -> 0 | H10: =+'06'!D11 -> 0 | I10: =+'07'!D11 -> 0 | J10: =+'08'!D11 -> 0 | K10: =+'09'!D11 -> 0 | L10: =+'10'!D11 -> 0 | M10: =+'11'!D11 -> 0 | N10: =+'12'!D11 -> 0 | AH10: =+C10+D10+E10+F10+G10+H10+I10+J10+K10+L10+M10+N10+O10+P10+Q10+R10+S10+T10+U10+V10+W10+X10+Y10+Z10+AA10+AB10+AC10+AD10+AE10+AF10+AG10 -> 0 | AK10: =+AH10-AJ10 -> 0
A11: 5 | B11: องค์กรปกครองส่วนท้องถิ่น (OPD) ((3.6)) | C11: =+'01'!D12 -> 250757 | D11: =+'02'!D12 -> 204218.5 | E11: =+'03'!D12 -> 99684.5 | F11: =+'04'!D12 -> 173171.75 | G11: =+'05'!D12 -> 8111.5 | H11: =+'06'!D12 -> 2595 | I11: =+'07'!D12 -> 194220.5 | J11: =+'08'!D12 -> 148808.5 | K11: =+'09'!D12 -> 221222.5 | L11: =+'10'!D12 -> 98994.25 | M11: =+'11'!D12 -> 101994.75 | N11: =+'12'!D12 -> 11465.25 | AH11: =+C11+D11+E11+F11+G11+H11+I11+J11+K11+L11+M11+N11+O11+P11+Q11+R11+S11+T11+U11+V11+W11+X11+Y11+Z11+AA11+AB11+AC11+AD11+AE11+AF11+AG11 -> 1515244 | AK11: =+AH11-AJ11 -> 1515244
B12: องค์กรปกครองส่วนท้องถิ่น (OPD) ไตเทียม ((3.6)) | C12: =+'01'!D13 -> 0 | D12: =+'02'!D13 -> 0 | E12: =+'03'!D13 -> 0 | F12: =+'04'!D13 -> 0 | G12: =+'05'!D13 -> 0 | H12: =+'06'!D13 -> 0 | I12: =+'07'!D13 -> 0 | J12: =+'08'!D13 -> 0 | K12: =+'09'!D13 -> 0 | L12: =+'10'!D13 -> 0 | M12: =+'11'!D13 -> 0 | N12: =+'12'!D13 -> 0 | AH12: =+C12+D12+E12+F12+G12+H12+I12+J12+K12+L12+M12+N12+O12+P12+Q12+R12+S12+T12+U12+V12+W12+X12+Y12+Z12+AA12+AB12+AC12+AD12+AE12+AF12+AG12 -> 0 | AK12: =+AH12-AJ12 -> 0
A13: 6 | B13: องค์กรปกครองส่วนท้องถิ่น (IPD) ((3.5)) | C13: =+'01'!D14 -> 0 | D13: =+'02'!D14 -> 0 | E13: =+'03'!D14 -> 251744.69 | F13: =+'04'!D14 -> 28292.75 | G13: =+'05'!D14 -> 97963 | H13: =+'06'!D14 -> 18868.54 | I13: =+'07'!D14 -> 19090 | J13: =+'08'!D14 -> 0 | K13: =+'09'!D14 -> 29935.54 | L13: =+'10'!D14 -> 27436.75 | M13: =+'11'!D14 -> 27597.75 | N13: =+'12'!D14 -> 18074.75 | AH13: =+C13+D13+E13+F13+G13+H13+I13+J13+K13+L13+M13+N13+O13+P13+Q13+R13+S13+T13+U13+V13+W13+X13+Y13+Z13+AA13+AB13+AC13+AD13+AE13+AF13+AG13 -> 519003.77 | AK13: =+AH13-AJ13 -> 519003.77
B14: องค์กรปกครองส่วนท้องถิ่น (IPD) ไตเทียม ((3.5)) | C14: =+'01'!D15 -> 0 | D14: =+'02'!D15 -> 0 | E14: =+'03'!D15 -> 0 | F14: =+'04'!D15 -> 0 | G14: =+'05'!D15 -> 0 | H14: =+'06'!D15 -> 0 | I14: =+'07'!D15 -> 0 | J14: =+'08'!D15 -> 0 | K14: =+'09'!D15 -> 0 | L14: =+'10'!D15 -> 12192 | M14: =+'11'!#REF! -> #REF! | N14: =+'12'!D15 -> 0 | AH14: =+C14+D14+E14+F14+G14+H14+I14+J14+K14+L14+M14+N14+O14+P14+Q14+R14+S14+T14+U14+V14+W14+X14+Y14+Z14+AA14+AB14+AC14+AD14+AE14+AF14+AG14 -> #REF! | AK14: =+AH14-AJ14 -> #REF!
A15: 7 | B15: สิทธิ พรบ. เรียกเก็บ OPD ((2.2)) | C15: =+'01'!D16 -> 7239 | D15: =+'02'!D16 -> 30121 | E15: =+'03'!D16 -> 58020 | F15: =+'04'!D16 -> 19277.5 | G15: =+'05'!D16 -> 23759.75 | H15: =+'06'!D16 -> 10755 | I15: =+'07'!D16 -> 20087 | J15: =+'08'!D16 -> 24517.75 | K15: =+'09'!D16 -> 24679.25 | L15: =+'10'!D16 -> 12590.25 | M15: =+'11'!D16 -> 31367.5 | N15: =+'12'!D16 -> 33764.2 | AH15: =+C15+D15+E15+F15+G15+H15+I15+J15+K15+L15+M15+N15+O15+P15+Q15+R15+S15+T15+U15+V15+W15+X15+Y15+Z15+AA15+AB15+AC15+AD15+AE15+AF15+AG15 -> 296178.2 | AK15: =+AH15-AJ15 -> 296178.2
B16: สิทธิ พรบ. เรียกเก็บ IPD ((2.1)) | C16: =+'01'!D17 -> 127214 | D16: =+'02'!D17 -> 11539 | E16: =+'03'!D17 -> 154651.5 | F16: =+'04'!D17 -> 205807.5 | G16: =+'05'!D17 -> 50020.05 | H16: =+'06'!D17 -> 61025.29 | I16: =+'07'!D17 -> 36617.5 | J16: =+'08'!D17 -> 110000 | K16: =+'09'!D17 -> 118398.25 | L16: =+'10'!D17 -> 68207 | M16: =+'11'!D17 -> 52150 | N16: =+'12'!D17 -> 18635 | AH16: =+C16+D16+E16+F16+G16+H16+I16+J16+K16+L16+M16+N16+O16+P16+Q16+R16+S16+T16+U16+V16+W16+X16+Y16+Z16+AA16+AB16+AC16+AD16+AE16+AF16+AG16 -> 1014265.1 | AK16: =+AH16-AJ16 -> 1014265.1
A17: 8 | B17: สิทธิ ประกันชีวิต/ต่างประเทศ OPD ((3.2 OPD)) | C17: =+'01'!D18 -> 25213.75 | D17: =+'02'!D18 -> 27194.5 | E17: =+'03'!D18 -> 14609.61 | F17: =+'04'!D18 -> 5605.25 | G17: =+'05'!D18 -> 236441.6 | H17: =+'06'!D18 -> 99126.25 | I17: =+'07'!D18 -> 0 | J17: =+'08'!D18 -> 115636.25 | K17: =+'09'!D18 -> 1111 | L17: =+'10'!D18 -> 2200 | M17: =+'11'!D18 -> 15872.46 | N17: =+'12'!D18 -> 6342 | AH17: =+C17+D17+E17+F17+G17+H17+I17+J17+K17+L17+M17+N17+O17+P17+Q17+R17+S17+T17+U17+V17+W17+X17+Y17+Z17+AA17+AB17+AC17+AD17+AE17+AF17+AG17 -> 549352.67 | AK17: =+AH17-AJ17 -> 549352.67
B18: สิทธิ ประกันชีวิต/ต่างประเทศ IPD ((3.1 IPD)) | C18: =+'01'!D19 -> 125498.75 | D18: =+'02'!D19 -> 132334.75 | E18: =+'03'!D19 -> 192659.1 | F18: =+'04'!D19 -> 194130.65 | G18: =+'05'!D19 -> 89096 | H18: =+'06'!D19 -> 0 | I18: =+'07'!D19 -> 3809.75 | J18: =+'08'!D19 -> 1427767.2 | K18: =+'09'!D19 -> 128417.54 | L18: =+'10'!D19 -> 35649.25 | M18: =+'11'!D19 -> 263533.25 | N18: =+'12'!D19 -> 58909.97 | AH18: =+C18+D18+E18+F18+G18+H18+I18+J18+K18+L18+M18+N18+O18+P18+Q18+R18+S18+T18+U18+V18+W18+X18+Y18+Z18+AA18+AB18+AC18+AD18+AE18+AF18+AG18 -> 2651806.2 | AK18: =+AH18-AJ18 -> 2651806.2
A19: 9 | B19: เบิกต้นสังกัด/บริษัทห้างร้าน OPD ((3.4)) | C19: =+'01'!D20 -> 0 | D19: =+'02'!D20 -> 0 | E19: =+'03'!D20 -> 0 | F19: =+'04'!D20 -> 0 | G19: =+'05'!D20 -> 0 | H19: =+'06'!D20 -> 0 | I19: =+'07'!D20 -> 180409.49 | J19: =+'08'!D20 -> 168326.84 | K19: =+'09'!D20 -> 41760 | L19: =+'10'!D20 -> 0 | M19: =+'11'!D20 -> 0 | N19: =+'12'!D20 -> 0 | AH19: =+C19+D19+E19+F19+G19+H19+I19+J19+K19+L19+M19+N19+O19+P19+Q19+R19+S19+T19+U19+V19+W19+X19+Y19+Z19+AA19+AB19+AC19+AD19+AE19+AF19+AG19 -> 390496.33 | AK19: =+AH19-AJ19 -> 390496.33
B20: เบิกต้นสังกัด/บริษัทห้างร้าน IPD ((3.3)) | C20: =+'01'!D21 -> 0 | D20: =+'02'!D21 -> 0 | E20: =+'03'!D21 -> 0 | F20: =+'04'!D21 -> 0 | G20: =+'05'!D21 -> 0 | H20: =+'06'!D21 -> 0 | I20: =+'07'!D21 -> 0 | J20: =+'08'!D21 -> 366945.81 | K20: =+'09'!D21 -> 0 | L20: =+'10'!D21 -> 0 | M20: =+'11'!D21 -> 0 | N20: =+'12'!D21 -> 0 | AH20: =+C20+D20+E20+F20+G20+H20+I20+J20+K20+L20+M20+N20+O20+P20+Q20+R20+S20+T20+U20+V20+W20+X20+Y20+Z20+AA20+AB20+AC20+AD20+AE20+AF20+AG20 -> 366945.81 | AK20: =+AH20-AJ20 -> 366945.81
A21: 10 | B21: ปกส.-OP เครือข่าย ((9.6)) | C21: =+'01'!D22 -> 1660407.5 | D21: =+'02'!D22 -> 938187.56 | E21: =+'03'!D22 -> 865509.33 | F21: =+'04'!D22 -> 774877.8 | G21: =+'05'!D22 -> 226607 | H21: =+'06'!D22 -> 133636.25 | I21: =+'07'!D22 -> 978100.91 | J21: =+'08'!D22 -> 838568.94 | K21: =+'09'!D22 -> 983400.33 | L21: =+'10'!D22 -> 936833.08 | M21: =+'11'!D22 -> 730131.14 | N21: =+'12'!D22 -> 80634.75 | AH21: =+C21+D21+E21+F21+G21+H21+I21+J21+K21+L21+M21+N21+O21+P21+Q21+R21+S21+T21+U21+V21+W21+X21+Y21+Z21+AA21+AB21+AC21+AD21+AE21+AF21+AG21 -> 9146894.6 | AK21: =+AH21-AJ21 -> 9146894.6
B22: ปกส.-OP ต่างเครือข่าย | C22: =+'01'!D23 -> 6699.49 | D22: =+'02'!D23 -> 10215.86 | E22: =+'03'!D23 -> 12373.25 | F22: =+'04'!D23 -> 17662.25 | G22: =+'05'!D23 -> 0 | H22: =+'06'!D23 -> 0 | I22: =+'07'!D23 -> 13612.5 | J22: =+'08'!D23 -> 61550.25 | K22: =+'09'!D23 -> 31911.1 | L22: =+'10'!D23 -> 6565 | M22: =+'11'!D23 -> 15900.5 | N22: =+'12'!D23 -> 8150 | AH22: =+C22+D22+E22+F22+G22+H22+I22+J22+K22+L22+M22+N22+O22+P22+Q22+R22+S22+T22+U22+V22+W22+X22+Y22+Z22+AA22+AB22+AC22+AD22+AE22+AF22+AG22 -> 184640.2 | AK22: =+AH22-AJ22 -> 184640.2
B23: ปกส.-72 ชม. ((9.1))((1102050194.306)) | C23: =+'01'!D24 -> 0 | D23: =+'02'!D24 -> 0 | E23: =+'03'!D24 -> 0 | F23: =+'04'!D24 -> 0 | G23: =+'05'!D24 -> 0 | H23: =+'06'!D24 -> 0 | I23: =+'07'!D24 -> 0 | J23: =+'08'!D24 -> 0 | K23: =+'09'!D24 -> 0 | L23: =+'10'!D24 -> 0 | M23: =+'11'!D24 -> 0 | N23: =+'12'!D24 -> 0 | AH23: =+C23+D23+E23+F23+G23+H23+I23+J23+K23+L23+M23+N23+O23+P23+Q23+R23+S23+T23+U23+V23+W23+X23+Y23+Z23+AA23+AB23+AC23+AD23+AE23+AF23+AG23 -> 0 | AK23: =+AH23-AJ23 -> 0
B24: ปกส.-OP ทุพพลภาพ | C24: =+'01'!D25 -> 0 | D24: =+'02'!D25 -> 0 | E24: =+'03'!D25 -> 0 | F24: =+'04'!D25 -> 0 | G24: =+'05'!D25 -> 0 | H24: =+'06'!D25 -> 0 | I24: =+'07'!D25 -> 0 | J24: =+'08'!D25 -> 0 | K24: =+'09'!D25 -> 0 | L24: =+'10'!D25 -> 0 | M24: =+'11'!D25 -> 0 | N24: =+'12'!D25 -> 0 | AH24: =+C24+D24+E24+F24+G24+H24+I24+J24+K24+L24+M24+N24+O24+P24+Q24+R24+S24+T24+U24+V24+W24+X24+Y24+Z24+AA24+AB24+AC24+AD24+AE24+AF24+AG24 -> 0 | AK24: =+AH24-AJ24 -> 0
B25: ปกส.-OP คชจ.สูง ((9.1))((1102050194.307)) | C25: =+'01'!D26 -> 9047.5 | D25: =+'02'!D26 -> 7115.5 | E25: =+'03'!D26 -> 2410 | F25: =+'04'!D26 -> 14704.75 | G25: =+'05'!D26 -> 0 | H25: =+'06'!D26 -> 0 | I25: =+'07'!D26 -> 0 | J25: =+'08'!D26 -> 5847.5 | K25: =+'09'!D26 -> 18964 | L25: =+'10'!D26 -> 6296 | M25: =+'11'!D26 -> 3360 | N25: =+'12'!D26 -> 0 | AH25: =+C25+D25+E25+F25+G25+H25+I25+J25+K25+L25+M25+N25+O25+P25+Q25+R25+S25+T25+U25+V25+W25+X25+Y25+Z25+AA25+AB25+AC25+AD25+AE25+AF25+AG25 -> 67745.25 | AK25: =+AH25-AJ25 -> 67745.25
B26: ปกส.-กองทุนทดแทน ((9.1))((1102050194.305)) | C26: =+'01'!D27 -> 4980.5 | D26: =+'02'!D27 -> 664 | E26: =+'03'!D27 -> 2192.5 | F26: =+'04'!D27 -> 1899.25 | G26: =+'05'!D27 -> 0 | H26: =+'06'!D27 -> 0 | I26: =+'07'!D27 -> 1726.5 | J26: =+'08'!D27 -> 1560 | K26: =+'09'!D27 -> 706.5 | L26: =+'10'!D27 -> 944.5 | M26: =+'11'!D27 -> 6848.25 | N26: =+'12'!D27 -> 510 | AH26: =+C26+D26+E26+F26+G26+H26+I26+J26+K26+L26+M26+N26+O26+P26+Q26+R26+S26+T26+U26+V26+W26+X26+Y26+Z26+AA26+AB26+AC26+AD26+AE26+AF26+AG26 -> 22032 | AK26: =+AH26-AJ26 -> 22032
A27: 11 | B27: UC OP ใน CUP ((10.5)) | C27: =+'01'!D33 -> 1222242.4 | D27: =+'02'!D33 -> 1266343.8 | E27: =+'03'!D33 -> 1167566.6 | F27: =+'04'!D33 -> 1112166.1 | G27: =+'05'!D33 -> 244067.75 | H27: =+'06'!D33 -> 124433.5 | I27: =+'07'!D33 -> 1387628.5 | J27: =+'08'!D33 -> 1241451.9 | K27: =+'09'!D33 -> 1462710.2 | L27: =+'10'!D33 -> 1366664.1 | M27: =+'11'!D33 -> 1122964.6 | N27: =+'12'!D33 -> 228290 | AH27: =+C27+D27+E27+F27+G27+H27+I27+J27+K27+L27+M27+N27+O27+P27+Q27+R27+S27+T27+U27+V27+W27+X27+Y27+Z27+AA27+AB27+AC27+AD27+AE27+AF27+AG27 -> 11946529 | AK27: =+AH27-AJ27 -> 11946529
B28: UC OP นอก CUP ใน จ.(สธ) - รพ.ถลาง ((10.6)) | C28: =+'01'!D34 -> 370752.2 | D28: =+'02'!D34 -> 615414.86 | E28: =+'03'!D34 -> 674531.67 | F28: =+'04'!D34 -> 529573.55 | G28: =+'05'!D34 -> 61069 | H28: =+'06'!D34 -> 116071.5 | I28: =+'07'!D34 -> 570201.81 | J28: =+'08'!D34 -> 638330.57 | K28: =+'09'!D34 -> 611267.23 | L28: =+'10'!D34 -> 658466.92 | M28: =+'11'!D34 -> 412806.98 | N28: =+'12'!D34 -> 106269.5 | AH28: =+C28+D28+E28+F28+G28+H28+I28+J28+K28+L28+M28+N28+O28+P28+Q28+R28+S28+T28+U28+V28+W28+X28+Y28+Z28+AA28+AB28+AC28+AD28+AE28+AF28+AG28 -> 5364755.8 | AK28: =+AH28-AJ28 -> 5364755.8
B29: UC OP นอก CUP ใน จ.(สธ) - รพ.ป่าตอง ((10.6)) | C29: =+'01'!D35 -> 22118 | D29: =+'02'!D35 -> 35414 | E29: =+'03'!D35 -> 27541.25 | F29: =+'04'!D35 -> 28076.86 | G29: =+'05'!D35 -> 19832 | H29: =+'06'!D35 -> 1765 | I29: =+'07'!D35 -> 61644.75 | J29: =+'08'!D35 -> 16419.99 | K29: =+'09'!D35 -> 26275.5 | L29: =+'10'!D35 -> 67903 | M29: =+'11'!D35 -> 55226.61 | N29: =+'12'!D35 -> 14794.5 | AH29: =+C29+D29+E29+F29+G29+H29+I29+J29+K29+L29+M29+N29+O29+P29+Q29+R29+S29+T29+U29+V29+W29+X29+Y29+Z29+AA29+AB29+AC29+AD29+AE29+AF29+AG29 -> 377011.46 | AK29: =+AH29-AJ29 -> 377011.46
B30: UC OP นอก CUP ใน จ.(นอก สธ.) - อบจ. ((10.7)) | C30: =+'01'!D37 -> 5820 | D30: =+'02'!D37 -> 2685 | E30: =+'03'!D37 -> 1555 | F30: =+'04'!D37 -> 1838 | G30: =+'05'!D37 -> 0 | H30: =+'06'!D37 -> 0 | I30: =+'07'!D37 -> 7272.5 | J30: =+'08'!D37 -> 9643 | K30: =+'09'!D37 -> 585 | L30: =+'10'!D37 -> 2430 | M30: =+'11'!D37 -> 4718 | N30: =+'12'!D37 -> 0 | AH30: =+C30+D30+E30+F30+G30+H30+I30+J30+K30+L30+M30+N30+O30+P30+Q30+R30+S30+T30+U30+V30+W30+X30+Y30+Z30+AA30+AB30+AC30+AD30+AE30+AF30+AG30 -> 36546.5 | AK30: =+AH30-AJ30 -> 36546.5
B31: UC OP Refer ตจว. ((11.2)) | C31: =+'01'!D38 -> 1535726.2 | D31: =+'02'!D38 -> 2169107.7 | E31: =+'03'!D38 -> 816129.47 | F31: =+'04'!D38 -> 1251111.2 | G31: =+'05'!D38 -> 1898325.6 | H31: =+'06'!D38 -> 1106423.5 | I31: =+'07'!D38 -> 1621478.2 | J31: =+'08'!D38 -> 1777126.9 | K31: =+'09'!D38 -> 2927898.5 | L31: =+'10'!D38 -> 1960123.9 | M31: =+'11'!D38 -> 1446952.1 | N31: =+'12'!D38 -> 1711423 | AH31: =+C31+D31+E31+F31+G31+H31+I31+J31+K31+L31+M31+N31+O31+P31+Q31+R31+S31+T31+U31+V31+W31+X31+Y31+Z31+AA31+AB31+AC31+AD31+AE31+AF31+AG31 -> 20221826 | AK31: =+AH31-AJ31 -> 20221826
B32: UC OP AE ((4.1)) | C32: =+'01'!D39 -> 567205.23 | D32: =+'02'!D39 -> 575516.5 | E32: =+'03'!D39 -> 1243635.7 | F32: =+'04'!D39 -> 1717552.7 | G32: =+'05'!D39 -> 1157793.4 | H32: =+'06'!D39 -> 493655.86 | I32: =+'07'!D39 -> 783751.39 | J32: =+'08'!D39 -> 1147823.5 | K32: =+'09'!D39 -> 966376.92 | L32: =+'10'!D39 -> 1601905.4 | M32: =+'11'!D39 -> 1509485.8 | N32: =+'12'!D39 -> 385144.25 | AH32: =+C32+D32+E32+F32+G32+H32+I32+J32+K32+L32+M32+N32+O32+P32+Q32+R32+S32+T32+U32+V32+W32+X32+Y32+Z32+AA32+AB32+AC32+AD32+AE32+AF32+AG32 -> 12149847 | AK32: =+AH32-AJ32 -> 12149847
B33: UC - สิทธิว่างมาตรา 8 / เด็กแรกเกิด ((4.1.1)) | C33: =+'01'!D40 -> 2527 | D33: =+'02'!D40 -> 0 | E33: =+'03'!D40 -> 162342.51 | F33: =+'04'!D40 -> 40984.47 | G33: =+'05'!D40 -> 63156.5 | H33: =+'06'!D40 -> 0 | I33: =+'07'!D40 -> 0 | J33: =+'08'!D40 -> 65669.25 | K33: =+'09'!D40 -> 0 | L33: =+'10'!D40 -> 24780.54 | M33: =+'11'!D40 -> 0 | N33: =+'12'!D40 -> 0 | AH33: =+C33+D33+E33+F33+G33+H33+I33+J33+K33+L33+M33+N33+O33+P33+Q33+R33+S33+T33+U33+V33+W33+X33+Y33+Z33+AA33+AB33+AC33+AD33+AE33+AF33+AG33 -> 359460.27 | AK33: =+AH33-AJ33 -> 359460.27
B34: UC - ส่งเสริมป้องกันโรค | C34: =+'01'!D41 -> 754506.97 | D34: =+'02'!D41 -> 993293.46 | E34: =+'03'!D41 -> 1611545.8 | F34: =+'04'!D41 -> 1219605.8 | G34: =+'05'!D41 -> 1334709.9 | H34: =+'06'!D41 -> 493544.22 | I34: =+'07'!D41 -> 1915723.1 | J34: =+'08'!D41 -> 753466.3 | K34: =+'09'!D41 -> 1372885.9 | L34: =+'10'!D41 -> 1304515.1 | M34: =+'11'!D41 -> 869365.35 | N34: =+'12'!D41 -> 931177.85 | AH34: =+C34+D34+E34+F34+G34+H34+I34+J34+K34+L34+M34+N34+O34+P34+Q34+R34+S34+T34+U34+V34+W34+X34+Y34+Z34+AA34+AB34+AC34+AD34+AE34+AF34+AG34 -> 13554340 | AK34: =+AH34-AJ34 -> 13554340
B35: UC - ฟอกไต | C35: =+'01'!D42 -> 248522.75 | D35: =+'02'!D42 -> 1083490 | E35: =+'03'!D42 -> 640976.75 | F35: =+'04'!D42 -> 71301.25 | G35: =+'05'!D42 -> 36374.25 | H35: =+'06'!D42 -> 33857 | I35: =+'07'!D42 -> 99323.5 | J35: =+'08'!D42 -> 39470.5 | K35: =+'09'!D42 -> 162319.98 | L35: =+'10'!D42 -> 74526.75 | M35: =+'11'!D42 -> 422138.5 | N35: =+'12'!D42 -> 230003 | AH35: =+C35+D35+E35+F35+G35+H35+I35+J35+K35+L35+M35+N35+O35+P35+Q35+R35+S35+T35+U35+V35+W35+X35+Y35+Z35+AA35+AB35+AC35+AD35+AE35+AF35+AG35 -> 3142304.2 | AK35: =+AH35-AJ35 -> 3142304.2
A36: 12 | B36: แรงงานต่างด้าว OP ใน CUP ((7.1)) | C36: =+'01'!D45 -> 99602.5 | D36: =+'02'!D45 -> 77565 | E36: =+'03'!D45 -> 65053.36 | F36: =+'04'!D45 -> 84567.75 | G36: =+'05'!D45 -> 7652 | H36: =+'06'!D45 -> 11894.5 | I36: =+'07'!D45 -> 71145.87 | J36: =+'08'!D45 -> 93009.87 | K36: =+'09'!D45 -> 81143.86 | L36: =+'10'!D45 -> 90666.33 | M36: =+'11'!D45 -> 92454 | N36: =+'12'!D45 -> 31920.5 | AH36: =+C36+D36+E36+F36+G36+H36+I36+J36+K36+L36+M36+N36+O36+P36+Q36+R36+S36+T36+U36+V36+W36+X36+Y36+Z36+AA36+AB36+AC36+AD36+AE36+AF36+AG36 -> 806675.54 | AK36: =+AH36-AJ36 -> 806675.54
B37: แรงงานต่างด้าว OP นอก CUP- (เรียกเก็บ)*** ((6.1)) | C37: =+'01'!D46 -> 1321 | D37: =+'02'!D46 -> 6417 | E37: =+'03'!D46 -> 2872.5 | F37: =+'04'!D46 -> 410 | G37: =+'05'!D46 -> 0 | H37: =+'06'!D46 -> 0 | I37: =+'07'!D46 -> 16377.49 | J37: =+'08'!D46 -> 7111 | K37: =+'09'!D46 -> 0 | L37: =+'10'!D46 -> 0 | M37: =+'11'!D46 -> 0 | N37: =+'12'!D46 -> 0 | AH37: =+C37+D37+E37+F37+G37+H37+I37+J37+K37+L37+M37+N37+O37+P37+Q37+R37+S37+T37+U37+V37+W37+X37+Y37+Z37+AA37+AB37+AC37+AD37+AE37+AF37+AG37 -> 34508.99 | AK37: =+AH37-AJ37 -> 34508.99
A38: 13 | B38: ต่างด้าวสถานะ&สิทธิ OP ใน CUP ((14.1)) | C38: =+'01'!D50 -> 6976.5 | D38: =+'02'!D50 -> 5246.5 | E38: =+'03'!D50 -> 1519 | F38: =+'04'!D50 -> 190 | G38: =+'05'!D50 -> 0 | H38: =+'06'!D50 -> 0 | I38: =+'07'!D50 -> 0 | J38: =+'08'!D50 -> 130 | K38: =+'09'!D50 -> 0 | L38: =+'10'!D50 -> 0 | M38: =+'11'!D50 -> 1313.5 | N38: =+'12'!D50 -> 0 | AH38: =+C38+D38+E38+F38+G38+H38+I38+J38+K38+L38+M38+N38+O38+P38+Q38+R38+S38+T38+U38+V38+W38+X38+Y38+Z38+AA38+AB38+AC38+AD38+AE38+AF38+AG38 -> 15375.5 | AK38: =+AH38-AJ38 -> 15375.5
B39: ต่างด้าวสถานะ&สิทธิ OP นอก CUP (เรียกเก็บ)** ((12.2)) | C39: =+'01'!D51 -> 0 | D39: =+'02'!D51 -> 333 | E39: =+'03'!D51 -> 0 | F39: =+'04'!D51 -> 0 | G39: =+'05'!D51 -> 0 | H39: =+'06'!D51 -> 0 | I39: =+'07'!D51 -> 0 | J39: =+'08'!D51 -> 0 | K39: =+'09'!D51 -> 0 | L39: =+'10'!D51 -> 0 | M39: =+'11'!D51 -> 0 | N39: =+'12'!D51 -> 0 | AH39: =+C39+D39+E39+F39+G39+H39+I39+J39+K39+L39+M39+N39+O39+P39+Q39+R39+S39+T39+U39+V39+W39+X39+Y39+Z39+AA39+AB39+AC39+AD39+AE39+AF39+AG39 -> 333 | AK39: =+AH39-AJ39 -> 333
A40: 14 | B40: ล/น.เบิกจ่ายตรงกรมบ/ช.กลาง -ฉลอง** ((1.3 / ฉลอง)) | C40: =+'01'!D52 -> 0 | D40: =+'02'!D52 -> 0 | E40: =+'03'!D52 -> 0 | F40: =+'04'!D52 -> 0 | G40: =+'05'!D52 -> 0 | H40: =+'06'!D52 -> 0 | I40: =+'07'!D52 -> 246629.84 | J40: =+'08'!D52 -> 0 | K40: =+'09'!D52 -> 0 | L40: =+'10'!D52 -> 0 | M40: =+'11'!D52 -> 0 | N40: =+'12'!D52 -> 0 | AH40: =+C40+D40+E40+F40+G40+H40+I40+J40+K40+L40+M40+N40+O40+P40+Q40+R40+S40+T40+U40+V40+W40+X40+Y40+Z40+AA40+AB40+AC40+AD40+AE40+AF40+AG40 -> 246629.84 | AK40: =+AH40-AJ40 -> 246629.84
...

Sheet 1-30 กย.69
A1: รายงานสรุปค่ารักษาพยาบาลประจำวัน
A2: ประจำเดือน กันยายน 2569
A3: รายการ / วันที่ | C3: 1 มีค.65 | D3: 2 มีค.65 | E3: 3 มีค.65 | F3: 4 มีค.65 | G3: 5 มีค.65 | H3: 6 มีค.65 | I3: 7 มีค.65 | J3: 8 มีค.65 | K3: 9 มีค.65 | L3: 10 มีค.65 | M3: 11 มีค.65 | N3: 12 มีค.65 | O3: 13 มีค.65 | P3: 14 มีค.65 | Q3: 15 มีค.65 | R3: 16 มีค.65 | S3: 17 มีค.65 | T3: 18 มีค.65 | U3: 19 มีค.65 | V3: 20 มีค.65 | W3: 21 มีค.65 | X3: 22 มีค.65 | Y3: 23 มีค.65 | Z3: 24 มีค.65 | AA3: 25 มีค.65 | AB3: 26 มีค.65 | AC3: 27 มีค.65 | AD3: 28 มีค.65 | AE3: 29 มีค.65 | AF3: 30 มีค.65 | AG3: 31 มีค.65 | AH3: รวม
A4: ลำดับ | B4: สิทธิการรักษา | C4: จำนวนเงิน | D4: จำนวนเงิน | E4: จำนวนเงิน | F4: จำนวนเงิน | G4: จำนวนเงิน | H4: จำนวนเงิน | I4: จำนวนเงิน | J4: จำนวนเงิน | K4: จำนวนเงิน | L4: จำนวนเงิน | M4: จำนวนเงิน | N4: จำนวนเงิน | O4: จำนวนเงิน | P4: จำนวนเงิน | Q4: จำนวนเงิน | R4: จำนวนเงิน | S4: จำนวนเงิน | T4: จำนวนเงิน | U4: จำนวนเงิน | V4: จำนวนเงิน | W4: จำนวนเงิน | X4: จำนวนเงิน | Y4: จำนวนเงิน | Z4: จำนวนเงิน | AA4: จำนวนเงิน | AB4: จำนวนเงิน | AC4: จำนวนเงิน | AD4: จำนวนเงิน | AE4: จำนวนเงิน | AF4: จำนวนเงิน | AG4: จำนวนเงิน | AH4: จำนวนเงิน
A5: 1 | B5: ชำระเงินสด (OPD) >>ไม่ลงบ/ช.<< | C5: =+'01'!D4 -> 0 | D5: =+'02'!D4 -> 0 | E5: =+'03'!D4 -> 0 | F5: =+'04'!D4 -> 0 | G5: =+'05'!D4 -> 0 | H5: =+'06'!D4 -> 0 | I5: =+'06'!D4 -> 0 | J5: =+'08'!D4 -> 0 | K5: =+'09'!D4 -> 0 | L5: =+'10'!D4 -> 0 | M5: =+'11'!D4 -> 0 | N5: =+'12'!D4 -> 0 | O5: =+'13'!D4 -> 0 | P5: =+'14'!D4 -> 0 | Q5: =+'15'!D4 -> 0 | R5: =+'16'!D4 -> 0 | S5: =+'17'!D4 -> 0 | T5: =+'18'!D4 -> 0 | U5: =+'19'!D4 -> 0 | V5: =+'20'!D4 -> 0 | W5: =+'21'!D4 -> 0 | X5: =+'22'!D4 -> 0 | Y5: =+'23'!D4 -> 0 | Z5: =+'24'!D4 -> 0 | AA5: =+'25'!D4 -> 0 | AB5: =+'26'!D4 -> 0 | AC5: =+'27'!D4 -> 0 | AD5: =+'28'!D4 -> 0 | AE5: =+'29'!D4 -> 0 | AF5: =+'30'!D4 -> 0 | AG5: =+'31'!D4 -> 0 | AH5: =+C5+D5+E5+F5+G5+H5+I5+J5+K5+L5+M5+N5+O5+P5+Q5+R5+S5+T5+U5+V5+W5+X5+Y5+Z5+AA5+AB5+AC5+AD5+AE5+AF5+AG5 -> 0
A6: 2 | B6: ชำระเงินสด (IPD) >>ไม่ลงบ/ช.<< | C6: =+'01'!D5 -> 0 | D6: =+'02'!D5 -> 0 | E6: =+'03'!D5 -> 0 | F6: =+'04'!D5 -> 0 | G6: =+'05'!D5 -> 0 | H6: =+'06'!D5 -> 0 | I6: =+'06'!D5 -> 0 | J6: =+'08'!D5 -> 0 | K6: =+'09'!D5 -> 0 | L6: =+'10'!D5 -> 0 | M6: =+'11'!D5 -> 0 | N6: =+'12'!D5 -> 0 | O6: =+'13'!D5 -> 0 | P6: =+'14'!D5 -> 0 | Q6: =+'15'!D5 -> 0 | R6: =+'16'!D5 -> 0 | S6: =+'17'!D5 -> 0 | T6: =+'18'!D5 -> 0 | U6: =+'19'!D5 -> 0 | V6: =+'20'!D5 -> 0 | W6: =+'21'!D5 -> 0 | X6: =+'22'!D5 -> 0 | Y6: =+'23'!D5 -> 0 | Z6: =+'24'!D5 -> 0 | AA6: =+'25'!D5 -> 0 | AB6: =+'26'!D5 -> 0 | AC6: =+'27'!D5 -> 0 | AD6: =+'28'!D5 -> 0 | AE6: =+'29'!D5 -> 0 | AF6: =+'30'!D5 -> 0 | AG6: =+'31'!D5 -> 0 | AH6: =+C6+D6+E6+F6+G6+H6+I6+J6+K6+L6+M6+N6+O6+P6+Q6+R6+S6+T6+U6+V6+W6+X6+Y6+Z6+AA6+AB6+AC6+AD6+AE6+AF6+AG6 -> 0
A7: 3 | B7: เบิกกรมบัญชีกลาง (OPD) ((1.3)) | C7: =+'01'!D6 -> 1196065.4 | D7: =+'02'!D6 -> 991915.36 | E7: =+'03'!D6 -> 1013029.4 | F7: =+'04'!D6 -> 1091659.6 | G7: =+'05'!D6 -> 201880 | H7: =+'06'!D6 -> 258386.09 | I7: =+'07'!D6 -> 1297943.5 | J7: =+'08'!D6 -> 996194.45 | K7: =+'09'!D6 -> 1017542.3 | L7: =+'10'!D6 -> 1108876.4 | M7: =+'11'!D6 -> 986978.24 | N7: =+'12'!D6 -> 110870.75 | O7: =+'13'!D6 -> 170846.61 | P7: =+'14'!D6 -> 1018355.9 | Q7: =+'15'!D6 -> 1274832.1 | R7: =+'16'!D6 -> 1008976.2 | S7: =+'17'!D6 -> 839863.98 | T7: =+'18'!D6 -> 1122239.2 | U7: =+'19'!D6 -> 193825.25 | V7: =+'20'!D6 -> 329834.85 | W7: =+'21'!D6 -> 913597.87 | X7: =+'22'!D6 -> 1218743.8 | Y7: =+'23'!D6 -> 913086.85 | Z7: =+'24'!D6 -> 859308.97 | AA7: =+'25'!D6 -> 1081041.9 | AB7: =+'26'!D6 -> 355204.73 | AC7: =+'27'!D6 -> 137010.5 | AD7: =+'28'!D6 -> 1149593 | AE7: =+'29'!D6 -> 1021933.1 | AF7: =+'30'!D6 -> 1282664 | AG7: =+'31'!D6 -> 0 | AH7: =+C7+D7+E7+F7+G7+H7+I7+J7+K7+L7+M7+N7+O7+P7+Q7+R7+S7+T7+U7+V7+W7+X7+Y7+Z7+AA7+AB7+AC7+AD7+AE7+AF7+AG7 -> 25162300 | AJ7: =12735375.97+12426924.26 -> 25162300 | AK7: =+AH7-AJ7 -> 0
B8: เบิกกรมบัญชีกลาง (OPD) กทม. ((1.3)) | C8: =+'01'!D7 -> 0 | D8: =+'02'!D7 -> 0 | E8: =+'03'!D7 -> 0 | F8: =+'04'!D7 -> 0 | G8: =+'05'!D7 -> 0 | H8: =+'06'!D7 -> 0 | I8: =+'07'!D7 -> 0 | J8: =+'08'!D7 -> 0 | K8: =+'09'!D7 -> 0 | L8: =+'10'!D7 -> 0 | M8: =+'11'!D7 -> 0 | N8: =+'12'!D7 -> 0 | O8: =+'13'!D7 -> 0 | P8: =+'14'!D7 -> 0 | Q8: =+'15'!D7 -> 0 | R8: =+'16'!D7 -> 0 | S8: =+'17'!D7 -> 0 | T8: =+'18'!D7 -> 0 | U8: =+'19'!D7 -> 0 | V8: =+'20'!D7 -> 0 | W8: =+'21'!D7 -> 0 | X8: =+'22'!D7 -> 0 | Y8: =+'23'!D7 -> 0 | Z8: =+'24'!D7 -> 0 | AA8: =+'25'!D7 -> 0 | AB8: =+'26'!D7 -> 0 | AC8: =+'27'!D7 -> 0 | AD8: =+'28'!D7 -> 0 | AE8: =+'29'!D7 -> 0 | AF8: =+'30'!D7 -> 0 | AG8: =+'31'!D7 -> 0 | AH8: =+C8+D8+E8+F8+G8+H8+I8+J8+K8+L8+M8+N8+O8+P8+Q8+R8+S8+T8+U8+V8+W8+X8+Y8+Z8+AA8+AB8+AC8+AD8+AE8+AF8+AG8 -> 0 | AK8: =+AH8-AJ8 -> 0
B9: เบิกกรมบัญชีกลาง (OPD) ไตเทียม ((1.4)) | C9: =+'01'!D8 -> 0 | D9: =+'02'!D8 -> 0 | E9: =+'03'!D8 -> 0 | F9: =+'04'!D8 -> 0 | G9: =+'05'!D8 -> 0 | H9: =+'06'!D8 -> 0 | I9: =+'07'!D8 -> 0 | J9: =+'08'!D8 -> 0 | K9: =+'09'!D8 -> 0 | L9: =+'10'!D8 -> 0 | M9: =+'11'!D8 -> 0 | N9: =+'12'!D8 -> 0 | O9: =+'13'!D8 -> 0 | P9: =+'14'!D8 -> 0 | Q9: =+'15'!D8 -> 0 | R9: =+'16'!D8 -> 0 | S9: =+'17'!D8 -> 0 | T9: =+'18'!D8 -> 0 | U9: =+'19'!D8 -> 0 | V9: =+'20'!D8 -> 0 | W9: =+'21'!D8 -> 0 | X9: =+'22'!D8 -> 0 | Y9: =+'23'!D8 -> 0 | Z9: =+'24'!D8 -> 0 | AA9: =+'25'!D8 -> 0 | AB9: =+'26'!D8 -> 0 | AC9: =+'27'!D8 -> 0 | AD9: =+'28'!D8 -> 0 | AE9: =+'29'!D8 -> 0 | AF9: =+'30'!D8 -> 0 | AG9: =+'31'!D8 -> 0 | AH9: =+C9+D9+E9+F9+G9+H9+I9+J9+K9+L9+M9+N9+O9+P9+Q9+R9+S9+T9+U9+V9+W9+X9+Y9+Z9+AA9+AB9+AC9+AD9+AE9+AF9+AG9 -> 0 | AK9: =+AH9-AJ9 -> 0
A10: 4 | B10: เบิกกรมบัญชีกลาง (IPD) ((1.5)) | C10: =+'01'!D9 -> 14625.57 | D10: =+'02'!D9 -> 10241.75 | E10: =+'03'!D9 -> 1002440.3 | F10: =+'04'!D9 -> 301960.54 | G10: =+'05'!D9 -> 2011182.8 | H10: =+'06'!D9 -> 119707.28 | I10: =+'07'!D9 -> 395076.87 | J10: =+'08'!D9 -> 39275.5 | K10: =+'09'!D9 -> 606366.98 | L10: =+'10'!D9 -> 520167.66 | M10: =+'11'!D9 -> 511836.05 | N10: =+'12'!D9 -> 97675.5 | O10: =+'13'!D9 -> 355525.54 | P10: =+'14'!D9 -> 601392.47 | Q10: =+'15'!D9 -> 274115 | R10: =+'16'!D9 -> 679335.82 | S10: =+'17'!D9 -> 745840.03 | T10: =+'18'!D9 -> 624372.94 | U10: =+'19'!D9 -> 318129 | V10: =+'20'!D9 -> 241412.25 | W10: =+'21'!D9 -> 227948.23 | X10: =+'22'!D9 -> 506953.09 | Y10: =+'23'!D9 -> 263419.79 | Z10: =+'24'!D9 -> 1076650 | AA10: =+'25'!D9 -> 378301.64 | AB10: =+'26'!D9 -> 652944.31 | AC10: =+'27'!D9 -> 242887.03 | AD10: =+'28'!D9 -> 403418.64 | AE10: =+'29'!D9 -> 198262.26 | AF10: =+'30'!D9 -> 314636.63 | AG10: =+'31'!D9 -> 0 | AH10: =+C10+D10+E10+F10+G10+H10+I10+J10+K10+L10+M10+N10+O10+P10+Q10+R10+S10+T10+U10+V10+W10+X10+Y10+Z10+AA10+AB10+AC10+AD10+AE10+AF10+AG10 -> 13736101 | AJ10: =6861589.76+6874511.62 -> 13736101 | AK10: =+AH10-AJ10 -> 0
B11: เบิกกรมบัญชีกลาง (IPD) กทม. ((1.5)) | C11: =+'01'!D10 -> 0 | D11: =+'02'!D10 -> 0 | E11: =+'03'!D10 -> 0 | F11: =+'04'!D10 -> 0 | G11: =+'05'!D10 -> 0 | H11: =+'06'!D10 -> 0 | I11: =+'07'!D10 -> 0 | J11: =+'08'!D10 -> 0 | K11: =+'09'!D10 -> 0 | L11: =+'10'!D10 -> 0 | M11: =+'11'!D10 -> 0 | N11: =+'12'!D10 -> 0 | O11: =+'13'!D10 -> 0 | P11: =+'14'!D10 -> 0 | Q11: =+'15'!D10 -> 0 | R11: =+'16'!D10 -> 0 | S11: =+'17'!D10 -> 0 | T11: =+'18'!D10 -> 0 | U11: =+'19'!D10 -> 0 | V11: =+'20'!D10 -> 0 | W11: =+'21'!D10 -> 0 | X11: =+'22'!D10 -> 0 | Y11: =+'23'!D10 -> 0 | Z11: =+'24'!D10 -> 0 | AA11: =+'25'!D10 -> 0 | AB11: =+'26'!D10 -> 0 | AC11: =+'27'!D10 -> 0 | AD11: =+'28'!D10 -> 0 | AE11: =+'29'!D10 -> 0 | AF11: =+'30'!D10 -> 0 | AG11: =+'31'!D10 -> 0 | AH11: =+C11+D11+E11+F11+G11+H11+I11+J11+K11+L11+M11+N11+O11+P11+Q11+R11+S11+T11+U11+V11+W11+X11+Y11+Z11+AA11+AB11+AC11+AD11+AE11+AF11+AG11 -> 0 | AK11: =+AH11-AJ11 -> 0
B12: เบิกกรมบัญชีกลาง (IPD) ไตเทียม ((1.1)) | C12: =+'01'!D11 -> 0 | D12: =+'02'!D11 -> 0 | E12: =+'03'!D11 -> 0 | F12: =+'04'!D11 -> 0 | G12: =+'05'!D11 -> 0 | H12: =+'06'!D11 -> 0 | I12: =+'07'!D11 -> 0 | J12: =+'08'!D11 -> 0 | K12: =+'09'!D11 -> 0 | L12: =+'10'!D11 -> 0 | M12: =+'11'!D11 -> 0 | N12: =+'12'!D11 -> 0 | O12: =+'13'!D11 -> 0 | P12: =+'14'!D11 -> 0 | Q12: =+'15'!D11 -> 0 | R12: =+'16'!D11 -> 0 | S12: =+'17'!D11 -> 0 | T12: =+'18'!D11 -> 0 | U12: =+'19'!D11 -> 24110 | V12: =+'20'!D11 -> 0 | W12: =+'21'!D11 -> 0 | X12: =+'22'!D11 -> 0 | Y12: =+'23'!D11 -> 0 | Z12: =+'24'!D11 -> 33072 | AA12: =+'25'!D11 -> 8392 | AB12: =+'26'!D11 -> 0 | AC12: =+'27'!D11 -> 18548 | AD12: =+'28'!D11 -> 0 | AE12: =+'29'!D11 -> 0 | AF12: =+'30'!D11 -> 0 | AG12: =+'31'!D11 -> 0 | AH12: =+C12+D12+E12+F12+G12+H12+I12+J12+K12+L12+M12+N12+O12+P12+Q12+R12+S12+T12+U12+V12+W12+X12+Y12+Z12+AA12+AB12+AC12+AD12+AE12+AF12+AG12 -> 84122 | AJ12: 84122 | AK12: =+AH12-AJ12 -> 0
A13: 5 | B13: องค์กรปกครองส่วนท้องถิ่น (OPD) ((3.6)) | C13: =+'01'!D12 -> 250757 | D13: =+'02'!D12 -> 204218.5 | E13: =+'03'!D12 -> 99684.5 | F13: =+'04'!D12 -> 173171.75 | G13: =+'05'!D12 -> 8111.5 | H13: =+'06'!D12 -> 2595 | I13: =+'07'!D12 -> 194220.5 | J13: =+'08'!D12 -> 148808.5 | K13: =+'09'!D12 -> 221222.5 | L13: =+'10'!D12 -> 98994.25 | M13: =+'11'!D12 -> 101994.75 | N13: =+'12'!D12 -> 11465.25 | O13: =+'13'!D12 -> 1080 | P13: =+'14'!D12 -> 99846.75 | Q13: =+'15'!D12 -> 152161 | R13: =+'16'!D12 -> 206032 | S13: =+'17'!D12 -> 116098.5 | T13: =+'18'!D12 -> 152679.75 | U13: =+'19'!D12 -> 31056 | V13: =+'20'!D12 -> 1965 | W13: =+'21'!D12 -> 135374.75 | X13: =+'22'!D12 -> 189018 | Y13: =+'23'!D12 -> 114224.25 | Z13: =+'24'!D12 -> 84758.25 | AA13: =+'25'!D12 -> 98683.24 | AB13: =+'26'!D12 -> 31477.75 | AC13: =+'27'!D12 -> 990 | AD13: =+'28'!D12 -> 184521 | AE13: =+'29'!D12 -> 160522.5 | AF13: =+'30'!D12 -> 235698.87 | AG13: =+'31'!D12 -> 0 | AH13: =+C13+D13+E13+F13+G13+H13+I13+J13+K13+L13+M13+N13+O13+P13+Q13+R13+S13+T13+U13+V13+W13+X13+Y13+Z13+AA13+AB13+AC13+AD13+AE13+AF13+AG13 -> 3511431.6 | AJ13: =1768331.75+1743099.86 -> 3511431.6 | AK13: =+AH13-AJ13 -> 0
B14: องค์กรปกครองส่วนท้องถิ่น (OPD) ไตเทียม ((3.6)) | C14: =+'01'!D13 -> 0 | D14: =+'02'!D13 -> 0 | E14: =+'03'!D13 -> 0 | F14: =+'04'!D13 -> 0 | G14: =+'05'!D13 -> 0 | H14: =+'06'!D13 -> 0 | I14: =+'07'!D13 -> 0 | J14: =+'08'!D13 -> 0 | K14: =+'09'!D13 -> 0 | L14: =+'10'!D13 -> 0 | M14: =+'11'!D13 -> 0 | N14: =+'12'!D13 -> 0 | O14: =+'13'!D13 -> 0 | P14: =+'14'!D13 -> 0 | Q14: =+'15'!D13 -> 0 | R14: =+'16'!D13 -> 0 | S14: =+'17'!D13 -> 0 | T14: =+'18'!D13 -> 0 | U14: =+'19'!D13 -> 0 | V14: =+'20'!D13 -> 0 | W14: =+'21'!D13 -> 0 | X14: =+'22'!D13 -> 0 | Y14: =+'23'!D13 -> 0 | Z14: =+'24'!D13 -> 0 | AA14: =+'25'!D13 -> 0 | AB14: =+'26'!D13 -> 0 | AC14: =+'27'!D13 -> 0 | AD14: =+'28'!D13 -> 0 | AE14: =+'29'!D13 -> 0 | AF14: =+'30'!D13 -> 0 | AG14: =+'31'!D13 -> 0 | AH14: =+C14+D14+E14+F14+G14+H14+I14+J14+K14+L14+M14+N14+O14+P14+Q14+R14+S14+T14+U14+V14+W14+X14+Y14+Z14+AA14+AB14+AC14+AD14+AE14+AF14+AG14 -> 0 | AK14: =+AH14-AJ14 -> 0
A15: 6 | B15: องค์กรปกครองส่วนท้องถิ่น (IPD) ((3.5)) | C15: =+'01'!D14 -> 0 | D15: =+'02'!D14 -> 0 | E15: =+'03'!D14 -> 251744.69 | F15: =+'04'!D14 -> 28292.75 | G15: =+'05'!D14 -> 97963 | H15: =+'06'!D14 -> 18868.54 | I15: =+'07'!D14 -> 19090 | J15: =+'08'!D14 -> 0 | K15: =+'09'!D14 -> 29935.54 | L15: =+'10'!D14 -> 27436.75 | M15: =+'11'!D14 -> 27597.75 | N15: =+'12'!D14 -> 18074.75 | O15: =+'13'!D14 -> 211667.87 | P15: =+'14'!D14 -> 13183.5 | Q15: =+'15'!D14 -> 710974 | R15: =+'16'!D14 -> 0 | S15: =+'17'!D14 -> 47681.81 | T15: =+'18'!D14 -> 0 | U15: =+'19'!D14 -> 0 | V15: =+'20'!D14 -> 5160.25 | W15: =+'21'!D14 -> 62977.3 | X15: =+'22'!D14 -> 74546.17 | Y15: =+'23'!D14 -> 0 | Z15: =+'24'!D14 -> 17331 | AA15: =+'25'!D14 -> 114142 | AB15: =+'26'!D14 -> 76135.26 | AC15: =+'27'!D14 -> 0 | AD15: =+'28'!D14 -> 0 | AE15: =+'29'!D14 -> 105573.14 | AF15: =+'30'!D14 -> 422763.02 | AG15: =+'31'!D14 -> 0 | AH15: =+C15+D15+E15+F15+G15+H15+I15+J15+K15+L15+M15+N15+O15+P15+Q15+R15+S15+T15+U15+V15+W15+X15+Y15+Z15+AA15+AB15+AC15+AD15+AE15+AF15+AG15 -> 2381139.1 | AJ15: =1454829.14+926309.95 -> 2381139.1 | AK15: =+AH15-AJ15 -> 0
B16: องค์กรปกครองส่วนท้องถิ่น (IPD) ไตเทียม ((3.5)) | C16: =+'01'!D15 -> 0 | D16: =+'02'!D15 -> 0 | E16: =+'03'!D15 -> 0 | F16: =+'04'!D15 -> 0 | G16: =+'05'!D15 -> 0 | H16: =+'06'!D15 -> 0 | I16: =+'07'!D15 -> 0 | J16: =+'08'!D15 -> 0 | K16: =+'09'!D15 -> 0 | L16: =+'10'!D15 -> 12192 | M16: =+'11'!D15 -> 0 | N16: =+'12'!D15 -> 0 | O16: =+'13'!D15 -> 0 | P16: =+'14'!D15 -> 0 | Q16: =+'15'!D15 -> 0 | R16: =+'16'!D15 -> 0 | S16: =+'17'!D15 -> 0 | T16: =+'18'!D15 -> 0 | U16: =+'19'!D15 -> 0 | V16: =+'20'!D15 -> 0 | W16: =+'21'!D15 -> 8624 | X16: =+'22'!D15 -> 0 | Y16: =+'23'!D15 -> 0 | Z16: =+'24'!D15 -> 0 | AA16: =+'25'!D15 -> 0 | AB16: =+'26'!D15 -> 0 | AC16: =+'27'!D15 -> 0 | AD16: =+'28'!D15 -> 0 | AE16: =+'29'!D15 -> 0 | AF16: =+'30'!D15 -> 0 | AG16: =+'31'!D15 -> 0 | AH16: =+C16+D16+E16+F16+G16+H16+I16+J16+K16+L16+M16+N16+O16+P16+Q16+R16+S16+T16+U16+V16+W16+X16+Y16+Z16+AA16+AB16+AC16+AD16+AE16+AF16+AG16 -> 20816 | AJ16: 20816 | AK16: =+AH16-AJ16 -> 0
A17: 7 | B17: สิทธิ พรบ. เรียกเก็บ OPD ((2.2)) | C17: =+'01'!D16 -> 7239 | D17: =+'02'!D16 -> 30121 | E17: =+'03'!D16 -> 58020 | F17: =+'04'!D16 -> 19277.5 | G17: =+'05'!D16 -> 23759.75 | H17: =+'06'!D16 -> 10755 | I17: =+'07'!D16 -> 20087 | J17: =+'08'!D16 -> 24517.75 | K17: =+'09'!D16 -> 24679.25 | L17: =+'10'!D16 -> 12590.25 | M17: =+'11'!D16 -> 31367.5 | N17: =+'12'!D16 -> 33764.2 | O17: =+'13'!D16 -> 10921.75 | P17: =+'14'!D16 -> 28001.25 | Q17: =+'15'!D16 -> 25006.5 | R17: =+'16'!D16 -> 21258.75 | S17: =+'17'!D16 -> 38196.5 | T17: =+'18'!D16 -> 6652.5 | U17: =+'19'!D16 -> 18016.46 | V17: =+'20'!D16 -> 6330.5 | W17: =+'21'!D16 -> 5960 | X17: =+'22'!D16 -> 8498 | Y17: =+'23'!D16 -> 24203.46 | Z17: =+'24'!D16 -> 7886.75 | AA17: =+'25'!D16 -> 7619 | AB17: =+'26'!D16 -> 21004.5 | AC17: =+'27'!D16 -> 14450 | AD17: =+'28'!D16 -> 36037 | AE17: =+'29'!D16 -> 16403.25 | AF17: =+'30'!D16 -> 26170.25 | AG17: =+'31'!D16 -> 0 | AH17: =+C17+D17+E17+F17+G17+H17+I17+J17+K17+L17+M17+N17+O17+P17+Q17+R17+S17+T17+U17+V17+W17+X17+Y17+Z17+AA17+AB17+AC17+AD17+AE17+AF17+AG17 -> 618794.62 | AJ17: =193777+187589.45+158817.67+78610.5 -> 618794.62 | AK17: =+AH17-AJ17 -> 0
B18: สิทธิ พรบ. เรียกเก็บ IPD ((2.1)) | C18: =+'01'!D17 -> 127214 | D18: =+'02'!D17 -> 11539 | E18: =+'03'!D17 -> 154651.5 | F18: =+'04'!D17 -> 205807.5 | G18: =+'05'!D17 -> 50020.05 | H18: =+'06'!D17 -> 61025.29 | I18: =+'07'!D17 -> 36617.5 | J18: =+'08'!D17 -> 110000 | K18: =+'09'!D17 -> 118398.25 | L18: =+'10'!D17 -> 68207 | M18: =+'11'!D17 -> 52150 | N18: =+'12'!D17 -> 18635 | O18: =+'13'!D17 -> 36471.75 | P18: =+'14'!D17 -> 151340 | Q18: =+'15'!D17 -> 60000 | R18: =+'16'!D17 -> 173062.25 | S18: =+'17'!D17 -> 109589 | T18: =+'18'!D17 -> 93704.5 | U18: =+'19'!D17 -> 121843.55 | V18: =+'20'!D17 -> 0 | W18: =+'21'!D17 -> 112645 | X18: =+'22'!D17 -> 0 | Y18: =+'23'!D17 -> 51607.25 | Z18: =+'24'!D17 -> 63715 | AA18: =+'25'!D17 -> 30000 | AB18: =+'26'!D17 -> 30000 | AC18: =+'27'!D17 -> 0 | AD18: =+'28'!D17 -> 79461.75 | AE18: =+'29'!D17 -> 131655.75 | AF18: =+'30'!D17 -> 0 | AG18: =+'31'!D17 -> 0 | AH18: =+C18+D18+E18+F18+G18+H18+I18+J18+K18+L18+M18+N18+O18+P18+Q18+R18+S18+T18+U18+V18+W18+X18+Y18+Z18+AA18+AB18+AC18+AD18+AE18+AF18+AG18 -> 2259360.9 | AJ18: =756874.84+678264.25+613104.3+211117.5 -> 2259360.9 | AK18: =+AH18-AJ18 -> 0
A19: 8 | B19: สิทธิ ประกันชีวิต/ต่างประเทศ OPD ((3.2 OPD)) | C19: =+'01'!D18 -> 25213.75 | D19: =+'02'!D18 -> 27194.5 | E19: =+'03'!D18 -> 14609.61 | F19: =+'04'!D18 -> 5605.25 | G19: =+'05'!D18 -> 236441.6 | H19: =+'06'!D18 -> 99126.25 | I19: =+'07'!D18 -> 0 | J19: =+'08'!D18 -> 115636.25 | K19: =+'09'!D18 -> 1111 | L19: =+'10'!D18 -> 2200 | M19: =+'11'!D18 -> 15872.46 | N19: =+'12'!D18 -> 6342 | O19: =+'13'!D18 -> 1250 | P19: =+'14'!D18 -> 4080.5 | Q19: =+'15'!D18 -> 6302 | R19: =+'16'!D18 -> 22713.5 | S19: =+'17'!D18 -> 1603 | T19: =+'18'!D18 -> 5692 | U19: =+'19'!D18 -> 17971 | V19: =+'20'!D18 -> 0 | W19: =+'21'!D18 -> 18079 | X19: =+'22'!D18 -> 114178.86 | Y19: =+'23'!D18 -> 80981.96 | Z19: =+'24'!D18 -> 9672 | AA19: =+'25'!D18 -> 1959 | AB19: =+'26'!D18 -> 32171 | AC19: =+'27'!D18 -> 6170.2 | AD19: =+'28'!D18 -> 3852 | AE19: =+'29'!D18 -> 78532.52 | AF19: =+'30'!D18 -> 0 | AG19: =+'31'!D18 -> 0 | AH19: =+C19+D19+E19+F19+G19+H19+I19+J19+K19+L19+M19+N19+O19+P19+Q19+R19+S19+T19+U19+V19+W19+X19+Y19+Z19+AA19+AB19+AC19+AD19+AE19+AF19+AG19 -> 954561.21 | AJ19: 954561.21 | AK19: =+AH19-AJ19 -> 0
B20: สิทธิ ประกันชีวิต/ต่างประเทศ IPD ((3.1 IPD)) | C20: =+'01'!D19 -> 125498.75 | D20: =+'02'!D19 -> 132334.75 | E20: =+'03'!D19 -> 192659.1 | F20: =+'04'!D19 -> 194130.65 | G20: =+'05'!D19 -> 89096 | H20: =+'06'!D19 -> 0 | I20: =+'07'!D19 -> 3809.75 | J20: =+'08'!D19 -> 1427767.2 | K20: =+'09'!D19 -> 128417.54 | L20: =+'10'!D19 -> 35649.25 | M20: =+'11'!D19 -> 263533.25 | N20: =+'12'!D19 -> 58909.97 | O20: =+'13'!D19 -> 42362.75 | P20: =+'14'!D19 -> 0 | Q20: =+'15'!D19 -> 132534.75 | R20: =+'16'!D19 -> 130690 | S20: =+'17'!D19 -> 245048 | T20: =+'18'!D19 -> 689861.06 | U20: =+'19'!D19 -> 57138.25 | V20: =+'20'!D19 -> 264527.04 | W20: =+'21'!D19 -> 317808.75 | X20: =+'22'!D19 -> 167039.26 | Y20: =+'23'!D19 -> 139151.28 | Z20: =+'24'!D19 -> 6263415.3 | AA20: =+'25'!D19 -> 532900.28 | AB20: =+'26'!D19 -> 6800 | AC20: =+'27'!D19 -> 0 | AD20: =+'28'!D19 -> 157130.75 | AE20: =+'29'!D19 -> 5320 | AF20: =+'30'!D19 -> 0 | AG20: =+'31'!D19 -> 0 | AH20: =+C20+D20+E20+F20+G20+H20+I20+J20+K20+L20+M20+N20+O20+P20+Q20+R20+S20+T20+U20+V20+W20+X20+Y20+Z20+AA20+AB20+AC20+AD20+AE20+AF20+AG20 -> 11803534 | AJ20: 11803534 | AK20: =+AH20-AJ20 -> 0
A21: 9 | B21: เบิกต้นสังกัด/บริษัทห้างร้าน OPD ((3.4)) | C21: =+'01'!D20 -> 0 | D21: =+'02'!D20 -> 0 | E21: =+'03'!D20 -> 0 | F21: =+'04'!D20 -> 0 | G21: =+'05'!D20 -> 0 | H21: =+'06'!D20 -> 0 | I21: =+'07'!D20 -> 180409.49 | J21: =+'08'!D20 -> 168326.84 | K21: =+'09'!D20 -> 41760 | L21: =+'10'!D20 -> 0 | M21: =+'11'!D20 -> 0 | N21: =+'12'!D20 -> 0 | O21: =+'13'!D20 -> 0 | P21: =+'14'!D20 -> 44650 | Q21: =+'15'!D20 -> 619616.61 | R21: =+'16'!D20 -> 0 | S21: =+'17'!D20 -> 268694.23 | T21: =+'18'!D20 -> 915081.36 | U21: =+'19'!D20 -> 0 | V21: =+'20'!D20 -> 0 | W21: =+'21'!D20 -> 20210.61 | X21: =+'22'!D20 -> 51508.61 | Y21: =+'23'!D20 -> 0 | Z21: =+'24'!D20 -> 0 | AA21: =+'25'!D20 -> 0 | AB21: =+'26'!D20 -> 0 | AC21: =+'27'!D20 -> 0 | AD21: =+'28'!D20 -> 704822.46 | AE21: =+'29'!D20 -> 417100.36 | AF21: =+'30'!D20 -> 178015.82 | AG21: =+'31'!D20 -> 0 | AH21: =+C21+D21+E21+F21+G21+H21+I21+J21+K21+L21+M21+N21+O21+P21+Q21+R21+S21+T21+U21+V21+W21+X21+Y21+Z21+AA21+AB21+AC21+AD21+AE21+AF21+AG21 -> 3610196.4 | AJ21: =1054762.94+2555433.45 -> 3610196.4 | AK21: =+AH21-AJ21 -> 0
B22: เบิกต้นสังกัด/บริษัทห้างร้าน IPD ((3.3)) | C22: =+'01'!D21 -> 0 | D22: =+'02'!D21 -> 0 | E22: =+'03'!D21 -> 0 | F22: =+'04'!D21 -> 0 | G22: =+'05'!D21 -> 0 | H22: =+'06'!D21 -> 0 | I22: =+'07'!D21 -> 0 | J22: =+'08'!D21 -> 366945.81 | K22: =+'09'!D21 -> 0 | L22: =+'10'!D21 -> 0 | M22: =+'11'!D21 -> 0 | N22: =+'12'!D21 -> 0 | O22: =+'13'!D21 -> 0 | P22: =+'14'!D21 -> 0 | Q22: =+'15'!D21 -> 0 | R22: =+'16'!D21 -> 0 | S22: =+'17'!D21 -> 812100.79 | T22: =+'18'!D21 -> 0 | U22: =+'19'!D21 -> 0 | V22: =+'20'!D21 -> 0 | W22: =+'21'!D21 -> 0 | X22: =+'22'!D21 -> 2737615.6 | Y22: =+'23'!D21 -> 0 | Z22: =+'24'!D21 -> 0 | AA22: =+'25'!D21 -> 0 | AB22: =+'26'!D21 -> 0 | AC22: =+'27'!D21 -> 0 | AD22: =+'28'!D21 -> 1608995.7 | AE22: =+'29'!D21 -> 0 | AF22: =+'30'!D21 -> 0 | AG22: =+'31'!D21 -> 0 | AH22: =+C22+D22+E22+F22+G22+H22+I22+J22+K22+L22+M22+N22+O22+P22+Q22+R22+S22+T22+U22+V22+W22+X22+Y22+Z22+AA22+AB22+AC22+AD22+AE22+AF22+AG22 -> 5525657.9 | AJ22: =366945.81+5158712.09 -> 5525657.9 | AK22: =+AH22-AJ22 -> 0
A23: 10 | B23: ปกส.-OP เครือข่าย ((9.6)) | C23: =+'01'!D22 -> 1660407.5 | D23: =+'02'!D22 -> 938187.56 | E23: =+'03'!D22 -> 865509.33 | F23: =+'04'!D22 -> 774877.8 | G23: =+'05'!D22 -> 226607 | H23: =+'06'!D22 -> 133636.25 | I23: =+'07'!D22 -> 978100.91 | J23: =+'08'!D22 -> 838568.94 | K23: =+'09'!D22 -> 983400.33 | L23: =+'10'!D22 -> 936833.08 | M23: =+'11'!D22 -> 730131.14 | N23: =+'12'!D22 -> 80634.75 | O23: =+'13'!D22 -> 110851.5 | P23: =+'14'!D22 -> 821070.08 | Q23: =+'15'!D22 -> 919973.33 | R23: =+'16'!D22 -> 1041912.5 | S23: =+'17'!D22 -> 1010094 | T23: =+'18'!D22 -> 774252.67 | U23: =+'19'!D22 -> 116848.25 | V23: =+'20'!D22 -> 155818 | W23: =+'21'!D22 -> 844824.19 | X23: =+'22'!D22 -> 866438.97 | Y23: =+'23'!D22 -> 794683.45 | Z23: =+'24'!D22 -> 864949.58 | AA23: =+'25'!D22 -> 778999.94 | AB23: =+'26'!D22 -> 161525.5 | AC23: =+'27'!D22 -> 134518.25 | AD23: =+'28'!D22 -> 833059.93 | AE23: =+'29'!D22 -> 856072.97 | AF23: =+'30'!D22 -> 896187.06 | AG23: =+'31'!D22 -> 0 | AH23: =+C23+D23+E23+F23+G23+H23+I23+J23+K23+L23+M23+N23+O23+P23+Q23+R23+S23+T23+U23+V23+W23+X23+Y23+Z23+AA23+AB23+AC23+AD23+AE23+AF23+AG23 -> 21128975 | AJ23: 21128975 | AK23: =+AH23-AJ23 -> 0
B24: ปกส.-OP ต่างเครือข่าย | C24: =+'01'!D23 -> 6699.49 | D24: =+'02'!D23 -> 10215.86 | E24: =+'03'!D23 -> 12373.25 | F24: =+'04'!D23 -> 17662.25 | G24: =+'05'!D23 -> 0 | H24: =+'06'!D23 -> 0 | I24: =+'07'!D23 -> 13612.5 | J24: =+'08'!D23 -> 61550.25 | K24: =+'09'!D23 -> 31911.1 | L24: =+'10'!D23 -> 6565 | M24: =+'11'!D23 -> 15900.5 | N24: =+'12'!D23 -> 8150 | O24: =+'13'!D23 -> 0 | P24: =+'14'!D23 -> 43878.25 | Q24: =+'15'!D23 -> 42419.86 | R24: =+'16'!D23 -> 30094.49 | S24: =+'17'!D23 -> 31606.5 | T24: =+'18'!D23 -> 16069.5 | U24: =+'19'!D23 -> 7070 | V24: =+'20'!D23 -> 0 | W24: =+'21'!D23 -> 47849.25 | X24: =+'22'!D23 -> 67892.24 | Y24: =+'23'!D23 -> 35073.75 | Z24: =+'24'!D23 -> 39028.25 | AA24: =+'25'!D23 -> 28681.5 | AB24: =+'26'!D23 -> 0 | AC24: =+'27'!D23 -> 0 | AD24: =+'28'!D23 -> 9322.25 | AE24: =+'29'!D23 -> 14436.86 | AF24: =+'30'!D23 -> 33006.97 | AG24: =+'31'!D23 -> 0 | AH24: =+C24+D24+E24+F24+G24+H24+I24+J24+K24+L24+M24+N24+O24+P24+Q24+R24+S24+T24+U24+V24+W24+X24+Y24+Z24+AA24+AB24+AC24+AD24+AE24+AF24+AG24 -> 631069.87 | AJ24: 631069.87 | AK24: =+AH24-AJ24 -> 0
B25: ปกส.-72 ชม. ((9.1))((1102050194.306)) | C25: =+'01'!D24 -> 0 | D25: =+'02'!D24 -> 0 | E25: =+'03'!D24 -> 0 | F25: =+'04'!D24 -> 0 | G25: =+'05'!D24 -> 0 | H25: =+'06'!D24 -> 0 | I25: =+'07'!D24 -> 0 | J25: =+'08'!D24 -> 0 | K25: =+'09'!D24 -> 0 | L25: =+'10'!D24 -> 0 | M25: =+'11'!D24 -> 0 | N25: =+'12'!D24 -> 0 | O25: =+'13'!D24 -> 0 | P25: =+'14'!D24 -> 0 | Q25: =+'15'!D24 -> 0 | R25: =+'16'!D24 -> 0 | S25: =+'17'!D24 -> 0 | T25: =+'18'!D24 -> 0 | U25: =+'19'!D24 -> 0 | V25: =+'20'!D24 -> 0 | W25: =+'21'!D24 -> 0 | X25: =+'22'!D24 -> 0 | Y25: =+'23'!D24 -> 0 | Z25: =+'24'!D24 -> 0 | AA25: =+'25'!D24 -> 0 | AB25: =+'26'!D24 -> 0 | AC25: =+'27'!D24 -> 0 | AD25: =+'28'!D24 -> 0 | AE25: =+'29'!D24 -> 0 | AF25: =+'30'!D24 -> 0 | AG25: =+'31'!D24 -> 0 | AH25: =+C25+D25+E25+F25+G25+H25+I25+J25+K25+L25+M25+N25+O25+P25+Q25+R25+S25+T25+U25+V25+W25+X25+Y25+Z25+AA25+AB25+AC25+AD25+AE25+AF25+AG25 -> 0 | AK25: =+AH25-AJ25 -> 0
B26: ปกส.-OP ทุพพลภาพ | C26: =+'01'!D25 -> 0 | D26: =+'02'!D25 -> 0 | E26: =+'03'!D25 -> 0 | F26: =+'04'!D25 -> 0 | G26: =+'05'!D25 -> 0 | H26: =+'06'!D25 -> 0 | I26: =+'07'!D25 -> 0 | J26: =+'08'!D25 -> 0 | K26: =+'09'!D25 -> 0 | L26: =+'10'!D25 -> 0 | M26: =+'11'!D25 -> 0 | N26: =+'12'!D25 -> 0 | O26: =+'13'!D25 -> 0 | P26: =+'14'!D25 -> 0 | Q26: =+'15'!D25 -> 0 | R26: =+'16'!D25 -> 0 | S26: =+'17'!D25 -> 0 | T26: =+'18'!D25 -> 0 | U26: =+'19'!D25 -> 0 | V26: =+'20'!D25 -> 0 | W26: =+'21'!D25 -> 0 | X26: =+'22'!D25 -> 0 | Y26: =+'23'!D25 -> 0 | Z26: =+'24'!D25 -> 0 | AA26: =+'25'!D25 -> 0 | AB26: =+'26'!D25 -> 0 | AC26: =+'27'!D25 -> 0 | AD26: =+'28'!D25 -> 0 | AE26: =+'29'!D25 -> 0 | AF26: =+'30'!D25 -> 0 | AG26: =+'31'!D25 -> 0 | AH26: =+C26+D26+E26+F26+G26+H26+I26+J26+K26+L26+M26+N26+O26+P26+Q26+R26+S26+T26+U26+V26+W26+X26+Y26+Z26+AA26+AB26+AC26+AD26+AE26+AF26+AG26 -> 0 | AK26: =+AH26-AJ26 -> 0
B27: ปกส.-OP คชจ.สูง ((9.1))((1102050194.307)) | C27: =+'01'!D26 -> 9047.5 | D27: =+'02'!D26 -> 7115.5 | E27: =+'03'!D26 -> 2410 | F27: =+'04'!D26 -> 14704.75 | G27: =+'05'!D26 -> 0 | H27: =+'06'!D26 -> 0 | I27: =+'07'!D26 -> 0 | J27: =+'08'!D26 -> 5847.5 | K27: =+'09'!D26 -> 18964 | L27: =+'10'!D26 -> 6296 | M27: =+'11'!D26 -> 3360 | N27: =+'12'!D26 -> 0 | O27: =+'13'!D26 -> 0 | P27: =+'14'!D26 -> 50550 | Q27: =+'15'!D26 -> 27495.5 | R27: =+'16'!D26 -> 25233 | S27: =+'17'!D26 -> 24783.5 | T27: =+'18'!D26 -> 23152 | U27: =+'19'!D26 -> 0 | V27: =+'20'!D26 -> 0 | W27: =+'21'!D26 -> 23897 | X27: =+'22'!D26 -> 55685 | Y27: =+'23'!D26 -> 10895.25 | Z27: =+'24'!D26 -> 3900 | AA27: =+'25'!D26 -> 3542 | AB27: =+'26'!D26 -> 0 | AC27: =+'27'!D26 -> 0 | AD27: =+'28'!D26 -> 4110 | AE27: =+'29'!D26 -> 9267.5 | AF27: =+'30'!D26 -> 32216 | AG27: =+'31'!D26 -> 0 | AH27: =+C27+D27+E27+F27+G27+H27+I27+J27+K27+L27+M27+N27+O27+P27+Q27+R27+S27+T27+U27+V27+W27+X27+Y27+Z27+AA27+AB27+AC27+AD27+AE27+AF27+AG27 -> 362472 | AJ27: 362472 | AK27: =+AH27-AJ27 -> 0
B28: ปกส.-กองทุนทดแทน ((9.1))((1102050194.305)) | C28: =+'01'!D27 -> 4980.5 | D28: =+'02'!D27 -> 664 | E28: =+'03'!D27 -> 2192.5 | F28: =+'04'!D27 -> 1899.25 | G28: =+'05'!D27 -> 0 | H28: =+'06'!D27 -> 0 | I28: =+'07'!D27 -> 1726.5 | J28: =+'08'!D27 -> 1560 | K28: =+'09'!D27 -> 706.5 | L28: =+'10'!D27 -> 944.5 | M28: =+'11'!D27 -> 6848.25 | N28: =+'12'!D27 -> 510 | O28: =+'13'!D27 -> 0 | P28: =+'14'!D27 -> 930 | Q28: =+'15'!D27 -> 201 | R28: =+'16'!D27 -> 217 | S28: =+'17'!D27 -> 1021 | T28: =+'18'!D27 -> 991 | U28: =+'19'!D27 -> 1064 | V28: =+'20'!D27 -> 0 | W28: =+'21'!D27 -> 3625.25 | X28: =+'22'!D27 -> 1483 | Y28: =+'23'!D27 -> 351 | Z28: =+'24'!D27 -> 0 | AA28: =+'25'!D27 -> 1377 | AB28: =+'26'!D27 -> 1574.5 | AC28: =+'27'!D27 -> 150 | AD28: =+'28'!D27 -> 0 | AE28: =+'29'!D27 -> 1013.75 | AF28: =+'30'!D27 -> 369 | AG28: =+'31'!D27 -> 0 | AH28: =+C28+D28+E28+F28+G28+H28+I28+J28+K28+L28+M28+N28+O28+P28+Q28+R28+S28+T28+U28+V28+W28+X28+Y28+Z28+AA28+AB28+AC28+AD28+AE28+AF28+AG28 -> 36399.5 | AJ28: 36399.5 | AK28: =+AH28-AJ28 -> 0
A29: 11 | B29: ปกส.-IP ในเครือข่าย (( 9.2)) | C29: =+'01'!D28 -> 1098330.9 | D29: =+'02'!D28 -> 430639.9 | E29: =+'03'!D28 -> 1498993.2 | F29: =+'04'!D28 -> 862996.33 | G29: =+'05'!D28 -> 1344580.4 | H29: =+'06'!D28 -> 1667736.1 | I29: =+'07'!D28 -> 771498.1 | J29: =+'08'!D28 -> 852919.58 | K29: =+'09'!D28 -> 698918.18 | L29: =+'10'!D28 -> 642768.02 | M29: =+'11'!D28 -> 718547.52 | N29: =+'12'!D28 -> 1426684.1 | O29: =+'13'!D28 -> 632274.63 | P29: =+'14'!D28 -> 494504.48 | Q29: =+'15'!D28 -> 958032.57 | R29: =+'16'!D28 -> 834777.44 | S29: =+'17'!D28 -> 1136339.2 | T29: =+'18'!D28 -> 697927.35 | U29: =+'19'!D28 -> 733162.47 | V29: =+'20'!D28 -> 456264.88 | W29: =+'21'!D28 -> 668477.11 | X29: =+'22'!D28 -> 290191.33 | Y29: =+'23'!D28 -> 1031923 | Z29: =+'24'!D28 -> 758848.19 | AA29: =+'25'!D28 -> 552103.74 | AB29: =+'26'!D28 -> 743753.97 | AC29: =+'27'!D28 -> 731220.36 | AD29: =+'28'!D28 -> 525262.48 | AE29: =+'29'!D28 -> 508752.27 | AF29: =+'30'!D28 -> 903954.85 | AG29: =+'31'!D28 -> 0 | AH29: =+C29+D29+E29+F29+G29+H29+I29+J29+K29+L29+M29+N29+O29+P29+Q29+R29+S29+T29+U29+V29+W29+X29+Y29+Z29+AA29+AB29+AC29+AD29+AE29+AF29+AG29 -> 24672383 | AJ29: 24672383 | AK29: =+AH29-AJ29 -> 0
B30: ปกส.-IP ต่างเครือข่าย | C30: =+'01'!D29 -> 282249.6 | D30: =+'02'!D29 -> 104949 | E30: =+'03'!D29 -> 48009.5 | F30: =+'04'!D29 -> 725753.17 | G30: =+'05'!D29 -> 73593.25 | H30: =+'06'!D29 -> 106301.5 | I30: =+'07'!D29 -> 32986.25 | J30: =+'08'!D29 -> 127695.47 | K30: =+'09'!D29 -> 23367.5 | L30: =+'10'!D29 -> 81201.25 | M30: =+'11'!D29 -> 86994 | N30: =+'12'!D29 -> 49087.25 | O30: =+'13'!D29 -> 69711.29 | P30: =+'14'!D29 -> 0 | Q30: =+'15'!D29 -> 14976.25 | R30: =+'16'!D29 -> 64348.32 | S30: =+'17'!D29 -> 91333.47 | T30: =+'18'!D29 -> 97138.5 | U30: =+'19'!D29 -> 1830697.8 | V30: =+'20'!D29 -> 0 | W30: =+'21'!D29 -> 199881.13 | X30: =+'22'!D29 -> 59129.25 | Y30: =+'23'!D29 -> 58291.78 | Z30: =+'24'!D29 -> 0 | AA30: =+'25'!D29 -> 341954.12 | AB30: =+'26'!D29 -> 131622.25 | AC30: =+'27'!D29 -> 58233 | AD30: =+'28'!D29 -> 0 | AE30: =+'29'!D29 -> 0 | AF30: =+'30'!D29 -> 0 | AG30: =+'31'!D29 -> 0 | AH30: =+C30+D30+E30+F30+G30+H30+I30+J30+K30+L30+M30+N30+O30+P30+Q30+R30+S30+T30+U30+V30+W30+X30+Y30+Z30+AA30+AB30+AC30+AD30+AE30+AF30+AG30 -> 4759504.9 | AJ30: 4759504.9 | AK30: =+AH30-AJ30 -> 0
B31: ปกส.-72 ชม. ((9.1))((1102050194.306)) | C31: =+'01'!D30 -> 0 | D31: =+'02'!D30 -> 0 | E31: =+'03'!D30 -> 0 | F31: =+'04'!D30 -> 35573 | G31: =+'05'!D30 -> 11461 | H31: =+'06'!D30 -> 0 | I31: =+'07'!D30 -> 20123 | J31: =+'08'!D30 -> 30908.47 | K31: =+'09'!D30 -> 0 | L31: =+'10'!D30 -> 0 | M31: =+'11'!D30 -> 0 | N31: =+'12'!D30 -> 0 | O31: =+'13'!D30 -> 0 | P31: =+'14'!D30 -> 0 | Q31: =+'15'!D30 -> 0 | R31: =+'16'!D30 -> 32079.75 | S31: =+'17'!D30 -> 0 | T31: =+'18'!D30 -> 0 | U31: =+'19'!D30 -> 104586.97 | V31: =+'20'!D30 -> 0 | W31: =+'21'!D30 -> 26825.5 | X31: =+'22'!D30 -> 43613.91 | Y31: =+'23'!D30 -> 23917.75 | Z31: =+'24'!D30 -> 0 | AA31: =+'25'!D30 -> 36809.5 | AB31: =+'26'!D30 -> 0 | AC31: =+'27'!D30 -> 124932 | AD31: =+'28'!D30 -> 39725.25 | AE31: =+'29'!D30 -> 196051.1 | AF31: =+'30'!D30 -> 0 | AG31: =+'31'!D30 -> 0 | AH31: =+C31+D31+E31+F31+G31+H31+I31+J31+K31+L31+M31+N31+O31+P31+Q31+R31+S31+T31+U31+V31+W31+X31+Y31+Z31+AA31+AB31+AC31+AD31+AE31+AF31+AG31 -> 726607.2 | AJ31: 726607.2 | AK31: =+AH31-AJ31 -> 0
B32: ปกส.-IP คชจ.สูง ((9.1))((1102050194.307)) | C32: =+'01'!D31 -> 0 | D32: =+'02'!D31 -> 11313.75 | E32: =+'03'!D31 -> 0 | F32: =+'04'!D31 -> 0 | G32: =+'05'!D31 -> 0 | H32: =+'06'!D31 -> 0 | I32: =+'07'!D31 -> 0 | J32: =+'08'!D31 -> 0 | K32: =+'09'!D31 -> 0 | L32: =+'10'!D31 -> 0 | M32: =+'11'!D31 -> 0 | N32: =+'12'!D31 -> 0 | O32: =+'13'!D31 -> 0 | P32: =+'14'!D31 -> 0 | Q32: =+'15'!D31 -> 0 | R32: =+'16'!D31 -> 0 | S32: =+'17'!D31 -> 0 | T32: =+'18'!D31 -> 44064.25 | U32: =+'19'!D31 -> 0 | V32: =+'20'!D31 -> 0 | W32: =+'21'!D31 -> 0 | X32: =+'22'!D31 -> 0 | Y32: =+'23'!D31 -> 21918.5 | Z32: =+'24'!D31 -> 0 | AA32: =+'25'!D31 -> 0 | AB32: =+'26'!D31 -> 0 | AC32: =+'27'!D31 -> 0 | AD32: =+'28'!D31 -> 0 | AE32: =+'29'!D31 -> 0 | AF32: =+'30'!D31 -> 0 | AG32: =+'31'!D31 -> 0 | AH32: =+C32+D32+E32+F32+G32+H32+I32+J32+K32+L32+M32+N32+O32+P32+Q32+R32+S32+T32+U32+V32+W32+X32+Y32+Z32+AA32+AB32+AC32+AD32+AE32+AF32+AG32 -> 77296.5 | AJ32: 77296.5 | AK32: =+AH32-AJ32 -> 0
B33: ปกส.-กองทุนทดแทน ((9.1))((1102050194.305)) | C33: =+'01'!D32 -> 0 | D33: =+'02'!D32 -> 78269.75 | E33: =+'03'!D32 -> 0 | F33: =+'04'!D32 -> 25216.54 | G33: =+'05'!D32 -> 0 | H33: =+'06'!D32 -> 0 | I33: =+'07'!D32 -> 0 | J33: =+'08'!D32 -> 0 | K33: =+'09'!D32 -> 0 | L33: =+'10'!D32 -> 0 | M33: =+'11'!D32 -> 0 | N33: =+'12'!D32 -> 0 | O33: =+'13'!D32 -> 0 | P33: =+'14'!D32 -> 0 | Q33: =+'15'!D32 -> 0 | R33: =+'16'!D32 -> 0 | S33: =+'17'!D32 -> 0 | T33: =+'18'!D32 -> 0 | U33: =+'19'!D32 -> 0 | V33: =+'20'!D32 -> 0 | W33: =+'21'!D32 -> 0 | X33: =+'22'!D32 -> 0 | Y33: =+'23'!D32 -> 0 | Z33: =+'24'!D32 -> 0 | AA33: =+'25'!D32 -> 0 | AB33: =+'26'!D32 -> 0 | AC33: =+'27'!D32 -> 0 | AD33: =+'28'!D32 -> 0 | AE33: =+'29'!D32 -> 0 | AF33: =+'30'!D32 -> 0 | AG33: =+'31'!D32 -> 0 | AH33: =+C33+D33+E33+F33+G33+H33+I33+J33+K33+L33+M33+N33+O33+P33+Q33+R33+S33+T33+U33+V33+W33+X33+Y33+Z33+AA33+AB33+AC33+AD33+AE33+AF33+AG33 -> 103486.29 | AJ33: 103486.29 | AK33: =+AH33-AJ33 -> 0
A34: 12 | B34: UC OP ใน CUP ((10.5)) | C34: =+'01'!D33 -> 1222242.4 | D34: =+'02'!D33 -> 1266343.8 | E34: =+'03'!D33 -> 1167566.6 | F34: =+'04'!D33 -> 1112166.1 | G34: =+'05'!D33 -> 244067.75 | H34: =+'06'!D33 -> 124433.5 | I34: =+'07'!D33 -> 1387628.5 | J34: =+'08'!D33 -> 1241451.9 | K34: =+'09'!D33 -> 1462710.2 | L34: =+'10'!D33 -> 1366664.1 | M34: =+'11'!D33 -> 1122964.6 | N34: =+'12'!D33 -> 228290 | O34: =+'13'!D33 -> 205904.75 | P34: =+'14'!D33 -> 1440432.4 | Q34: =+'15'!D33 -> 1353671.4 | R34: =+'16'!D33 -> 1485180.7 | S34: =+'17'!D33 -> 1556664.7 | T34: =+'18'!D33 -> 1007904.3 | U34: =+'19'!D33 -> 202677.25 | V34: =+'20'!D33 -> 212405.5 | W34: =+'21'!D33 -> 1227861.1 | X34: =+'22'!D33 -> 1355179.2 | Y34: =+'23'!D33 -> 1323939.4 | Z34: =+'24'!D33 -> 1324815.6 | AA34: =+'25'!D33 -> 1111569.3 | AB34: =+'26'!D33 -> 205101.25 | AC34: =+'27'!D33 -> 236420.25 | AD34: =+'28'!D33 -> 1386783.9 | AE34: =+'29'!D33 -> 1252206.7 | AF34: =+'30'!D33 -> 1381736.3 | AG34: =+'31'!D33 -> 0 | AH34: =+C34+D34+E34+F34+G34+H34+I34+J34+K34+L34+M34+N34+O34+P34+Q34+R34+S34+T34+U34+V34+W34+X34+Y34+Z34+AA34+AB34+AC34+AD34+AE34+AF34+AG34 -> 30216983 | AJ34: 30216983 | AK34: =+AH34-AJ34 -> 0
B35: UC OP นอก CUP ใน จ.(สธ) - รพ.ป่าตอง,ฉลอง,ถลาง ((10.6)) | C35: =+'01'!D34 -> 370752.2 | D35: =+'02'!D34 -> 615414.86 | E35: =+'03'!D34 -> 674531.67 | F35: =+'04'!D34 -> 529573.55 | G35: =+'05'!D34 -> 61069 | H35: =+'06'!D34 -> 116071.5 | I35: =+'07'!D34 -> 570201.81 | J35: =+'08'!D34 -> 638330.57 | K35: =+'09'!D34 -> 611267.23 | L35: =+'10'!D34 -> 658466.92 | M35: =+'11'!D34 -> 412806.98 | N35: =+'12'!D34 -> 106269.5 | O35: =+'13'!D34 -> 55080.75 | P35: =+'14'!D34 -> 609629.16 | Q35: =+'15'!D34 -> 505068.73 | R35: =+'16'!D34 -> 602301.31 | S35: =+'17'!D34 -> 669072.28 | T35: =+'18'!D34 -> 598318.42 | U35: =+'19'!D34 -> 81474.25 | V35: =+'20'!D34 -> 70002.25 | W35: =+'21'!D34 -> 616941.34 | X35: =+'22'!D34 -> 576801.07 | Y35: =+'23'!D34 -> 517843.73 | Z35: =+'24'!D34 -> 587589.34 | AA35: =+'25'!D34 -> 355310.23 | AB35: =+'26'!D34 -> 104979.25 | AC35: =+'27'!D34 -> 46996.5 | AD35: =+'28'!D34 -> 556134.07 | AE35: =+'29'!D34 -> 587044.44 | AF35: =+'30'!D34 -> 498708.05 | AG35: =+'31'!D34 -> 0 | AH35: =+C35+D35+E35+F35+G35+H35+I35+J35+K35+L35+M35+N35+O35+P35+Q35+R35+S35+T35+U35+V35+W35+X35+Y35+Z35+AA35+AB35+AC35+AD35+AE35+AF35+AG35 -> 13004051 | AJ35: 13004051 | AK35: =+AH35-AJ35 -> 0
