Workbook

Sheet แยกประเภทเงินบำรุงศูนย์แพทย 
A1: แยกประเภทเงินบำรุง - ศูนย์แพทย์ศาสตร์ชั้นคลีนิค
A2: ประจำเดือน ตุลาคม 2568
A4: พ.ศ. | B4: 45931 | C4: ที่ | D4: เลขที่เช็ค | E4: รายการ | F4: บริษัท/ห้าง/ร้าน/บุคคล | G4: เดบิต | H4: เครดิต | I4: ยอดคงเหลือ
A5: เดือน | B5: วันที่ | C5: เอกสาร
A6: 44105 | E6: ยอดยกมา | I6: 17088815
E7: รวมประจำเดือน | G7: 0 | H7: 0 | I7: =+I6 -> 17088815
A9: แยกประเภทเงินบำรุง - ศูนย์แพทย์ศาสตร์ชั้นคลีนิค
A10: ประจำเดือน พฤศจิกายน 2568
A12: พ.ศ. | B12: 45931 | C12: ที่ | D12: เลขที่เช็ค | E12: รายการ | F12: บริษัท/ห้าง/ร้าน/บุคคล | G12: เดบิต | H12: เครดิต | I12: ยอดคงเหลือ
A13: เดือน | B13: วันที่ | C13: เอกสาร
A14: พ.ย. | E14: ยอดยกมา | G14: 0 | H14: 0 | I14: 17088815
E15: รวมประจำปี | G15: 0 | H15: 0 | I15: 17088815 | J15: =+#REF!-I15 -> #REF! | K15: =85.67+85.67 -> 171.34
A17: แยกประเภทเงินบำรุง - ศูนย์แพทย์ศาสตร์ชั้นคลีนิค
A18: ประจำเดือน ธันวาคม 2568
A20: พ.ศ. | B20: 45931 | C20: ที่ | D20: เลขที่เช็ค | E20: รายการ | F20: บริษัท/ห้าง/ร้าน/บุคคล | G20: เดบิต | H20: เครดิต | I20: ยอดคงเหลือ
A21: เดือน | B21: วันที่ | C21: เอกสาร
A22: ธ.ค. | E22: ยอดยกมา | G22: 0 | H22: 0 | I22: 17088815
B23: 4 | C23: OE6900636 | D23: 10718730 | E23: ค่าซ่อมน้ำรั่วห้องพักนักศึกษาแพทย์ | F23: นางสาววิชชุกร วิเชียรธร | G23: 41827.5
C24: JV68120003 | E24: ภาษี | G24: 422.5
B25: 23 | C25: OE6900714 | D25: 10718731 | E25: ค่าติดตั้งเหล็กกันตก ค่าติดตั้งกันสาดหน้าต่าง | F25: นางสาววิชชุกร วิเชียรธร | G25: 117290.25
C26: JV681223007 | E26: ภาษี | G26: 1184.75
C27: OE6900715 | E27: ค่ากำจัดปลวก | F27: บจก.ไทยซัคเซสโซลูชั่น | G27: 9080.99
C28: JV681223008 | E28: ภาษี | G28: 85.67
C29: OE6900716 | E29: ค่ากำจัดปลวก ก.ย.69 | F29: บจก.ไทยซัคเซสโซลูชั่น | G29: 9080.99
C30: JV681223009 | E30: ภาษี | G30: 85.67
C31: OE6900717 | E31: ค่ากำจัดปลวก ต.ค.68 | F31: บจก.ไทยซัคเซสโซลูชั่น | G31: 9080.99
C32: JV681223010 | E32: ภาษี | G32: 85.67
C33: OE6900718 | E33: ค่ากำจัดปลวก พ.ย.68 | F33: บจก.ไทยซัคเซสโซลูชั่น | G33: 9081.23
C34: JV681223001 | E34: ภาษี | G34: 85.67
E35: รวมประจำเดือน | G35: =SUM(G23:G34) -> 197391.88 | H35: =SUM(H23:H34) -> 0 | I35: =+I22+H35-G35 -> 16891423 | K35: =+G24+G26+G28+G30+G32+G34 -> 1949.93
E36: รวมประจำปี | G36: =+G22+G35 -> 197391.88 | H36: =+H22+H35 -> 0 | I36: =+I6+H36-G36 -> 16891423
A38: แยกประเภทเงินบำรุง - ศูนย์แพทย์ศาสตร์ชั้นคลีนิค
A39: ประจำเดือน มกราคม 2569
A41: พ.ศ. | B41: 46296 | C41: ที่ | D41: เลขที่เช็ค | E41: รายการ | F41: บริษัท/ห้าง/ร้าน/บุคคล | G41: เดบิต | H41: เครดิต | I41: ยอดคงเหลือ
A42: เดือน | B42: วันที่ | C42: เอกสาร
A43: ม.ค. | E43: ยอดยกมา | G43: 197391.88 | H43: 0 | I43: 16891423
E44: รวมประจำปี | G44: =+G43 -> 197391.88 | H44: =+H43 -> 0 | I44: 16891423 | J44: =+#REF!-I44 -> #REF!
A46: แยกประเภทเงินบำรุง - ศูนย์แพทย์ศาสตร์ชั้นคลีนิค
A47: ประจำเดือน มีนาคม 2569
A49: พ.ศ. | B49: 46296 | C49: ที่ | D49: เลขที่เช็ค | E49: รายการ | F49: บริษัท/ห้าง/ร้าน/บุคคล | G49: เดบิต | H49: เครดิต | I49: ยอดคงเหลือ
...

Sheet ศูนย์แพทย์เงินบำรุง44-3 รายวัน
A1: เงินฝากธนาคารกระแสรายวัน เลขที่บัญชี 805-6-05844-3
A2: ประจำเดือน ตุลาคม 2568
A4: พ.ศ. | B4: 45931 | C4: ที่ | D4: เลขที่เช็ค | E4: รายการ | F4: บริษัท/ห้าง/ร้าน/บุคคล | G4: เดบิต | H4: เครดิต | I4: ยอดคงเหลือ
A5: เดือน | B5: วันที่ | C5: เอกสาร
A6: 44105 | E6: ยอดยกมา | I6: 17088986
B7: 9 | C7: OE6900067 | E7: ภาษี เดือน ก.ย.68 ภงด.53 | F7: กรมสรรพกร | H7: 171.34
E8: รวมประจำเดือน | G8: =SUM(G7) -> 0 | H8: =SUM(H7) -> 171.34 | I8: =+I6+G8-H8 -> 17088815 | K8: ภาษี ต.ค. 64
E9: รวมประจำปี | G9: =+G8+G6 -> 0 | H9: =+H8+H6 -> 171.34 | I9: =+I6+G9-H9 -> 17088815
A11: เงินฝากธนาคารกระแสรายวัน เลขที่บัญชี 805-6-05844-3
A12: ประจำเดือน พฤศจิกายน 2568
A14: พ.ศ. | B14: 45931 | C14: ที่ | D14: เลขที่เช็ค | E14: รายการ | F14: บริษัท/ห้าง/ร้าน/บุคคล | G14: เดบิต | H14: เครดิต | I14: ยอดคงเหลือ
A15: เดือน | B15: วันที่ | C15: เอกสาร
A16: พ.ย. | E16: ยอดยกมา | G16: 0 | H16: 171.34 | I16: 17088815
E17: รวมประจำปี | G17: 0 | H17: 171.34 | I17: 17088815
A19: เงินฝากธนาคารกระแสรายวัน เลขที่บัญชี 805-6-05844-3
A20: ประจำเดือน ธันวาคม 2568
A22: พ.ศ. | B22: 45931 | C22: ที่ | D22: เลขที่เช็ค | E22: รายการ | F22: บริษัท/ห้าง/ร้าน/บุคคล | G22: เดบิต | H22: เครดิต | I22: ยอดคงเหลือ
A23: เดือน | B23: วันที่ | C23: เอกสาร
A24: ธ.ค. | E24: ยอดยกมา | G24: 0 | H24: 171.34 | I24: 17088815
B25: 4 | C25: OE6900636 | D25: 10718730 | E25: ค่าซ่อมน้ำรั่วห้องพักนักศึกษาแพทย์ | F25: นางสาววิชชุกร วิเชียรธร | H25: 41827.5
B26: 23 | C26: OE6900714 | D26: 10718731 | E26: ค่าติดตั้งเหล็กกันตก ค่าติดตั้งกันสาดหน้าต่าง | F26: นางสาววิชชุกร วิเชียรธร | H26: 117290.25
C27: OE6900715 | E27: ค่ากำจัดปลวก | F27: บจก.ไทยซัคเซสโซลูชั่น | H27: 9080.99
C28: OE6900716 | E28: ค่ากำจัดปลวก ก.ย.69 | F28: บจก.ไทยซัคเซสโซลูชั่น | H28: 9080.99
C29: OE6900717 | E29: ค่ากำจัดปลวก ต.ค.68 | F29: บจก.ไทยซัคเซสโซลูชั่น | H29: 9080.99
C30: OE6900718 | E30: ค่ากำจัดปลวก พ.ย.68 | F30: บจก.ไทยซัคเซสโซลูชั่น | H30: 9081.23
E31: รวมประจำเดือน | G31: =SUM(G25:G30) -> 0 | H31: =SUM(H25:H30) -> 195441.95 | I31: =+I24-H31 -> 16893373
E32: รวมประจำปี | G32: =+G24+G31 -> 0 | H32: =+H24+H31 -> 195613.29 | I32: =+I6+G32-H32 -> 16893373
A34: เงินฝากธนาคารกระแสรายวัน เลขที่บัญชี 805-6-05844-3
A35: ประจำเดือน มกราคม 2569
A37: พ.ศ. | B37: 46296 | C37: ที่ | D37: เลขที่เช็ค | E37: รายการ | F37: บริษัท/ห้าง/ร้าน/บุคคล | G37: เดบิต | H37: เครดิต | I37: ยอดคงเหลือ
A38: เดือน | B38: วันที่ | C38: เอกสาร
A39: ม.ค. | E39: ยอดยกมา | G39: 0 | H39: 195613.29 | I39: 16893373
B40: 9 | C40: OE6900946 | E40: ภาษี เดือน ธ.ค.68 ภงด.53 | F40: กรมสรรพกร | H40: 342.68
C41: OE6900947 | E41: ภาษี เดือน ธ.ค.68 ภงด.54 | F41: กรมสรรพกร | H41: 1607.25
E42: รวมประจำเดือน | G42: =SUM(G40:G41) -> 0 | H42: =SUM(H40:H41) -> 1949.93 | I42: =+I39+G42-H42 -> 16891423
E43: รวมประจำปี | G43: =+G39+G42 -> 0 | H43: =+H39+H42 -> 197563.22 | I43: =+I6+G43-H43 -> 16891423 | J43: =+I42-I43 -> 0
A45: เงินฝากธนาคารกระแสรายวัน เลขที่บัญชี 805-6-05844-3
A46: ประจำเดือน มีนาคม 2569
A48: พ.ศ. | B48: 46296 | C48: ที่ | D48: เลขที่เช็ค | E48: รายการ | F48: บริษัท/ห้าง/ร้าน/บุคคล | G48: เดบิต | H48: เครดิต | I48: ยอดคงเหลือ
A49: เดือน | B49: วันที่ | C49: เอกสาร
...
